package com.gildedgames.the_aether.world.dungeon.osmium;

import java.util.Random;

import com.gildedgames.the_aether.blocks.BlocksAether;

import net.minecraft.block.Block;
import net.minecraft.world.World;
import net.minecraft.world.gen.feature.WorldGenerator;

public class OsmiumDungeonGen20 extends WorldGenerator {

	public OsmiumDungeonGen20() {

	}
	
	public boolean generate(final World world, final Random random, final int i, final int j, final int k) {
		
		world.setBlock(i + 28, j + 57, k + 31, placeBuildingBlock(random), 0, 2);
		world.setBlock(i + 32, j + 57, k + 31, placeBuildingBlock(random), 0, 2);
		world.setBlock(i + 46, j + 57, k + 31, placeBuildingBlock(random), 0, 2);
		world.setBlock(i + 50, j + 57, k + 31, placeBuildingBlock(random), 0, 2);
		world.setBlock(i + 51, j + 57, k + 31, placeBuildingBlock(random), 0, 2);
		world.setBlock(i + 26, j + 57, k + 32, placeBuildingBlock(random), 0, 2);
		world.setBlock(i + 27, j + 57, k + 32, placeBuildingBlock(random), 0, 2);
		world.setBlock(i + 31, j + 57, k + 32, placeBuildingBlock(random), 0, 2);
		world.setBlock(i + 47, j + 57, k + 32, placeBuildingBlock(random), 0, 2);
		world.setBlock(i + 51, j + 57, k + 32, placeBuildingBlock(random), 0, 2);
		world.setBlock(i + 52, j + 57, k + 32, placeBuildingBlock(random), 0, 2);
		world.setBlock(i + 25, j + 57, k + 33, placeBuildingBlock(random), 0, 2);
		world.setBlock(i + 26, j + 57, k + 33, placeBuildingBlock(random), 0, 2);
		world.setBlock(i + 30, j + 57, k + 33, placeBuildingBlock(random), 0, 2);
		world.setBlock(i + 48, j + 57, k + 33, placeBuildingBlock(random), 0, 2);
		world.setBlock(i + 52, j + 57, k + 33, placeBuildingBlock(random), 0, 2);
		world.setBlock(i + 53, j + 57, k + 33, placeBuildingBlock(random), 0, 2);
		world.setBlock(i + 24, j + 57, k + 34, placeBuildingBlock(random), 0, 2);
		world.setBlock(i + 25, j + 57, k + 34, placeBuildingBlock(random), 0, 2);
		world.setBlock(i + 29, j + 57, k + 34, placeBuildingBlock(random), 0, 2);
		world.setBlock(i + 49, j + 57, k + 34, placeBuildingBlock(random), 0, 2);
		world.setBlock(i + 53, j + 57, k + 34, placeBuildingBlock(random), 0, 2);
		world.setBlock(i + 54, j + 57, k + 34, placeBuildingBlock(random), 0, 2);
		world.setBlock(i + 23, j + 57, k + 35, placeBuildingBlock(random), 0, 2);
		world.setBlock(i + 24, j + 57, k + 35, placeBuildingBlock(random), 0, 2);
		world.setBlock(i + 28, j + 57, k + 35, placeBuildingBlock(random), 0, 2);
		world.setBlock(i + 50, j + 57, k + 35, placeBuildingBlock(random), 0, 2);
		world.setBlock(i + 54, j + 57, k + 35, placeBuildingBlock(random), 0, 2);
		world.setBlock(i + 55, j + 57, k + 35, placeBuildingBlock(random), 0, 2);
		world.setBlock(i + 22, j + 57, k + 36, placeBuildingBlock(random), 0, 2);
		world.setBlock(i + 23, j + 57, k + 36, placeBuildingBlock(random), 0, 2);
		world.setBlock(i + 27, j + 57, k + 36, placeBuildingBlock(random), 0, 2);
		world.setBlock(i + 51, j + 57, k + 36, placeBuildingBlock(random), 0, 2);
		world.setBlock(i + 55, j + 57, k + 36, placeBuildingBlock(random), 0, 2);
		world.setBlock(i + 56, j + 57, k + 36, placeBuildingBlock(random), 0, 2);
		world.setBlock(i + 21, j + 57, k + 37, placeBuildingBlock(random), 0, 2);
		world.setBlock(i + 22, j + 57, k + 37, placeBuildingBlock(random), 0, 2);
		world.setBlock(i + 26, j + 57, k + 37, placeBuildingBlock(random), 0, 2);
		world.setBlock(i + 52, j + 57, k + 37, BlocksAether.locked_creeping_stone, 0, 2);
		world.setBlock(i + 53, j + 57, k + 37, placeBuildingBlock(random), 0, 2);
		world.setBlock(i + 56, j + 57, k + 37, placeBuildingBlock(random), 0, 2);
		world.setBlock(i + 57, j + 57, k + 37, placeBuildingBlock(random), 0, 2);
		world.setBlock(i + 20, j + 57, k + 38, placeBuildingBlock(random), 0, 2);
		world.setBlock(i + 21, j + 57, k + 38, placeBuildingBlock(random), 0, 2);
		world.setBlock(i + 25, j + 57, k + 38, placeBuildingBlock(random), 0, 2);
		world.setBlock(i + 26, j + 57, k + 38, placeBuildingBlock(random), 0, 2);
		world.setBlock(i + 39, j + 57, k + 38, BlocksAether.divine_oak_fence, 0, 2);
		world.setBlock(i + 52, j + 57, k + 38, placeBuildingBlock(random), 0, 2);
		world.setBlock(i + 53, j + 57, k + 38, placeBuildingBlock(random), 0, 2);
		world.setBlock(i + 57, j + 57, k + 38, placeBuildingBlock(random), 0, 2);
		world.setBlock(i + 58, j + 57, k + 38, placeBuildingBlock(random), 0, 2);
		world.setBlock(i + 21, j + 57, k + 39, placeBuildingBlock(random), 0, 2);
		world.setBlock(i + 22, j + 57, k + 39, placeBuildingBlock(random), 0, 2);
		world.setBlock(i + 26, j + 57, k + 39, placeBuildingBlock(random), 0, 2);
		world.setBlock(i + 52, j + 57, k + 39, placeBuildingBlock(random), 0, 2);
		world.setBlock(i + 53, j + 57, k + 39, placeBuildingBlock(random), 0, 2);
		world.setBlock(i + 56, j + 57, k + 39, placeBuildingBlock(random), 0, 2);
		world.setBlock(i + 57, j + 57, k + 39, placeBuildingBlock(random), 0, 2);
		world.setBlock(i + 22, j + 57, k + 40, placeBuildingBlock(random), 0, 2);
		world.setBlock(i + 23, j + 57, k + 40, placeBuildingBlock(random), 0, 2);
		world.setBlock(i + 27, j + 57, k + 40, placeBuildingBlock(random), 0, 2);
		world.setBlock(i + 51, j + 57, k + 40, placeBuildingBlock(random), 0, 2);
		world.setBlock(i + 55, j + 57, k + 40, placeBuildingBlock(random), 0, 2);
		world.setBlock(i + 56, j + 57, k + 40, placeBuildingBlock(random), 0, 2);
		world.setBlock(i + 23, j + 57, k + 41, placeBuildingBlock(random), 0, 2);
		world.setBlock(i + 24, j + 57, k + 41, placeBuildingBlock(random), 0, 2);
		world.setBlock(i + 28, j + 57, k + 41, placeBuildingBlock(random), 0, 2);
		world.setBlock(i + 50, j + 57, k + 41, placeBuildingBlock(random), 0, 2);
		world.setBlock(i + 54, j + 57, k + 41, placeBuildingBlock(random), 0, 2);
		world.setBlock(i + 55, j + 57, k + 41, placeBuildingBlock(random), 0, 2);
		world.setBlock(i + 24, j + 57, k + 42, placeBuildingBlock(random), 0, 2);
		world.setBlock(i + 25, j + 57, k + 42, placeBuildingBlock(random), 0, 2);
		world.setBlock(i + 29, j + 57, k + 42, placeBuildingBlock(random), 0, 2);
		world.setBlock(i + 49, j + 57, k + 42, placeBuildingBlock(random), 0, 2);
		world.setBlock(i + 53, j + 57, k + 42, placeBuildingBlock(random), 0, 2);
		world.setBlock(i + 54, j + 57, k + 42, placeBuildingBlock(random), 0, 2);
		world.setBlock(i + 25, j + 57, k + 43, placeBuildingBlock(random), 0, 2);
		world.setBlock(i + 26, j + 57, k + 43, placeBuildingBlock(random), 0, 2);
		world.setBlock(i + 30, j + 57, k + 43, placeBuildingBlock(random), 0, 2);
		world.setBlock(i + 48, j + 57, k + 43, placeBuildingBlock(random), 0, 2);
		world.setBlock(i + 52, j + 57, k + 43, placeBuildingBlock(random), 0, 2);
		world.setBlock(i + 53, j + 57, k + 43, placeBuildingBlock(random), 0, 2);
		world.setBlock(i + 26, j + 57, k + 44, placeBuildingBlock(random), 0, 2);
		world.setBlock(i + 27, j + 57, k + 44, placeBuildingBlock(random), 0, 2);
		world.setBlock(i + 31, j + 57, k + 44, placeBuildingBlock(random), 0, 2);
		world.setBlock(i + 39, j + 57, k + 44, BlocksAether.arctic_glowstone, 0, 2);
		world.setBlock(i + 47, j + 57, k + 44, placeBuildingBlock(random), 0, 2);
		world.setBlock(i + 51, j + 57, k + 44, placeBuildingBlock(random), 0, 2);
		world.setBlock(i + 52, j + 57, k + 44, placeBuildingBlock(random), 0, 2);
		world.setBlock(i + 27, j + 57, k + 45, placeBuildingBlock(random), 0, 2);
		world.setBlock(i + 28, j + 57, k + 45, placeBuildingBlock(random), 0, 2);
		world.setBlock(i + 32, j + 57, k + 45, placeBuildingBlock(random), 0, 2);
		world.setBlock(i + 46, j + 57, k + 45, placeBuildingBlock(random), 0, 2);
		world.setBlock(i + 50, j + 57, k + 45, placeBuildingBlock(random), 0, 2);
		world.setBlock(i + 51, j + 57, k + 45, placeBuildingBlock(random), 0, 2);
		world.setBlock(i + 28, j + 57, k + 46, placeBuildingBlock(random), 0, 2);
		world.setBlock(i + 29, j + 57, k + 46, placeBuildingBlock(random), 0, 2);
		world.setBlock(i + 33, j + 57, k + 46, placeBuildingBlock(random), 0, 2);
		world.setBlock(i + 45, j + 57, k + 46, placeBuildingBlock(random), 0, 2);
		world.setBlock(i + 49, j + 57, k + 46, placeBuildingBlock(random), 0, 2);
		world.setBlock(i + 50, j + 57, k + 46, placeBuildingBlock(random), 0, 2);
		world.setBlock(i + 29, j + 57, k + 47, placeBuildingBlock(random), 0, 2);
		world.setBlock(i + 30, j + 57, k + 47, placeBuildingBlock(random), 0, 2);
		world.setBlock(i + 34, j + 57, k + 47, placeBuildingBlock(random), 0, 2);
		world.setBlock(i + 44, j + 57, k + 47, placeBuildingBlock(random), 0, 2);
		world.setBlock(i + 48, j + 57, k + 47, placeBuildingBlock(random), 0, 2);
		world.setBlock(i + 49, j + 57, k + 47, placeBuildingBlock(random), 0, 2);
		world.setBlock(i + 30, j + 57, k + 48, placeBuildingBlock(random), 0, 2);
		world.setBlock(i + 31, j + 57, k + 48, placeBuildingBlock(random), 0, 2);
		world.setBlock(i + 35, j + 57, k + 48, placeBuildingBlock(random), 0, 2);
		world.setBlock(i + 43, j + 57, k + 48, placeBuildingBlock(random), 0, 2);
		world.setBlock(i + 47, j + 57, k + 48, placeBuildingBlock(random), 0, 2);
		world.setBlock(i + 48, j + 57, k + 48, placeBuildingBlock(random), 0, 2);
		world.setBlock(i + 31, j + 57, k + 49, placeBuildingBlock(random), 0, 2);
		world.setBlock(i + 32, j + 57, k + 49, placeBuildingBlock(random), 0, 2);
		world.setBlock(i + 36, j + 57, k + 49, placeBuildingBlock(random), 0, 2);
		world.setBlock(i + 42, j + 57, k + 49, placeBuildingBlock(random), 0, 2);
		world.setBlock(i + 46, j + 57, k + 49, placeBuildingBlock(random), 0, 2);
		world.setBlock(i + 47, j + 57, k + 49, placeBuildingBlock(random), 0, 2);
		world.setBlock(i + 32, j + 57, k + 50, placeBuildingBlock(random), 0, 2);
		world.setBlock(i + 33, j + 57, k + 50, placeBuildingBlock(random), 0, 2);
		world.setBlock(i + 37, j + 57, k + 50, placeBuildingBlock(random), 0, 2);
		world.setBlock(i + 41, j + 57, k + 50, placeBuildingBlock(random), 0, 2);
		world.setBlock(i + 45, j + 57, k + 50, placeBuildingBlock(random), 0, 2);
		world.setBlock(i + 46, j + 57, k + 50, placeBuildingBlock(random), 0, 2);
		world.setBlock(i + 33, j + 57, k + 51, placeBuildingBlock(random), 0, 2);
		world.setBlock(i + 34, j + 57, k + 51, placeBuildingBlock(random), 0, 2);
		world.setBlock(i + 38, j + 57, k + 51, placeBuildingBlock(random), 0, 2);
		world.setBlock(i + 39, j + 57, k + 51, placeBuildingBlock(random), 0, 2);
		world.setBlock(i + 40, j + 57, k + 51, placeBuildingBlock(random), 0, 2);
		world.setBlock(i + 44, j + 57, k + 51, placeBuildingBlock(random), 0, 2);
		world.setBlock(i + 45, j + 57, k + 51, placeBuildingBlock(random), 0, 2);
		world.setBlock(i + 34, j + 57, k + 52, placeBuildingBlock(random), 0, 2);
		world.setBlock(i + 35, j + 57, k + 52, placeBuildingBlock(random), 0, 2);
		world.setBlock(i + 39, j + 57, k + 52, placeBuildingBlock(random), 0, 2);
		world.setBlock(i + 43, j + 57, k + 52, placeBuildingBlock(random), 0, 2);
		world.setBlock(i + 44, j + 57, k + 52, placeBuildingBlock(random), 0, 2);
		world.setBlock(i + 35, j + 57, k + 53, placeBuildingBlock(random), 0, 2);
		world.setBlock(i + 36, j + 57, k + 53, placeBuildingBlock(random), 0, 2);
		world.setBlock(i + 42, j + 57, k + 53, placeBuildingBlock(random), 0, 2);
		world.setBlock(i + 43, j + 57, k + 53, placeBuildingBlock(random), 0, 2);
		world.setBlock(i + 36, j + 57, k + 54, placeBuildingBlock(random), 0, 2);
		world.setBlock(i + 37, j + 57, k + 54, placeBuildingBlock(random), 0, 2);
		world.setBlock(i + 41, j + 57, k + 54, placeBuildingBlock(random), 0, 2);
		world.setBlock(i + 42, j + 57, k + 54, placeBuildingBlock(random), 0, 2);
		world.setBlock(i + 37, j + 57, k + 55, placeBuildingBlock(random), 0, 2);
		world.setBlock(i + 38, j + 57, k + 55, placeBuildingBlock(random), 0, 2);
		world.setBlock(i + 40, j + 57, k + 55, placeBuildingBlock(random), 0, 2);
		world.setBlock(i + 41, j + 57, k + 55, placeBuildingBlock(random), 0, 2);
		world.setBlock(i + 38, j + 57, k + 56, placeBuildingBlock(random), 0, 2);
		world.setBlock(i + 39, j + 57, k + 56, placeBuildingBlock(random), 0, 2);
		world.setBlock(i + 40, j + 57, k + 56, placeBuildingBlock(random), 0, 2);
		world.setBlock(i + 39, j + 57, k + 57, placeBuildingBlock(random), 0, 2);
		world.setBlock(i + 39, j + 58, k + 21, placeBuildingBlock(random), 0, 2);
		world.setBlock(i + 38, j + 58, k + 22, placeBuildingBlock(random), 0, 2);
		world.setBlock(i + 39, j + 58, k + 22, placeBuildingBlock(random), 0, 2);
		world.setBlock(i + 40, j + 58, k + 22, placeBuildingBlock(random), 0, 2);
		world.setBlock(i + 37, j + 58, k + 23, placeBuildingBlock(random), 0, 2);
		world.setBlock(i + 38, j + 58, k + 23, placeBuildingBlock(random), 0, 2);
		world.setBlock(i + 40, j + 58, k + 23, placeBuildingBlock(random), 0, 2);
		world.setBlock(i + 41, j + 58, k + 23, placeBuildingBlock(random), 0, 2);
		world.setBlock(i + 36, j + 58, k + 24, placeBuildingBlock(random), 0, 2);
		world.setBlock(i + 37, j + 58, k + 24, placeBuildingBlock(random), 0, 2);
		world.setBlock(i + 39, j + 58, k + 24, placeBuildingBlock(random), 0, 2);
		world.setBlock(i + 41, j + 58, k + 24, placeBuildingBlock(random), 0, 2);
		world.setBlock(i + 42, j + 58, k + 24, placeBuildingBlock(random), 0, 2);
		world.setBlock(i + 35, j + 58, k + 25, placeBuildingBlock(random), 0, 2);
		world.setBlock(i + 36, j + 58, k + 25, placeBuildingBlock(random), 0, 2);
		world.setBlock(i + 38, j + 58, k + 25, placeBuildingBlock(random), 0, 2);
		world.setBlock(i + 39, j + 58, k + 25, placeBuildingBlock(random), 0, 2);
		world.setBlock(i + 40, j + 58, k + 25, placeBuildingBlock(random), 0, 2);
		world.setBlock(i + 42, j + 58, k + 25, placeBuildingBlock(random), 0, 2);
		world.setBlock(i + 43, j + 58, k + 25, placeBuildingBlock(random), 0, 2);
		world.setBlock(i + 34, j + 58, k + 26, placeBuildingBlock(random), 0, 2);
		world.setBlock(i + 35, j + 58, k + 26, placeBuildingBlock(random), 0, 2);
		world.setBlock(i + 37, j + 58, k + 26, placeBuildingBlock(random), 0, 2);
		world.setBlock(i + 41, j + 58, k + 26, placeBuildingBlock(random), 0, 2);
		world.setBlock(i + 43, j + 58, k + 26, placeBuildingBlock(random), 0, 2);
		world.setBlock(i + 44, j + 58, k + 26, placeBuildingBlock(random), 0, 2);
		world.setBlock(i + 33, j + 58, k + 27, placeBuildingBlock(random), 0, 2);
		world.setBlock(i + 34, j + 58, k + 27, placeBuildingBlock(random), 0, 2);
		world.setBlock(i + 36, j + 58, k + 27, placeBuildingBlock(random), 0, 2);
		world.setBlock(i + 42, j + 58, k + 27, placeBuildingBlock(random), 0, 2);
		world.setBlock(i + 44, j + 58, k + 27, placeBuildingBlock(random), 0, 2);
		world.setBlock(i + 45, j + 58, k + 27, placeBuildingBlock(random), 0, 2);
		world.setBlock(i + 32, j + 58, k + 28, placeBuildingBlock(random), 0, 2);
		world.setBlock(i + 33, j + 58, k + 28, placeBuildingBlock(random), 0, 2);
		world.setBlock(i + 35, j + 58, k + 28, placeBuildingBlock(random), 0, 2);
		world.setBlock(i + 43, j + 58, k + 28, placeBuildingBlock(random), 0, 2);
		world.setBlock(i + 45, j + 58, k + 28, placeBuildingBlock(random), 0, 2);
		world.setBlock(i + 46, j + 58, k + 28, placeBuildingBlock(random), 0, 2);
		world.setBlock(i + 31, j + 58, k + 29, placeBuildingBlock(random), 0, 2);
		world.setBlock(i + 32, j + 58, k + 29, placeBuildingBlock(random), 0, 2);
		world.setBlock(i + 34, j + 58, k + 29, placeBuildingBlock(random), 0, 2);
		world.setBlock(i + 44, j + 58, k + 29, placeBuildingBlock(random), 0, 2);
		world.setBlock(i + 46, j + 58, k + 29, placeBuildingBlock(random), 0, 2);
		world.setBlock(i + 47, j + 58, k + 29, placeBuildingBlock(random), 0, 2);
		world.setBlock(i + 30, j + 58, k + 30, placeBuildingBlock(random), 0, 2);
		world.setBlock(i + 31, j + 58, k + 30, placeBuildingBlock(random), 0, 2);
		world.setBlock(i + 33, j + 58, k + 30, placeBuildingBlock(random), 0, 2);
		world.setBlock(i + 39, j + 58, k + 30, BlocksAether.divine_oak_fence, 0, 2);
		world.setBlock(i + 45, j + 58, k + 30, placeBuildingBlock(random), 0, 2);
		world.setBlock(i + 47, j + 58, k + 30, placeBuildingBlock(random), 0, 2);
		world.setBlock(i + 48, j + 58, k + 30, placeBuildingBlock(random), 0, 2);
		world.setBlock(i + 29, j + 58, k + 31, placeBuildingBlock(random), 0, 2);
		world.setBlock(i + 30, j + 58, k + 31, placeBuildingBlock(random), 0, 2);
		world.setBlock(i + 32, j + 58, k + 31, placeBuildingBlock(random), 0, 2);
		world.setBlock(i + 46, j + 58, k + 31, placeBuildingBlock(random), 0, 2);
		world.setBlock(i + 48, j + 58, k + 31, placeBuildingBlock(random), 0, 2);
		world.setBlock(i + 49, j + 58, k + 31, placeBuildingBlock(random), 0, 2);
		world.setBlock(i + 28, j + 58, k + 32, placeBuildingBlock(random), 0, 2);
		world.setBlock(i + 29, j + 58, k + 32, placeBuildingBlock(random), 0, 2);
		world.setBlock(i + 31, j + 58, k + 32, placeBuildingBlock(random), 0, 2);
		world.setBlock(i + 47, j + 58, k + 32, placeBuildingBlock(random), 0, 2);
		world.setBlock(i + 49, j + 58, k + 32, placeBuildingBlock(random), 0, 2);
		world.setBlock(i + 50, j + 58, k + 32, placeBuildingBlock(random), 0, 2);
		world.setBlock(i + 27, j + 58, k + 33, placeBuildingBlock(random), 0, 2);
		world.setBlock(i + 28, j + 58, k + 33, placeBuildingBlock(random), 0, 2);
		world.setBlock(i + 30, j + 58, k + 33, placeBuildingBlock(random), 0, 2);
		world.setBlock(i + 48, j + 58, k + 33, placeBuildingBlock(random), 0, 2);
		world.setBlock(i + 50, j + 58, k + 33, placeBuildingBlock(random), 0, 2);
		world.setBlock(i + 51, j + 58, k + 33, placeBuildingBlock(random), 0, 2);
		world.setBlock(i + 26, j + 58, k + 34, placeBuildingBlock(random), 0, 2);
		world.setBlock(i + 27, j + 58, k + 34, placeBuildingBlock(random), 0, 2);
		world.setBlock(i + 29, j + 58, k + 34, placeBuildingBlock(random), 0, 2);
		world.setBlock(i + 49, j + 58, k + 34, placeBuildingBlock(random), 0, 2);
		world.setBlock(i + 51, j + 58, k + 34, placeBuildingBlock(random), 0, 2);
		world.setBlock(i + 52, j + 58, k + 34, placeBuildingBlock(random), 0, 2);
		world.setBlock(i + 25, j + 58, k + 35, placeBuildingBlock(random), 0, 2);
		world.setBlock(i + 26, j + 58, k + 35, placeBuildingBlock(random), 0, 2);
		world.setBlock(i + 28, j + 58, k + 35, placeBuildingBlock(random), 0, 2);
		world.setBlock(i + 50, j + 58, k + 35, placeBuildingBlock(random), 0, 2);
		world.setBlock(i + 52, j + 58, k + 35, placeBuildingBlock(random), 0, 2);
		world.setBlock(i + 53, j + 58, k + 35, placeBuildingBlock(random), 0, 2);
		world.setBlock(i + 24, j + 58, k + 36, placeBuildingBlock(random), 0, 2);
		world.setBlock(i + 25, j + 58, k + 36, placeBuildingBlock(random), 0, 2);
		world.setBlock(i + 27, j + 58, k + 36, placeBuildingBlock(random), 0, 2);
		world.setBlock(i + 51, j + 58, k + 36, placeBuildingBlock(random), 0, 2);
		world.setBlock(i + 53, j + 58, k + 36, placeBuildingBlock(random), 0, 2);
		world.setBlock(i + 54, j + 58, k + 36, placeBuildingBlock(random), 0, 2);
		world.setBlock(i + 23, j + 58, k + 37, placeBuildingBlock(random), 0, 2);
		world.setBlock(i + 24, j + 58, k + 37, placeBuildingBlock(random), 0, 2);
		world.setBlock(i + 26, j + 58, k + 37, placeBuildingBlock(random), 0, 2);
		world.setBlock(i + 52, j + 58, k + 37, placeBuildingBlock(random), 0, 2);
		world.setBlock(i + 53, j + 58, k + 37, placeBuildingBlock(random), 0, 2);
		world.setBlock(i + 54, j + 58, k + 37, placeBuildingBlock(random), 0, 2);
		world.setBlock(i + 55, j + 58, k + 37, placeBuildingBlock(random), 0, 2);
		world.setBlock(i + 22, j + 58, k + 38, placeBuildingBlock(random), 0, 2);
		world.setBlock(i + 23, j + 58, k + 38, placeBuildingBlock(random), 0, 2);
		world.setBlock(i + 25, j + 58, k + 38, placeBuildingBlock(random), 0, 2);
		world.setBlock(i + 26, j + 58, k + 38, placeBuildingBlock(random), 0, 2);
		world.setBlock(i + 39, j + 58, k + 38, BlocksAether.divine_oak_fence, 0, 2);
		world.setBlock(i + 52, j + 58, k + 38, placeBuildingBlock(random), 0, 2);
		world.setBlock(i + 53, j + 58, k + 38, placeBuildingBlock(random), 0, 2);
		world.setBlock(i + 54, j + 58, k + 38, placeBuildingBlock(random), 0, 2);
		world.setBlock(i + 55, j + 58, k + 38, placeBuildingBlock(random), 0, 2);
		world.setBlock(i + 56, j + 58, k + 38, placeBuildingBlock(random), 0, 2);
		world.setBlock(i + 23, j + 58, k + 39, placeBuildingBlock(random), 0, 2);
		world.setBlock(i + 24, j + 58, k + 39, placeBuildingBlock(random), 0, 2);
		world.setBlock(i + 26, j + 58, k + 39, placeBuildingBlock(random), 0, 2);
		world.setBlock(i + 52, j + 58, k + 39, placeBuildingBlock(random), 0, 2);
		world.setBlock(i + 53, j + 58, k + 39, placeBuildingBlock(random), 0, 2);
		world.setBlock(i + 54, j + 58, k + 39, placeBuildingBlock(random), 0, 2);
		world.setBlock(i + 55, j + 58, k + 39, placeBuildingBlock(random), 0, 2);
		world.setBlock(i + 24, j + 58, k + 40, placeBuildingBlock(random), 0, 2);
		world.setBlock(i + 25, j + 58, k + 40, placeBuildingBlock(random), 0, 2);
		world.setBlock(i + 27, j + 58, k + 40, placeBuildingBlock(random), 0, 2);
		world.setBlock(i + 51, j + 58, k + 40, BlocksAether.locked_creeping_stone, 0, 2);
		world.setBlock(i + 53, j + 58, k + 40, placeBuildingBlock(random), 0, 2);
		world.setBlock(i + 54, j + 58, k + 40, placeBuildingBlock(random), 0, 2);
		world.setBlock(i + 25, j + 58, k + 41, placeBuildingBlock(random), 0, 2);
		world.setBlock(i + 26, j + 58, k + 41, placeBuildingBlock(random), 0, 2);
		world.setBlock(i + 28, j + 58, k + 41, placeBuildingBlock(random), 0, 2);
		world.setBlock(i + 50, j + 58, k + 41, placeBuildingBlock(random), 0, 2);
		world.setBlock(i + 52, j + 58, k + 41, placeBuildingBlock(random), 0, 2);
		world.setBlock(i + 53, j + 58, k + 41, placeBuildingBlock(random), 0, 2);
		world.setBlock(i + 26, j + 58, k + 42, placeBuildingBlock(random), 0, 2);
		world.setBlock(i + 27, j + 58, k + 42, placeBuildingBlock(random), 0, 2);
		world.setBlock(i + 29, j + 58, k + 42, placeBuildingBlock(random), 0, 2);
		world.setBlock(i + 49, j + 58, k + 42, placeBuildingBlock(random), 0, 2);
		world.setBlock(i + 51, j + 58, k + 42, placeBuildingBlock(random), 0, 2);
		world.setBlock(i + 52, j + 58, k + 42, placeBuildingBlock(random), 0, 2);
		world.setBlock(i + 27, j + 58, k + 43, placeBuildingBlock(random), 0, 2);
		world.setBlock(i + 28, j + 58, k + 43, placeBuildingBlock(random), 0, 2);
		world.setBlock(i + 30, j + 58, k + 43, placeBuildingBlock(random), 0, 2);
		world.setBlock(i + 48, j + 58, k + 43, placeBuildingBlock(random), 0, 2);
		world.setBlock(i + 50, j + 58, k + 43, placeBuildingBlock(random), 0, 2);
		world.setBlock(i + 51, j + 58, k + 43, placeBuildingBlock(random), 0, 2);
		world.setBlock(i + 28, j + 58, k + 44, placeBuildingBlock(random), 0, 2);
		world.setBlock(i + 29, j + 58, k + 44, placeBuildingBlock(random), 0, 2);
		world.setBlock(i + 31, j + 58, k + 44, placeBuildingBlock(random), 0, 2);
		world.setBlock(i + 39, j + 58, k + 44, BlocksAether.divine_oak_fence, 0, 2);
		world.setBlock(i + 47, j + 58, k + 44, placeBuildingBlock(random), 0, 2);
		world.setBlock(i + 49, j + 58, k + 44, placeBuildingBlock(random), 0, 2);
		world.setBlock(i + 50, j + 58, k + 44, placeBuildingBlock(random), 0, 2);
		world.setBlock(i + 29, j + 58, k + 45, placeBuildingBlock(random), 0, 2);
		world.setBlock(i + 30, j + 58, k + 45, placeBuildingBlock(random), 0, 2);
		world.setBlock(i + 32, j + 58, k + 45, placeBuildingBlock(random), 0, 2);
		world.setBlock(i + 46, j + 58, k + 45, placeBuildingBlock(random), 0, 2);
		world.setBlock(i + 48, j + 58, k + 45, placeBuildingBlock(random), 0, 2);
		world.setBlock(i + 49, j + 58, k + 45, placeBuildingBlock(random), 0, 2);
		world.setBlock(i + 30, j + 58, k + 46, placeBuildingBlock(random), 0, 2);
		world.setBlock(i + 31, j + 58, k + 46, placeBuildingBlock(random), 0, 2);
		world.setBlock(i + 33, j + 58, k + 46, placeBuildingBlock(random), 0, 2);
		world.setBlock(i + 45, j + 58, k + 46, placeBuildingBlock(random), 0, 2);
		world.setBlock(i + 47, j + 58, k + 46, placeBuildingBlock(random), 0, 2);
		world.setBlock(i + 48, j + 58, k + 46, placeBuildingBlock(random), 0, 2);
		world.setBlock(i + 31, j + 58, k + 47, placeBuildingBlock(random), 0, 2);
		world.setBlock(i + 32, j + 58, k + 47, placeBuildingBlock(random), 0, 2);
		world.setBlock(i + 34, j + 58, k + 47, placeBuildingBlock(random), 0, 2);
		world.setBlock(i + 44, j + 58, k + 47, placeBuildingBlock(random), 0, 2);
		world.setBlock(i + 46, j + 58, k + 47, placeBuildingBlock(random), 0, 2);
		world.setBlock(i + 47, j + 58, k + 47, placeBuildingBlock(random), 0, 2);
		world.setBlock(i + 32, j + 58, k + 48, placeBuildingBlock(random), 0, 2);
		world.setBlock(i + 33, j + 58, k + 48, placeBuildingBlock(random), 0, 2);
		world.setBlock(i + 35, j + 58, k + 48, placeBuildingBlock(random), 0, 2);
		world.setBlock(i + 43, j + 58, k + 48, placeBuildingBlock(random), 0, 2);
		world.setBlock(i + 45, j + 58, k + 48, placeBuildingBlock(random), 0, 2);
		world.setBlock(i + 46, j + 58, k + 48, placeBuildingBlock(random), 0, 2);
		world.setBlock(i + 33, j + 58, k + 49, placeBuildingBlock(random), 0, 2);
		world.setBlock(i + 34, j + 58, k + 49, placeBuildingBlock(random), 0, 2);
		world.setBlock(i + 36, j + 58, k + 49, placeBuildingBlock(random), 0, 2);
		world.setBlock(i + 42, j + 58, k + 49, placeBuildingBlock(random), 0, 2);
		world.setBlock(i + 44, j + 58, k + 49, placeBuildingBlock(random), 0, 2);
		world.setBlock(i + 45, j + 58, k + 49, placeBuildingBlock(random), 0, 2);
		world.setBlock(i + 34, j + 58, k + 50, placeBuildingBlock(random), 0, 2);
		world.setBlock(i + 35, j + 58, k + 50, placeBuildingBlock(random), 0, 2);
		world.setBlock(i + 37, j + 58, k + 50, placeBuildingBlock(random), 0, 2);
		world.setBlock(i + 41, j + 58, k + 50, placeBuildingBlock(random), 0, 2);
		world.setBlock(i + 43, j + 58, k + 50, placeBuildingBlock(random), 0, 2);
		world.setBlock(i + 44, j + 58, k + 50, placeBuildingBlock(random), 0, 2);
		world.setBlock(i + 35, j + 58, k + 51, placeBuildingBlock(random), 0, 2);
		world.setBlock(i + 36, j + 58, k + 51, placeBuildingBlock(random), 0, 2);
		world.setBlock(i + 38, j + 58, k + 51, placeBuildingBlock(random), 0, 2);
		world.setBlock(i + 39, j + 58, k + 51, placeBuildingBlock(random), 0, 2);
		world.setBlock(i + 40, j + 58, k + 51, placeBuildingBlock(random), 0, 2);
		world.setBlock(i + 42, j + 58, k + 51, placeBuildingBlock(random), 0, 2);
		world.setBlock(i + 43, j + 58, k + 51, placeBuildingBlock(random), 0, 2);
		world.setBlock(i + 36, j + 58, k + 52, placeBuildingBlock(random), 0, 2);
		world.setBlock(i + 37, j + 58, k + 52, placeBuildingBlock(random), 0, 2);
		world.setBlock(i + 39, j + 58, k + 52, placeBuildingBlock(random), 0, 2);
		world.setBlock(i + 41, j + 58, k + 52, placeBuildingBlock(random), 0, 2);
		world.setBlock(i + 42, j + 58, k + 52, placeBuildingBlock(random), 0, 2);
		world.setBlock(i + 37, j + 58, k + 53, placeBuildingBlock(random), 0, 2);
		world.setBlock(i + 38, j + 58, k + 53, placeBuildingBlock(random), 0, 2);
		world.setBlock(i + 40, j + 58, k + 53, placeBuildingBlock(random), 0, 2);
		world.setBlock(i + 41, j + 58, k + 53, placeBuildingBlock(random), 0, 2);
		world.setBlock(i + 38, j + 58, k + 54, placeBuildingBlock(random), 0, 2);
		world.setBlock(i + 39, j + 58, k + 54, placeBuildingBlock(random), 0, 2);
		world.setBlock(i + 40, j + 58, k + 54, placeBuildingBlock(random), 0, 2);
		world.setBlock(i + 39, j + 58, k + 55, placeBuildingBlock(random), 0, 2);
		world.setBlock(i + 39, j + 59, k + 23, placeBuildingBlock(random), 0, 2);
		world.setBlock(i + 38, j + 59, k + 24, placeBuildingBlock(random), 0, 2);
		world.setBlock(i + 39, j + 59, k + 24, placeBuildingBlock(random), 0, 2);
		world.setBlock(i + 40, j + 59, k + 24, placeBuildingBlock(random), 0, 2);
		world.setBlock(i + 37, j + 59, k + 25, placeBuildingBlock(random), 0, 2);
		world.setBlock(i + 38, j + 59, k + 25, placeBuildingBlock(random), 0, 2);
		world.setBlock(i + 39, j + 59, k + 25, placeBuildingBlock(random), 0, 2);
		world.setBlock(i + 40, j + 59, k + 25, placeBuildingBlock(random), 0, 2);
		world.setBlock(i + 41, j + 59, k + 25, placeBuildingBlock(random), 0, 2);
		world.setBlock(i + 36, j + 59, k + 26, placeBuildingBlock(random), 0, 2);
		world.setBlock(i + 37, j + 59, k + 26, placeBuildingBlock(random), 0, 2);
		world.setBlock(i + 41, j + 59, k + 26, placeBuildingBlock(random), 0, 2);
		world.setBlock(i + 42, j + 59, k + 26, placeBuildingBlock(random), 0, 2);
		world.setBlock(i + 35, j + 59, k + 27, placeBuildingBlock(random), 0, 2);
		world.setBlock(i + 36, j + 59, k + 27, placeBuildingBlock(random), 0, 2);
		world.setBlock(i + 42, j + 59, k + 27, placeBuildingBlock(random), 0, 2);
		world.setBlock(i + 43, j + 59, k + 27, placeBuildingBlock(random), 0, 2);
		world.setBlock(i + 34, j + 59, k + 28, placeBuildingBlock(random), 0, 2);
		world.setBlock(i + 35, j + 59, k + 28, placeBuildingBlock(random), 0, 2);
		world.setBlock(i + 43, j + 59, k + 28, placeBuildingBlock(random), 0, 2);
		world.setBlock(i + 44, j + 59, k + 28, placeBuildingBlock(random), 0, 2);
		world.setBlock(i + 33, j + 59, k + 29, placeBuildingBlock(random), 0, 2);
		world.setBlock(i + 34, j + 59, k + 29, placeBuildingBlock(random), 0, 2);
		world.setBlock(i + 44, j + 59, k + 29, placeBuildingBlock(random), 0, 2);
		world.setBlock(i + 45, j + 59, k + 29, placeBuildingBlock(random), 0, 2);
		world.setBlock(i + 32, j + 59, k + 30, placeBuildingBlock(random), 0, 2);
		world.setBlock(i + 33, j + 59, k + 30, placeBuildingBlock(random), 0, 2);
		world.setBlock(i + 39, j + 59, k + 30, BlocksAether.divine_oak_fence, 0, 2);
		world.setBlock(i + 45, j + 59, k + 30, placeBuildingBlock(random), 0, 2);
		world.setBlock(i + 46, j + 59, k + 30, placeBuildingBlock(random), 0, 2);
		world.setBlock(i + 31, j + 59, k + 31, placeBuildingBlock(random), 0, 2);
		world.setBlock(i + 32, j + 59, k + 31, placeBuildingBlock(random), 0, 2);
		world.setBlock(i + 46, j + 59, k + 31, placeBuildingBlock(random), 0, 2);
		world.setBlock(i + 47, j + 59, k + 31, placeBuildingBlock(random), 0, 2);
		world.setBlock(i + 30, j + 59, k + 32, placeBuildingBlock(random), 0, 2);
		world.setBlock(i + 31, j + 59, k + 32, placeBuildingBlock(random), 0, 2);
		world.setBlock(i + 47, j + 59, k + 32, placeBuildingBlock(random), 0, 2);
		world.setBlock(i + 48, j + 59, k + 32, placeBuildingBlock(random), 0, 2);
		world.setBlock(i + 29, j + 59, k + 33, placeBuildingBlock(random), 0, 2);
		world.setBlock(i + 30, j + 59, k + 33, placeBuildingBlock(random), 0, 2);
		world.setBlock(i + 48, j + 59, k + 33, placeBuildingBlock(random), 0, 2);
		world.setBlock(i + 49, j + 59, k + 33, placeBuildingBlock(random), 0, 2);
		world.setBlock(i + 28, j + 59, k + 34, placeBuildingBlock(random), 0, 2);
		world.setBlock(i + 29, j + 59, k + 34, placeBuildingBlock(random), 0, 2);
		world.setBlock(i + 49, j + 59, k + 34, placeBuildingBlock(random), 0, 2);
		world.setBlock(i + 50, j + 59, k + 34, placeBuildingBlock(random), 0, 2);
		world.setBlock(i + 27, j + 59, k + 35, placeBuildingBlock(random), 0, 2);
		world.setBlock(i + 28, j + 59, k + 35, placeBuildingBlock(random), 0, 2);
		world.setBlock(i + 50, j + 59, k + 35, placeBuildingBlock(random), 0, 2);
		world.setBlock(i + 51, j + 59, k + 35, placeBuildingBlock(random), 0, 2);
		world.setBlock(i + 26, j + 59, k + 36, placeBuildingBlock(random), 0, 2);
		world.setBlock(i + 27, j + 59, k + 36, placeBuildingBlock(random), 0, 2);
		world.setBlock(i + 51, j + 59, k + 36, placeBuildingBlock(random), 0, 2);
		world.setBlock(i + 52, j + 59, k + 36, placeBuildingBlock(random), 0, 2);
		world.setBlock(i + 25, j + 59, k + 37, placeBuildingBlock(random), 0, 2);
		world.setBlock(i + 26, j + 59, k + 37, placeBuildingBlock(random), 0, 2);
		world.setBlock(i + 52, j + 59, k + 37, placeBuildingBlock(random), 0, 2);
		world.setBlock(i + 53, j + 59, k + 37, placeBuildingBlock(random), 0, 2);
		world.setBlock(i + 24, j + 59, k + 38, placeBuildingBlock(random), 0, 2);
		world.setBlock(i + 25, j + 59, k + 38, placeBuildingBlock(random), 0, 2);
		world.setBlock(i + 26, j + 59, k + 38, placeBuildingBlock(random), 0, 2);
		world.setBlock(i + 39, j + 59, k + 38, BlocksAether.divine_oak_fence, 0, 2);
		world.setBlock(i + 47, j + 59, k + 38, BlocksAether.arctic_glowstone, 0, 2);
		world.setBlock(i + 52, j + 59, k + 38, placeBuildingBlock(random), 0, 2);
		world.setBlock(i + 53, j + 59, k + 38, placeBuildingBlock(random), 0, 2);
		world.setBlock(i + 54, j + 59, k + 38, placeBuildingBlock(random), 0, 2);
		world.setBlock(i + 25, j + 59, k + 39, placeBuildingBlock(random), 0, 2);
		world.setBlock(i + 26, j + 59, k + 39, placeBuildingBlock(random), 0, 2);
		world.setBlock(i + 52, j + 59, k + 39, placeBuildingBlock(random), 0, 2);
		world.setBlock(i + 53, j + 59, k + 39, placeBuildingBlock(random), 0, 2);
		world.setBlock(i + 26, j + 59, k + 40, placeBuildingBlock(random), 0, 2);
		world.setBlock(i + 27, j + 59, k + 40, placeBuildingBlock(random), 0, 2);
		world.setBlock(i + 51, j + 59, k + 40, placeBuildingBlock(random), 0, 2);
		world.setBlock(i + 52, j + 59, k + 40, placeBuildingBlock(random), 0, 2);
		world.setBlock(i + 27, j + 59, k + 41, placeBuildingBlock(random), 0, 2);
		world.setBlock(i + 28, j + 59, k + 41, placeBuildingBlock(random), 0, 2);
		world.setBlock(i + 50, j + 59, k + 41, placeBuildingBlock(random), 0, 2);
		world.setBlock(i + 51, j + 59, k + 41, placeBuildingBlock(random), 0, 2);
		world.setBlock(i + 28, j + 59, k + 42, placeBuildingBlock(random), 0, 2);
		world.setBlock(i + 29, j + 59, k + 42, placeBuildingBlock(random), 0, 2);
		world.setBlock(i + 49, j + 59, k + 42, placeBuildingBlock(random), 0, 2);
		world.setBlock(i + 50, j + 59, k + 42, placeBuildingBlock(random), 0, 2);
		world.setBlock(i + 29, j + 59, k + 43, placeBuildingBlock(random), 0, 2);
		world.setBlock(i + 30, j + 59, k + 43, placeBuildingBlock(random), 0, 2);
		world.setBlock(i + 48, j + 59, k + 43, placeBuildingBlock(random), 0, 2);
		world.setBlock(i + 49, j + 59, k + 43, placeBuildingBlock(random), 0, 2);
		world.setBlock(i + 30, j + 59, k + 44, placeBuildingBlock(random), 0, 2);
		world.setBlock(i + 31, j + 59, k + 44, placeBuildingBlock(random), 0, 2);
		world.setBlock(i + 39, j + 59, k + 44, BlocksAether.divine_oak_fence, 0, 2);
		world.setBlock(i + 47, j + 59, k + 44, placeBuildingBlock(random), 0, 2);
		world.setBlock(i + 48, j + 59, k + 44, placeBuildingBlock(random), 0, 2);
		world.setBlock(i + 31, j + 59, k + 45, placeBuildingBlock(random), 0, 2);
		world.setBlock(i + 32, j + 59, k + 45, placeBuildingBlock(random), 0, 2);
		world.setBlock(i + 46, j + 59, k + 45, placeBuildingBlock(random), 0, 2);
		world.setBlock(i + 47, j + 59, k + 45, placeBuildingBlock(random), 0, 2);
		world.setBlock(i + 32, j + 59, k + 46, placeBuildingBlock(random), 0, 2);
		world.setBlock(i + 33, j + 59, k + 46, placeBuildingBlock(random), 0, 2);
		world.setBlock(i + 45, j + 59, k + 46, placeBuildingBlock(random), 0, 2);
		world.setBlock(i + 46, j + 59, k + 46, placeBuildingBlock(random), 0, 2);
		world.setBlock(i + 33, j + 59, k + 47, placeBuildingBlock(random), 0, 2);
		world.setBlock(i + 34, j + 59, k + 47, placeBuildingBlock(random), 0, 2);
		world.setBlock(i + 44, j + 59, k + 47, placeBuildingBlock(random), 0, 2);
		world.setBlock(i + 45, j + 59, k + 47, placeBuildingBlock(random), 0, 2);
		world.setBlock(i + 34, j + 59, k + 48, placeBuildingBlock(random), 0, 2);
		world.setBlock(i + 35, j + 59, k + 48, placeBuildingBlock(random), 0, 2);
		world.setBlock(i + 43, j + 59, k + 48, placeBuildingBlock(random), 0, 2);
		world.setBlock(i + 44, j + 59, k + 48, placeBuildingBlock(random), 0, 2);
		world.setBlock(i + 35, j + 59, k + 49, placeBuildingBlock(random), 0, 2);
		world.setBlock(i + 36, j + 59, k + 49, placeBuildingBlock(random), 0, 2);
		world.setBlock(i + 42, j + 59, k + 49, placeBuildingBlock(random), 0, 2);
		world.setBlock(i + 43, j + 59, k + 49, placeBuildingBlock(random), 0, 2);
		world.setBlock(i + 36, j + 59, k + 50, placeBuildingBlock(random), 0, 2);
		world.setBlock(i + 37, j + 59, k + 50, placeBuildingBlock(random), 0, 2);
		world.setBlock(i + 41, j + 59, k + 50, placeBuildingBlock(random), 0, 2);
		world.setBlock(i + 42, j + 59, k + 50, placeBuildingBlock(random), 0, 2);
		world.setBlock(i + 37, j + 59, k + 51, placeBuildingBlock(random), 0, 2);
		world.setBlock(i + 38, j + 59, k + 51, placeBuildingBlock(random), 0, 2);
		world.setBlock(i + 39, j + 59, k + 51, placeBuildingBlock(random), 0, 2);
		world.setBlock(i + 40, j + 59, k + 51, placeBuildingBlock(random), 0, 2);
		world.setBlock(i + 41, j + 59, k + 51, placeBuildingBlock(random), 0, 2);
		world.setBlock(i + 38, j + 59, k + 52, placeBuildingBlock(random), 0, 2);
		world.setBlock(i + 39, j + 59, k + 52, placeBuildingBlock(random), 0, 2);
		world.setBlock(i + 40, j + 59, k + 52, placeBuildingBlock(random), 0, 2);
		world.setBlock(i + 39, j + 59, k + 53, placeBuildingBlock(random), 0, 2);
		world.setBlock(i + 39, j + 60, k + 25, placeBuildingBlock(random), 0, 2);
		world.setBlock(i + 38, j + 60, k + 26, placeBuildingBlock(random), 0, 2);
		world.setBlock(i + 39, j + 60, k + 26, placeBuildingBlock(random), 0, 2);
		world.setBlock(i + 40, j + 60, k + 26, placeBuildingBlock(random), 0, 2);
		world.setBlock(i + 37, j + 60, k + 27, placeBuildingBlock(random), 0, 2);
		world.setBlock(i + 38, j + 60, k + 27, placeBuildingBlock(random), 0, 2);
		world.setBlock(i + 40, j + 60, k + 27, placeBuildingBlock(random), 0, 2);
		world.setBlock(i + 41, j + 60, k + 27, placeBuildingBlock(random), 0, 2);
		world.setBlock(i + 36, j + 60, k + 28, placeBuildingBlock(random), 0, 2);
		world.setBlock(i + 37, j + 60, k + 28, placeBuildingBlock(random), 0, 2);
		world.setBlock(i + 41, j + 60, k + 28, placeBuildingBlock(random), 0, 2);
		world.setBlock(i + 42, j + 60, k + 28, placeBuildingBlock(random), 0, 2);
		world.setBlock(i + 35, j + 60, k + 29, placeBuildingBlock(random), 0, 2);
		world.setBlock(i + 36, j + 60, k + 29, placeBuildingBlock(random), 0, 2);
		world.setBlock(i + 42, j + 60, k + 29, placeBuildingBlock(random), 0, 2);
		world.setBlock(i + 43, j + 60, k + 29, placeBuildingBlock(random), 0, 2);
		world.setBlock(i + 34, j + 60, k + 30, placeBuildingBlock(random), 0, 2);
		world.setBlock(i + 35, j + 60, k + 30, placeBuildingBlock(random), 0, 2);
		world.setBlock(i + 39, j + 60, k + 30, BlocksAether.divine_oak_fence, 0, 2);
		world.setBlock(i + 43, j + 60, k + 30, placeBuildingBlock(random), 0, 2);
		world.setBlock(i + 44, j + 60, k + 30, placeBuildingBlock(random), 0, 2);
		world.setBlock(i + 33, j + 60, k + 31, placeBuildingBlock(random), 0, 2);
		world.setBlock(i + 34, j + 60, k + 31, placeBuildingBlock(random), 0, 2);
		world.setBlock(i + 44, j + 60, k + 31, placeBuildingBlock(random), 0, 2);
		world.setBlock(i + 45, j + 60, k + 31, placeBuildingBlock(random), 0, 2);
		world.setBlock(i + 32, j + 60, k + 32, placeBuildingBlock(random), 0, 2);
		world.setBlock(i + 33, j + 60, k + 32, placeBuildingBlock(random), 0, 2);
		world.setBlock(i + 45, j + 60, k + 32, placeBuildingBlock(random), 0, 2);
		world.setBlock(i + 46, j + 60, k + 32, placeBuildingBlock(random), 0, 2);
		world.setBlock(i + 31, j + 60, k + 33, placeBuildingBlock(random), 0, 2);
		world.setBlock(i + 32, j + 60, k + 33, placeBuildingBlock(random), 0, 2);
		world.setBlock(i + 46, j + 60, k + 33, placeBuildingBlock(random), 0, 2);
		world.setBlock(i + 47, j + 60, k + 33, placeBuildingBlock(random), 0, 2);
		world.setBlock(i + 30, j + 60, k + 34, placeBuildingBlock(random), 0, 2);
		world.setBlock(i + 31, j + 60, k + 34, placeBuildingBlock(random), 0, 2);
		world.setBlock(i + 47, j + 60, k + 34, placeBuildingBlock(random), 0, 2);
		world.setBlock(i + 48, j + 60, k + 34, placeBuildingBlock(random), 0, 2);
		world.setBlock(i + 29, j + 60, k + 35, placeBuildingBlock(random), 0, 2);
		world.setBlock(i + 30, j + 60, k + 35, placeBuildingBlock(random), 0, 2);
		world.setBlock(i + 48, j + 60, k + 35, placeBuildingBlock(random), 0, 2);
		world.setBlock(i + 49, j + 60, k + 35, placeBuildingBlock(random), 0, 2);
		world.setBlock(i + 28, j + 60, k + 36, placeBuildingBlock(random), 0, 2);
		world.setBlock(i + 29, j + 60, k + 36, placeBuildingBlock(random), 0, 2);
		world.setBlock(i + 49, j + 60, k + 36, placeBuildingBlock(random), 0, 2);
		world.setBlock(i + 50, j + 60, k + 36, placeBuildingBlock(random), 0, 2);
		world.setBlock(i + 27, j + 60, k + 37, placeBuildingBlock(random), 0, 2);
		world.setBlock(i + 28, j + 60, k + 37, placeBuildingBlock(random), 0, 2);
		world.setBlock(i + 50, j + 60, k + 37, placeBuildingBlock(random), 0, 2);
		world.setBlock(i + 51, j + 60, k + 37, placeBuildingBlock(random), 0, 2);
		world.setBlock(i + 26, j + 60, k + 38, placeBuildingBlock(random), 0, 2);
		world.setBlock(i + 27, j + 60, k + 38, placeBuildingBlock(random), 0, 2);
		world.setBlock(i + 33, j + 60, k + 38, BlocksAether.arctic_glowstone, 0, 2);
		world.setBlock(i + 39, j + 60, k + 38, BlocksAether.divine_oak_fence, 0, 2);
		world.setBlock(i + 47, j + 60, k + 38, BlocksAether.divine_oak_fence, 0, 2);
		world.setBlock(i + 51, j + 60, k + 38, placeBuildingBlock(random), 0, 2);
		world.setBlock(i + 52, j + 60, k + 38, placeBuildingBlock(random), 0, 2);
		world.setBlock(i + 27, j + 60, k + 39, placeBuildingBlock(random), 0, 2);
		world.setBlock(i + 28, j + 60, k + 39, placeBuildingBlock(random), 0, 2);
		world.setBlock(i + 50, j + 60, k + 39, placeBuildingBlock(random), 0, 2);
		world.setBlock(i + 51, j + 60, k + 39, placeBuildingBlock(random), 0, 2);
		world.setBlock(i + 28, j + 60, k + 40, placeBuildingBlock(random), 0, 2);
		world.setBlock(i + 29, j + 60, k + 40, placeBuildingBlock(random), 0, 2);
		world.setBlock(i + 49, j + 60, k + 40, placeBuildingBlock(random), 0, 2);
		world.setBlock(i + 50, j + 60, k + 40, placeBuildingBlock(random), 0, 2);
		world.setBlock(i + 29, j + 60, k + 41, placeBuildingBlock(random), 0, 2);
		world.setBlock(i + 30, j + 60, k + 41, placeBuildingBlock(random), 0, 2);
		world.setBlock(i + 48, j + 60, k + 41, placeBuildingBlock(random), 0, 2);
		world.setBlock(i + 49, j + 60, k + 41, placeBuildingBlock(random), 0, 2);
		world.setBlock(i + 30, j + 60, k + 42, placeBuildingBlock(random), 0, 2);
		world.setBlock(i + 31, j + 60, k + 42, placeBuildingBlock(random), 0, 2);
		world.setBlock(i + 47, j + 60, k + 42, placeBuildingBlock(random), 0, 2);
		world.setBlock(i + 48, j + 60, k + 42, placeBuildingBlock(random), 0, 2);
		world.setBlock(i + 31, j + 60, k + 43, placeBuildingBlock(random), 0, 2);
		world.setBlock(i + 32, j + 60, k + 43, placeBuildingBlock(random), 0, 2);
		world.setBlock(i + 46, j + 60, k + 43, placeBuildingBlock(random), 0, 2);
		world.setBlock(i + 47, j + 60, k + 43, placeBuildingBlock(random), 0, 2);
		world.setBlock(i + 32, j + 60, k + 44, placeBuildingBlock(random), 0, 2);
		world.setBlock(i + 33, j + 60, k + 44, placeBuildingBlock(random), 0, 2);
		world.setBlock(i + 39, j + 60, k + 44, BlocksAether.divine_oak_fence, 0, 2);
		world.setBlock(i + 45, j + 60, k + 44, placeBuildingBlock(random), 0, 2);
		world.setBlock(i + 46, j + 60, k + 44, placeBuildingBlock(random), 0, 2);
		world.setBlock(i + 33, j + 60, k + 45, placeBuildingBlock(random), 0, 2);
		world.setBlock(i + 34, j + 60, k + 45, placeBuildingBlock(random), 0, 2);
		world.setBlock(i + 44, j + 60, k + 45, placeBuildingBlock(random), 0, 2);
		world.setBlock(i + 45, j + 60, k + 45, placeBuildingBlock(random), 0, 2);
		world.setBlock(i + 34, j + 60, k + 46, placeBuildingBlock(random), 0, 2);
		world.setBlock(i + 35, j + 60, k + 46, placeBuildingBlock(random), 0, 2);
		world.setBlock(i + 43, j + 60, k + 46, placeBuildingBlock(random), 0, 2);
		world.setBlock(i + 44, j + 60, k + 46, placeBuildingBlock(random), 0, 2);
		world.setBlock(i + 35, j + 60, k + 47, placeBuildingBlock(random), 0, 2);
		world.setBlock(i + 36, j + 60, k + 47, placeBuildingBlock(random), 0, 2);
		world.setBlock(i + 42, j + 60, k + 47, placeBuildingBlock(random), 0, 2);
		world.setBlock(i + 43, j + 60, k + 47, placeBuildingBlock(random), 0, 2);
		world.setBlock(i + 36, j + 60, k + 48, placeBuildingBlock(random), 0, 2);
		world.setBlock(i + 37, j + 60, k + 48, placeBuildingBlock(random), 0, 2);
		world.setBlock(i + 41, j + 60, k + 48, placeBuildingBlock(random), 0, 2);
		world.setBlock(i + 42, j + 60, k + 48, placeBuildingBlock(random), 0, 2);
		world.setBlock(i + 37, j + 60, k + 49, placeBuildingBlock(random), 0, 2);
		world.setBlock(i + 38, j + 60, k + 49, placeBuildingBlock(random), 0, 2);
		world.setBlock(i + 40, j + 60, k + 49, placeBuildingBlock(random), 0, 2);
		world.setBlock(i + 41, j + 60, k + 49, placeBuildingBlock(random), 0, 2);
		world.setBlock(i + 38, j + 60, k + 50, placeBuildingBlock(random), 0, 2);
		world.setBlock(i + 39, j + 60, k + 50, placeBuildingBlock(random), 0, 2);
		world.setBlock(i + 40, j + 60, k + 50, placeBuildingBlock(random), 0, 2);
		world.setBlock(i + 39, j + 60, k + 51, placeBuildingBlock(random), 0, 2);
		world.setBlock(i + 39, j + 61, k + 27, placeBuildingBlock(random), 0, 2);
		world.setBlock(i + 38, j + 61, k + 28, placeBuildingBlock(random), 0, 2);
		world.setBlock(i + 39, j + 61, k + 28, placeBuildingBlock(random), 0, 2);
		world.setBlock(i + 40, j + 61, k + 28, placeBuildingBlock(random), 0, 2);
		world.setBlock(i + 37, j + 61, k + 29, placeBuildingBlock(random), 0, 2);
		world.setBlock(i + 38, j + 61, k + 29, placeBuildingBlock(random), 0, 2);
		world.setBlock(i + 40, j + 61, k + 29, placeBuildingBlock(random), 0, 2);
		world.setBlock(i + 41, j + 61, k + 29, placeBuildingBlock(random), 0, 2);
		world.setBlock(i + 36, j + 61, k + 30, placeBuildingBlock(random), 0, 2);
		world.setBlock(i + 37, j + 61, k + 30, placeBuildingBlock(random), 0, 2);
		world.setBlock(i + 39, j + 61, k + 30, BlocksAether.divine_oak_fence, 0, 2);
		world.setBlock(i + 41, j + 61, k + 30, placeBuildingBlock(random), 0, 2);
		world.setBlock(i + 42, j + 61, k + 30, placeBuildingBlock(random), 0, 2);
		world.setBlock(i + 35, j + 61, k + 31, placeBuildingBlock(random), 0, 2);
		world.setBlock(i + 36, j + 61, k + 31, placeBuildingBlock(random), 0, 2);
		world.setBlock(i + 42, j + 61, k + 31, placeBuildingBlock(random), 0, 2);
		world.setBlock(i + 43, j + 61, k + 31, placeBuildingBlock(random), 0, 2);
		world.setBlock(i + 34, j + 61, k + 32, placeBuildingBlock(random), 0, 2);
		world.setBlock(i + 35, j + 61, k + 32, placeBuildingBlock(random), 0, 2);
		world.setBlock(i + 43, j + 61, k + 32, placeBuildingBlock(random), 0, 2);
		world.setBlock(i + 44, j + 61, k + 32, placeBuildingBlock(random), 0, 2);
		world.setBlock(i + 33, j + 61, k + 33, placeBuildingBlock(random), 0, 2);
		world.setBlock(i + 34, j + 61, k + 33, placeBuildingBlock(random), 0, 2);
		world.setBlock(i + 44, j + 61, k + 33, placeBuildingBlock(random), 0, 2);
		world.setBlock(i + 45, j + 61, k + 33, placeBuildingBlock(random), 0, 2);
		world.setBlock(i + 32, j + 61, k + 34, placeBuildingBlock(random), 0, 2);
		world.setBlock(i + 33, j + 61, k + 34, placeBuildingBlock(random), 0, 2);
		world.setBlock(i + 45, j + 61, k + 34, placeBuildingBlock(random), 0, 2);
		world.setBlock(i + 46, j + 61, k + 34, placeBuildingBlock(random), 0, 2);
		world.setBlock(i + 31, j + 61, k + 35, placeBuildingBlock(random), 0, 2);
		world.setBlock(i + 32, j + 61, k + 35, placeBuildingBlock(random), 0, 2);
		world.setBlock(i + 46, j + 61, k + 35, placeBuildingBlock(random), 0, 2);
		world.setBlock(i + 47, j + 61, k + 35, placeBuildingBlock(random), 0, 2);
		world.setBlock(i + 30, j + 61, k + 36, placeBuildingBlock(random), 0, 2);
		world.setBlock(i + 31, j + 61, k + 36, placeBuildingBlock(random), 0, 2);
		world.setBlock(i + 47, j + 61, k + 36, placeBuildingBlock(random), 0, 2);
		world.setBlock(i + 48, j + 61, k + 36, placeBuildingBlock(random), 0, 2);
		world.setBlock(i + 29, j + 61, k + 37, placeBuildingBlock(random), 0, 2);
		world.setBlock(i + 30, j + 61, k + 37, placeBuildingBlock(random), 0, 2);
		world.setBlock(i + 48, j + 61, k + 37, placeBuildingBlock(random), 0, 2);
		world.setBlock(i + 49, j + 61, k + 37, placeBuildingBlock(random), 0, 2);
		world.setBlock(i + 28, j + 61, k + 38, placeBuildingBlock(random), 0, 2);
		world.setBlock(i + 29, j + 61, k + 38, placeBuildingBlock(random), 0, 2);
		world.setBlock(i + 33, j + 61, k + 38, BlocksAether.divine_oak_fence, 0, 2);
		world.setBlock(i + 39, j + 61, k + 38, BlocksAether.divine_oak_fence, 0, 2);
		world.setBlock(i + 47, j + 61, k + 38, BlocksAether.divine_oak_fence, 0, 2);
		world.setBlock(i + 49, j + 61, k + 38, placeBuildingBlock(random), 0, 2);
		world.setBlock(i + 50, j + 61, k + 38, placeBuildingBlock(random), 0, 2);
		world.setBlock(i + 29, j + 61, k + 39, placeBuildingBlock(random), 0, 2);
		world.setBlock(i + 30, j + 61, k + 39, placeBuildingBlock(random), 0, 2);
		world.setBlock(i + 48, j + 61, k + 39, placeBuildingBlock(random), 0, 2);
		world.setBlock(i + 49, j + 61, k + 39, placeBuildingBlock(random), 0, 2);
		world.setBlock(i + 30, j + 61, k + 40, placeBuildingBlock(random), 0, 2);
		world.setBlock(i + 31, j + 61, k + 40, placeBuildingBlock(random), 0, 2);
		world.setBlock(i + 47, j + 61, k + 40, placeBuildingBlock(random), 0, 2);
		world.setBlock(i + 48, j + 61, k + 40, placeBuildingBlock(random), 0, 2);
		world.setBlock(i + 31, j + 61, k + 41, placeBuildingBlock(random), 0, 2);
		world.setBlock(i + 32, j + 61, k + 41, placeBuildingBlock(random), 0, 2);
		world.setBlock(i + 46, j + 61, k + 41, placeBuildingBlock(random), 0, 2);
		world.setBlock(i + 47, j + 61, k + 41, placeBuildingBlock(random), 0, 2);
		world.setBlock(i + 32, j + 61, k + 42, placeBuildingBlock(random), 0, 2);
		world.setBlock(i + 33, j + 61, k + 42, placeBuildingBlock(random), 0, 2);
		world.setBlock(i + 45, j + 61, k + 42, placeBuildingBlock(random), 0, 2);
		world.setBlock(i + 46, j + 61, k + 42, placeBuildingBlock(random), 0, 2);
		world.setBlock(i + 33, j + 61, k + 43, placeBuildingBlock(random), 0, 2);
		world.setBlock(i + 34, j + 61, k + 43, placeBuildingBlock(random), 0, 2);
		world.setBlock(i + 44, j + 61, k + 43, placeBuildingBlock(random), 0, 2);
		world.setBlock(i + 45, j + 61, k + 43, placeBuildingBlock(random), 0, 2);
		world.setBlock(i + 34, j + 61, k + 44, placeBuildingBlock(random), 0, 2);
		world.setBlock(i + 35, j + 61, k + 44, placeBuildingBlock(random), 0, 2);
		world.setBlock(i + 39, j + 61, k + 44, BlocksAether.divine_oak_fence, 0, 2);
		world.setBlock(i + 43, j + 61, k + 44, placeBuildingBlock(random), 0, 2);
		world.setBlock(i + 44, j + 61, k + 44, placeBuildingBlock(random), 0, 2);
		world.setBlock(i + 35, j + 61, k + 45, placeBuildingBlock(random), 0, 2);
		world.setBlock(i + 36, j + 61, k + 45, placeBuildingBlock(random), 0, 2);
		world.setBlock(i + 42, j + 61, k + 45, placeBuildingBlock(random), 0, 2);
		world.setBlock(i + 43, j + 61, k + 45, placeBuildingBlock(random), 0, 2);
		world.setBlock(i + 36, j + 61, k + 46, placeBuildingBlock(random), 0, 2);
		world.setBlock(i + 37, j + 61, k + 46, placeBuildingBlock(random), 0, 2);
		world.setBlock(i + 41, j + 61, k + 46, placeBuildingBlock(random), 0, 2);
		world.setBlock(i + 42, j + 61, k + 46, placeBuildingBlock(random), 0, 2);
		world.setBlock(i + 37, j + 61, k + 47, placeBuildingBlock(random), 0, 2);
		world.setBlock(i + 38, j + 61, k + 47, placeBuildingBlock(random), 0, 2);
		world.setBlock(i + 40, j + 61, k + 47, placeBuildingBlock(random), 0, 2);
		world.setBlock(i + 41, j + 61, k + 47, placeBuildingBlock(random), 0, 2);
		world.setBlock(i + 38, j + 61, k + 48, placeBuildingBlock(random), 0, 2);
		world.setBlock(i + 39, j + 61, k + 48, placeBuildingBlock(random), 0, 2);
		world.setBlock(i + 40, j + 61, k + 48, placeBuildingBlock(random), 0, 2);
		world.setBlock(i + 39, j + 61, k + 49, placeBuildingBlock(random), 0, 2);
		world.setBlock(i + 39, j + 62, k + 29, placeBuildingBlock(random), 0, 2);
		world.setBlock(i + 38, j + 62, k + 30, placeBuildingBlock(random), 0, 2);
		world.setBlock(i + 39, j + 62, k + 30, placeBuildingBlock(random), 0, 2);
		world.setBlock(i + 40, j + 62, k + 30, placeBuildingBlock(random), 0, 2);
		world.setBlock(i + 37, j + 62, k + 31, placeBuildingBlock(random), 0, 2);
		world.setBlock(i + 38, j + 62, k + 31, placeBuildingBlock(random), 0, 2);
		world.setBlock(i + 40, j + 62, k + 31, placeBuildingBlock(random), 0, 2);
		world.setBlock(i + 41, j + 62, k + 31, placeBuildingBlock(random), 0, 2);
		world.setBlock(i + 36, j + 62, k + 32, placeBuildingBlock(random), 0, 2);
		world.setBlock(i + 37, j + 62, k + 32, placeBuildingBlock(random), 0, 2);
		world.setBlock(i + 41, j + 62, k + 32, placeBuildingBlock(random), 0, 2);
		world.setBlock(i + 42, j + 62, k + 32, placeBuildingBlock(random), 0, 2);
		world.setBlock(i + 35, j + 62, k + 33, placeBuildingBlock(random), 0, 2);
		world.setBlock(i + 36, j + 62, k + 33, placeBuildingBlock(random), 0, 2);
		world.setBlock(i + 42, j + 62, k + 33, placeBuildingBlock(random), 0, 2);
		world.setBlock(i + 43, j + 62, k + 33, placeBuildingBlock(random), 0, 2);
		world.setBlock(i + 34, j + 62, k + 34, placeBuildingBlock(random), 0, 2);
		world.setBlock(i + 35, j + 62, k + 34, placeBuildingBlock(random), 0, 2);
		world.setBlock(i + 43, j + 62, k + 34, placeBuildingBlock(random), 0, 2);
		world.setBlock(i + 44, j + 62, k + 34, placeBuildingBlock(random), 0, 2);
		world.setBlock(i + 33, j + 62, k + 35, placeBuildingBlock(random), 0, 2);
		world.setBlock(i + 34, j + 62, k + 35, placeBuildingBlock(random), 0, 2);
		world.setBlock(i + 44, j + 62, k + 35, placeBuildingBlock(random), 0, 2);
		world.setBlock(i + 45, j + 62, k + 35, placeBuildingBlock(random), 0, 2);
		world.setBlock(i + 32, j + 62, k + 36, placeBuildingBlock(random), 0, 2);
		world.setBlock(i + 33, j + 62, k + 36, placeBuildingBlock(random), 0, 2);
		world.setBlock(i + 45, j + 62, k + 36, placeBuildingBlock(random), 0, 2);
		world.setBlock(i + 46, j + 62, k + 36, placeBuildingBlock(random), 0, 2);
		world.setBlock(i + 31, j + 62, k + 37, placeBuildingBlock(random), 0, 2);
		world.setBlock(i + 32, j + 62, k + 37, placeBuildingBlock(random), 0, 2);
		world.setBlock(i + 46, j + 62, k + 37, placeBuildingBlock(random), 0, 2);
		world.setBlock(i + 47, j + 62, k + 37, placeBuildingBlock(random), 0, 2);
		world.setBlock(i + 30, j + 62, k + 38, placeBuildingBlock(random), 0, 2);
		world.setBlock(i + 31, j + 62, k + 38, placeBuildingBlock(random), 0, 2);
		world.setBlock(i + 33, j + 62, k + 38, BlocksAether.divine_oak_fence, 0, 2);
		world.setBlock(i + 39, j + 62, k + 38, BlocksAether.divine_oak_fence, 0, 2);
		world.setBlock(i + 47, j + 62, k + 38, placeBuildingBlock(random), 0, 2);
		world.setBlock(i + 48, j + 62, k + 38, placeBuildingBlock(random), 0, 2);
		world.setBlock(i + 31, j + 62, k + 39, placeBuildingBlock(random), 0, 2);
		world.setBlock(i + 32, j + 62, k + 39, placeBuildingBlock(random), 0, 2);
		world.setBlock(i + 46, j + 62, k + 39, placeBuildingBlock(random), 0, 2);
		world.setBlock(i + 47, j + 62, k + 39, placeBuildingBlock(random), 0, 2);
		world.setBlock(i + 32, j + 62, k + 40, placeBuildingBlock(random), 0, 2);
		world.setBlock(i + 33, j + 62, k + 40, placeBuildingBlock(random), 0, 2);
		world.setBlock(i + 45, j + 62, k + 40, placeBuildingBlock(random), 0, 2);
		world.setBlock(i + 46, j + 62, k + 40, placeBuildingBlock(random), 0, 2);
		world.setBlock(i + 33, j + 62, k + 41, placeBuildingBlock(random), 0, 2);
		world.setBlock(i + 34, j + 62, k + 41, placeBuildingBlock(random), 0, 2);
		world.setBlock(i + 44, j + 62, k + 41, placeBuildingBlock(random), 0, 2);
		world.setBlock(i + 45, j + 62, k + 41, placeBuildingBlock(random), 0, 2);
		world.setBlock(i + 34, j + 62, k + 42, placeBuildingBlock(random), 0, 2);
		world.setBlock(i + 35, j + 62, k + 42, placeBuildingBlock(random), 0, 2);
		world.setBlock(i + 43, j + 62, k + 42, placeBuildingBlock(random), 0, 2);
		world.setBlock(i + 44, j + 62, k + 42, placeBuildingBlock(random), 0, 2);
		world.setBlock(i + 35, j + 62, k + 43, placeBuildingBlock(random), 0, 2);
		world.setBlock(i + 36, j + 62, k + 43, placeBuildingBlock(random), 0, 2);
		world.setBlock(i + 42, j + 62, k + 43, placeBuildingBlock(random), 0, 2);
		world.setBlock(i + 43, j + 62, k + 43, placeBuildingBlock(random), 0, 2);
		world.setBlock(i + 36, j + 62, k + 44, placeBuildingBlock(random), 0, 2);
		world.setBlock(i + 37, j + 62, k + 44, placeBuildingBlock(random), 0, 2);
		world.setBlock(i + 39, j + 62, k + 44, BlocksAether.divine_oak_fence, 0, 2);
		world.setBlock(i + 41, j + 62, k + 44, placeBuildingBlock(random), 0, 2);
		world.setBlock(i + 42, j + 62, k + 44, placeBuildingBlock(random), 0, 2);
		world.setBlock(i + 37, j + 62, k + 45, placeBuildingBlock(random), 0, 2);
		world.setBlock(i + 38, j + 62, k + 45, placeBuildingBlock(random), 0, 2);
		world.setBlock(i + 40, j + 62, k + 45, placeBuildingBlock(random), 0, 2);
		world.setBlock(i + 41, j + 62, k + 45, placeBuildingBlock(random), 0, 2);
		world.setBlock(i + 38, j + 62, k + 46, placeBuildingBlock(random), 0, 2);
		world.setBlock(i + 39, j + 62, k + 46, placeBuildingBlock(random), 0, 2);
		world.setBlock(i + 40, j + 62, k + 46, placeBuildingBlock(random), 0, 2);
		world.setBlock(i + 39, j + 62, k + 47, placeBuildingBlock(random), 0, 2);
		world.setBlock(i + 39, j + 63, k + 31, placeBuildingBlock(random), 0, 2);
		world.setBlock(i + 38, j + 63, k + 32, placeBuildingBlock(random), 0, 2);
		world.setBlock(i + 39, j + 63, k + 32, placeBuildingBlock(random), 0, 2);
		world.setBlock(i + 40, j + 63, k + 32, placeBuildingBlock(random), 0, 2);
		world.setBlock(i + 37, j + 63, k + 33, placeBuildingBlock(random), 0, 2);
		world.setBlock(i + 38, j + 63, k + 33, placeBuildingBlock(random), 0, 2);
		world.setBlock(i + 40, j + 63, k + 33, placeBuildingBlock(random), 0, 2);
		world.setBlock(i + 41, j + 63, k + 33, placeBuildingBlock(random), 0, 2);
		world.setBlock(i + 36, j + 63, k + 34, placeBuildingBlock(random), 0, 2);
		world.setBlock(i + 37, j + 63, k + 34, placeBuildingBlock(random), 0, 2);
		world.setBlock(i + 41, j + 63, k + 34, placeBuildingBlock(random), 0, 2);
		world.setBlock(i + 42, j + 63, k + 34, placeBuildingBlock(random), 0, 2);
		world.setBlock(i + 35, j + 63, k + 35, placeBuildingBlock(random), 0, 2);
		world.setBlock(i + 36, j + 63, k + 35, placeBuildingBlock(random), 0, 2);
		world.setBlock(i + 42, j + 63, k + 35, placeBuildingBlock(random), 0, 2);
		world.setBlock(i + 43, j + 63, k + 35, placeBuildingBlock(random), 0, 2);
		world.setBlock(i + 34, j + 63, k + 36, placeBuildingBlock(random), 0, 2);
		world.setBlock(i + 35, j + 63, k + 36, placeBuildingBlock(random), 0, 2);
		world.setBlock(i + 43, j + 63, k + 36, placeBuildingBlock(random), 0, 2);
		world.setBlock(i + 44, j + 63, k + 36, placeBuildingBlock(random), 0, 2);
		world.setBlock(i + 33, j + 63, k + 37, placeBuildingBlock(random), 0, 2);
		world.setBlock(i + 34, j + 63, k + 37, placeBuildingBlock(random), 0, 2);
		world.setBlock(i + 44, j + 63, k + 37, placeBuildingBlock(random), 0, 2);
		world.setBlock(i + 45, j + 63, k + 37, placeBuildingBlock(random), 0, 2);
		world.setBlock(i + 32, j + 63, k + 38, placeBuildingBlock(random), 0, 2);
		world.setBlock(i + 33, j + 63, k + 38, placeBuildingBlock(random), 0, 2);
		world.setBlock(i + 39, j + 63, k + 38, BlocksAether.divine_oak_fence, 0, 2);
		world.setBlock(i + 45, j + 63, k + 38, placeBuildingBlock(random), 0, 2);
		world.setBlock(i + 46, j + 63, k + 38, placeBuildingBlock(random), 0, 2);
		world.setBlock(i + 33, j + 63, k + 39, placeBuildingBlock(random), 0, 2);
		world.setBlock(i + 34, j + 63, k + 39, placeBuildingBlock(random), 0, 2);
		world.setBlock(i + 44, j + 63, k + 39, placeBuildingBlock(random), 0, 2);
		world.setBlock(i + 45, j + 63, k + 39, placeBuildingBlock(random), 0, 2);
		world.setBlock(i + 34, j + 63, k + 40, placeBuildingBlock(random), 0, 2);
		world.setBlock(i + 35, j + 63, k + 40, placeBuildingBlock(random), 0, 2);
		world.setBlock(i + 43, j + 63, k + 40, placeBuildingBlock(random), 0, 2);
		world.setBlock(i + 44, j + 63, k + 40, placeBuildingBlock(random), 0, 2);
		world.setBlock(i + 35, j + 63, k + 41, placeBuildingBlock(random), 0, 2);
		world.setBlock(i + 36, j + 63, k + 41, placeBuildingBlock(random), 0, 2);
		world.setBlock(i + 42, j + 63, k + 41, placeBuildingBlock(random), 0, 2);
		world.setBlock(i + 43, j + 63, k + 41, placeBuildingBlock(random), 0, 2);
		world.setBlock(i + 36, j + 63, k + 42, placeBuildingBlock(random), 0, 2);
		world.setBlock(i + 37, j + 63, k + 42, placeBuildingBlock(random), 0, 2);
		world.setBlock(i + 41, j + 63, k + 42, placeBuildingBlock(random), 0, 2);
		world.setBlock(i + 42, j + 63, k + 42, placeBuildingBlock(random), 0, 2);
		world.setBlock(i + 37, j + 63, k + 43, placeBuildingBlock(random), 0, 2);
		world.setBlock(i + 38, j + 63, k + 43, placeBuildingBlock(random), 0, 2);
		world.setBlock(i + 40, j + 63, k + 43, placeBuildingBlock(random), 0, 2);
		world.setBlock(i + 41, j + 63, k + 43, placeBuildingBlock(random), 0, 2);
		world.setBlock(i + 38, j + 63, k + 44, placeBuildingBlock(random), 0, 2);
		world.setBlock(i + 39, j + 63, k + 44, placeBuildingBlock(random), 0, 2);
		world.setBlock(i + 40, j + 63, k + 44, placeBuildingBlock(random), 0, 2);
		world.setBlock(i + 39, j + 63, k + 45, placeBuildingBlock(random), 0, 2);
		world.setBlock(i + 39, j + 64, k + 33, placeBuildingBlock(random), 0, 2);
		world.setBlock(i + 38, j + 64, k + 34, placeBuildingBlock(random), 0, 2);
		world.setBlock(i + 39, j + 64, k + 34, placeBuildingBlock(random), 0, 2);
		world.setBlock(i + 40, j + 64, k + 34, placeBuildingBlock(random), 0, 2);
		world.setBlock(i + 37, j + 64, k + 35, placeBuildingBlock(random), 0, 2);
		world.setBlock(i + 38, j + 64, k + 35, placeBuildingBlock(random), 0, 2);
		world.setBlock(i + 39, j + 64, k + 35, placeBuildingBlock(random), 0, 2);
		world.setBlock(i + 40, j + 64, k + 35, placeBuildingBlock(random), 0, 2);
		world.setBlock(i + 41, j + 64, k + 35, placeBuildingBlock(random), 0, 2);
		world.setBlock(i + 36, j + 64, k + 36, placeBuildingBlock(random), 0, 2);
		world.setBlock(i + 37, j + 64, k + 36, placeBuildingBlock(random), 0, 2);
		world.setBlock(i + 38, j + 64, k + 36, placeBuildingBlock(random), 0, 2);
		world.setBlock(i + 39, j + 64, k + 36, placeBuildingBlock(random), 0, 2);
		world.setBlock(i + 40, j + 64, k + 36, placeBuildingBlock(random), 0, 2);
		world.setBlock(i + 41, j + 64, k + 36, placeBuildingBlock(random), 0, 2);
		world.setBlock(i + 42, j + 64, k + 36, placeBuildingBlock(random), 0, 2);
		world.setBlock(i + 35, j + 64, k + 37, placeBuildingBlock(random), 0, 2);
		world.setBlock(i + 36, j + 64, k + 37, placeBuildingBlock(random), 0, 2);
		world.setBlock(i + 37, j + 64, k + 37, placeBuildingBlock(random), 0, 2);
		world.setBlock(i + 38, j + 64, k + 37, placeBuildingBlock(random), 0, 2);
		world.setBlock(i + 39, j + 64, k + 37, placeBuildingBlock(random), 0, 2);
		world.setBlock(i + 40, j + 64, k + 37, placeBuildingBlock(random), 0, 2);
		world.setBlock(i + 41, j + 64, k + 37, placeBuildingBlock(random), 0, 2);
		world.setBlock(i + 42, j + 64, k + 37, placeBuildingBlock(random), 0, 2);
		world.setBlock(i + 43, j + 64, k + 37, placeBuildingBlock(random), 0, 2);
		world.setBlock(i + 34, j + 64, k + 38, placeBuildingBlock(random), 0, 2);
		world.setBlock(i + 35, j + 64, k + 38, placeBuildingBlock(random), 0, 2);
		world.setBlock(i + 36, j + 64, k + 38, placeBuildingBlock(random), 0, 2);
		world.setBlock(i + 37, j + 64, k + 38, placeBuildingBlock(random), 0, 2);
		world.setBlock(i + 38, j + 64, k + 38, placeBuildingBlock(random), 0, 2);
		world.setBlock(i + 39, j + 64, k + 38, placeBuildingBlock(random), 0, 2);
		world.setBlock(i + 40, j + 64, k + 38, placeBuildingBlock(random), 0, 2);
		world.setBlock(i + 41, j + 64, k + 38, placeBuildingBlock(random), 0, 2);
		world.setBlock(i + 42, j + 64, k + 38, placeBuildingBlock(random), 0, 2);
		world.setBlock(i + 43, j + 64, k + 38, placeBuildingBlock(random), 0, 2);
		world.setBlock(i + 44, j + 64, k + 38, placeBuildingBlock(random), 0, 2);
		world.setBlock(i + 35, j + 64, k + 39, placeBuildingBlock(random), 0, 2);
		world.setBlock(i + 36, j + 64, k + 39, placeBuildingBlock(random), 0, 2);
		world.setBlock(i + 37, j + 64, k + 39, placeBuildingBlock(random), 0, 2);
		world.setBlock(i + 38, j + 64, k + 39, placeBuildingBlock(random), 0, 2);
		world.setBlock(i + 39, j + 64, k + 39, placeBuildingBlock(random), 0, 2);
		world.setBlock(i + 40, j + 64, k + 39, placeBuildingBlock(random), 0, 2);
		world.setBlock(i + 41, j + 64, k + 39, placeBuildingBlock(random), 0, 2);
		world.setBlock(i + 42, j + 64, k + 39, placeBuildingBlock(random), 0, 2);
		world.setBlock(i + 43, j + 64, k + 39, placeBuildingBlock(random), 0, 2);
		world.setBlock(i + 36, j + 64, k + 40, placeBuildingBlock(random), 0, 2);
		world.setBlock(i + 37, j + 64, k + 40, placeBuildingBlock(random), 0, 2);
		world.setBlock(i + 38, j + 64, k + 40, placeBuildingBlock(random), 0, 2);
		world.setBlock(i + 39, j + 64, k + 40, placeBuildingBlock(random), 0, 2);
		world.setBlock(i + 40, j + 64, k + 40, placeBuildingBlock(random), 0, 2);
		world.setBlock(i + 41, j + 64, k + 40, placeBuildingBlock(random), 0, 2);
		world.setBlock(i + 42, j + 64, k + 40, placeBuildingBlock(random), 0, 2);
		world.setBlock(i + 37, j + 64, k + 41, placeBuildingBlock(random), 0, 2);
		world.setBlock(i + 38, j + 64, k + 41, placeBuildingBlock(random), 0, 2);
		world.setBlock(i + 39, j + 64, k + 41, placeBuildingBlock(random), 0, 2);
		world.setBlock(i + 40, j + 64, k + 41, placeBuildingBlock(random), 0, 2);
		world.setBlock(i + 41, j + 64, k + 41, placeBuildingBlock(random), 0, 2);
		world.setBlock(i + 38, j + 64, k + 42, placeBuildingBlock(random), 0, 2);
		world.setBlock(i + 39, j + 64, k + 42, placeBuildingBlock(random), 0, 2);
		world.setBlock(i + 40, j + 64, k + 42, placeBuildingBlock(random), 0, 2);
		world.setBlock(i + 39, j + 64, k + 43, placeBuildingBlock(random), 0, 2);
		world.setBlock(i + 39, j + 65, k + 35, placeBuildingBlock(random), 0, 2);
		world.setBlock(i + 38, j + 65, k + 36, placeBuildingBlock(random), 0, 2);
		world.setBlock(i + 39, j + 65, k + 36, placeBuildingBlock(random), 0, 2);
		world.setBlock(i + 40, j + 65, k + 36, placeBuildingBlock(random), 0, 2);
		world.setBlock(i + 37, j + 65, k + 37, placeBuildingBlock(random), 0, 2);
		world.setBlock(i + 38, j + 65, k + 37, placeBuildingBlock(random), 0, 2);
		world.setBlock(i + 39, j + 65, k + 37, placeBuildingBlock(random), 0, 2);
		world.setBlock(i + 40, j + 65, k + 37, placeBuildingBlock(random), 0, 2);
		world.setBlock(i + 41, j + 65, k + 37, placeBuildingBlock(random), 0, 2);
		world.setBlock(i + 36, j + 65, k + 38, placeBuildingBlock(random), 0, 2);
		world.setBlock(i + 37, j + 65, k + 38, placeBuildingBlock(random), 0, 2);
		world.setBlock(i + 38, j + 65, k + 38, placeBuildingBlock(random), 0, 2);
		world.setBlock(i + 39, j + 65, k + 38, placeBuildingBlock(random), 0, 2);
		world.setBlock(i + 40, j + 65, k + 38, placeBuildingBlock(random), 0, 2);
		world.setBlock(i + 41, j + 65, k + 38, placeBuildingBlock(random), 0, 2);
		world.setBlock(i + 42, j + 65, k + 38, placeBuildingBlock(random), 0, 2);
		world.setBlock(i + 37, j + 65, k + 39, placeBuildingBlock(random), 0, 2);
		world.setBlock(i + 38, j + 65, k + 39, placeBuildingBlock(random), 0, 2);
		world.setBlock(i + 39, j + 65, k + 39, placeBuildingBlock(random), 0, 2);
		world.setBlock(i + 40, j + 65, k + 39, placeBuildingBlock(random), 0, 2);
		world.setBlock(i + 41, j + 65, k + 39, placeBuildingBlock(random), 0, 2);
		world.setBlock(i + 38, j + 65, k + 40, placeBuildingBlock(random), 0, 2);
		world.setBlock(i + 39, j + 65, k + 40, placeBuildingBlock(random), 0, 2);
		world.setBlock(i + 40, j + 65, k + 40, placeBuildingBlock(random), 0, 2);
		world.setBlock(i + 39, j + 65, k + 41, placeBuildingBlock(random), 0, 2);
		world.setBlock(i + 39, j + 66, k + 37, placeBuildingBlock(random), 0, 2);
		world.setBlock(i + 38, j + 66, k + 38, placeBuildingBlock(random), 0, 2);
		world.setBlock(i + 39, j + 66, k + 38, placeBuildingBlock(random), 0, 2);
		world.setBlock(i + 40, j + 66, k + 38, placeBuildingBlock(random), 0, 2);
		world.setBlock(i + 39, j + 66, k + 39, placeBuildingBlock(random), 0, 2);
		world.setBlock(i + 39, j + 67, k + 38, placeBuildingBlock(random), 0, 2);
		
		return true;
	}
	
	private Block placeBuildingBlock(Random random) {
        if (random.nextDouble() < 0.005) {
            return BlocksAether.fuse_trap;
        } else if (random.nextDouble() >= 0.005 && random.nextDouble() < 0.01) {
        	return BlocksAether.fuse_trap_2;
        } else if (random.nextDouble() >= 0.01 && random.nextDouble() < 0.05) {
        	return BlocksAether.locked_creeping_stone;
        } else {
            return BlocksAether.locked_fuse_stone;
        }
    }

}
