package com.gildedgames.the_aether.world.dungeon.osmium;

import java.util.Random;

import com.gildedgames.the_aether.blocks.BlocksAether;

import net.minecraft.block.Block;
import net.minecraft.init.Blocks;
import net.minecraft.world.World;
import net.minecraft.world.gen.feature.WorldGenerator;

public class OsmiumDungeonStormAercloudGen1 extends WorldGenerator {

	public OsmiumDungeonStormAercloudGen1() {

	}
	
	public boolean generate(final World world, final Random random, final int i, final int j, final int k) {
		
		world.setBlock(i + 41, j + 0, k + 21, placeBuildingBlock(random), 0, 2);
		world.setBlock(i + 40, j + 0, k + 22, placeBuildingBlock(random), 0, 2);
		world.setBlock(i + 42, j + 0, k + 22, placeBuildingBlock(random), 0, 2);
		world.setBlock(i + 39, j + 0, k + 23, placeBuildingBlock(random), 0, 2);
		world.setBlock(i + 43, j + 0, k + 23, placeBuildingBlock(random), 0, 2);
		world.setBlock(i + 38, j + 0, k + 24, placeBuildingBlock(random), 0, 2);
		world.setBlock(i + 44, j + 0, k + 24, placeBuildingBlock(random), 0, 2);
		world.setBlock(i + 37, j + 0, k + 25, placeBuildingBlock(random), 0, 2);
		world.setBlock(i + 45, j + 0, k + 25, placeBuildingBlock(random), 0, 2);
		world.setBlock(i + 36, j + 0, k + 26, placeBuildingBlock(random), 0, 2);
		world.setBlock(i + 46, j + 0, k + 26, placeBuildingBlock(random), 0, 2);
		world.setBlock(i + 35, j + 0, k + 27, placeBuildingBlock(random), 0, 2);
		world.setBlock(i + 47, j + 0, k + 27, placeBuildingBlock(random), 0, 2);
		world.setBlock(i + 34, j + 0, k + 28, placeBuildingBlock(random), 0, 2);
		world.setBlock(i + 48, j + 0, k + 28, placeBuildingBlock(random), 0, 2);
		world.setBlock(i + 33, j + 0, k + 29, placeBuildingBlock(random), 0, 2);
		world.setBlock(i + 49, j + 0, k + 29, placeBuildingBlock(random), 0, 2);
		world.setBlock(i + 32, j + 0, k + 30, placeBuildingBlock(random), 0, 2);
		world.setBlock(i + 50, j + 0, k + 30, placeBuildingBlock(random), 0, 2);
		world.setBlock(i + 31, j + 0, k + 31, placeBuildingBlock(random), 0, 2);
		world.setBlock(i + 51, j + 0, k + 31, placeBuildingBlock(random), 0, 2);
		world.setBlock(i + 30, j + 0, k + 32, placeBuildingBlock(random), 0, 2);
		world.setBlock(i + 52, j + 0, k + 32, placeBuildingBlock(random), 0, 2);
		world.setBlock(i + 29, j + 0, k + 33, placeBuildingBlock(random), 0, 2);
		world.setBlock(i + 53, j + 0, k + 33, placeBuildingBlock(random), 0, 2);
		world.setBlock(i + 28, j + 0, k + 34, placeBuildingBlock(random), 0, 2);
		world.setBlock(i + 54, j + 0, k + 34, placeBuildingBlock(random), 0, 2);
		world.setBlock(i + 27, j + 0, k + 35, placeBuildingBlock(random), 0, 2);
		world.setBlock(i + 55, j + 0, k + 35, placeBuildingBlock(random), 0, 2);
		world.setBlock(i + 26, j + 0, k + 36, placeBuildingBlock(random), 0, 2);
		world.setBlock(i + 56, j + 0, k + 36, placeBuildingBlock(random), 0, 2);
		world.setBlock(i + 25, j + 0, k + 37, placeBuildingBlock(random), 0, 2);
		world.setBlock(i + 57, j + 0, k + 37, placeBuildingBlock(random), 0, 2);
		world.setBlock(i + 24, j + 0, k + 38, placeBuildingBlock(random), 0, 2);
		world.setBlock(i + 58, j + 0, k + 38, placeBuildingBlock(random), 0, 2);
		world.setBlock(i + 23, j + 0, k + 39, placeBuildingBlock(random), 0, 2);
		world.setBlock(i + 59, j + 0, k + 39, placeBuildingBlock(random), 0, 2);
		world.setBlock(i + 22, j + 0, k + 40, placeBuildingBlock(random), 0, 2);
		world.setBlock(i + 60, j + 0, k + 40, placeBuildingBlock(random), 0, 2);
		world.setBlock(i + 21, j + 0, k + 41, placeBuildingBlock(random), 0, 2);
		world.setBlock(i + 61, j + 0, k + 41, placeBuildingBlock(random), 0, 2);
		world.setBlock(i + 20, j + 0, k + 42, placeBuildingBlock(random), 0, 2);
		world.setBlock(i + 62, j + 0, k + 42, placeBuildingBlock(random), 0, 2);
		world.setBlock(i + 19, j + 0, k + 43, placeBuildingBlock(random), 0, 2);
		world.setBlock(i + 63, j + 0, k + 43, placeBuildingBlock(random), 0, 2);
		world.setBlock(i + 18, j + 0, k + 44, placeBuildingBlock(random), 0, 2);
		world.setBlock(i + 64, j + 0, k + 44, placeBuildingBlock(random), 0, 2);
		world.setBlock(i + 17, j + 0, k + 45, placeBuildingBlock(random), 0, 2);
		world.setBlock(i + 65, j + 0, k + 45, placeBuildingBlock(random), 0, 2);
		world.setBlock(i + 16, j + 0, k + 46, placeBuildingBlock(random), 0, 2);
		world.setBlock(i + 66, j + 0, k + 46, placeBuildingBlock(random), 0, 2);
		world.setBlock(i + 15, j + 0, k + 47, placeBuildingBlock(random), 0, 2);
		world.setBlock(i + 67, j + 0, k + 47, placeBuildingBlock(random), 0, 2);
		world.setBlock(i + 14, j + 0, k + 48, placeBuildingBlock(random), 0, 2);
		world.setBlock(i + 68, j + 0, k + 48, placeBuildingBlock(random), 0, 2);
		world.setBlock(i + 13, j + 0, k + 49, placeBuildingBlock(random), 0, 2);
		world.setBlock(i + 69, j + 0, k + 49, placeBuildingBlock(random), 0, 2);
		world.setBlock(i + 14, j + 0, k + 50, placeBuildingBlock(random), 0, 2);
		world.setBlock(i + 68, j + 0, k + 50, placeBuildingBlock(random), 0, 2);
		world.setBlock(i + 15, j + 0, k + 51, placeBuildingBlock(random), 0, 2);
		world.setBlock(i + 67, j + 0, k + 51, placeBuildingBlock(random), 0, 2);
		world.setBlock(i + 16, j + 0, k + 52, placeBuildingBlock(random), 0, 2);
		world.setBlock(i + 66, j + 0, k + 52, placeBuildingBlock(random), 0, 2);
		world.setBlock(i + 17, j + 0, k + 53, placeBuildingBlock(random), 0, 2);
		world.setBlock(i + 65, j + 0, k + 53, placeBuildingBlock(random), 0, 2);
		world.setBlock(i + 18, j + 0, k + 54, placeBuildingBlock(random), 0, 2);
		world.setBlock(i + 64, j + 0, k + 54, placeBuildingBlock(random), 0, 2);
		world.setBlock(i + 19, j + 0, k + 55, placeBuildingBlock(random), 0, 2);
		world.setBlock(i + 63, j + 0, k + 55, placeBuildingBlock(random), 0, 2);
		world.setBlock(i + 20, j + 0, k + 56, placeBuildingBlock(random), 0, 2);
		world.setBlock(i + 62, j + 0, k + 56, placeBuildingBlock(random), 0, 2);
		world.setBlock(i + 21, j + 0, k + 57, placeBuildingBlock(random), 0, 2);
		world.setBlock(i + 61, j + 0, k + 57, placeBuildingBlock(random), 0, 2);
		world.setBlock(i + 22, j + 0, k + 58, placeBuildingBlock(random), 0, 2);
		world.setBlock(i + 60, j + 0, k + 58, placeBuildingBlock(random), 0, 2);
		world.setBlock(i + 23, j + 0, k + 59, placeBuildingBlock(random), 0, 2);
		world.setBlock(i + 59, j + 0, k + 59, placeBuildingBlock(random), 0, 2);
		world.setBlock(i + 24, j + 0, k + 60, placeBuildingBlock(random), 0, 2);
		world.setBlock(i + 58, j + 0, k + 60, placeBuildingBlock(random), 0, 2);
		world.setBlock(i + 25, j + 0, k + 61, placeBuildingBlock(random), 0, 2);
		world.setBlock(i + 57, j + 0, k + 61, placeBuildingBlock(random), 0, 2);
		world.setBlock(i + 26, j + 0, k + 62, placeBuildingBlock(random), 0, 2);
		world.setBlock(i + 56, j + 0, k + 62, placeBuildingBlock(random), 0, 2);
		world.setBlock(i + 27, j + 0, k + 63, placeBuildingBlock(random), 0, 2);
		world.setBlock(i + 55, j + 0, k + 63, placeBuildingBlock(random), 0, 2);
		world.setBlock(i + 28, j + 0, k + 64, placeBuildingBlock(random), 0, 2);
		world.setBlock(i + 54, j + 0, k + 64, placeBuildingBlock(random), 0, 2);
		world.setBlock(i + 29, j + 0, k + 65, placeBuildingBlock(random), 0, 2);
		world.setBlock(i + 53, j + 0, k + 65, placeBuildingBlock(random), 0, 2);
		world.setBlock(i + 30, j + 0, k + 66, placeBuildingBlock(random), 0, 2);
		world.setBlock(i + 52, j + 0, k + 66, placeBuildingBlock(random), 0, 2);
		world.setBlock(i + 31, j + 0, k + 67, placeBuildingBlock(random), 0, 2);
		world.setBlock(i + 51, j + 0, k + 67, placeBuildingBlock(random), 0, 2);
		world.setBlock(i + 32, j + 0, k + 68, placeBuildingBlock(random), 0, 2);
		world.setBlock(i + 50, j + 0, k + 68, placeBuildingBlock(random), 0, 2);
		world.setBlock(i + 33, j + 0, k + 69, placeBuildingBlock(random), 0, 2);
		world.setBlock(i + 49, j + 0, k + 69, placeBuildingBlock(random), 0, 2);
		world.setBlock(i + 34, j + 0, k + 70, placeBuildingBlock(random), 0, 2);
		world.setBlock(i + 48, j + 0, k + 70, placeBuildingBlock(random), 0, 2);
		world.setBlock(i + 35, j + 0, k + 71, placeBuildingBlock(random), 0, 2);
		world.setBlock(i + 47, j + 0, k + 71, placeBuildingBlock(random), 0, 2);
		world.setBlock(i + 36, j + 0, k + 72, placeBuildingBlock(random), 0, 2);
		world.setBlock(i + 46, j + 0, k + 72, placeBuildingBlock(random), 0, 2);
		world.setBlock(i + 37, j + 0, k + 73, placeBuildingBlock(random), 0, 2);
		world.setBlock(i + 45, j + 0, k + 73, placeBuildingBlock(random), 0, 2);
		world.setBlock(i + 38, j + 0, k + 74, placeBuildingBlock(random), 0, 2);
		world.setBlock(i + 44, j + 0, k + 74, placeBuildingBlock(random), 0, 2);
		world.setBlock(i + 39, j + 0, k + 75, placeBuildingBlock(random), 0, 2);
		world.setBlock(i + 43, j + 0, k + 75, placeBuildingBlock(random), 0, 2);
		world.setBlock(i + 40, j + 0, k + 76, placeBuildingBlock(random), 0, 2);
		world.setBlock(i + 42, j + 0, k + 76, placeBuildingBlock(random), 0, 2);
		world.setBlock(i + 41, j + 0, k + 77, placeBuildingBlock(random), 0, 2);
		world.setBlock(i + 41, j + 1, k + 16, placeBuildingBlock(random), 0, 2);
		world.setBlock(i + 41, j + 1, k + 17, placeBuildingBlock(random), 0, 2);
		world.setBlock(i + 40, j + 1, k + 18, placeBuildingBlock(random), 0, 2);
		world.setBlock(i + 41, j + 1, k + 18, placeBuildingBlock(random), 0, 2);
		world.setBlock(i + 42, j + 1, k + 18, placeBuildingBlock(random), 0, 2);
		world.setBlock(i + 39, j + 1, k + 19, placeBuildingBlock(random), 0, 2);
		world.setBlock(i + 40, j + 1, k + 19, placeBuildingBlock(random), 0, 2);
		world.setBlock(i + 41, j + 1, k + 19, placeBuildingBlock(random), 0, 2);
		world.setBlock(i + 42, j + 1, k + 19, placeBuildingBlock(random), 0, 2);
		world.setBlock(i + 43, j + 1, k + 19, placeBuildingBlock(random), 0, 2);
		world.setBlock(i + 38, j + 1, k + 20, placeBuildingBlock(random), 0, 2);
		world.setBlock(i + 39, j + 1, k + 20, placeBuildingBlock(random), 0, 2);
		world.setBlock(i + 40, j + 1, k + 20, placeBuildingBlock(random), 0, 2);
		world.setBlock(i + 41, j + 1, k + 20, placeBuildingBlock(random), 0, 2);
		world.setBlock(i + 42, j + 1, k + 20, placeBuildingBlock(random), 0, 2);
		world.setBlock(i + 43, j + 1, k + 20, placeBuildingBlock(random), 0, 2);
		world.setBlock(i + 44, j + 1, k + 20, placeBuildingBlock(random), 0, 2);
		world.setBlock(i + 37, j + 1, k + 21, placeBuildingBlock(random), 0, 2);
		world.setBlock(i + 38, j + 1, k + 21, placeBuildingBlock(random), 0, 2);
		world.setBlock(i + 39, j + 1, k + 21, placeBuildingBlock(random), 0, 2);
		world.setBlock(i + 40, j + 1, k + 21, placeBuildingBlock(random), 0, 2);
		world.setBlock(i + 42, j + 1, k + 21, placeBuildingBlock(random), 0, 2);
		world.setBlock(i + 43, j + 1, k + 21, placeBuildingBlock(random), 0, 2);
		world.setBlock(i + 44, j + 1, k + 21, placeBuildingBlock(random), 0, 2);
		world.setBlock(i + 45, j + 1, k + 21, placeBuildingBlock(random), 0, 2);
		world.setBlock(i + 36, j + 1, k + 22, placeBuildingBlock(random), 0, 2);
		world.setBlock(i + 37, j + 1, k + 22, placeBuildingBlock(random), 0, 2);
		world.setBlock(i + 38, j + 1, k + 22, placeBuildingBlock(random), 0, 2);
		world.setBlock(i + 39, j + 1, k + 22, placeBuildingBlock(random), 0, 2);
		world.setBlock(i + 43, j + 1, k + 22, placeBuildingBlock(random), 0, 2);
		world.setBlock(i + 44, j + 1, k + 22, placeBuildingBlock(random), 0, 2);
		world.setBlock(i + 45, j + 1, k + 22, placeBuildingBlock(random), 0, 2);
		world.setBlock(i + 46, j + 1, k + 22, placeBuildingBlock(random), 0, 2);
		world.setBlock(i + 35, j + 1, k + 23, placeBuildingBlock(random), 0, 2);
		world.setBlock(i + 36, j + 1, k + 23, placeBuildingBlock(random), 0, 2);
		world.setBlock(i + 37, j + 1, k + 23, placeBuildingBlock(random), 0, 2);
		world.setBlock(i + 38, j + 1, k + 23, placeBuildingBlock(random), 0, 2);
		world.setBlock(i + 44, j + 1, k + 23, placeBuildingBlock(random), 0, 2);
		world.setBlock(i + 45, j + 1, k + 23, placeBuildingBlock(random), 0, 2);
		world.setBlock(i + 46, j + 1, k + 23, placeBuildingBlock(random), 0, 2);
		world.setBlock(i + 47, j + 1, k + 23, placeBuildingBlock(random), 0, 2);
		world.setBlock(i + 34, j + 1, k + 24, placeBuildingBlock(random), 0, 2);
		world.setBlock(i + 35, j + 1, k + 24, placeBuildingBlock(random), 0, 2);
		world.setBlock(i + 36, j + 1, k + 24, placeBuildingBlock(random), 0, 2);
		world.setBlock(i + 37, j + 1, k + 24, placeBuildingBlock(random), 0, 2);
		world.setBlock(i + 45, j + 1, k + 24, placeBuildingBlock(random), 0, 2);
		world.setBlock(i + 46, j + 1, k + 24, placeBuildingBlock(random), 0, 2);
		world.setBlock(i + 47, j + 1, k + 24, placeBuildingBlock(random), 0, 2);
		world.setBlock(i + 48, j + 1, k + 24, placeBuildingBlock(random), 0, 2);
		world.setBlock(i + 33, j + 1, k + 25, placeBuildingBlock(random), 0, 2);
		world.setBlock(i + 34, j + 1, k + 25, placeBuildingBlock(random), 0, 2);
		world.setBlock(i + 35, j + 1, k + 25, placeBuildingBlock(random), 0, 2);
		world.setBlock(i + 36, j + 1, k + 25, placeBuildingBlock(random), 0, 2);
		world.setBlock(i + 46, j + 1, k + 25, placeBuildingBlock(random), 0, 2);
		world.setBlock(i + 47, j + 1, k + 25, placeBuildingBlock(random), 0, 2);
		world.setBlock(i + 48, j + 1, k + 25, placeBuildingBlock(random), 0, 2);
		world.setBlock(i + 49, j + 1, k + 25, placeBuildingBlock(random), 0, 2);
		world.setBlock(i + 32, j + 1, k + 26, placeBuildingBlock(random), 0, 2);
		world.setBlock(i + 33, j + 1, k + 26, placeBuildingBlock(random), 0, 2);
		world.setBlock(i + 34, j + 1, k + 26, placeBuildingBlock(random), 0, 2);
		world.setBlock(i + 35, j + 1, k + 26, placeBuildingBlock(random), 0, 2);
		world.setBlock(i + 47, j + 1, k + 26, placeBuildingBlock(random), 0, 2);
		world.setBlock(i + 48, j + 1, k + 26, placeBuildingBlock(random), 0, 2);
		world.setBlock(i + 49, j + 1, k + 26, placeBuildingBlock(random), 0, 2);
		world.setBlock(i + 50, j + 1, k + 26, placeBuildingBlock(random), 0, 2);
		world.setBlock(i + 31, j + 1, k + 27, placeBuildingBlock(random), 0, 2);
		world.setBlock(i + 32, j + 1, k + 27, placeBuildingBlock(random), 0, 2);
		world.setBlock(i + 33, j + 1, k + 27, placeBuildingBlock(random), 0, 2);
		world.setBlock(i + 34, j + 1, k + 27, placeBuildingBlock(random), 0, 2);
		world.setBlock(i + 48, j + 1, k + 27, placeBuildingBlock(random), 0, 2);
		world.setBlock(i + 49, j + 1, k + 27, placeBuildingBlock(random), 0, 2);
		world.setBlock(i + 50, j + 1, k + 27, placeBuildingBlock(random), 0, 2);
		world.setBlock(i + 51, j + 1, k + 27, placeBuildingBlock(random), 0, 2);
		world.setBlock(i + 30, j + 1, k + 28, placeBuildingBlock(random), 0, 2);
		world.setBlock(i + 31, j + 1, k + 28, placeBuildingBlock(random), 0, 2);
		world.setBlock(i + 32, j + 1, k + 28, placeBuildingBlock(random), 0, 2);
		world.setBlock(i + 33, j + 1, k + 28, placeBuildingBlock(random), 0, 2);
		world.setBlock(i + 49, j + 1, k + 28, placeBuildingBlock(random), 0, 2);
		world.setBlock(i + 50, j + 1, k + 28, placeBuildingBlock(random), 0, 2);
		world.setBlock(i + 51, j + 1, k + 28, placeBuildingBlock(random), 0, 2);
		world.setBlock(i + 52, j + 1, k + 28, placeBuildingBlock(random), 0, 2);
		world.setBlock(i + 29, j + 1, k + 29, placeBuildingBlock(random), 0, 2);
		world.setBlock(i + 30, j + 1, k + 29, placeBuildingBlock(random), 0, 2);
		world.setBlock(i + 31, j + 1, k + 29, placeBuildingBlock(random), 0, 2);
		world.setBlock(i + 32, j + 1, k + 29, placeBuildingBlock(random), 0, 2);
		world.setBlock(i + 50, j + 1, k + 29, placeBuildingBlock(random), 0, 2);
		world.setBlock(i + 51, j + 1, k + 29, placeBuildingBlock(random), 0, 2);
		world.setBlock(i + 52, j + 1, k + 29, placeBuildingBlock(random), 0, 2);
		world.setBlock(i + 53, j + 1, k + 29, placeBuildingBlock(random), 0, 2);
		world.setBlock(i + 28, j + 1, k + 30, placeBuildingBlock(random), 0, 2);
		world.setBlock(i + 29, j + 1, k + 30, placeBuildingBlock(random), 0, 2);
		world.setBlock(i + 30, j + 1, k + 30, placeBuildingBlock(random), 0, 2);
		world.setBlock(i + 31, j + 1, k + 30, placeBuildingBlock(random), 0, 2);
		world.setBlock(i + 51, j + 1, k + 30, placeBuildingBlock(random), 0, 2);
		world.setBlock(i + 52, j + 1, k + 30, placeBuildingBlock(random), 0, 2);
		world.setBlock(i + 53, j + 1, k + 30, placeBuildingBlock(random), 0, 2);
		world.setBlock(i + 54, j + 1, k + 30, placeBuildingBlock(random), 0, 2);
		world.setBlock(i + 27, j + 1, k + 31, placeBuildingBlock(random), 0, 2);
		world.setBlock(i + 28, j + 1, k + 31, placeBuildingBlock(random), 0, 2);
		world.setBlock(i + 29, j + 1, k + 31, placeBuildingBlock(random), 0, 2);
		world.setBlock(i + 30, j + 1, k + 31, placeBuildingBlock(random), 0, 2);
		world.setBlock(i + 52, j + 1, k + 31, placeBuildingBlock(random), 0, 2);
		world.setBlock(i + 53, j + 1, k + 31, placeBuildingBlock(random), 0, 2);
		world.setBlock(i + 54, j + 1, k + 31, placeBuildingBlock(random), 0, 2);
		world.setBlock(i + 55, j + 1, k + 31, placeBuildingBlock(random), 0, 2);
		world.setBlock(i + 26, j + 1, k + 32, placeBuildingBlock(random), 0, 2);
		world.setBlock(i + 27, j + 1, k + 32, placeBuildingBlock(random), 0, 2);
		world.setBlock(i + 28, j + 1, k + 32, placeBuildingBlock(random), 0, 2);
		world.setBlock(i + 29, j + 1, k + 32, placeBuildingBlock(random), 0, 2);
		world.setBlock(i + 53, j + 1, k + 32, placeBuildingBlock(random), 0, 2);
		world.setBlock(i + 54, j + 1, k + 32, placeBuildingBlock(random), 0, 2);
		world.setBlock(i + 55, j + 1, k + 32, placeBuildingBlock(random), 0, 2);
		world.setBlock(i + 56, j + 1, k + 32, placeBuildingBlock(random), 0, 2);
		world.setBlock(i + 25, j + 1, k + 33, placeBuildingBlock(random), 0, 2);
		world.setBlock(i + 26, j + 1, k + 33, placeBuildingBlock(random), 0, 2);
		world.setBlock(i + 27, j + 1, k + 33, placeBuildingBlock(random), 0, 2);
		world.setBlock(i + 28, j + 1, k + 33, placeBuildingBlock(random), 0, 2);
		world.setBlock(i + 54, j + 1, k + 33, placeBuildingBlock(random), 0, 2);
		world.setBlock(i + 55, j + 1, k + 33, placeBuildingBlock(random), 0, 2);
		world.setBlock(i + 56, j + 1, k + 33, placeBuildingBlock(random), 0, 2);
		world.setBlock(i + 57, j + 1, k + 33, placeBuildingBlock(random), 0, 2);
		world.setBlock(i + 24, j + 1, k + 34, placeBuildingBlock(random), 0, 2);
		world.setBlock(i + 25, j + 1, k + 34, placeBuildingBlock(random), 0, 2);
		world.setBlock(i + 26, j + 1, k + 34, placeBuildingBlock(random), 0, 2);
		world.setBlock(i + 27, j + 1, k + 34, placeBuildingBlock(random), 0, 2);
		world.setBlock(i + 55, j + 1, k + 34, placeBuildingBlock(random), 0, 2);
		world.setBlock(i + 56, j + 1, k + 34, placeBuildingBlock(random), 0, 2);
		world.setBlock(i + 57, j + 1, k + 34, placeBuildingBlock(random), 0, 2);
		world.setBlock(i + 58, j + 1, k + 34, placeBuildingBlock(random), 0, 2);
		world.setBlock(i + 23, j + 1, k + 35, placeBuildingBlock(random), 0, 2);
		world.setBlock(i + 24, j + 1, k + 35, placeBuildingBlock(random), 0, 2);
		world.setBlock(i + 25, j + 1, k + 35, placeBuildingBlock(random), 0, 2);
		world.setBlock(i + 26, j + 1, k + 35, placeBuildingBlock(random), 0, 2);
		world.setBlock(i + 56, j + 1, k + 35, placeBuildingBlock(random), 0, 2);
		world.setBlock(i + 57, j + 1, k + 35, placeBuildingBlock(random), 0, 2);
		world.setBlock(i + 58, j + 1, k + 35, placeBuildingBlock(random), 0, 2);
		world.setBlock(i + 59, j + 1, k + 35, placeBuildingBlock(random), 0, 2);
		world.setBlock(i + 22, j + 1, k + 36, placeBuildingBlock(random), 0, 2);
		world.setBlock(i + 23, j + 1, k + 36, placeBuildingBlock(random), 0, 2);
		world.setBlock(i + 24, j + 1, k + 36, placeBuildingBlock(random), 0, 2);
		world.setBlock(i + 25, j + 1, k + 36, placeBuildingBlock(random), 0, 2);
		world.setBlock(i + 57, j + 1, k + 36, placeBuildingBlock(random), 0, 2);
		world.setBlock(i + 58, j + 1, k + 36, placeBuildingBlock(random), 0, 2);
		world.setBlock(i + 59, j + 1, k + 36, placeBuildingBlock(random), 0, 2);
		world.setBlock(i + 60, j + 1, k + 36, placeBuildingBlock(random), 0, 2);
		world.setBlock(i + 21, j + 1, k + 37, placeBuildingBlock(random), 0, 2);
		world.setBlock(i + 22, j + 1, k + 37, placeBuildingBlock(random), 0, 2);
		world.setBlock(i + 23, j + 1, k + 37, placeBuildingBlock(random), 0, 2);
		world.setBlock(i + 24, j + 1, k + 37, placeBuildingBlock(random), 0, 2);
		world.setBlock(i + 58, j + 1, k + 37, placeBuildingBlock(random), 0, 2);
		world.setBlock(i + 59, j + 1, k + 37, placeBuildingBlock(random), 0, 2);
		world.setBlock(i + 60, j + 1, k + 37, placeBuildingBlock(random), 0, 2);
		world.setBlock(i + 61, j + 1, k + 37, placeBuildingBlock(random), 0, 2);
		world.setBlock(i + 20, j + 1, k + 38, placeBuildingBlock(random), 0, 2);
		world.setBlock(i + 21, j + 1, k + 38, placeBuildingBlock(random), 0, 2);
		world.setBlock(i + 22, j + 1, k + 38, placeBuildingBlock(random), 0, 2);
		world.setBlock(i + 23, j + 1, k + 38, placeBuildingBlock(random), 0, 2);
		world.setBlock(i + 59, j + 1, k + 38, placeBuildingBlock(random), 0, 2);
		world.setBlock(i + 60, j + 1, k + 38, placeBuildingBlock(random), 0, 2);
		world.setBlock(i + 61, j + 1, k + 38, placeBuildingBlock(random), 0, 2);
		world.setBlock(i + 62, j + 1, k + 38, placeBuildingBlock(random), 0, 2);
		world.setBlock(i + 19, j + 1, k + 39, placeBuildingBlock(random), 0, 2);
		world.setBlock(i + 20, j + 1, k + 39, placeBuildingBlock(random), 0, 2);
		world.setBlock(i + 21, j + 1, k + 39, placeBuildingBlock(random), 0, 2);
		world.setBlock(i + 22, j + 1, k + 39, placeBuildingBlock(random), 0, 2);
		world.setBlock(i + 60, j + 1, k + 39, placeBuildingBlock(random), 0, 2);
		world.setBlock(i + 61, j + 1, k + 39, placeBuildingBlock(random), 0, 2);
		world.setBlock(i + 62, j + 1, k + 39, placeBuildingBlock(random), 0, 2);
		world.setBlock(i + 63, j + 1, k + 39, placeBuildingBlock(random), 0, 2);
		world.setBlock(i + 18, j + 1, k + 40, placeBuildingBlock(random), 0, 2);
		world.setBlock(i + 19, j + 1, k + 40, placeBuildingBlock(random), 0, 2);
		world.setBlock(i + 20, j + 1, k + 40, placeBuildingBlock(random), 0, 2);
		world.setBlock(i + 21, j + 1, k + 40, placeBuildingBlock(random), 0, 2);
		world.setBlock(i + 61, j + 1, k + 40, placeBuildingBlock(random), 0, 2);
		world.setBlock(i + 62, j + 1, k + 40, placeBuildingBlock(random), 0, 2);
		world.setBlock(i + 63, j + 1, k + 40, placeBuildingBlock(random), 0, 2);
		world.setBlock(i + 64, j + 1, k + 40, placeBuildingBlock(random), 0, 2);
		world.setBlock(i + 17, j + 1, k + 41, placeBuildingBlock(random), 0, 2);
		world.setBlock(i + 18, j + 1, k + 41, placeBuildingBlock(random), 0, 2);
		world.setBlock(i + 19, j + 1, k + 41, placeBuildingBlock(random), 0, 2);
		world.setBlock(i + 20, j + 1, k + 41, placeBuildingBlock(random), 0, 2);
		world.setBlock(i + 62, j + 1, k + 41, placeBuildingBlock(random), 0, 2);
		world.setBlock(i + 63, j + 1, k + 41, placeBuildingBlock(random), 0, 2);
		world.setBlock(i + 64, j + 1, k + 41, placeBuildingBlock(random), 0, 2);
		world.setBlock(i + 65, j + 1, k + 41, placeBuildingBlock(random), 0, 2);
		world.setBlock(i + 16, j + 1, k + 42, placeBuildingBlock(random), 0, 2);
		world.setBlock(i + 17, j + 1, k + 42, placeBuildingBlock(random), 0, 2);
		world.setBlock(i + 18, j + 1, k + 42, placeBuildingBlock(random), 0, 2);
		world.setBlock(i + 19, j + 1, k + 42, placeBuildingBlock(random), 0, 2);
		world.setBlock(i + 63, j + 1, k + 42, placeBuildingBlock(random), 0, 2);
		world.setBlock(i + 64, j + 1, k + 42, placeBuildingBlock(random), 0, 2);
		world.setBlock(i + 65, j + 1, k + 42, placeBuildingBlock(random), 0, 2);
		world.setBlock(i + 66, j + 1, k + 42, placeBuildingBlock(random), 0, 2);
		world.setBlock(i + 15, j + 1, k + 43, placeBuildingBlock(random), 0, 2);
		world.setBlock(i + 16, j + 1, k + 43, placeBuildingBlock(random), 0, 2);
		world.setBlock(i + 17, j + 1, k + 43, placeBuildingBlock(random), 0, 2);
		world.setBlock(i + 18, j + 1, k + 43, placeBuildingBlock(random), 0, 2);
		world.setBlock(i + 64, j + 1, k + 43, placeBuildingBlock(random), 0, 2);
		world.setBlock(i + 65, j + 1, k + 43, placeBuildingBlock(random), 0, 2);
		world.setBlock(i + 66, j + 1, k + 43, placeBuildingBlock(random), 0, 2);
		world.setBlock(i + 67, j + 1, k + 43, placeBuildingBlock(random), 0, 2);
		world.setBlock(i + 14, j + 1, k + 44, placeBuildingBlock(random), 0, 2);
		world.setBlock(i + 15, j + 1, k + 44, placeBuildingBlock(random), 0, 2);
		world.setBlock(i + 16, j + 1, k + 44, placeBuildingBlock(random), 0, 2);
		world.setBlock(i + 17, j + 1, k + 44, placeBuildingBlock(random), 0, 2);
		world.setBlock(i + 65, j + 1, k + 44, placeBuildingBlock(random), 0, 2);
		world.setBlock(i + 66, j + 1, k + 44, placeBuildingBlock(random), 0, 2);
		world.setBlock(i + 67, j + 1, k + 44, placeBuildingBlock(random), 0, 2);
		world.setBlock(i + 68, j + 1, k + 44, placeBuildingBlock(random), 0, 2);
		world.setBlock(i + 13, j + 1, k + 45, placeBuildingBlock(random), 0, 2);
		world.setBlock(i + 14, j + 1, k + 45, placeBuildingBlock(random), 0, 2);
		world.setBlock(i + 15, j + 1, k + 45, placeBuildingBlock(random), 0, 2);
		world.setBlock(i + 16, j + 1, k + 45, placeBuildingBlock(random), 0, 2);
		world.setBlock(i + 66, j + 1, k + 45, placeBuildingBlock(random), 0, 2);
		world.setBlock(i + 67, j + 1, k + 45, placeBuildingBlock(random), 0, 2);
		world.setBlock(i + 68, j + 1, k + 45, placeBuildingBlock(random), 0, 2);
		world.setBlock(i + 69, j + 1, k + 45, placeBuildingBlock(random), 0, 2);
		world.setBlock(i + 12, j + 1, k + 46, placeBuildingBlock(random), 0, 2);
		world.setBlock(i + 13, j + 1, k + 46, placeBuildingBlock(random), 0, 2);
		world.setBlock(i + 14, j + 1, k + 46, placeBuildingBlock(random), 0, 2);
		world.setBlock(i + 15, j + 1, k + 46, placeBuildingBlock(random), 0, 2);
		world.setBlock(i + 67, j + 1, k + 46, placeBuildingBlock(random), 0, 2);
		world.setBlock(i + 68, j + 1, k + 46, placeBuildingBlock(random), 0, 2);
		world.setBlock(i + 69, j + 1, k + 46, placeBuildingBlock(random), 0, 2);
		world.setBlock(i + 70, j + 1, k + 46, placeBuildingBlock(random), 0, 2);
		world.setBlock(i + 11, j + 1, k + 47, placeBuildingBlock(random), 0, 2);
		world.setBlock(i + 12, j + 1, k + 47, placeBuildingBlock(random), 0, 2);
		world.setBlock(i + 13, j + 1, k + 47, placeBuildingBlock(random), 0, 2);
		world.setBlock(i + 14, j + 1, k + 47, placeBuildingBlock(random), 0, 2);
		world.setBlock(i + 68, j + 1, k + 47, placeBuildingBlock(random), 0, 2);
		world.setBlock(i + 69, j + 1, k + 47, placeBuildingBlock(random), 0, 2);
		world.setBlock(i + 70, j + 1, k + 47, placeBuildingBlock(random), 0, 2);
		world.setBlock(i + 71, j + 1, k + 47, placeBuildingBlock(random), 0, 2);
		world.setBlock(i + 10, j + 1, k + 48, placeBuildingBlock(random), 0, 2);
		world.setBlock(i + 11, j + 1, k + 48, placeBuildingBlock(random), 0, 2);
		world.setBlock(i + 12, j + 1, k + 48, placeBuildingBlock(random), 0, 2);
		world.setBlock(i + 13, j + 1, k + 48, placeBuildingBlock(random), 0, 2);
		world.setBlock(i + 69, j + 1, k + 48, placeBuildingBlock(random), 0, 2);
		world.setBlock(i + 70, j + 1, k + 48, placeBuildingBlock(random), 0, 2);
		world.setBlock(i + 71, j + 1, k + 48, placeBuildingBlock(random), 0, 2);
		world.setBlock(i + 72, j + 1, k + 48, placeBuildingBlock(random), 0, 2);
		world.setBlock(i + 8, j + 1, k + 49, placeBuildingBlock(random), 0, 2);
		world.setBlock(i + 9, j + 1, k + 49, placeBuildingBlock(random), 0, 2);
		world.setBlock(i + 10, j + 1, k + 49, placeBuildingBlock(random), 0, 2);
		world.setBlock(i + 11, j + 1, k + 49, placeBuildingBlock(random), 0, 2);
		world.setBlock(i + 12, j + 1, k + 49, placeBuildingBlock(random), 0, 2);
		world.setBlock(i + 70, j + 1, k + 49, placeBuildingBlock(random), 0, 2);
		world.setBlock(i + 71, j + 1, k + 49, placeBuildingBlock(random), 0, 2);
		world.setBlock(i + 72, j + 1, k + 49, placeBuildingBlock(random), 0, 2);
		world.setBlock(i + 73, j + 1, k + 49, placeBuildingBlock(random), 0, 2);
		world.setBlock(i + 10, j + 1, k + 50, placeBuildingBlock(random), 0, 2);
		world.setBlock(i + 11, j + 1, k + 50, placeBuildingBlock(random), 0, 2);
		world.setBlock(i + 12, j + 1, k + 50, placeBuildingBlock(random), 0, 2);
		world.setBlock(i + 13, j + 1, k + 50, placeBuildingBlock(random), 0, 2);
		world.setBlock(i + 69, j + 1, k + 50, placeBuildingBlock(random), 0, 2);
		world.setBlock(i + 70, j + 1, k + 50, placeBuildingBlock(random), 0, 2);
		world.setBlock(i + 71, j + 1, k + 50, placeBuildingBlock(random), 0, 2);
		world.setBlock(i + 72, j + 1, k + 50, placeBuildingBlock(random), 0, 2);
		world.setBlock(i + 11, j + 1, k + 51, placeBuildingBlock(random), 0, 2);
		world.setBlock(i + 12, j + 1, k + 51, placeBuildingBlock(random), 0, 2);
		world.setBlock(i + 13, j + 1, k + 51, placeBuildingBlock(random), 0, 2);
		world.setBlock(i + 14, j + 1, k + 51, placeBuildingBlock(random), 0, 2);
		world.setBlock(i + 68, j + 1, k + 51, placeBuildingBlock(random), 0, 2);
		world.setBlock(i + 69, j + 1, k + 51, placeBuildingBlock(random), 0, 2);
		world.setBlock(i + 70, j + 1, k + 51, placeBuildingBlock(random), 0, 2);
		world.setBlock(i + 71, j + 1, k + 51, placeBuildingBlock(random), 0, 2);
		world.setBlock(i + 12, j + 1, k + 52, placeBuildingBlock(random), 0, 2);
		world.setBlock(i + 13, j + 1, k + 52, placeBuildingBlock(random), 0, 2);
		world.setBlock(i + 14, j + 1, k + 52, placeBuildingBlock(random), 0, 2);
		world.setBlock(i + 15, j + 1, k + 52, placeBuildingBlock(random), 0, 2);
		world.setBlock(i + 67, j + 1, k + 52, placeBuildingBlock(random), 0, 2);
		world.setBlock(i + 68, j + 1, k + 52, placeBuildingBlock(random), 0, 2);
		world.setBlock(i + 69, j + 1, k + 52, placeBuildingBlock(random), 0, 2);
		world.setBlock(i + 70, j + 1, k + 52, placeBuildingBlock(random), 0, 2);
		world.setBlock(i + 13, j + 1, k + 53, placeBuildingBlock(random), 0, 2);
		world.setBlock(i + 14, j + 1, k + 53, placeBuildingBlock(random), 0, 2);
		world.setBlock(i + 15, j + 1, k + 53, placeBuildingBlock(random), 0, 2);
		world.setBlock(i + 16, j + 1, k + 53, placeBuildingBlock(random), 0, 2);
		world.setBlock(i + 66, j + 1, k + 53, placeBuildingBlock(random), 0, 2);
		world.setBlock(i + 67, j + 1, k + 53, placeBuildingBlock(random), 0, 2);
		world.setBlock(i + 68, j + 1, k + 53, placeBuildingBlock(random), 0, 2);
		world.setBlock(i + 69, j + 1, k + 53, placeBuildingBlock(random), 0, 2);
		world.setBlock(i + 14, j + 1, k + 54, placeBuildingBlock(random), 0, 2);
		world.setBlock(i + 15, j + 1, k + 54, placeBuildingBlock(random), 0, 2);
		world.setBlock(i + 16, j + 1, k + 54, placeBuildingBlock(random), 0, 2);
		world.setBlock(i + 17, j + 1, k + 54, placeBuildingBlock(random), 0, 2);
		world.setBlock(i + 65, j + 1, k + 54, placeBuildingBlock(random), 0, 2);
		world.setBlock(i + 66, j + 1, k + 54, placeBuildingBlock(random), 0, 2);
		world.setBlock(i + 67, j + 1, k + 54, placeBuildingBlock(random), 0, 2);
		world.setBlock(i + 68, j + 1, k + 54, placeBuildingBlock(random), 0, 2);
		world.setBlock(i + 15, j + 1, k + 55, placeBuildingBlock(random), 0, 2);
		world.setBlock(i + 16, j + 1, k + 55, placeBuildingBlock(random), 0, 2);
		world.setBlock(i + 17, j + 1, k + 55, placeBuildingBlock(random), 0, 2);
		world.setBlock(i + 18, j + 1, k + 55, placeBuildingBlock(random), 0, 2);
		world.setBlock(i + 64, j + 1, k + 55, placeBuildingBlock(random), 0, 2);
		world.setBlock(i + 65, j + 1, k + 55, placeBuildingBlock(random), 0, 2);
		world.setBlock(i + 66, j + 1, k + 55, placeBuildingBlock(random), 0, 2);
		world.setBlock(i + 67, j + 1, k + 55, placeBuildingBlock(random), 0, 2);
		world.setBlock(i + 16, j + 1, k + 56, placeBuildingBlock(random), 0, 2);
		world.setBlock(i + 17, j + 1, k + 56, placeBuildingBlock(random), 0, 2);
		world.setBlock(i + 18, j + 1, k + 56, placeBuildingBlock(random), 0, 2);
		world.setBlock(i + 19, j + 1, k + 56, placeBuildingBlock(random), 0, 2);
		world.setBlock(i + 63, j + 1, k + 56, placeBuildingBlock(random), 0, 2);
		world.setBlock(i + 64, j + 1, k + 56, placeBuildingBlock(random), 0, 2);
		world.setBlock(i + 65, j + 1, k + 56, placeBuildingBlock(random), 0, 2);
		world.setBlock(i + 66, j + 1, k + 56, placeBuildingBlock(random), 0, 2);
		world.setBlock(i + 17, j + 1, k + 57, placeBuildingBlock(random), 0, 2);
		world.setBlock(i + 18, j + 1, k + 57, placeBuildingBlock(random), 0, 2);
		world.setBlock(i + 19, j + 1, k + 57, placeBuildingBlock(random), 0, 2);
		world.setBlock(i + 20, j + 1, k + 57, placeBuildingBlock(random), 0, 2);
		world.setBlock(i + 62, j + 1, k + 57, placeBuildingBlock(random), 0, 2);
		world.setBlock(i + 63, j + 1, k + 57, placeBuildingBlock(random), 0, 2);
		world.setBlock(i + 64, j + 1, k + 57, placeBuildingBlock(random), 0, 2);
		world.setBlock(i + 65, j + 1, k + 57, placeBuildingBlock(random), 0, 2);
		world.setBlock(i + 18, j + 1, k + 58, placeBuildingBlock(random), 0, 2);
		world.setBlock(i + 19, j + 1, k + 58, placeBuildingBlock(random), 0, 2);
		world.setBlock(i + 20, j + 1, k + 58, placeBuildingBlock(random), 0, 2);
		world.setBlock(i + 21, j + 1, k + 58, placeBuildingBlock(random), 0, 2);
		world.setBlock(i + 61, j + 1, k + 58, placeBuildingBlock(random), 0, 2);
		world.setBlock(i + 62, j + 1, k + 58, placeBuildingBlock(random), 0, 2);
		world.setBlock(i + 63, j + 1, k + 58, placeBuildingBlock(random), 0, 2);
		world.setBlock(i + 64, j + 1, k + 58, placeBuildingBlock(random), 0, 2);
		world.setBlock(i + 19, j + 1, k + 59, placeBuildingBlock(random), 0, 2);
		world.setBlock(i + 20, j + 1, k + 59, placeBuildingBlock(random), 0, 2);
		world.setBlock(i + 21, j + 1, k + 59, placeBuildingBlock(random), 0, 2);
		world.setBlock(i + 22, j + 1, k + 59, placeBuildingBlock(random), 0, 2);
		world.setBlock(i + 60, j + 1, k + 59, placeBuildingBlock(random), 0, 2);
		world.setBlock(i + 61, j + 1, k + 59, placeBuildingBlock(random), 0, 2);
		world.setBlock(i + 62, j + 1, k + 59, placeBuildingBlock(random), 0, 2);
		world.setBlock(i + 63, j + 1, k + 59, placeBuildingBlock(random), 0, 2);
		world.setBlock(i + 20, j + 1, k + 60, placeBuildingBlock(random), 0, 2);
		world.setBlock(i + 21, j + 1, k + 60, placeBuildingBlock(random), 0, 2);
		world.setBlock(i + 22, j + 1, k + 60, placeBuildingBlock(random), 0, 2);
		world.setBlock(i + 23, j + 1, k + 60, placeBuildingBlock(random), 0, 2);
		world.setBlock(i + 59, j + 1, k + 60, placeBuildingBlock(random), 0, 2);
		world.setBlock(i + 60, j + 1, k + 60, placeBuildingBlock(random), 0, 2);
		world.setBlock(i + 61, j + 1, k + 60, placeBuildingBlock(random), 0, 2);
		world.setBlock(i + 62, j + 1, k + 60, placeBuildingBlock(random), 0, 2);
		world.setBlock(i + 21, j + 1, k + 61, placeBuildingBlock(random), 0, 2);
		world.setBlock(i + 22, j + 1, k + 61, placeBuildingBlock(random), 0, 2);
		world.setBlock(i + 23, j + 1, k + 61, placeBuildingBlock(random), 0, 2);
		world.setBlock(i + 24, j + 1, k + 61, placeBuildingBlock(random), 0, 2);
		world.setBlock(i + 58, j + 1, k + 61, placeBuildingBlock(random), 0, 2);
		world.setBlock(i + 59, j + 1, k + 61, placeBuildingBlock(random), 0, 2);
		world.setBlock(i + 60, j + 1, k + 61, placeBuildingBlock(random), 0, 2);
		world.setBlock(i + 61, j + 1, k + 61, placeBuildingBlock(random), 0, 2);
		world.setBlock(i + 22, j + 1, k + 62, placeBuildingBlock(random), 0, 2);
		world.setBlock(i + 23, j + 1, k + 62, placeBuildingBlock(random), 0, 2);
		world.setBlock(i + 24, j + 1, k + 62, placeBuildingBlock(random), 0, 2);
		world.setBlock(i + 25, j + 1, k + 62, placeBuildingBlock(random), 0, 2);
		world.setBlock(i + 57, j + 1, k + 62, placeBuildingBlock(random), 0, 2);
		world.setBlock(i + 58, j + 1, k + 62, placeBuildingBlock(random), 0, 2);
		world.setBlock(i + 59, j + 1, k + 62, placeBuildingBlock(random), 0, 2);
		world.setBlock(i + 60, j + 1, k + 62, placeBuildingBlock(random), 0, 2);
		world.setBlock(i + 23, j + 1, k + 63, placeBuildingBlock(random), 0, 2);
		world.setBlock(i + 24, j + 1, k + 63, placeBuildingBlock(random), 0, 2);
		world.setBlock(i + 25, j + 1, k + 63, placeBuildingBlock(random), 0, 2);
		world.setBlock(i + 26, j + 1, k + 63, placeBuildingBlock(random), 0, 2);
		world.setBlock(i + 56, j + 1, k + 63, placeBuildingBlock(random), 0, 2);
		world.setBlock(i + 57, j + 1, k + 63, placeBuildingBlock(random), 0, 2);
		world.setBlock(i + 58, j + 1, k + 63, placeBuildingBlock(random), 0, 2);
		world.setBlock(i + 59, j + 1, k + 63, placeBuildingBlock(random), 0, 2);
		world.setBlock(i + 24, j + 1, k + 64, placeBuildingBlock(random), 0, 2);
		world.setBlock(i + 25, j + 1, k + 64, placeBuildingBlock(random), 0, 2);
		world.setBlock(i + 26, j + 1, k + 64, placeBuildingBlock(random), 0, 2);
		world.setBlock(i + 27, j + 1, k + 64, placeBuildingBlock(random), 0, 2);
		world.setBlock(i + 55, j + 1, k + 64, placeBuildingBlock(random), 0, 2);
		world.setBlock(i + 56, j + 1, k + 64, placeBuildingBlock(random), 0, 2);
		world.setBlock(i + 57, j + 1, k + 64, placeBuildingBlock(random), 0, 2);
		world.setBlock(i + 58, j + 1, k + 64, placeBuildingBlock(random), 0, 2);
		world.setBlock(i + 25, j + 1, k + 65, placeBuildingBlock(random), 0, 2);
		world.setBlock(i + 26, j + 1, k + 65, placeBuildingBlock(random), 0, 2);
		world.setBlock(i + 27, j + 1, k + 65, placeBuildingBlock(random), 0, 2);
		world.setBlock(i + 28, j + 1, k + 65, placeBuildingBlock(random), 0, 2);
		world.setBlock(i + 54, j + 1, k + 65, placeBuildingBlock(random), 0, 2);
		world.setBlock(i + 55, j + 1, k + 65, placeBuildingBlock(random), 0, 2);
		world.setBlock(i + 56, j + 1, k + 65, placeBuildingBlock(random), 0, 2);
		world.setBlock(i + 57, j + 1, k + 65, placeBuildingBlock(random), 0, 2);
		world.setBlock(i + 26, j + 1, k + 66, placeBuildingBlock(random), 0, 2);
		world.setBlock(i + 27, j + 1, k + 66, placeBuildingBlock(random), 0, 2);
		world.setBlock(i + 28, j + 1, k + 66, placeBuildingBlock(random), 0, 2);
		world.setBlock(i + 29, j + 1, k + 66, placeBuildingBlock(random), 0, 2);
		world.setBlock(i + 53, j + 1, k + 66, placeBuildingBlock(random), 0, 2);
		world.setBlock(i + 54, j + 1, k + 66, placeBuildingBlock(random), 0, 2);
		world.setBlock(i + 55, j + 1, k + 66, placeBuildingBlock(random), 0, 2);
		world.setBlock(i + 56, j + 1, k + 66, placeBuildingBlock(random), 0, 2);
		world.setBlock(i + 27, j + 1, k + 67, placeBuildingBlock(random), 0, 2);
		world.setBlock(i + 28, j + 1, k + 67, placeBuildingBlock(random), 0, 2);
		world.setBlock(i + 29, j + 1, k + 67, placeBuildingBlock(random), 0, 2);
		world.setBlock(i + 30, j + 1, k + 67, placeBuildingBlock(random), 0, 2);
		world.setBlock(i + 52, j + 1, k + 67, placeBuildingBlock(random), 0, 2);
		world.setBlock(i + 53, j + 1, k + 67, placeBuildingBlock(random), 0, 2);
		world.setBlock(i + 54, j + 1, k + 67, placeBuildingBlock(random), 0, 2);
		world.setBlock(i + 55, j + 1, k + 67, placeBuildingBlock(random), 0, 2);
		world.setBlock(i + 28, j + 1, k + 68, placeBuildingBlock(random), 0, 2);
		world.setBlock(i + 29, j + 1, k + 68, placeBuildingBlock(random), 0, 2);
		world.setBlock(i + 30, j + 1, k + 68, placeBuildingBlock(random), 0, 2);
		world.setBlock(i + 31, j + 1, k + 68, placeBuildingBlock(random), 0, 2);
		world.setBlock(i + 51, j + 1, k + 68, placeBuildingBlock(random), 0, 2);
		world.setBlock(i + 52, j + 1, k + 68, placeBuildingBlock(random), 0, 2);
		world.setBlock(i + 53, j + 1, k + 68, placeBuildingBlock(random), 0, 2);
		world.setBlock(i + 54, j + 1, k + 68, placeBuildingBlock(random), 0, 2);
		world.setBlock(i + 29, j + 1, k + 69, placeBuildingBlock(random), 0, 2);
		world.setBlock(i + 30, j + 1, k + 69, placeBuildingBlock(random), 0, 2);
		world.setBlock(i + 31, j + 1, k + 69, placeBuildingBlock(random), 0, 2);
		world.setBlock(i + 32, j + 1, k + 69, placeBuildingBlock(random), 0, 2);
		world.setBlock(i + 50, j + 1, k + 69, placeBuildingBlock(random), 0, 2);
		world.setBlock(i + 51, j + 1, k + 69, placeBuildingBlock(random), 0, 2);
		world.setBlock(i + 52, j + 1, k + 69, placeBuildingBlock(random), 0, 2);
		world.setBlock(i + 53, j + 1, k + 69, placeBuildingBlock(random), 0, 2);
		world.setBlock(i + 30, j + 1, k + 70, placeBuildingBlock(random), 0, 2);
		world.setBlock(i + 31, j + 1, k + 70, placeBuildingBlock(random), 0, 2);
		world.setBlock(i + 32, j + 1, k + 70, placeBuildingBlock(random), 0, 2);
		world.setBlock(i + 33, j + 1, k + 70, placeBuildingBlock(random), 0, 2);
		world.setBlock(i + 49, j + 1, k + 70, placeBuildingBlock(random), 0, 2);
		world.setBlock(i + 50, j + 1, k + 70, placeBuildingBlock(random), 0, 2);
		world.setBlock(i + 51, j + 1, k + 70, placeBuildingBlock(random), 0, 2);
		world.setBlock(i + 52, j + 1, k + 70, placeBuildingBlock(random), 0, 2);
		world.setBlock(i + 31, j + 1, k + 71, placeBuildingBlock(random), 0, 2);
		world.setBlock(i + 32, j + 1, k + 71, placeBuildingBlock(random), 0, 2);
		world.setBlock(i + 33, j + 1, k + 71, placeBuildingBlock(random), 0, 2);
		world.setBlock(i + 34, j + 1, k + 71, placeBuildingBlock(random), 0, 2);
		world.setBlock(i + 48, j + 1, k + 71, placeBuildingBlock(random), 0, 2);
		world.setBlock(i + 49, j + 1, k + 71, placeBuildingBlock(random), 0, 2);
		world.setBlock(i + 50, j + 1, k + 71, placeBuildingBlock(random), 0, 2);
		world.setBlock(i + 51, j + 1, k + 71, placeBuildingBlock(random), 0, 2);
		world.setBlock(i + 32, j + 1, k + 72, placeBuildingBlock(random), 0, 2);
		world.setBlock(i + 33, j + 1, k + 72, placeBuildingBlock(random), 0, 2);
		world.setBlock(i + 34, j + 1, k + 72, placeBuildingBlock(random), 0, 2);
		world.setBlock(i + 35, j + 1, k + 72, placeBuildingBlock(random), 0, 2);
		world.setBlock(i + 47, j + 1, k + 72, placeBuildingBlock(random), 0, 2);
		world.setBlock(i + 48, j + 1, k + 72, placeBuildingBlock(random), 0, 2);
		world.setBlock(i + 49, j + 1, k + 72, placeBuildingBlock(random), 0, 2);
		world.setBlock(i + 50, j + 1, k + 72, placeBuildingBlock(random), 0, 2);
		world.setBlock(i + 33, j + 1, k + 73, placeBuildingBlock(random), 0, 2);
		world.setBlock(i + 34, j + 1, k + 73, placeBuildingBlock(random), 0, 2);
		world.setBlock(i + 35, j + 1, k + 73, placeBuildingBlock(random), 0, 2);
		world.setBlock(i + 36, j + 1, k + 73, placeBuildingBlock(random), 0, 2);
		world.setBlock(i + 46, j + 1, k + 73, placeBuildingBlock(random), 0, 2);
		world.setBlock(i + 47, j + 1, k + 73, placeBuildingBlock(random), 0, 2);
		world.setBlock(i + 48, j + 1, k + 73, placeBuildingBlock(random), 0, 2);
		world.setBlock(i + 49, j + 1, k + 73, placeBuildingBlock(random), 0, 2);
		world.setBlock(i + 34, j + 1, k + 74, placeBuildingBlock(random), 0, 2);
		world.setBlock(i + 35, j + 1, k + 74, placeBuildingBlock(random), 0, 2);
		world.setBlock(i + 36, j + 1, k + 74, placeBuildingBlock(random), 0, 2);
		world.setBlock(i + 37, j + 1, k + 74, placeBuildingBlock(random), 0, 2);
		world.setBlock(i + 45, j + 1, k + 74, placeBuildingBlock(random), 0, 2);
		world.setBlock(i + 46, j + 1, k + 74, placeBuildingBlock(random), 0, 2);
		world.setBlock(i + 47, j + 1, k + 74, placeBuildingBlock(random), 0, 2);
		world.setBlock(i + 48, j + 1, k + 74, placeBuildingBlock(random), 0, 2);
		world.setBlock(i + 35, j + 1, k + 75, placeBuildingBlock(random), 0, 2);
		world.setBlock(i + 36, j + 1, k + 75, placeBuildingBlock(random), 0, 2);
		world.setBlock(i + 37, j + 1, k + 75, placeBuildingBlock(random), 0, 2);
		world.setBlock(i + 38, j + 1, k + 75, placeBuildingBlock(random), 0, 2);
		world.setBlock(i + 44, j + 1, k + 75, placeBuildingBlock(random), 0, 2);
		world.setBlock(i + 45, j + 1, k + 75, placeBuildingBlock(random), 0, 2);
		world.setBlock(i + 46, j + 1, k + 75, placeBuildingBlock(random), 0, 2);
		world.setBlock(i + 47, j + 1, k + 75, placeBuildingBlock(random), 0, 2);
		world.setBlock(i + 36, j + 1, k + 76, placeBuildingBlock(random), 0, 2);
		world.setBlock(i + 37, j + 1, k + 76, placeBuildingBlock(random), 0, 2);
		world.setBlock(i + 38, j + 1, k + 76, placeBuildingBlock(random), 0, 2);
		world.setBlock(i + 39, j + 1, k + 76, placeBuildingBlock(random), 0, 2);
		world.setBlock(i + 43, j + 1, k + 76, placeBuildingBlock(random), 0, 2);
		world.setBlock(i + 44, j + 1, k + 76, placeBuildingBlock(random), 0, 2);
		world.setBlock(i + 45, j + 1, k + 76, placeBuildingBlock(random), 0, 2);
		world.setBlock(i + 46, j + 1, k + 76, placeBuildingBlock(random), 0, 2);
		world.setBlock(i + 37, j + 1, k + 77, placeBuildingBlock(random), 0, 2);
		world.setBlock(i + 38, j + 1, k + 77, placeBuildingBlock(random), 0, 2);
		world.setBlock(i + 39, j + 1, k + 77, placeBuildingBlock(random), 0, 2);
		world.setBlock(i + 40, j + 1, k + 77, placeBuildingBlock(random), 0, 2);
		world.setBlock(i + 42, j + 1, k + 77, placeBuildingBlock(random), 0, 2);
		world.setBlock(i + 43, j + 1, k + 77, placeBuildingBlock(random), 0, 2);
		world.setBlock(i + 44, j + 1, k + 77, placeBuildingBlock(random), 0, 2);
		world.setBlock(i + 45, j + 1, k + 77, placeBuildingBlock(random), 0, 2);
		world.setBlock(i + 38, j + 1, k + 78, placeBuildingBlock(random), 0, 2);
		world.setBlock(i + 39, j + 1, k + 78, placeBuildingBlock(random), 0, 2);
		world.setBlock(i + 40, j + 1, k + 78, placeBuildingBlock(random), 0, 2);
		world.setBlock(i + 41, j + 1, k + 78, placeBuildingBlock(random), 0, 2);
		world.setBlock(i + 42, j + 1, k + 78, placeBuildingBlock(random), 0, 2);
		world.setBlock(i + 43, j + 1, k + 78, placeBuildingBlock(random), 0, 2);
		world.setBlock(i + 44, j + 1, k + 78, placeBuildingBlock(random), 0, 2);
		world.setBlock(i + 39, j + 1, k + 79, placeBuildingBlock(random), 0, 2);
		world.setBlock(i + 40, j + 1, k + 79, placeBuildingBlock(random), 0, 2);
		world.setBlock(i + 41, j + 1, k + 79, placeBuildingBlock(random), 0, 2);
		world.setBlock(i + 42, j + 1, k + 79, placeBuildingBlock(random), 0, 2);
		world.setBlock(i + 43, j + 1, k + 79, placeBuildingBlock(random), 0, 2);
		world.setBlock(i + 40, j + 1, k + 80, placeBuildingBlock(random), 0, 2);
		world.setBlock(i + 41, j + 1, k + 80, placeBuildingBlock(random), 0, 2);
		world.setBlock(i + 42, j + 1, k + 80, placeBuildingBlock(random), 0, 2);
		world.setBlock(i + 41, j + 1, k + 81, placeBuildingBlock(random), 0, 2);
		world.setBlock(i + 41, j + 2, k + 16, placeBuildingBlock(random), 0, 2);
		world.setBlock(i + 41, j + 2, k + 17, placeBuildingBlock(random), 0, 2);
		world.setBlock(i + 40, j + 2, k + 18, placeBuildingBlock(random), 0, 2);
		world.setBlock(i + 41, j + 2, k + 18, placeBuildingBlock(random), 0, 2);
		world.setBlock(i + 42, j + 2, k + 18, placeBuildingBlock(random), 0, 2);
		world.setBlock(i + 39, j + 2, k + 19, placeBuildingBlock(random), 0, 2);
		world.setBlock(i + 40, j + 2, k + 19, placeBuildingBlock(random), 0, 2);
		world.setBlock(i + 41, j + 2, k + 19, placeBuildingBlock(random), 0, 2);
		world.setBlock(i + 42, j + 2, k + 19, placeBuildingBlock(random), 0, 2);
		world.setBlock(i + 43, j + 2, k + 19, placeBuildingBlock(random), 0, 2);
		world.setBlock(i + 38, j + 2, k + 20, placeBuildingBlock(random), 0, 2);
		world.setBlock(i + 39, j + 2, k + 20, placeBuildingBlock(random), 0, 2);
		world.setBlock(i + 40, j + 2, k + 20, placeBuildingBlock(random), 0, 2);
		world.setBlock(i + 42, j + 2, k + 20, placeBuildingBlock(random), 0, 2);
		world.setBlock(i + 43, j + 2, k + 20, placeBuildingBlock(random), 0, 2);
		world.setBlock(i + 44, j + 2, k + 20, placeBuildingBlock(random), 0, 2);
		world.setBlock(i + 37, j + 2, k + 21, placeBuildingBlock(random), 0, 2);
		world.setBlock(i + 38, j + 2, k + 21, placeBuildingBlock(random), 0, 2);
		world.setBlock(i + 39, j + 2, k + 21, placeBuildingBlock(random), 0, 2);
		world.setBlock(i + 43, j + 2, k + 21, placeBuildingBlock(random), 0, 2);
		world.setBlock(i + 44, j + 2, k + 21, placeBuildingBlock(random), 0, 2);
		world.setBlock(i + 45, j + 2, k + 21, placeBuildingBlock(random), 0, 2);
		world.setBlock(i + 36, j + 2, k + 22, placeBuildingBlock(random), 0, 2);
		world.setBlock(i + 37, j + 2, k + 22, placeBuildingBlock(random), 0, 2);
		world.setBlock(i + 38, j + 2, k + 22, placeBuildingBlock(random), 0, 2);
		world.setBlock(i + 44, j + 2, k + 22, placeBuildingBlock(random), 0, 2);
		world.setBlock(i + 45, j + 2, k + 22, placeBuildingBlock(random), 0, 2);
		world.setBlock(i + 46, j + 2, k + 22, placeBuildingBlock(random), 0, 2);
		world.setBlock(i + 35, j + 2, k + 23, placeBuildingBlock(random), 0, 2);
		world.setBlock(i + 36, j + 2, k + 23, placeBuildingBlock(random), 0, 2);
		world.setBlock(i + 37, j + 2, k + 23, placeBuildingBlock(random), 0, 2);
		world.setBlock(i + 45, j + 2, k + 23, placeBuildingBlock(random), 0, 2);
		world.setBlock(i + 46, j + 2, k + 23, placeBuildingBlock(random), 0, 2);
		world.setBlock(i + 47, j + 2, k + 23, placeBuildingBlock(random), 0, 2);
		world.setBlock(i + 34, j + 2, k + 24, placeBuildingBlock(random), 0, 2);
		world.setBlock(i + 35, j + 2, k + 24, placeBuildingBlock(random), 0, 2);
		world.setBlock(i + 36, j + 2, k + 24, placeBuildingBlock(random), 0, 2);
		world.setBlock(i + 46, j + 2, k + 24, placeBuildingBlock(random), 0, 2);
		world.setBlock(i + 47, j + 2, k + 24, placeBuildingBlock(random), 0, 2);
		world.setBlock(i + 48, j + 2, k + 24, placeBuildingBlock(random), 0, 2);
		world.setBlock(i + 33, j + 2, k + 25, placeBuildingBlock(random), 0, 2);
		world.setBlock(i + 34, j + 2, k + 25, placeBuildingBlock(random), 0, 2);
		world.setBlock(i + 35, j + 2, k + 25, placeBuildingBlock(random), 0, 2);
		world.setBlock(i + 47, j + 2, k + 25, placeBuildingBlock(random), 0, 2);
		world.setBlock(i + 48, j + 2, k + 25, placeBuildingBlock(random), 0, 2);
		world.setBlock(i + 49, j + 2, k + 25, placeBuildingBlock(random), 0, 2);
		world.setBlock(i + 32, j + 2, k + 26, placeBuildingBlock(random), 0, 2);
		world.setBlock(i + 33, j + 2, k + 26, placeBuildingBlock(random), 0, 2);
		world.setBlock(i + 34, j + 2, k + 26, placeBuildingBlock(random), 0, 2);
		world.setBlock(i + 48, j + 2, k + 26, placeBuildingBlock(random), 0, 2);
		world.setBlock(i + 49, j + 2, k + 26, placeBuildingBlock(random), 0, 2);
		world.setBlock(i + 50, j + 2, k + 26, placeBuildingBlock(random), 0, 2);
		world.setBlock(i + 31, j + 2, k + 27, placeBuildingBlock(random), 0, 2);
		world.setBlock(i + 32, j + 2, k + 27, placeBuildingBlock(random), 0, 2);
		world.setBlock(i + 33, j + 2, k + 27, placeBuildingBlock(random), 0, 2);
		world.setBlock(i + 49, j + 2, k + 27, placeBuildingBlock(random), 0, 2);
		world.setBlock(i + 50, j + 2, k + 27, placeBuildingBlock(random), 0, 2);
		world.setBlock(i + 51, j + 2, k + 27, placeBuildingBlock(random), 0, 2);
		world.setBlock(i + 30, j + 2, k + 28, placeBuildingBlock(random), 0, 2);
		world.setBlock(i + 31, j + 2, k + 28, placeBuildingBlock(random), 0, 2);
		world.setBlock(i + 32, j + 2, k + 28, placeBuildingBlock(random), 0, 2);
		world.setBlock(i + 50, j + 2, k + 28, placeBuildingBlock(random), 0, 2);
		world.setBlock(i + 51, j + 2, k + 28, placeBuildingBlock(random), 0, 2);
		world.setBlock(i + 52, j + 2, k + 28, placeBuildingBlock(random), 0, 2);
		world.setBlock(i + 29, j + 2, k + 29, placeBuildingBlock(random), 0, 2);
		world.setBlock(i + 30, j + 2, k + 29, placeBuildingBlock(random), 0, 2);
		world.setBlock(i + 31, j + 2, k + 29, placeBuildingBlock(random), 0, 2);
		world.setBlock(i + 51, j + 2, k + 29, placeBuildingBlock(random), 0, 2);
		world.setBlock(i + 52, j + 2, k + 29, placeBuildingBlock(random), 0, 2);
		world.setBlock(i + 53, j + 2, k + 29, placeBuildingBlock(random), 0, 2);
		world.setBlock(i + 28, j + 2, k + 30, placeBuildingBlock(random), 0, 2);
		world.setBlock(i + 29, j + 2, k + 30, placeBuildingBlock(random), 0, 2);
		world.setBlock(i + 30, j + 2, k + 30, placeBuildingBlock(random), 0, 2);
		world.setBlock(i + 52, j + 2, k + 30, placeBuildingBlock(random), 0, 2);
		world.setBlock(i + 53, j + 2, k + 30, placeBuildingBlock(random), 0, 2);
		world.setBlock(i + 54, j + 2, k + 30, placeBuildingBlock(random), 0, 2);
		world.setBlock(i + 27, j + 2, k + 31, placeBuildingBlock(random), 0, 2);
		world.setBlock(i + 28, j + 2, k + 31, placeBuildingBlock(random), 0, 2);
		world.setBlock(i + 29, j + 2, k + 31, placeBuildingBlock(random), 0, 2);
		world.setBlock(i + 53, j + 2, k + 31, placeBuildingBlock(random), 0, 2);
		world.setBlock(i + 54, j + 2, k + 31, placeBuildingBlock(random), 0, 2);
		world.setBlock(i + 55, j + 2, k + 31, placeBuildingBlock(random), 0, 2);
		world.setBlock(i + 26, j + 2, k + 32, placeBuildingBlock(random), 0, 2);
		world.setBlock(i + 27, j + 2, k + 32, placeBuildingBlock(random), 0, 2);
		world.setBlock(i + 28, j + 2, k + 32, placeBuildingBlock(random), 0, 2);
		world.setBlock(i + 54, j + 2, k + 32, placeBuildingBlock(random), 0, 2);
		world.setBlock(i + 55, j + 2, k + 32, placeBuildingBlock(random), 0, 2);
		world.setBlock(i + 56, j + 2, k + 32, placeBuildingBlock(random), 0, 2);
		world.setBlock(i + 25, j + 2, k + 33, placeBuildingBlock(random), 0, 2);
		world.setBlock(i + 26, j + 2, k + 33, placeBuildingBlock(random), 0, 2);
		world.setBlock(i + 27, j + 2, k + 33, placeBuildingBlock(random), 0, 2);
		world.setBlock(i + 55, j + 2, k + 33, placeBuildingBlock(random), 0, 2);
		world.setBlock(i + 56, j + 2, k + 33, placeBuildingBlock(random), 0, 2);
		world.setBlock(i + 57, j + 2, k + 33, placeBuildingBlock(random), 0, 2);
		world.setBlock(i + 24, j + 2, k + 34, placeBuildingBlock(random), 0, 2);
		world.setBlock(i + 25, j + 2, k + 34, placeBuildingBlock(random), 0, 2);
		world.setBlock(i + 26, j + 2, k + 34, placeBuildingBlock(random), 0, 2);
		world.setBlock(i + 56, j + 2, k + 34, placeBuildingBlock(random), 0, 2);
		world.setBlock(i + 57, j + 2, k + 34, placeBuildingBlock(random), 0, 2);
		world.setBlock(i + 58, j + 2, k + 34, placeBuildingBlock(random), 0, 2);
		world.setBlock(i + 23, j + 2, k + 35, placeBuildingBlock(random), 0, 2);
		world.setBlock(i + 24, j + 2, k + 35, placeBuildingBlock(random), 0, 2);
		world.setBlock(i + 25, j + 2, k + 35, placeBuildingBlock(random), 0, 2);
		world.setBlock(i + 57, j + 2, k + 35, placeBuildingBlock(random), 0, 2);
		world.setBlock(i + 58, j + 2, k + 35, placeBuildingBlock(random), 0, 2);
		world.setBlock(i + 59, j + 2, k + 35, placeBuildingBlock(random), 0, 2);
		world.setBlock(i + 22, j + 2, k + 36, placeBuildingBlock(random), 0, 2);
		world.setBlock(i + 23, j + 2, k + 36, placeBuildingBlock(random), 0, 2);
		world.setBlock(i + 24, j + 2, k + 36, placeBuildingBlock(random), 0, 2);
		world.setBlock(i + 58, j + 2, k + 36, placeBuildingBlock(random), 0, 2);
		world.setBlock(i + 59, j + 2, k + 36, placeBuildingBlock(random), 0, 2);
		world.setBlock(i + 60, j + 2, k + 36, placeBuildingBlock(random), 0, 2);
		world.setBlock(i + 21, j + 2, k + 37, placeBuildingBlock(random), 0, 2);
		world.setBlock(i + 22, j + 2, k + 37, placeBuildingBlock(random), 0, 2);
		world.setBlock(i + 23, j + 2, k + 37, placeBuildingBlock(random), 0, 2);
		world.setBlock(i + 59, j + 2, k + 37, placeBuildingBlock(random), 0, 2);
		world.setBlock(i + 60, j + 2, k + 37, placeBuildingBlock(random), 0, 2);
		world.setBlock(i + 61, j + 2, k + 37, placeBuildingBlock(random), 0, 2);
		world.setBlock(i + 20, j + 2, k + 38, placeBuildingBlock(random), 0, 2);
		world.setBlock(i + 21, j + 2, k + 38, placeBuildingBlock(random), 0, 2);
		world.setBlock(i + 22, j + 2, k + 38, placeBuildingBlock(random), 0, 2);
		world.setBlock(i + 60, j + 2, k + 38, placeBuildingBlock(random), 0, 2);
		world.setBlock(i + 61, j + 2, k + 38, placeBuildingBlock(random), 0, 2);
		world.setBlock(i + 62, j + 2, k + 38, placeBuildingBlock(random), 0, 2);
		world.setBlock(i + 19, j + 2, k + 39, placeBuildingBlock(random), 0, 2);
		world.setBlock(i + 20, j + 2, k + 39, placeBuildingBlock(random), 0, 2);
		world.setBlock(i + 21, j + 2, k + 39, placeBuildingBlock(random), 0, 2);
		world.setBlock(i + 61, j + 2, k + 39, placeBuildingBlock(random), 0, 2);
		world.setBlock(i + 62, j + 2, k + 39, placeBuildingBlock(random), 0, 2);
		world.setBlock(i + 63, j + 2, k + 39, placeBuildingBlock(random), 0, 2);
		world.setBlock(i + 18, j + 2, k + 40, placeBuildingBlock(random), 0, 2);
		world.setBlock(i + 19, j + 2, k + 40, placeBuildingBlock(random), 0, 2);
		world.setBlock(i + 20, j + 2, k + 40, placeBuildingBlock(random), 0, 2);
		world.setBlock(i + 62, j + 2, k + 40, placeBuildingBlock(random), 0, 2);
		world.setBlock(i + 63, j + 2, k + 40, placeBuildingBlock(random), 0, 2);
		world.setBlock(i + 64, j + 2, k + 40, placeBuildingBlock(random), 0, 2);
		world.setBlock(i + 17, j + 2, k + 41, placeBuildingBlock(random), 0, 2);
		world.setBlock(i + 18, j + 2, k + 41, placeBuildingBlock(random), 0, 2);
		world.setBlock(i + 19, j + 2, k + 41, placeBuildingBlock(random), 0, 2);
		world.setBlock(i + 63, j + 2, k + 41, placeBuildingBlock(random), 0, 2);
		world.setBlock(i + 64, j + 2, k + 41, placeBuildingBlock(random), 0, 2);
		world.setBlock(i + 65, j + 2, k + 41, placeBuildingBlock(random), 0, 2);
		world.setBlock(i + 16, j + 2, k + 42, placeBuildingBlock(random), 0, 2);
		world.setBlock(i + 17, j + 2, k + 42, placeBuildingBlock(random), 0, 2);
		world.setBlock(i + 18, j + 2, k + 42, placeBuildingBlock(random), 0, 2);
		world.setBlock(i + 64, j + 2, k + 42, placeBuildingBlock(random), 0, 2);
		world.setBlock(i + 65, j + 2, k + 42, placeBuildingBlock(random), 0, 2);
		world.setBlock(i + 66, j + 2, k + 42, placeBuildingBlock(random), 0, 2);
		world.setBlock(i + 15, j + 2, k + 43, placeBuildingBlock(random), 0, 2);
		world.setBlock(i + 16, j + 2, k + 43, placeBuildingBlock(random), 0, 2);
		world.setBlock(i + 17, j + 2, k + 43, placeBuildingBlock(random), 0, 2);
		world.setBlock(i + 65, j + 2, k + 43, placeBuildingBlock(random), 0, 2);
		world.setBlock(i + 66, j + 2, k + 43, placeBuildingBlock(random), 0, 2);
		world.setBlock(i + 67, j + 2, k + 43, placeBuildingBlock(random), 0, 2);
		world.setBlock(i + 14, j + 2, k + 44, placeBuildingBlock(random), 0, 2);
		world.setBlock(i + 15, j + 2, k + 44, placeBuildingBlock(random), 0, 2);
		world.setBlock(i + 16, j + 2, k + 44, placeBuildingBlock(random), 0, 2);
		world.setBlock(i + 66, j + 2, k + 44, placeBuildingBlock(random), 0, 2);
		world.setBlock(i + 67, j + 2, k + 44, placeBuildingBlock(random), 0, 2);
		world.setBlock(i + 68, j + 2, k + 44, placeBuildingBlock(random), 0, 2);
		world.setBlock(i + 13, j + 2, k + 45, placeBuildingBlock(random), 0, 2);
		world.setBlock(i + 14, j + 2, k + 45, placeBuildingBlock(random), 0, 2);
		world.setBlock(i + 15, j + 2, k + 45, placeBuildingBlock(random), 0, 2);
		world.setBlock(i + 67, j + 2, k + 45, placeBuildingBlock(random), 0, 2);
		world.setBlock(i + 68, j + 2, k + 45, placeBuildingBlock(random), 0, 2);
		world.setBlock(i + 69, j + 2, k + 45, placeBuildingBlock(random), 0, 2);
		world.setBlock(i + 12, j + 2, k + 46, placeBuildingBlock(random), 0, 2);
		world.setBlock(i + 13, j + 2, k + 46, placeBuildingBlock(random), 0, 2);
		world.setBlock(i + 14, j + 2, k + 46, placeBuildingBlock(random), 0, 2);
		world.setBlock(i + 68, j + 2, k + 46, placeBuildingBlock(random), 0, 2);
		world.setBlock(i + 69, j + 2, k + 46, placeBuildingBlock(random), 0, 2);
		world.setBlock(i + 70, j + 2, k + 46, placeBuildingBlock(random), 0, 2);
		world.setBlock(i + 11, j + 2, k + 47, placeBuildingBlock(random), 0, 2);
		world.setBlock(i + 12, j + 2, k + 47, placeBuildingBlock(random), 0, 2);
		world.setBlock(i + 13, j + 2, k + 47, placeBuildingBlock(random), 0, 2);
		world.setBlock(i + 69, j + 2, k + 47, placeBuildingBlock(random), 0, 2);
		world.setBlock(i + 70, j + 2, k + 47, placeBuildingBlock(random), 0, 2);
		world.setBlock(i + 71, j + 2, k + 47, placeBuildingBlock(random), 0, 2);
		world.setBlock(i + 10, j + 2, k + 48, placeBuildingBlock(random), 0, 2);
		world.setBlock(i + 11, j + 2, k + 48, placeBuildingBlock(random), 0, 2);
		world.setBlock(i + 12, j + 2, k + 48, placeBuildingBlock(random), 0, 2);
		world.setBlock(i + 70, j + 2, k + 48, placeBuildingBlock(random), 0, 2);
		world.setBlock(i + 71, j + 2, k + 48, placeBuildingBlock(random), 0, 2);
		world.setBlock(i + 72, j + 2, k + 48, placeBuildingBlock(random), 0, 2);
		world.setBlock(i + 8, j + 2, k + 49, placeBuildingBlock(random), 0, 2);
		world.setBlock(i + 9, j + 2, k + 49, placeBuildingBlock(random), 0, 2);
		world.setBlock(i + 10, j + 2, k + 49, placeBuildingBlock(random), 0, 2);
		world.setBlock(i + 11, j + 2, k + 49, placeBuildingBlock(random), 0, 2);
		world.setBlock(i + 71, j + 2, k + 49, placeBuildingBlock(random), 0, 2);
		world.setBlock(i + 72, j + 2, k + 49, placeBuildingBlock(random), 0, 2);
		world.setBlock(i + 73, j + 2, k + 49, placeBuildingBlock(random), 0, 2);
		world.setBlock(i + 10, j + 2, k + 50, placeBuildingBlock(random), 0, 2);
		world.setBlock(i + 11, j + 2, k + 50, placeBuildingBlock(random), 0, 2);
		world.setBlock(i + 12, j + 2, k + 50, placeBuildingBlock(random), 0, 2);
		world.setBlock(i + 70, j + 2, k + 50, placeBuildingBlock(random), 0, 2);
		world.setBlock(i + 71, j + 2, k + 50, placeBuildingBlock(random), 0, 2);
		world.setBlock(i + 72, j + 2, k + 50, placeBuildingBlock(random), 0, 2);
		world.setBlock(i + 11, j + 2, k + 51, placeBuildingBlock(random), 0, 2);
		world.setBlock(i + 12, j + 2, k + 51, placeBuildingBlock(random), 0, 2);
		world.setBlock(i + 13, j + 2, k + 51, placeBuildingBlock(random), 0, 2);
		world.setBlock(i + 69, j + 2, k + 51, placeBuildingBlock(random), 0, 2);
		world.setBlock(i + 70, j + 2, k + 51, placeBuildingBlock(random), 0, 2);
		world.setBlock(i + 71, j + 2, k + 51, placeBuildingBlock(random), 0, 2);
		world.setBlock(i + 12, j + 2, k + 52, placeBuildingBlock(random), 0, 2);
		world.setBlock(i + 13, j + 2, k + 52, placeBuildingBlock(random), 0, 2);
		world.setBlock(i + 14, j + 2, k + 52, placeBuildingBlock(random), 0, 2);
		world.setBlock(i + 68, j + 2, k + 52, placeBuildingBlock(random), 0, 2);
		world.setBlock(i + 69, j + 2, k + 52, placeBuildingBlock(random), 0, 2);
		world.setBlock(i + 70, j + 2, k + 52, placeBuildingBlock(random), 0, 2);
		world.setBlock(i + 13, j + 2, k + 53, placeBuildingBlock(random), 0, 2);
		world.setBlock(i + 14, j + 2, k + 53, placeBuildingBlock(random), 0, 2);
		world.setBlock(i + 15, j + 2, k + 53, placeBuildingBlock(random), 0, 2);
		world.setBlock(i + 67, j + 2, k + 53, placeBuildingBlock(random), 0, 2);
		world.setBlock(i + 68, j + 2, k + 53, placeBuildingBlock(random), 0, 2);
		world.setBlock(i + 69, j + 2, k + 53, placeBuildingBlock(random), 0, 2);
		world.setBlock(i + 14, j + 2, k + 54, placeBuildingBlock(random), 0, 2);
		world.setBlock(i + 15, j + 2, k + 54, placeBuildingBlock(random), 0, 2);
		world.setBlock(i + 16, j + 2, k + 54, placeBuildingBlock(random), 0, 2);
		world.setBlock(i + 66, j + 2, k + 54, placeBuildingBlock(random), 0, 2);
		world.setBlock(i + 67, j + 2, k + 54, placeBuildingBlock(random), 0, 2);
		world.setBlock(i + 68, j + 2, k + 54, placeBuildingBlock(random), 0, 2);
		world.setBlock(i + 15, j + 2, k + 55, placeBuildingBlock(random), 0, 2);
		world.setBlock(i + 16, j + 2, k + 55, placeBuildingBlock(random), 0, 2);
		world.setBlock(i + 17, j + 2, k + 55, placeBuildingBlock(random), 0, 2);
		world.setBlock(i + 65, j + 2, k + 55, placeBuildingBlock(random), 0, 2);
		world.setBlock(i + 66, j + 2, k + 55, placeBuildingBlock(random), 0, 2);
		world.setBlock(i + 67, j + 2, k + 55, placeBuildingBlock(random), 0, 2);
		world.setBlock(i + 16, j + 2, k + 56, placeBuildingBlock(random), 0, 2);
		world.setBlock(i + 17, j + 2, k + 56, placeBuildingBlock(random), 0, 2);
		world.setBlock(i + 18, j + 2, k + 56, placeBuildingBlock(random), 0, 2);
		world.setBlock(i + 64, j + 2, k + 56, placeBuildingBlock(random), 0, 2);
		world.setBlock(i + 65, j + 2, k + 56, placeBuildingBlock(random), 0, 2);
		world.setBlock(i + 66, j + 2, k + 56, placeBuildingBlock(random), 0, 2);
		world.setBlock(i + 17, j + 2, k + 57, placeBuildingBlock(random), 0, 2);
		world.setBlock(i + 18, j + 2, k + 57, placeBuildingBlock(random), 0, 2);
		world.setBlock(i + 19, j + 2, k + 57, placeBuildingBlock(random), 0, 2);
		world.setBlock(i + 63, j + 2, k + 57, placeBuildingBlock(random), 0, 2);
		world.setBlock(i + 64, j + 2, k + 57, placeBuildingBlock(random), 0, 2);
		world.setBlock(i + 65, j + 2, k + 57, placeBuildingBlock(random), 0, 2);
		world.setBlock(i + 18, j + 2, k + 58, placeBuildingBlock(random), 0, 2);
		world.setBlock(i + 19, j + 2, k + 58, placeBuildingBlock(random), 0, 2);
		world.setBlock(i + 20, j + 2, k + 58, placeBuildingBlock(random), 0, 2);
		world.setBlock(i + 62, j + 2, k + 58, placeBuildingBlock(random), 0, 2);
		world.setBlock(i + 63, j + 2, k + 58, placeBuildingBlock(random), 0, 2);
		world.setBlock(i + 64, j + 2, k + 58, placeBuildingBlock(random), 0, 2);
		world.setBlock(i + 19, j + 2, k + 59, placeBuildingBlock(random), 0, 2);
		world.setBlock(i + 20, j + 2, k + 59, placeBuildingBlock(random), 0, 2);
		world.setBlock(i + 21, j + 2, k + 59, placeBuildingBlock(random), 0, 2);
		world.setBlock(i + 61, j + 2, k + 59, placeBuildingBlock(random), 0, 2);
		world.setBlock(i + 62, j + 2, k + 59, placeBuildingBlock(random), 0, 2);
		world.setBlock(i + 63, j + 2, k + 59, placeBuildingBlock(random), 0, 2);
		world.setBlock(i + 20, j + 2, k + 60, placeBuildingBlock(random), 0, 2);
		world.setBlock(i + 21, j + 2, k + 60, placeBuildingBlock(random), 0, 2);
		world.setBlock(i + 22, j + 2, k + 60, placeBuildingBlock(random), 0, 2);
		world.setBlock(i + 60, j + 2, k + 60, placeBuildingBlock(random), 0, 2);
		world.setBlock(i + 61, j + 2, k + 60, placeBuildingBlock(random), 0, 2);
		world.setBlock(i + 62, j + 2, k + 60, placeBuildingBlock(random), 0, 2);
		world.setBlock(i + 21, j + 2, k + 61, placeBuildingBlock(random), 0, 2);
		world.setBlock(i + 22, j + 2, k + 61, placeBuildingBlock(random), 0, 2);
		world.setBlock(i + 23, j + 2, k + 61, placeBuildingBlock(random), 0, 2);
		world.setBlock(i + 59, j + 2, k + 61, placeBuildingBlock(random), 0, 2);
		world.setBlock(i + 60, j + 2, k + 61, placeBuildingBlock(random), 0, 2);
		world.setBlock(i + 61, j + 2, k + 61, placeBuildingBlock(random), 0, 2);
		world.setBlock(i + 22, j + 2, k + 62, placeBuildingBlock(random), 0, 2);
		world.setBlock(i + 23, j + 2, k + 62, placeBuildingBlock(random), 0, 2);
		world.setBlock(i + 24, j + 2, k + 62, placeBuildingBlock(random), 0, 2);
		world.setBlock(i + 58, j + 2, k + 62, placeBuildingBlock(random), 0, 2);
		world.setBlock(i + 59, j + 2, k + 62, placeBuildingBlock(random), 0, 2);
		world.setBlock(i + 60, j + 2, k + 62, placeBuildingBlock(random), 0, 2);
		world.setBlock(i + 23, j + 2, k + 63, placeBuildingBlock(random), 0, 2);
		world.setBlock(i + 24, j + 2, k + 63, placeBuildingBlock(random), 0, 2);
		world.setBlock(i + 25, j + 2, k + 63, placeBuildingBlock(random), 0, 2);
		world.setBlock(i + 57, j + 2, k + 63, placeBuildingBlock(random), 0, 2);
		world.setBlock(i + 58, j + 2, k + 63, placeBuildingBlock(random), 0, 2);
		world.setBlock(i + 59, j + 2, k + 63, placeBuildingBlock(random), 0, 2);
		world.setBlock(i + 24, j + 2, k + 64, placeBuildingBlock(random), 0, 2);
		world.setBlock(i + 25, j + 2, k + 64, placeBuildingBlock(random), 0, 2);
		world.setBlock(i + 26, j + 2, k + 64, placeBuildingBlock(random), 0, 2);
		world.setBlock(i + 56, j + 2, k + 64, placeBuildingBlock(random), 0, 2);
		world.setBlock(i + 57, j + 2, k + 64, placeBuildingBlock(random), 0, 2);
		world.setBlock(i + 58, j + 2, k + 64, placeBuildingBlock(random), 0, 2);
		world.setBlock(i + 25, j + 2, k + 65, placeBuildingBlock(random), 0, 2);
		world.setBlock(i + 26, j + 2, k + 65, placeBuildingBlock(random), 0, 2);
		world.setBlock(i + 27, j + 2, k + 65, placeBuildingBlock(random), 0, 2);
		world.setBlock(i + 55, j + 2, k + 65, placeBuildingBlock(random), 0, 2);
		world.setBlock(i + 56, j + 2, k + 65, placeBuildingBlock(random), 0, 2);
		world.setBlock(i + 57, j + 2, k + 65, placeBuildingBlock(random), 0, 2);
		world.setBlock(i + 26, j + 2, k + 66, placeBuildingBlock(random), 0, 2);
		world.setBlock(i + 27, j + 2, k + 66, placeBuildingBlock(random), 0, 2);
		world.setBlock(i + 28, j + 2, k + 66, placeBuildingBlock(random), 0, 2);
		world.setBlock(i + 54, j + 2, k + 66, placeBuildingBlock(random), 0, 2);
		world.setBlock(i + 55, j + 2, k + 66, placeBuildingBlock(random), 0, 2);
		world.setBlock(i + 56, j + 2, k + 66, placeBuildingBlock(random), 0, 2);
		world.setBlock(i + 27, j + 2, k + 67, placeBuildingBlock(random), 0, 2);
		world.setBlock(i + 28, j + 2, k + 67, placeBuildingBlock(random), 0, 2);
		world.setBlock(i + 29, j + 2, k + 67, placeBuildingBlock(random), 0, 2);
		world.setBlock(i + 53, j + 2, k + 67, placeBuildingBlock(random), 0, 2);
		world.setBlock(i + 54, j + 2, k + 67, placeBuildingBlock(random), 0, 2);
		world.setBlock(i + 55, j + 2, k + 67, placeBuildingBlock(random), 0, 2);
		world.setBlock(i + 28, j + 2, k + 68, placeBuildingBlock(random), 0, 2);
		world.setBlock(i + 29, j + 2, k + 68, placeBuildingBlock(random), 0, 2);
		world.setBlock(i + 30, j + 2, k + 68, placeBuildingBlock(random), 0, 2);
		world.setBlock(i + 52, j + 2, k + 68, placeBuildingBlock(random), 0, 2);
		world.setBlock(i + 53, j + 2, k + 68, placeBuildingBlock(random), 0, 2);
		world.setBlock(i + 54, j + 2, k + 68, placeBuildingBlock(random), 0, 2);
		world.setBlock(i + 29, j + 2, k + 69, placeBuildingBlock(random), 0, 2);
		world.setBlock(i + 30, j + 2, k + 69, placeBuildingBlock(random), 0, 2);
		world.setBlock(i + 31, j + 2, k + 69, placeBuildingBlock(random), 0, 2);
		world.setBlock(i + 51, j + 2, k + 69, placeBuildingBlock(random), 0, 2);
		world.setBlock(i + 52, j + 2, k + 69, placeBuildingBlock(random), 0, 2);
		world.setBlock(i + 53, j + 2, k + 69, placeBuildingBlock(random), 0, 2);
		world.setBlock(i + 30, j + 2, k + 70, placeBuildingBlock(random), 0, 2);
		world.setBlock(i + 31, j + 2, k + 70, placeBuildingBlock(random), 0, 2);
		world.setBlock(i + 32, j + 2, k + 70, placeBuildingBlock(random), 0, 2);
		world.setBlock(i + 50, j + 2, k + 70, placeBuildingBlock(random), 0, 2);
		world.setBlock(i + 51, j + 2, k + 70, placeBuildingBlock(random), 0, 2);
		world.setBlock(i + 52, j + 2, k + 70, placeBuildingBlock(random), 0, 2);
		world.setBlock(i + 31, j + 2, k + 71, placeBuildingBlock(random), 0, 2);
		world.setBlock(i + 32, j + 2, k + 71, placeBuildingBlock(random), 0, 2);
		world.setBlock(i + 33, j + 2, k + 71, placeBuildingBlock(random), 0, 2);
		world.setBlock(i + 49, j + 2, k + 71, placeBuildingBlock(random), 0, 2);
		world.setBlock(i + 50, j + 2, k + 71, placeBuildingBlock(random), 0, 2);
		world.setBlock(i + 51, j + 2, k + 71, placeBuildingBlock(random), 0, 2);
		world.setBlock(i + 32, j + 2, k + 72, placeBuildingBlock(random), 0, 2);
		world.setBlock(i + 33, j + 2, k + 72, placeBuildingBlock(random), 0, 2);
		world.setBlock(i + 34, j + 2, k + 72, placeBuildingBlock(random), 0, 2);
		world.setBlock(i + 48, j + 2, k + 72, placeBuildingBlock(random), 0, 2);
		world.setBlock(i + 49, j + 2, k + 72, placeBuildingBlock(random), 0, 2);
		world.setBlock(i + 50, j + 2, k + 72, placeBuildingBlock(random), 0, 2);
		world.setBlock(i + 33, j + 2, k + 73, placeBuildingBlock(random), 0, 2);
		world.setBlock(i + 34, j + 2, k + 73, placeBuildingBlock(random), 0, 2);
		world.setBlock(i + 35, j + 2, k + 73, placeBuildingBlock(random), 0, 2);
		world.setBlock(i + 47, j + 2, k + 73, placeBuildingBlock(random), 0, 2);
		world.setBlock(i + 48, j + 2, k + 73, placeBuildingBlock(random), 0, 2);
		world.setBlock(i + 49, j + 2, k + 73, placeBuildingBlock(random), 0, 2);
		world.setBlock(i + 34, j + 2, k + 74, placeBuildingBlock(random), 0, 2);
		world.setBlock(i + 35, j + 2, k + 74, placeBuildingBlock(random), 0, 2);
		world.setBlock(i + 36, j + 2, k + 74, placeBuildingBlock(random), 0, 2);
		world.setBlock(i + 46, j + 2, k + 74, placeBuildingBlock(random), 0, 2);
		world.setBlock(i + 47, j + 2, k + 74, placeBuildingBlock(random), 0, 2);
		world.setBlock(i + 48, j + 2, k + 74, placeBuildingBlock(random), 0, 2);
		world.setBlock(i + 35, j + 2, k + 75, placeBuildingBlock(random), 0, 2);
		world.setBlock(i + 36, j + 2, k + 75, placeBuildingBlock(random), 0, 2);
		world.setBlock(i + 37, j + 2, k + 75, placeBuildingBlock(random), 0, 2);
		world.setBlock(i + 45, j + 2, k + 75, placeBuildingBlock(random), 0, 2);
		world.setBlock(i + 46, j + 2, k + 75, placeBuildingBlock(random), 0, 2);
		world.setBlock(i + 47, j + 2, k + 75, placeBuildingBlock(random), 0, 2);
		world.setBlock(i + 36, j + 2, k + 76, placeBuildingBlock(random), 0, 2);
		world.setBlock(i + 37, j + 2, k + 76, placeBuildingBlock(random), 0, 2);
		world.setBlock(i + 38, j + 2, k + 76, placeBuildingBlock(random), 0, 2);
		world.setBlock(i + 44, j + 2, k + 76, placeBuildingBlock(random), 0, 2);
		world.setBlock(i + 45, j + 2, k + 76, placeBuildingBlock(random), 0, 2);
		world.setBlock(i + 46, j + 2, k + 76, placeBuildingBlock(random), 0, 2);
		world.setBlock(i + 37, j + 2, k + 77, placeBuildingBlock(random), 0, 2);
		world.setBlock(i + 38, j + 2, k + 77, placeBuildingBlock(random), 0, 2);
		world.setBlock(i + 39, j + 2, k + 77, placeBuildingBlock(random), 0, 2);
		world.setBlock(i + 43, j + 2, k + 77, placeBuildingBlock(random), 0, 2);
		world.setBlock(i + 44, j + 2, k + 77, placeBuildingBlock(random), 0, 2);
		world.setBlock(i + 45, j + 2, k + 77, placeBuildingBlock(random), 0, 2);
		world.setBlock(i + 38, j + 2, k + 78, placeBuildingBlock(random), 0, 2);
		world.setBlock(i + 39, j + 2, k + 78, placeBuildingBlock(random), 0, 2);
		world.setBlock(i + 40, j + 2, k + 78, placeBuildingBlock(random), 0, 2);
		world.setBlock(i + 42, j + 2, k + 78, placeBuildingBlock(random), 0, 2);
		world.setBlock(i + 43, j + 2, k + 78, placeBuildingBlock(random), 0, 2);
		world.setBlock(i + 44, j + 2, k + 78, placeBuildingBlock(random), 0, 2);
		world.setBlock(i + 39, j + 2, k + 79, placeBuildingBlock(random), 0, 2);
		world.setBlock(i + 40, j + 2, k + 79, placeBuildingBlock(random), 0, 2);
		world.setBlock(i + 41, j + 2, k + 79, placeBuildingBlock(random), 0, 2);
		world.setBlock(i + 42, j + 2, k + 79, placeBuildingBlock(random), 0, 2);
		world.setBlock(i + 43, j + 2, k + 79, placeBuildingBlock(random), 0, 2);
		world.setBlock(i + 40, j + 2, k + 80, placeBuildingBlock(random), 0, 2);
		world.setBlock(i + 41, j + 2, k + 80, placeBuildingBlock(random), 0, 2);
		world.setBlock(i + 42, j + 2, k + 80, placeBuildingBlock(random), 0, 2);
		world.setBlock(i + 41, j + 2, k + 81, placeBuildingBlock(random), 0, 2);
		world.setBlock(i + 41, j + 3, k + 15, placeBuildingBlock(random), 0, 2);
		world.setBlock(i + 41, j + 3, k + 16, placeBuildingBlock(random), 0, 2);
		world.setBlock(i + 41, j + 3, k + 17, placeBuildingBlock(random), 0, 2);
		world.setBlock(i + 40, j + 3, k + 18, placeBuildingBlock(random), 0, 2);
		world.setBlock(i + 41, j + 3, k + 18, placeBuildingBlock(random), 0, 2);
		world.setBlock(i + 42, j + 3, k + 18, placeBuildingBlock(random), 0, 2);
		world.setBlock(i + 39, j + 3, k + 19, placeBuildingBlock(random), 0, 2);
		world.setBlock(i + 40, j + 3, k + 19, placeBuildingBlock(random), 0, 2);
		world.setBlock(i + 42, j + 3, k + 19, placeBuildingBlock(random), 0, 2);
		world.setBlock(i + 43, j + 3, k + 19, placeBuildingBlock(random), 0, 2);
		world.setBlock(i + 38, j + 3, k + 20, placeBuildingBlock(random), 0, 2);
		world.setBlock(i + 39, j + 3, k + 20, placeBuildingBlock(random), 0, 2);
		world.setBlock(i + 43, j + 3, k + 20, placeBuildingBlock(random), 0, 2);
		world.setBlock(i + 44, j + 3, k + 20, placeBuildingBlock(random), 0, 2);
		world.setBlock(i + 37, j + 3, k + 21, placeBuildingBlock(random), 0, 2);
		world.setBlock(i + 38, j + 3, k + 21, placeBuildingBlock(random), 0, 2);
		world.setBlock(i + 44, j + 3, k + 21, placeBuildingBlock(random), 0, 2);
		world.setBlock(i + 45, j + 3, k + 21, placeBuildingBlock(random), 0, 2);
		world.setBlock(i + 36, j + 3, k + 22, placeBuildingBlock(random), 0, 2);
		world.setBlock(i + 37, j + 3, k + 22, placeBuildingBlock(random), 0, 2);
		world.setBlock(i + 45, j + 3, k + 22, placeBuildingBlock(random), 0, 2);
		world.setBlock(i + 46, j + 3, k + 22, placeBuildingBlock(random), 0, 2);
		world.setBlock(i + 35, j + 3, k + 23, placeBuildingBlock(random), 0, 2);
		world.setBlock(i + 36, j + 3, k + 23, placeBuildingBlock(random), 0, 2);
		world.setBlock(i + 46, j + 3, k + 23, placeBuildingBlock(random), 0, 2);
		world.setBlock(i + 47, j + 3, k + 23, placeBuildingBlock(random), 0, 2);
		world.setBlock(i + 34, j + 3, k + 24, placeBuildingBlock(random), 0, 2);
		world.setBlock(i + 35, j + 3, k + 24, placeBuildingBlock(random), 0, 2);
		world.setBlock(i + 47, j + 3, k + 24, placeBuildingBlock(random), 0, 2);
		world.setBlock(i + 48, j + 3, k + 24, placeBuildingBlock(random), 0, 2);
		world.setBlock(i + 33, j + 3, k + 25, placeBuildingBlock(random), 0, 2);
		world.setBlock(i + 34, j + 3, k + 25, placeBuildingBlock(random), 0, 2);
		world.setBlock(i + 48, j + 3, k + 25, placeBuildingBlock(random), 0, 2);
		world.setBlock(i + 49, j + 3, k + 25, placeBuildingBlock(random), 0, 2);
		world.setBlock(i + 32, j + 3, k + 26, placeBuildingBlock(random), 0, 2);
		world.setBlock(i + 33, j + 3, k + 26, placeBuildingBlock(random), 0, 2);
		world.setBlock(i + 49, j + 3, k + 26, placeBuildingBlock(random), 0, 2);
		world.setBlock(i + 50, j + 3, k + 26, placeBuildingBlock(random), 0, 2);
		world.setBlock(i + 31, j + 3, k + 27, placeBuildingBlock(random), 0, 2);
		world.setBlock(i + 32, j + 3, k + 27, placeBuildingBlock(random), 0, 2);
		world.setBlock(i + 50, j + 3, k + 27, placeBuildingBlock(random), 0, 2);
		world.setBlock(i + 51, j + 3, k + 27, placeBuildingBlock(random), 0, 2);
		world.setBlock(i + 30, j + 3, k + 28, placeBuildingBlock(random), 0, 2);
		world.setBlock(i + 31, j + 3, k + 28, placeBuildingBlock(random), 0, 2);
		world.setBlock(i + 51, j + 3, k + 28, placeBuildingBlock(random), 0, 2);
		world.setBlock(i + 52, j + 3, k + 28, placeBuildingBlock(random), 0, 2);
		world.setBlock(i + 29, j + 3, k + 29, placeBuildingBlock(random), 0, 2);
		world.setBlock(i + 30, j + 3, k + 29, placeBuildingBlock(random), 0, 2);
		world.setBlock(i + 52, j + 3, k + 29, placeBuildingBlock(random), 0, 2);
		world.setBlock(i + 53, j + 3, k + 29, placeBuildingBlock(random), 0, 2);
		world.setBlock(i + 28, j + 3, k + 30, placeBuildingBlock(random), 0, 2);
		world.setBlock(i + 29, j + 3, k + 30, placeBuildingBlock(random), 0, 2);
		world.setBlock(i + 53, j + 3, k + 30, placeBuildingBlock(random), 0, 2);
		world.setBlock(i + 54, j + 3, k + 30, placeBuildingBlock(random), 0, 2);
		world.setBlock(i + 27, j + 3, k + 31, placeBuildingBlock(random), 0, 2);
		world.setBlock(i + 28, j + 3, k + 31, placeBuildingBlock(random), 0, 2);
		world.setBlock(i + 54, j + 3, k + 31, placeBuildingBlock(random), 0, 2);
		world.setBlock(i + 55, j + 3, k + 31, placeBuildingBlock(random), 0, 2);
		world.setBlock(i + 26, j + 3, k + 32, placeBuildingBlock(random), 0, 2);
		world.setBlock(i + 27, j + 3, k + 32, placeBuildingBlock(random), 0, 2);
		world.setBlock(i + 55, j + 3, k + 32, placeBuildingBlock(random), 0, 2);
		world.setBlock(i + 56, j + 3, k + 32, placeBuildingBlock(random), 0, 2);
		world.setBlock(i + 25, j + 3, k + 33, placeBuildingBlock(random), 0, 2);
		world.setBlock(i + 26, j + 3, k + 33, placeBuildingBlock(random), 0, 2);
		world.setBlock(i + 56, j + 3, k + 33, placeBuildingBlock(random), 0, 2);
		world.setBlock(i + 57, j + 3, k + 33, placeBuildingBlock(random), 0, 2);
		world.setBlock(i + 24, j + 3, k + 34, placeBuildingBlock(random), 0, 2);
		world.setBlock(i + 25, j + 3, k + 34, placeBuildingBlock(random), 0, 2);
		world.setBlock(i + 57, j + 3, k + 34, placeBuildingBlock(random), 0, 2);
		world.setBlock(i + 58, j + 3, k + 34, placeBuildingBlock(random), 0, 2);
		world.setBlock(i + 23, j + 3, k + 35, placeBuildingBlock(random), 0, 2);
		world.setBlock(i + 24, j + 3, k + 35, placeBuildingBlock(random), 0, 2);
		world.setBlock(i + 58, j + 3, k + 35, placeBuildingBlock(random), 0, 2);
		world.setBlock(i + 59, j + 3, k + 35, placeBuildingBlock(random), 0, 2);
		world.setBlock(i + 22, j + 3, k + 36, placeBuildingBlock(random), 0, 2);
		world.setBlock(i + 23, j + 3, k + 36, placeBuildingBlock(random), 0, 2);
		world.setBlock(i + 59, j + 3, k + 36, placeBuildingBlock(random), 0, 2);
		world.setBlock(i + 60, j + 3, k + 36, placeBuildingBlock(random), 0, 2);
		world.setBlock(i + 21, j + 3, k + 37, placeBuildingBlock(random), 0, 2);
		world.setBlock(i + 22, j + 3, k + 37, placeBuildingBlock(random), 0, 2);
		world.setBlock(i + 60, j + 3, k + 37, placeBuildingBlock(random), 0, 2);
		world.setBlock(i + 61, j + 3, k + 37, placeBuildingBlock(random), 0, 2);
		world.setBlock(i + 20, j + 3, k + 38, placeBuildingBlock(random), 0, 2);
		world.setBlock(i + 21, j + 3, k + 38, placeBuildingBlock(random), 0, 2);
		world.setBlock(i + 61, j + 3, k + 38, placeBuildingBlock(random), 0, 2);
		world.setBlock(i + 62, j + 3, k + 38, placeBuildingBlock(random), 0, 2);
		world.setBlock(i + 19, j + 3, k + 39, placeBuildingBlock(random), 0, 2);
		world.setBlock(i + 20, j + 3, k + 39, placeBuildingBlock(random), 0, 2);
		world.setBlock(i + 62, j + 3, k + 39, placeBuildingBlock(random), 0, 2);
		world.setBlock(i + 63, j + 3, k + 39, placeBuildingBlock(random), 0, 2);
		world.setBlock(i + 18, j + 3, k + 40, placeBuildingBlock(random), 0, 2);
		world.setBlock(i + 19, j + 3, k + 40, placeBuildingBlock(random), 0, 2);
		world.setBlock(i + 63, j + 3, k + 40, placeBuildingBlock(random), 0, 2);
		world.setBlock(i + 64, j + 3, k + 40, placeBuildingBlock(random), 0, 2);
		world.setBlock(i + 17, j + 3, k + 41, placeBuildingBlock(random), 0, 2);
		world.setBlock(i + 18, j + 3, k + 41, placeBuildingBlock(random), 0, 2);
		world.setBlock(i + 64, j + 3, k + 41, placeBuildingBlock(random), 0, 2);
		world.setBlock(i + 65, j + 3, k + 41, placeBuildingBlock(random), 0, 2);
		world.setBlock(i + 16, j + 3, k + 42, placeBuildingBlock(random), 0, 2);
		world.setBlock(i + 17, j + 3, k + 42, placeBuildingBlock(random), 0, 2);
		world.setBlock(i + 65, j + 3, k + 42, placeBuildingBlock(random), 0, 2);
		world.setBlock(i + 66, j + 3, k + 42, placeBuildingBlock(random), 0, 2);
		world.setBlock(i + 15, j + 3, k + 43, placeBuildingBlock(random), 0, 2);
		world.setBlock(i + 16, j + 3, k + 43, placeBuildingBlock(random), 0, 2);
		world.setBlock(i + 66, j + 3, k + 43, placeBuildingBlock(random), 0, 2);
		world.setBlock(i + 67, j + 3, k + 43, placeBuildingBlock(random), 0, 2);
		world.setBlock(i + 14, j + 3, k + 44, placeBuildingBlock(random), 0, 2);
		world.setBlock(i + 15, j + 3, k + 44, placeBuildingBlock(random), 0, 2);
		world.setBlock(i + 67, j + 3, k + 44, placeBuildingBlock(random), 0, 2);
		world.setBlock(i + 68, j + 3, k + 44, placeBuildingBlock(random), 0, 2);
		world.setBlock(i + 13, j + 3, k + 45, placeBuildingBlock(random), 0, 2);
		world.setBlock(i + 14, j + 3, k + 45, placeBuildingBlock(random), 0, 2);
		world.setBlock(i + 68, j + 3, k + 45, placeBuildingBlock(random), 0, 2);
		world.setBlock(i + 69, j + 3, k + 45, placeBuildingBlock(random), 0, 2);
		world.setBlock(i + 12, j + 3, k + 46, placeBuildingBlock(random), 0, 2);
		world.setBlock(i + 13, j + 3, k + 46, placeBuildingBlock(random), 0, 2);
		world.setBlock(i + 69, j + 3, k + 46, placeBuildingBlock(random), 0, 2);
		world.setBlock(i + 70, j + 3, k + 46, placeBuildingBlock(random), 0, 2);
		world.setBlock(i + 11, j + 3, k + 47, placeBuildingBlock(random), 0, 2);
		world.setBlock(i + 12, j + 3, k + 47, placeBuildingBlock(random), 0, 2);
		world.setBlock(i + 70, j + 3, k + 47, placeBuildingBlock(random), 0, 2);
		world.setBlock(i + 71, j + 3, k + 47, placeBuildingBlock(random), 0, 2);
		world.setBlock(i + 10, j + 3, k + 48, placeBuildingBlock(random), 0, 2);
		world.setBlock(i + 11, j + 3, k + 48, placeBuildingBlock(random), 0, 2);
		world.setBlock(i + 71, j + 3, k + 48, placeBuildingBlock(random), 0, 2);
		world.setBlock(i + 72, j + 3, k + 48, placeBuildingBlock(random), 0, 2);
		world.setBlock(i + 8, j + 3, k + 49, placeBuildingBlock(random), 0, 2);
		world.setBlock(i + 9, j + 3, k + 49, placeBuildingBlock(random), 0, 2);
		world.setBlock(i + 10, j + 3, k + 49, placeBuildingBlock(random), 0, 2);
		world.setBlock(i + 72, j + 3, k + 49, placeBuildingBlock(random), 0, 2);
		world.setBlock(i + 73, j + 3, k + 49, placeBuildingBlock(random), 0, 2);
		world.setBlock(i + 10, j + 3, k + 50, placeBuildingBlock(random), 0, 2);
		world.setBlock(i + 11, j + 3, k + 50, placeBuildingBlock(random), 0, 2);
		world.setBlock(i + 71, j + 3, k + 50, placeBuildingBlock(random), 0, 2);
		world.setBlock(i + 72, j + 3, k + 50, placeBuildingBlock(random), 0, 2);
		world.setBlock(i + 11, j + 3, k + 51, placeBuildingBlock(random), 0, 2);
		world.setBlock(i + 12, j + 3, k + 51, placeBuildingBlock(random), 0, 2);
		world.setBlock(i + 70, j + 3, k + 51, placeBuildingBlock(random), 0, 2);
		world.setBlock(i + 71, j + 3, k + 51, placeBuildingBlock(random), 0, 2);
		world.setBlock(i + 12, j + 3, k + 52, placeBuildingBlock(random), 0, 2);
		world.setBlock(i + 13, j + 3, k + 52, placeBuildingBlock(random), 0, 2);
		world.setBlock(i + 69, j + 3, k + 52, placeBuildingBlock(random), 0, 2);
		world.setBlock(i + 70, j + 3, k + 52, placeBuildingBlock(random), 0, 2);
		world.setBlock(i + 13, j + 3, k + 53, placeBuildingBlock(random), 0, 2);
		world.setBlock(i + 14, j + 3, k + 53, placeBuildingBlock(random), 0, 2);
		world.setBlock(i + 68, j + 3, k + 53, placeBuildingBlock(random), 0, 2);
		world.setBlock(i + 69, j + 3, k + 53, placeBuildingBlock(random), 0, 2);
		world.setBlock(i + 14, j + 3, k + 54, placeBuildingBlock(random), 0, 2);
		world.setBlock(i + 15, j + 3, k + 54, placeBuildingBlock(random), 0, 2);
		world.setBlock(i + 67, j + 3, k + 54, placeBuildingBlock(random), 0, 2);
		world.setBlock(i + 68, j + 3, k + 54, placeBuildingBlock(random), 0, 2);
		world.setBlock(i + 15, j + 3, k + 55, placeBuildingBlock(random), 0, 2);
		world.setBlock(i + 16, j + 3, k + 55, placeBuildingBlock(random), 0, 2);
		world.setBlock(i + 66, j + 3, k + 55, placeBuildingBlock(random), 0, 2);
		world.setBlock(i + 67, j + 3, k + 55, placeBuildingBlock(random), 0, 2);
		world.setBlock(i + 16, j + 3, k + 56, placeBuildingBlock(random), 0, 2);
		world.setBlock(i + 17, j + 3, k + 56, placeBuildingBlock(random), 0, 2);
		world.setBlock(i + 65, j + 3, k + 56, placeBuildingBlock(random), 0, 2);
		world.setBlock(i + 66, j + 3, k + 56, placeBuildingBlock(random), 0, 2);
		world.setBlock(i + 17, j + 3, k + 57, placeBuildingBlock(random), 0, 2);
		world.setBlock(i + 18, j + 3, k + 57, placeBuildingBlock(random), 0, 2);
		world.setBlock(i + 64, j + 3, k + 57, placeBuildingBlock(random), 0, 2);
		world.setBlock(i + 65, j + 3, k + 57, placeBuildingBlock(random), 0, 2);
		world.setBlock(i + 18, j + 3, k + 58, placeBuildingBlock(random), 0, 2);
		world.setBlock(i + 19, j + 3, k + 58, placeBuildingBlock(random), 0, 2);
		world.setBlock(i + 63, j + 3, k + 58, placeBuildingBlock(random), 0, 2);
		world.setBlock(i + 64, j + 3, k + 58, placeBuildingBlock(random), 0, 2);
		world.setBlock(i + 19, j + 3, k + 59, placeBuildingBlock(random), 0, 2);
		world.setBlock(i + 20, j + 3, k + 59, placeBuildingBlock(random), 0, 2);
		world.setBlock(i + 62, j + 3, k + 59, placeBuildingBlock(random), 0, 2);
		world.setBlock(i + 63, j + 3, k + 59, placeBuildingBlock(random), 0, 2);
		world.setBlock(i + 20, j + 3, k + 60, placeBuildingBlock(random), 0, 2);
		world.setBlock(i + 21, j + 3, k + 60, placeBuildingBlock(random), 0, 2);
		world.setBlock(i + 61, j + 3, k + 60, placeBuildingBlock(random), 0, 2);
		world.setBlock(i + 62, j + 3, k + 60, placeBuildingBlock(random), 0, 2);
		world.setBlock(i + 21, j + 3, k + 61, placeBuildingBlock(random), 0, 2);
		world.setBlock(i + 22, j + 3, k + 61, placeBuildingBlock(random), 0, 2);
		world.setBlock(i + 60, j + 3, k + 61, placeBuildingBlock(random), 0, 2);
		world.setBlock(i + 61, j + 3, k + 61, placeBuildingBlock(random), 0, 2);
		world.setBlock(i + 22, j + 3, k + 62, placeBuildingBlock(random), 0, 2);
		world.setBlock(i + 23, j + 3, k + 62, placeBuildingBlock(random), 0, 2);
		world.setBlock(i + 59, j + 3, k + 62, placeBuildingBlock(random), 0, 2);
		world.setBlock(i + 60, j + 3, k + 62, placeBuildingBlock(random), 0, 2);
		world.setBlock(i + 23, j + 3, k + 63, placeBuildingBlock(random), 0, 2);
		world.setBlock(i + 24, j + 3, k + 63, placeBuildingBlock(random), 0, 2);
		world.setBlock(i + 58, j + 3, k + 63, placeBuildingBlock(random), 0, 2);
		world.setBlock(i + 59, j + 3, k + 63, placeBuildingBlock(random), 0, 2);
		world.setBlock(i + 24, j + 3, k + 64, placeBuildingBlock(random), 0, 2);
		world.setBlock(i + 25, j + 3, k + 64, placeBuildingBlock(random), 0, 2);
		world.setBlock(i + 57, j + 3, k + 64, placeBuildingBlock(random), 0, 2);
		world.setBlock(i + 58, j + 3, k + 64, placeBuildingBlock(random), 0, 2);
		world.setBlock(i + 25, j + 3, k + 65, placeBuildingBlock(random), 0, 2);
		world.setBlock(i + 26, j + 3, k + 65, placeBuildingBlock(random), 0, 2);
		world.setBlock(i + 56, j + 3, k + 65, placeBuildingBlock(random), 0, 2);
		world.setBlock(i + 57, j + 3, k + 65, placeBuildingBlock(random), 0, 2);
		world.setBlock(i + 26, j + 3, k + 66, placeBuildingBlock(random), 0, 2);
		world.setBlock(i + 27, j + 3, k + 66, placeBuildingBlock(random), 0, 2);
		world.setBlock(i + 55, j + 3, k + 66, placeBuildingBlock(random), 0, 2);
		world.setBlock(i + 56, j + 3, k + 66, placeBuildingBlock(random), 0, 2);
		world.setBlock(i + 27, j + 3, k + 67, placeBuildingBlock(random), 0, 2);
		world.setBlock(i + 28, j + 3, k + 67, placeBuildingBlock(random), 0, 2);
		world.setBlock(i + 54, j + 3, k + 67, placeBuildingBlock(random), 0, 2);
		world.setBlock(i + 55, j + 3, k + 67, placeBuildingBlock(random), 0, 2);
		world.setBlock(i + 28, j + 3, k + 68, placeBuildingBlock(random), 0, 2);
		world.setBlock(i + 29, j + 3, k + 68, placeBuildingBlock(random), 0, 2);
		world.setBlock(i + 53, j + 3, k + 68, placeBuildingBlock(random), 0, 2);
		world.setBlock(i + 54, j + 3, k + 68, placeBuildingBlock(random), 0, 2);
		world.setBlock(i + 29, j + 3, k + 69, placeBuildingBlock(random), 0, 2);
		world.setBlock(i + 30, j + 3, k + 69, placeBuildingBlock(random), 0, 2);
		world.setBlock(i + 52, j + 3, k + 69, placeBuildingBlock(random), 0, 2);
		world.setBlock(i + 53, j + 3, k + 69, placeBuildingBlock(random), 0, 2);
		world.setBlock(i + 30, j + 3, k + 70, placeBuildingBlock(random), 0, 2);
		world.setBlock(i + 31, j + 3, k + 70, placeBuildingBlock(random), 0, 2);
		world.setBlock(i + 51, j + 3, k + 70, placeBuildingBlock(random), 0, 2);
		world.setBlock(i + 52, j + 3, k + 70, placeBuildingBlock(random), 0, 2);
		world.setBlock(i + 31, j + 3, k + 71, placeBuildingBlock(random), 0, 2);
		world.setBlock(i + 32, j + 3, k + 71, placeBuildingBlock(random), 0, 2);
		world.setBlock(i + 50, j + 3, k + 71, placeBuildingBlock(random), 0, 2);
		world.setBlock(i + 51, j + 3, k + 71, placeBuildingBlock(random), 0, 2);
		world.setBlock(i + 32, j + 3, k + 72, placeBuildingBlock(random), 0, 2);
		world.setBlock(i + 33, j + 3, k + 72, placeBuildingBlock(random), 0, 2);
		world.setBlock(i + 49, j + 3, k + 72, placeBuildingBlock(random), 0, 2);
		world.setBlock(i + 50, j + 3, k + 72, placeBuildingBlock(random), 0, 2);
		world.setBlock(i + 33, j + 3, k + 73, placeBuildingBlock(random), 0, 2);
		world.setBlock(i + 34, j + 3, k + 73, placeBuildingBlock(random), 0, 2);
		world.setBlock(i + 48, j + 3, k + 73, placeBuildingBlock(random), 0, 2);
		world.setBlock(i + 49, j + 3, k + 73, placeBuildingBlock(random), 0, 2);
		world.setBlock(i + 34, j + 3, k + 74, placeBuildingBlock(random), 0, 2);
		world.setBlock(i + 35, j + 3, k + 74, placeBuildingBlock(random), 0, 2);
		world.setBlock(i + 47, j + 3, k + 74, placeBuildingBlock(random), 0, 2);
		world.setBlock(i + 48, j + 3, k + 74, placeBuildingBlock(random), 0, 2);
		world.setBlock(i + 35, j + 3, k + 75, placeBuildingBlock(random), 0, 2);
		world.setBlock(i + 36, j + 3, k + 75, placeBuildingBlock(random), 0, 2);
		world.setBlock(i + 46, j + 3, k + 75, placeBuildingBlock(random), 0, 2);
		world.setBlock(i + 47, j + 3, k + 75, placeBuildingBlock(random), 0, 2);
		world.setBlock(i + 36, j + 3, k + 76, placeBuildingBlock(random), 0, 2);
		world.setBlock(i + 37, j + 3, k + 76, placeBuildingBlock(random), 0, 2);
		world.setBlock(i + 45, j + 3, k + 76, placeBuildingBlock(random), 0, 2);
		world.setBlock(i + 46, j + 3, k + 76, placeBuildingBlock(random), 0, 2);
		world.setBlock(i + 37, j + 3, k + 77, placeBuildingBlock(random), 0, 2);
		world.setBlock(i + 38, j + 3, k + 77, placeBuildingBlock(random), 0, 2);
		world.setBlock(i + 44, j + 3, k + 77, placeBuildingBlock(random), 0, 2);
		world.setBlock(i + 45, j + 3, k + 77, placeBuildingBlock(random), 0, 2);
		world.setBlock(i + 38, j + 3, k + 78, placeBuildingBlock(random), 0, 2);
		world.setBlock(i + 39, j + 3, k + 78, placeBuildingBlock(random), 0, 2);
		world.setBlock(i + 43, j + 3, k + 78, placeBuildingBlock(random), 0, 2);
		world.setBlock(i + 44, j + 3, k + 78, placeBuildingBlock(random), 0, 2);
		world.setBlock(i + 39, j + 3, k + 79, placeBuildingBlock(random), 0, 2);
		world.setBlock(i + 40, j + 3, k + 79, placeBuildingBlock(random), 0, 2);
		world.setBlock(i + 42, j + 3, k + 79, placeBuildingBlock(random), 0, 2);
		world.setBlock(i + 43, j + 3, k + 79, placeBuildingBlock(random), 0, 2);
		world.setBlock(i + 40, j + 3, k + 80, placeBuildingBlock(random), 0, 2);
		world.setBlock(i + 41, j + 3, k + 80, placeBuildingBlock(random), 0, 2);
		world.setBlock(i + 42, j + 3, k + 80, placeBuildingBlock(random), 0, 2);
		world.setBlock(i + 41, j + 3, k + 81, placeBuildingBlock(random), 0, 2);
		world.setBlock(i + 41, j + 4, k + 15, placeBuildingBlock(random), 0, 2);
		world.setBlock(i + 41, j + 4, k + 16, placeBuildingBlock(random), 0, 2);
		world.setBlock(i + 41, j + 4, k + 17, placeBuildingBlock(random), 0, 2);
		world.setBlock(i + 40, j + 4, k + 18, placeBuildingBlock(random), 0, 2);
		world.setBlock(i + 42, j + 4, k + 18, placeBuildingBlock(random), 0, 2);
		world.setBlock(i + 39, j + 4, k + 19, placeBuildingBlock(random), 0, 2);
		world.setBlock(i + 43, j + 4, k + 19, placeBuildingBlock(random), 0, 2);
		world.setBlock(i + 38, j + 4, k + 20, placeBuildingBlock(random), 0, 2);
		world.setBlock(i + 44, j + 4, k + 20, placeBuildingBlock(random), 0, 2);
		world.setBlock(i + 37, j + 4, k + 21, placeBuildingBlock(random), 0, 2);
		world.setBlock(i + 45, j + 4, k + 21, placeBuildingBlock(random), 0, 2);
		world.setBlock(i + 36, j + 4, k + 22, placeBuildingBlock(random), 0, 2);
		world.setBlock(i + 46, j + 4, k + 22, placeBuildingBlock(random), 0, 2);
		world.setBlock(i + 35, j + 4, k + 23, placeBuildingBlock(random), 0, 2);
		world.setBlock(i + 47, j + 4, k + 23, placeBuildingBlock(random), 0, 2);
		world.setBlock(i + 34, j + 4, k + 24, placeBuildingBlock(random), 0, 2);
		world.setBlock(i + 48, j + 4, k + 24, placeBuildingBlock(random), 0, 2);
		world.setBlock(i + 33, j + 4, k + 25, placeBuildingBlock(random), 0, 2);
		world.setBlock(i + 49, j + 4, k + 25, placeBuildingBlock(random), 0, 2);
		world.setBlock(i + 32, j + 4, k + 26, placeBuildingBlock(random), 0, 2);
		world.setBlock(i + 50, j + 4, k + 26, placeBuildingBlock(random), 0, 2);
		world.setBlock(i + 31, j + 4, k + 27, placeBuildingBlock(random), 0, 2);
		world.setBlock(i + 51, j + 4, k + 27, placeBuildingBlock(random), 0, 2);
		world.setBlock(i + 30, j + 4, k + 28, placeBuildingBlock(random), 0, 2);
		world.setBlock(i + 52, j + 4, k + 28, placeBuildingBlock(random), 0, 2);
		world.setBlock(i + 29, j + 4, k + 29, placeBuildingBlock(random), 0, 2);
		world.setBlock(i + 53, j + 4, k + 29, placeBuildingBlock(random), 0, 2);
		world.setBlock(i + 28, j + 4, k + 30, placeBuildingBlock(random), 0, 2);
		world.setBlock(i + 54, j + 4, k + 30, placeBuildingBlock(random), 0, 2);
		world.setBlock(i + 27, j + 4, k + 31, placeBuildingBlock(random), 0, 2);
		world.setBlock(i + 55, j + 4, k + 31, placeBuildingBlock(random), 0, 2);
		world.setBlock(i + 26, j + 4, k + 32, placeBuildingBlock(random), 0, 2);
		world.setBlock(i + 56, j + 4, k + 32, placeBuildingBlock(random), 0, 2);
		world.setBlock(i + 25, j + 4, k + 33, placeBuildingBlock(random), 0, 2);
		world.setBlock(i + 57, j + 4, k + 33, placeBuildingBlock(random), 0, 2);
		world.setBlock(i + 24, j + 4, k + 34, placeBuildingBlock(random), 0, 2);
		world.setBlock(i + 58, j + 4, k + 34, placeBuildingBlock(random), 0, 2);
		world.setBlock(i + 23, j + 4, k + 35, placeBuildingBlock(random), 0, 2);
		world.setBlock(i + 59, j + 4, k + 35, placeBuildingBlock(random), 0, 2);
		world.setBlock(i + 22, j + 4, k + 36, placeBuildingBlock(random), 0, 2);
		world.setBlock(i + 60, j + 4, k + 36, placeBuildingBlock(random), 0, 2);
		world.setBlock(i + 21, j + 4, k + 37, placeBuildingBlock(random), 0, 2);
		world.setBlock(i + 61, j + 4, k + 37, placeBuildingBlock(random), 0, 2);
		world.setBlock(i + 20, j + 4, k + 38, placeBuildingBlock(random), 0, 2);
		world.setBlock(i + 62, j + 4, k + 38, placeBuildingBlock(random), 0, 2);
		world.setBlock(i + 19, j + 4, k + 39, placeBuildingBlock(random), 0, 2);
		world.setBlock(i + 63, j + 4, k + 39, placeBuildingBlock(random), 0, 2);
		world.setBlock(i + 18, j + 4, k + 40, placeBuildingBlock(random), 0, 2);
		world.setBlock(i + 64, j + 4, k + 40, placeBuildingBlock(random), 0, 2);
		world.setBlock(i + 17, j + 4, k + 41, placeBuildingBlock(random), 0, 2);
		world.setBlock(i + 65, j + 4, k + 41, placeBuildingBlock(random), 0, 2);
		world.setBlock(i + 16, j + 4, k + 42, placeBuildingBlock(random), 0, 2);
		world.setBlock(i + 66, j + 4, k + 42, placeBuildingBlock(random), 0, 2);
		world.setBlock(i + 15, j + 4, k + 43, placeBuildingBlock(random), 0, 2);
		world.setBlock(i + 67, j + 4, k + 43, placeBuildingBlock(random), 0, 2);
		world.setBlock(i + 14, j + 4, k + 44, placeBuildingBlock(random), 0, 2);
		world.setBlock(i + 68, j + 4, k + 44, placeBuildingBlock(random), 0, 2);
		world.setBlock(i + 13, j + 4, k + 45, placeBuildingBlock(random), 0, 2);
		world.setBlock(i + 69, j + 4, k + 45, placeBuildingBlock(random), 0, 2);
		world.setBlock(i + 12, j + 4, k + 46, placeBuildingBlock(random), 0, 2);
		world.setBlock(i + 70, j + 4, k + 46, placeBuildingBlock(random), 0, 2);
		world.setBlock(i + 11, j + 4, k + 47, placeBuildingBlock(random), 0, 2);
		world.setBlock(i + 71, j + 4, k + 47, placeBuildingBlock(random), 0, 2);
		world.setBlock(i + 10, j + 4, k + 48, placeBuildingBlock(random), 0, 2);
		world.setBlock(i + 72, j + 4, k + 48, placeBuildingBlock(random), 0, 2);
		world.setBlock(i + 7, j + 4, k + 49, placeBuildingBlock(random), 0, 2);
		world.setBlock(i + 8, j + 4, k + 49, placeBuildingBlock(random), 0, 2);
		world.setBlock(i + 9, j + 4, k + 49, placeBuildingBlock(random), 0, 2);
		world.setBlock(i + 73, j + 4, k + 49, placeBuildingBlock(random), 0, 2);
		world.setBlock(i + 10, j + 4, k + 50, placeBuildingBlock(random), 0, 2);
		world.setBlock(i + 72, j + 4, k + 50, placeBuildingBlock(random), 0, 2);
		world.setBlock(i + 11, j + 4, k + 51, placeBuildingBlock(random), 0, 2);
		world.setBlock(i + 71, j + 4, k + 51, placeBuildingBlock(random), 0, 2);
		world.setBlock(i + 12, j + 4, k + 52, placeBuildingBlock(random), 0, 2);
		world.setBlock(i + 70, j + 4, k + 52, placeBuildingBlock(random), 0, 2);
		world.setBlock(i + 13, j + 4, k + 53, placeBuildingBlock(random), 0, 2);
		world.setBlock(i + 69, j + 4, k + 53, placeBuildingBlock(random), 0, 2);
		world.setBlock(i + 14, j + 4, k + 54, placeBuildingBlock(random), 0, 2);
		world.setBlock(i + 68, j + 4, k + 54, placeBuildingBlock(random), 0, 2);
		world.setBlock(i + 15, j + 4, k + 55, placeBuildingBlock(random), 0, 2);
		world.setBlock(i + 67, j + 4, k + 55, placeBuildingBlock(random), 0, 2);
		world.setBlock(i + 16, j + 4, k + 56, placeBuildingBlock(random), 0, 2);
		world.setBlock(i + 66, j + 4, k + 56, placeBuildingBlock(random), 0, 2);
		world.setBlock(i + 17, j + 4, k + 57, placeBuildingBlock(random), 0, 2);
		world.setBlock(i + 65, j + 4, k + 57, placeBuildingBlock(random), 0, 2);
		world.setBlock(i + 18, j + 4, k + 58, placeBuildingBlock(random), 0, 2);
		world.setBlock(i + 64, j + 4, k + 58, placeBuildingBlock(random), 0, 2);
		world.setBlock(i + 19, j + 4, k + 59, placeBuildingBlock(random), 0, 2);
		world.setBlock(i + 63, j + 4, k + 59, placeBuildingBlock(random), 0, 2);
		world.setBlock(i + 20, j + 4, k + 60, placeBuildingBlock(random), 0, 2);
		world.setBlock(i + 62, j + 4, k + 60, placeBuildingBlock(random), 0, 2);
		world.setBlock(i + 21, j + 4, k + 61, placeBuildingBlock(random), 0, 2);
		world.setBlock(i + 61, j + 4, k + 61, placeBuildingBlock(random), 0, 2);
		world.setBlock(i + 22, j + 4, k + 62, placeBuildingBlock(random), 0, 2);
		world.setBlock(i + 60, j + 4, k + 62, placeBuildingBlock(random), 0, 2);
