package com.gildedgames.the_aether.world.dungeon.osmium;

import java.util.Random;

import com.gildedgames.the_aether.blocks.BlocksAether;

import net.minecraft.block.Block;
import net.minecraft.world.World;
import net.minecraft.world.gen.feature.WorldGenerator;

public class OsmiumDungeonGen21 extends WorldGenerator {

	public OsmiumDungeonGen21() {

	}
	
	public boolean generate(final World world, final Random random, final int i, final int j, final int k) {
		
		world.setBlock(i + 21, j + 37, k + 49, placeBuildingBlock(random), 0, 2);
		world.setBlock(i + 22, j + 37, k + 49, placeBuildingBlock(random), 0, 2);
		world.setBlock(i + 23, j + 37, k + 49, placeBuildingBlock(random), 0, 2);
		world.setBlock(i + 24, j + 37, k + 49, placeBuildingBlock(random), 0, 2);
		world.setBlock(i + 25, j + 37, k + 49, placeBuildingBlock(random), 0, 2);
		world.setBlock(i + 26, j + 37, k + 49, placeBuildingBlock(random), 0, 2);
		world.setBlock(i + 27, j + 37, k + 49, BlocksAether.locked_creeping_stone, 0, 2);
		world.setBlock(i + 28, j + 37, k + 49, placeBuildingBlock(random), 0, 2);
		world.setBlock(i + 29, j + 37, k + 49, placeBuildingBlock(random), 0, 2);
		world.setBlock(i + 30, j + 37, k + 49, placeBuildingBlock(random), 0, 2);
		world.setBlock(i + 31, j + 37, k + 49, placeBuildingBlock(random), 0, 2);
		world.setBlock(i + 32, j + 37, k + 49, placeBuildingBlock(random), 0, 2);
		world.setBlock(i + 33, j + 37, k + 49, placeBuildingBlock(random), 0, 2);
		world.setBlock(i + 34, j + 37, k + 49, placeBuildingBlock(random), 0, 2);
		world.setBlock(i + 35, j + 37, k + 49, placeBuildingBlock(random), 0, 2);
		world.setBlock(i + 36, j + 37, k + 49, placeBuildingBlock(random), 0, 2);
		world.setBlock(i + 37, j + 37, k + 49, placeBuildingBlock(random), 0, 2);
		world.setBlock(i + 38, j + 37, k + 49, placeBuildingBlock(random), 0, 2);
		world.setBlock(i + 39, j + 37, k + 49, placeBuildingBlock(random), 0, 2);
		world.setBlock(i + 40, j + 37, k + 49, placeBuildingBlock(random), 0, 2);
		world.setBlock(i + 41, j + 37, k + 49, placeBuildingBlock(random), 0, 2);
		world.setBlock(i + 42, j + 37, k + 49, placeBuildingBlock(random), 0, 2);
		world.setBlock(i + 43, j + 37, k + 49, placeBuildingBlock(random), 0, 2);
		world.setBlock(i + 44, j + 37, k + 49, placeBuildingBlock(random), 0, 2);
		world.setBlock(i + 45, j + 37, k + 49, placeBuildingBlock(random), 0, 2);
		world.setBlock(i + 46, j + 37, k + 49, placeBuildingBlock(random), 0, 2);
		world.setBlock(i + 47, j + 37, k + 49, placeBuildingBlock(random), 0, 2);
		world.setBlock(i + 48, j + 37, k + 49, placeBuildingBlock(random), 0, 2);
		world.setBlock(i + 49, j + 37, k + 49, placeBuildingBlock(random), 0, 2);
		world.setBlock(i + 50, j + 37, k + 49, placeBuildingBlock(random), 0, 2);
		world.setBlock(i + 51, j + 37, k + 49, placeBuildingBlock(random), 0, 2);
		world.setBlock(i + 52, j + 37, k + 49, placeBuildingBlock(random), 0, 2);
		world.setBlock(i + 53, j + 37, k + 49, BlocksAether.locked_creeping_stone, 0, 2);
		world.setBlock(i + 54, j + 37, k + 49, placeBuildingBlock(random), 0, 2);
		world.setBlock(i + 55, j + 37, k + 49, placeBuildingBlock(random), 0, 2);
		world.setBlock(i + 56, j + 37, k + 49, placeBuildingBlock(random), 0, 2);
		world.setBlock(i + 57, j + 37, k + 49, placeBuildingBlock(random), 0, 2);
		world.setBlock(i + 58, j + 37, k + 49, placeBuildingBlock(random), 0, 2);
		world.setBlock(i + 59, j + 37, k + 49, BlocksAether.caelestia_stone, 0, 2);
		world.setBlock(i + 60, j + 37, k + 49, BlocksAether.caelestia_stone, 0, 2);
		world.setBlock(i + 61, j + 37, k + 49, BlocksAether.caelestia_stone, 0, 2);
		world.setBlock(i + 62, j + 37, k + 49, BlocksAether.caelestia_stone, 0, 2);
		world.setBlock(i + 63, j + 37, k + 49, BlocksAether.caelestia_stone, 0, 2);
		world.setBlock(i + 64, j + 37, k + 49, BlocksAether.caelestia_stone, 0, 2);
		world.setBlock(i + 65, j + 37, k + 49, BlocksAether.caelestia_stone, 0, 2);
		world.setBlock(i + 14, j + 37, k + 50, BlocksAether.caelestia_stone, 0, 2);
		world.setBlock(i + 15, j + 37, k + 50, BlocksAether.caelestia_stone, 0, 2);
		world.setBlock(i + 16, j + 37, k + 50, BlocksAether.caelestia_stone, 0, 2);
		world.setBlock(i + 17, j + 37, k + 50, BlocksAether.caelestia_stone, 0, 2);
		world.setBlock(i + 18, j + 37, k + 50, BlocksAether.caelestia_stone, 0, 2);
		world.setBlock(i + 19, j + 37, k + 50, BlocksAether.caelestia_stone, 0, 2);
		world.setBlock(i + 20, j + 37, k + 50, BlocksAether.caelestia_stone, 0, 2);
		world.setBlock(i + 21, j + 37, k + 50, placeBuildingBlock(random), 0, 2);
		world.setBlock(i + 22, j + 37, k + 50, placeBuildingBlock(random), 0, 2);
		world.setBlock(i + 23, j + 37, k + 50, placeBuildingBlock(random), 0, 2);
		world.setBlock(i + 24, j + 37, k + 50, placeBuildingBlock(random), 0, 2);
		world.setBlock(i + 25, j + 37, k + 50, placeBuildingBlock(random), 0, 2);
		world.setBlock(i + 26, j + 37, k + 50, placeBuildingBlock(random), 0, 2);
		world.setBlock(i + 27, j + 37, k + 50, placeBuildingBlock(random), 0, 2);
		world.setBlock(i + 28, j + 37, k + 50, placeBuildingBlock(random), 0, 2);
		world.setBlock(i + 29, j + 37, k + 50, placeBuildingBlock(random), 0, 2);
		world.setBlock(i + 30, j + 37, k + 50, placeBuildingBlock(random), 0, 2);
		world.setBlock(i + 31, j + 37, k + 50, placeBuildingBlock(random), 0, 2);
		world.setBlock(i + 32, j + 37, k + 50, placeBuildingBlock(random), 0, 2);
		world.setBlock(i + 33, j + 37, k + 50, placeBuildingBlock(random), 0, 2);
		world.setBlock(i + 34, j + 37, k + 50, placeBuildingBlock(random), 0, 2);
		world.setBlock(i + 35, j + 37, k + 50, placeBuildingBlock(random), 0, 2);
		world.setBlock(i + 36, j + 37, k + 50, placeBuildingBlock(random), 0, 2);
		world.setBlock(i + 37, j + 37, k + 50, placeBuildingBlock(random), 0, 2);
		world.setBlock(i + 38, j + 37, k + 50, placeBuildingBlock(random), 0, 2);
		world.setBlock(i + 39, j + 37, k + 50, placeBuildingBlock(random), 0, 2);
		world.setBlock(i + 40, j + 37, k + 50, placeBuildingBlock(random), 0, 2);
		world.setBlock(i + 41, j + 37, k + 50, placeBuildingBlock(random), 0, 2);
		world.setBlock(i + 42, j + 37, k + 50, placeBuildingBlock(random), 0, 2);
		world.setBlock(i + 43, j + 37, k + 50, placeBuildingBlock(random), 0, 2);
		world.setBlock(i + 44, j + 37, k + 50, placeBuildingBlock(random), 0, 2);
		world.setBlock(i + 45, j + 37, k + 50, placeBuildingBlock(random), 0, 2);
		world.setBlock(i + 46, j + 37, k + 50, placeBuildingBlock(random), 0, 2);
		world.setBlock(i + 47, j + 37, k + 50, placeBuildingBlock(random), 0, 2);
		world.setBlock(i + 48, j + 37, k + 50, placeBuildingBlock(random), 0, 2);
		world.setBlock(i + 49, j + 37, k + 50, placeBuildingBlock(random), 0, 2);
		world.setBlock(i + 50, j + 37, k + 50, placeBuildingBlock(random), 0, 2);
		world.setBlock(i + 51, j + 37, k + 50, placeBuildingBlock(random), 0, 2);
		world.setBlock(i + 52, j + 37, k + 50, placeBuildingBlock(random), 0, 2);
		world.setBlock(i + 53, j + 37, k + 50, placeBuildingBlock(random), 0, 2);
		world.setBlock(i + 54, j + 37, k + 50, placeBuildingBlock(random), 0, 2);
		world.setBlock(i + 55, j + 37, k + 50, placeBuildingBlock(random), 0, 2);
		world.setBlock(i + 56, j + 37, k + 50, placeBuildingBlock(random), 0, 2);
		world.setBlock(i + 57, j + 37, k + 50, placeBuildingBlock(random), 0, 2);
		world.setBlock(i + 58, j + 37, k + 50, BlocksAether.caelestia_stone, 0, 2);
		world.setBlock(i + 59, j + 37, k + 50, BlocksAether.caelestia_stone, 0, 2);
		world.setBlock(i + 60, j + 37, k + 50, BlocksAether.caelestia_stone, 0, 2);
		world.setBlock(i + 61, j + 37, k + 50, BlocksAether.caelestia_stone, 0, 2);
		world.setBlock(i + 62, j + 37, k + 50, BlocksAether.caelestia_stone, 0, 2);
		world.setBlock(i + 63, j + 37, k + 50, BlocksAether.caelestia_stone, 0, 2);
		world.setBlock(i + 64, j + 37, k + 50, BlocksAether.caelestia_stone, 0, 2);
		world.setBlock(i + 15, j + 37, k + 51, BlocksAether.caelestia_stone, 0, 2);
		world.setBlock(i + 16, j + 37, k + 51, BlocksAether.caelestia_stone, 0, 2);
		world.setBlock(i + 17, j + 37, k + 51, BlocksAether.caelestia_stone, 0, 2);
		world.setBlock(i + 18, j + 37, k + 51, BlocksAether.caelestia_stone, 0, 2);
		world.setBlock(i + 19, j + 37, k + 51, BlocksAether.caelestia_stone, 0, 2);
		world.setBlock(i + 20, j + 37, k + 51, BlocksAether.caelestia_stone, 0, 2);
		world.setBlock(i + 21, j + 37, k + 51, BlocksAether.caelestia_stone, 0, 2);
		world.setBlock(i + 22, j + 37, k + 51, placeBuildingBlock(random), 0, 2);
		world.setBlock(i + 23, j + 37, k + 51, placeBuildingBlock(random), 0, 2);
		world.setBlock(i + 24, j + 37, k + 51, placeBuildingBlock(random), 0, 2);
		world.setBlock(i + 25, j + 37, k + 51, placeBuildingBlock(random), 0, 2);
		world.setBlock(i + 26, j + 37, k + 51, placeBuildingBlock(random), 0, 2);
		world.setBlock(i + 27, j + 37, k + 51, placeBuildingBlock(random), 0, 2);
		world.setBlock(i + 28, j + 37, k + 51, placeBuildingBlock(random), 0, 2);
		world.setBlock(i + 29, j + 37, k + 51, placeBuildingBlock(random), 0, 2);
		world.setBlock(i + 30, j + 37, k + 51, placeBuildingBlock(random), 0, 2);
		world.setBlock(i + 31, j + 37, k + 51, placeBuildingBlock(random), 0, 2);
		world.setBlock(i + 32, j + 37, k + 51, placeBuildingBlock(random), 0, 2);
		world.setBlock(i + 33, j + 37, k + 51, placeBuildingBlock(random), 0, 2);
		world.setBlock(i + 34, j + 37, k + 51, placeBuildingBlock(random), 0, 2);
		world.setBlock(i + 35, j + 37, k + 51, placeBuildingBlock(random), 0, 2);
		world.setBlock(i + 36, j + 37, k + 51, placeBuildingBlock(random), 0, 2);
		world.setBlock(i + 37, j + 37, k + 51, placeBuildingBlock(random), 0, 2);
		world.setBlock(i + 38, j + 37, k + 51, placeBuildingBlock(random), 0, 2);
		world.setBlock(i + 39, j + 37, k + 51, placeBuildingBlock(random), 0, 2);
		world.setBlock(i + 40, j + 37, k + 51, placeBuildingBlock(random), 0, 2);
		world.setBlock(i + 41, j + 37, k + 51, placeBuildingBlock(random), 0, 2);
		world.setBlock(i + 42, j + 37, k + 51, BlocksAether.locked_creeping_stone, 0, 2);
		world.setBlock(i + 43, j + 37, k + 51, placeBuildingBlock(random), 0, 2);
		world.setBlock(i + 44, j + 37, k + 51, placeBuildingBlock(random), 0, 2);
		world.setBlock(i + 45, j + 37, k + 51, placeBuildingBlock(random), 0, 2);
		world.setBlock(i + 46, j + 37, k + 51, BlocksAether.locked_creeping_stone, 0, 2);
		world.setBlock(i + 47, j + 37, k + 51, placeBuildingBlock(random), 0, 2);
		world.setBlock(i + 48, j + 37, k + 51, placeBuildingBlock(random), 0, 2);
		world.setBlock(i + 49, j + 37, k + 51, placeBuildingBlock(random), 0, 2);
		world.setBlock(i + 50, j + 37, k + 51, placeBuildingBlock(random), 0, 2);
		world.setBlock(i + 51, j + 37, k + 51, BlocksAether.locked_creeping_stone, 0, 2);
		world.setBlock(i + 52, j + 37, k + 51, placeBuildingBlock(random), 0, 2);
		world.setBlock(i + 53, j + 37, k + 51, placeBuildingBlock(random), 0, 2);
		world.setBlock(i + 54, j + 37, k + 51, placeBuildingBlock(random), 0, 2);
		world.setBlock(i + 55, j + 37, k + 51, placeBuildingBlock(random), 0, 2);
		world.setBlock(i + 56, j + 37, k + 51, placeBuildingBlock(random), 0, 2);
		world.setBlock(i + 57, j + 37, k + 51, BlocksAether.caelestia_stone, 0, 2);
		world.setBlock(i + 58, j + 37, k + 51, BlocksAether.caelestia_stone, 0, 2);
		world.setBlock(i + 59, j + 37, k + 51, BlocksAether.caelestia_stone, 0, 2);
		world.setBlock(i + 60, j + 37, k + 51, BlocksAether.caelestia_stone, 0, 2);
		world.setBlock(i + 61, j + 37, k + 51, BlocksAether.caelestia_stone, 0, 2);
		world.setBlock(i + 62, j + 37, k + 51, BlocksAether.caelestia_stone, 0, 2);
		world.setBlock(i + 63, j + 37, k + 51, BlocksAether.caelestia_stone, 0, 2);
		world.setBlock(i + 16, j + 37, k + 52, BlocksAether.caelestia_stone, 0, 2);
		world.setBlock(i + 17, j + 37, k + 52, BlocksAether.caelestia_stone, 0, 2);
		world.setBlock(i + 18, j + 37, k + 52, BlocksAether.caelestia_stone, 0, 2);
		world.setBlock(i + 19, j + 37, k + 52, BlocksAether.caelestia_stone, 0, 2);
		world.setBlock(i + 20, j + 37, k + 52, BlocksAether.caelestia_stone, 0, 2);
		world.setBlock(i + 21, j + 37, k + 52, BlocksAether.caelestia_stone, 0, 2);
		world.setBlock(i + 22, j + 37, k + 52, BlocksAether.caelestia_stone, 0, 2);
		world.setBlock(i + 23, j + 37, k + 52, placeBuildingBlock(random), 0, 2);
		world.setBlock(i + 24, j + 37, k + 52, placeBuildingBlock(random), 0, 2);
		world.setBlock(i + 25, j + 37, k + 52, placeBuildingBlock(random), 0, 2);
		world.setBlock(i + 26, j + 37, k + 52, placeBuildingBlock(random), 0, 2);
		world.setBlock(i + 27, j + 37, k + 52, placeBuildingBlock(random), 0, 2);
		world.setBlock(i + 28, j + 37, k + 52, placeBuildingBlock(random), 0, 2);
		world.setBlock(i + 29, j + 37, k + 52, placeBuildingBlock(random), 0, 2);
		world.setBlock(i + 30, j + 37, k + 52, placeBuildingBlock(random), 0, 2);
		world.setBlock(i + 31, j + 37, k + 52, placeBuildingBlock(random), 0, 2);
		world.setBlock(i + 32, j + 37, k + 52, placeBuildingBlock(random), 0, 2);
		world.setBlock(i + 33, j + 37, k + 52, placeBuildingBlock(random), 0, 2);
		world.setBlock(i + 34, j + 37, k + 52, placeBuildingBlock(random), 0, 2);
		world.setBlock(i + 35, j + 37, k + 52, placeBuildingBlock(random), 0, 2);
		world.setBlock(i + 36, j + 37, k + 52, BlocksAether.locked_creeping_stone, 0, 2);
		world.setBlock(i + 37, j + 37, k + 52, placeBuildingBlock(random), 0, 2);
		world.setBlock(i + 38, j + 37, k + 52, placeBuildingBlock(random), 0, 2);
		world.setBlock(i + 39, j + 37, k + 52, placeBuildingBlock(random), 0, 2);
		world.setBlock(i + 40, j + 37, k + 52, placeBuildingBlock(random), 0, 2);
		world.setBlock(i + 41, j + 37, k + 52, placeBuildingBlock(random), 0, 2);
		world.setBlock(i + 42, j + 37, k + 52, placeBuildingBlock(random), 0, 2);
		world.setBlock(i + 43, j + 37, k + 52, placeBuildingBlock(random), 0, 2);
		world.setBlock(i + 44, j + 37, k + 52, placeBuildingBlock(random), 0, 2);
		world.setBlock(i + 45, j + 37, k + 52, placeBuildingBlock(random), 0, 2);
		world.setBlock(i + 46, j + 37, k + 52, placeBuildingBlock(random), 0, 2);
		world.setBlock(i + 47, j + 37, k + 52, placeBuildingBlock(random), 0, 2);
		world.setBlock(i + 48, j + 37, k + 52, placeBuildingBlock(random), 0, 2);
		world.setBlock(i + 49, j + 37, k + 52, placeBuildingBlock(random), 0, 2);
		world.setBlock(i + 50, j + 37, k + 52, placeBuildingBlock(random), 0, 2);
		world.setBlock(i + 51, j + 37, k + 52, placeBuildingBlock(random), 0, 2);
		world.setBlock(i + 52, j + 37, k + 52, placeBuildingBlock(random), 0, 2);
		world.setBlock(i + 53, j + 37, k + 52, placeBuildingBlock(random), 0, 2);
		world.setBlock(i + 54, j + 37, k + 52, placeBuildingBlock(random), 0, 2);
		world.setBlock(i + 55, j + 37, k + 52, placeBuildingBlock(random), 0, 2);
		world.setBlock(i + 56, j + 37, k + 52, BlocksAether.caelestia_stone, 0, 2);
		world.setBlock(i + 57, j + 37, k + 52, BlocksAether.caelestia_stone, 0, 2);
		world.setBlock(i + 58, j + 37, k + 52, BlocksAether.caelestia_stone, 0, 2);
		world.setBlock(i + 59, j + 37, k + 52, BlocksAether.caelestia_stone, 0, 2);
		world.setBlock(i + 60, j + 37, k + 52, BlocksAether.caelestia_stone, 0, 2);
		world.setBlock(i + 61, j + 37, k + 52, BlocksAether.caelestia_stone, 0, 2);
		world.setBlock(i + 62, j + 37, k + 52, BlocksAether.caelestia_stone, 0, 2);
		world.setBlock(i + 17, j + 37, k + 53, BlocksAether.caelestia_stone, 0, 2);
		world.setBlock(i + 18, j + 37, k + 53, BlocksAether.caelestia_stone, 0, 2);
		world.setBlock(i + 19, j + 37, k + 53, BlocksAether.caelestia_stone, 0, 2);
		world.setBlock(i + 20, j + 37, k + 53, BlocksAether.caelestia_stone, 0, 2);
		world.setBlock(i + 21, j + 37, k + 53, BlocksAether.caelestia_stone, 0, 2);
		world.setBlock(i + 22, j + 37, k + 53, BlocksAether.caelestia_stone, 0, 2);
		world.setBlock(i + 23, j + 37, k + 53, BlocksAether.caelestia_stone, 0, 2);
		world.setBlock(i + 24, j + 37, k + 53, placeBuildingBlock(random), 0, 2);
		world.setBlock(i + 25, j + 37, k + 53, placeBuildingBlock(random), 0, 2);
		world.setBlock(i + 26, j + 37, k + 53, placeBuildingBlock(random), 0, 2);
		world.setBlock(i + 27, j + 37, k + 53, placeBuildingBlock(random), 0, 2);
		world.setBlock(i + 28, j + 37, k + 53, placeBuildingBlock(random), 0, 2);
		world.setBlock(i + 29, j + 37, k + 53, placeBuildingBlock(random), 0, 2);
		world.setBlock(i + 18, j + 41, k + 29, placeBuildingBlock(random), 0, 2);
		world.setBlock(i + 31, j + 41, k + 29, placeBuildingBlock(random), 0, 2);
		world.setBlock(i + 34, j + 41, k + 29, placeBuildingBlock(random), 0, 2);
		world.setBlock(i + 44, j + 41, k + 29, placeBuildingBlock(random), 0, 2);
		world.setBlock(i + 49, j + 41, k + 29, placeBuildingBlock(random), 0, 2);
		world.setBlock(i + 60, j + 41, k + 29, placeBuildingBlock(random), 0, 2);
		world.setBlock(i + 61, j + 41, k + 29, placeBuildingBlock(random), 0, 2);
		world.setBlock(i + 62, j + 41, k + 29, placeBuildingBlock(random), 0, 2);
		world.setBlock(i + 11, j + 41, k + 30, BlocksAether.pillar, 0, 2);
		world.setBlock(i + 15, j + 41, k + 30, placeBuildingBlock(random), 0, 2);
		world.setBlock(i + 16, j + 41, k + 30, placeBuildingBlock(random), 0, 2);
		world.setBlock(i + 17, j + 41, k + 30, placeBuildingBlock(random), 0, 2);
		world.setBlock(i + 18, j + 41, k + 30, placeBuildingBlock(random), 0, 2);
		world.setBlock(i + 32, j + 41, k + 30, placeBuildingBlock(random), 0, 2);
		world.setBlock(i + 33, j + 41, k + 30, placeBuildingBlock(random), 0, 2);
		world.setBlock(i + 45, j + 41, k + 30, placeBuildingBlock(random), 0, 2);
		world.setBlock(i + 48, j + 41, k + 30, placeBuildingBlock(random), 0, 2);
		world.setBlock(i + 59, j + 41, k + 30, placeBuildingBlock(random), 0, 2);
		world.setBlock(i + 61, j + 41, k + 30, placeBuildingBlock(random), 0, 2);
		world.setBlock(i + 62, j + 41, k + 30, placeBuildingBlock(random), 0, 2);
		world.setBlock(i + 63, j + 41, k + 30, placeBuildingBlock(random), 0, 2);
		world.setBlock(i + 67, j + 41, k + 30, BlocksAether.pillar, 0, 2);
		world.setBlock(i + 14, j + 41, k + 31, placeBuildingBlock(random), 0, 2);
		world.setBlock(i + 15, j + 41, k + 31, placeBuildingBlock(random), 0, 2);
		world.setBlock(i + 16, j + 41, k + 31, placeBuildingBlock(random), 0, 2);
		world.setBlock(i + 19, j + 41, k + 31, placeBuildingBlock(random), 0, 2);
		world.setBlock(i + 32, j + 41, k + 31, placeBuildingBlock(random), 0, 2);
		world.setBlock(i + 46, j + 41, k + 31, placeBuildingBlock(random), 0, 2);
		world.setBlock(i + 47, j + 41, k + 31, placeBuildingBlock(random), 0, 2);
		world.setBlock(i + 58, j + 41, k + 31, placeBuildingBlock(random), 0, 2);
		world.setBlock(i + 62, j + 41, k + 31, placeBuildingBlock(random), 0, 2);
		world.setBlock(i + 63, j + 41, k + 31, placeBuildingBlock(random), 0, 2);
		world.setBlock(i + 64, j + 41, k + 31, placeBuildingBlock(random), 0, 2);
		world.setBlock(i + 13, j + 41, k + 32, placeBuildingBlock(random), 0, 2);
		world.setBlock(i + 14, j + 41, k + 32, placeBuildingBlock(random), 0, 2);
		world.setBlock(i + 15, j + 41, k + 32, placeBuildingBlock(random), 0, 2);
		world.setBlock(i + 20, j + 41, k + 32, placeBuildingBlock(random), 0, 2);
		world.setBlock(i + 31, j + 41, k + 32, placeBuildingBlock(random), 0, 2);
		world.setBlock(i + 47, j + 41, k + 32, placeBuildingBlock(random), 0, 2);
		world.setBlock(i + 57, j + 41, k + 32, placeBuildingBlock(random), 0, 2);
		world.setBlock(i + 63, j + 41, k + 32, placeBuildingBlock(random), 0, 2);
		world.setBlock(i + 64, j + 41, k + 32, placeBuildingBlock(random), 0, 2);
		world.setBlock(i + 65, j + 41, k + 32, placeBuildingBlock(random), 0, 2);
		world.setBlock(i + 12, j + 41, k + 33, placeBuildingBlock(random), 0, 2);
		world.setBlock(i + 13, j + 41, k + 33, placeBuildingBlock(random), 0, 2);
		world.setBlock(i + 14, j + 41, k + 33, placeBuildingBlock(random), 0, 2);
		world.setBlock(i + 21, j + 41, k + 33, placeBuildingBlock(random), 0, 2);
		world.setBlock(i + 30, j + 41, k + 33, placeBuildingBlock(random), 0, 2);
		world.setBlock(i + 48, j + 41, k + 33, placeBuildingBlock(random), 0, 2);
		world.setBlock(i + 56, j + 41, k + 33, placeBuildingBlock(random), 0, 2);
		world.setBlock(i + 64, j + 41, k + 33, placeBuildingBlock(random), 0, 2);
		world.setBlock(i + 65, j + 41, k + 33, placeBuildingBlock(random), 0, 2);
		world.setBlock(i + 66, j + 41, k + 33, placeBuildingBlock(random), 0, 2);
		world.setBlock(i + 11, j + 41, k + 34, placeBuildingBlock(random), 0, 2);
		world.setBlock(i + 12, j + 41, k + 34, placeBuildingBlock(random), 0, 2);
		world.setBlock(i + 13, j + 41, k + 34, placeBuildingBlock(random), 0, 2);
		world.setBlock(i + 22, j + 41, k + 34, placeBuildingBlock(random), 0, 2);
		world.setBlock(i + 29, j + 41, k + 34, placeBuildingBlock(random), 0, 2);
		world.setBlock(i + 49, j + 41, k + 34, placeBuildingBlock(random), 0, 2);
		world.setBlock(i + 55, j + 41, k + 34, placeBuildingBlock(random), 0, 2);
		world.setBlock(i + 65, j + 41, k + 34, placeBuildingBlock(random), 0, 2);
		world.setBlock(i + 66, j + 41, k + 34, placeBuildingBlock(random), 0, 2);
		world.setBlock(i + 67, j + 41, k + 34, placeBuildingBlock(random), 0, 2);
		world.setBlock(i + 10, j + 41, k + 35, placeBuildingBlock(random), 0, 2);
		world.setBlock(i + 11, j + 41, k + 35, placeBuildingBlock(random), 0, 2);
		world.setBlock(i + 12, j + 41, k + 35, placeBuildingBlock(random), 0, 2);
		world.setBlock(i + 23, j + 41, k + 35, placeBuildingBlock(random), 0, 2);
		world.setBlock(i + 28, j + 41, k + 35, placeBuildingBlock(random), 0, 2);
		world.setBlock(i + 50, j + 41, k + 35, placeBuildingBlock(random), 0, 2);
		world.setBlock(i + 54, j + 41, k + 35, placeBuildingBlock(random), 0, 2);
		world.setBlock(i + 66, j + 41, k + 35, placeBuildingBlock(random), 0, 2);
		world.setBlock(i + 67, j + 41, k + 35, placeBuildingBlock(random), 0, 2);
		world.setBlock(i + 68, j + 41, k + 35, placeBuildingBlock(random), 0, 2);
		world.setBlock(i + 9, j + 41, k + 36, placeBuildingBlock(random), 0, 2);
		world.setBlock(i + 10, j + 41, k + 36, placeBuildingBlock(random), 0, 2);
		world.setBlock(i + 11, j + 41, k + 36, placeBuildingBlock(random), 0, 2);
		world.setBlock(i + 22, j + 41, k + 36, placeBuildingBlock(random), 0, 2);
		world.setBlock(i + 23, j + 41, k + 36, placeBuildingBlock(random), 0, 2);
		world.setBlock(i + 24, j + 41, k + 36, placeBuildingBlock(random), 0, 2);
		world.setBlock(i + 27, j + 41, k + 36, placeBuildingBlock(random), 0, 2);
		world.setBlock(i + 51, j + 41, k + 36, placeBuildingBlock(random), 0, 2);
		world.setBlock(i + 53, j + 41, k + 36, placeBuildingBlock(random), 0, 2);
		world.setBlock(i + 67, j + 41, k + 36, placeBuildingBlock(random), 0, 2);
		world.setBlock(i + 68, j + 41, k + 36, placeBuildingBlock(random), 0, 2);
		world.setBlock(i + 69, j + 41, k + 36, placeBuildingBlock(random), 0, 2);
		world.setBlock(i + 8, j + 41, k + 37, placeBuildingBlock(random), 0, 2);
		world.setBlock(i + 9, j + 41, k + 37, placeBuildingBlock(random), 0, 2);
		world.setBlock(i + 10, j + 41, k + 37, placeBuildingBlock(random), 0, 2);
		world.setBlock(i + 21, j + 41, k + 37, placeBuildingBlock(random), 0, 2);
		world.setBlock(i + 22, j + 41, k + 37, BlocksAether.caelestia_stone_slab, 0, 2);
		world.setBlock(i + 25, j + 41, k + 37, placeBuildingBlock(random), 0, 2);
		world.setBlock(i + 26, j + 41, k + 37, placeBuildingBlock(random), 0, 2);
		world.setBlock(i + 52, j + 41, k + 37, placeBuildingBlock(random), 0, 2);
		world.setBlock(i + 53, j + 41, k + 37, placeBuildingBlock(random), 0, 2);
		world.setBlock(i + 68, j + 41, k + 37, placeBuildingBlock(random), 0, 2);
		world.setBlock(i + 69, j + 41, k + 37, placeBuildingBlock(random), 0, 2);
		world.setBlock(i + 70, j + 41, k + 37, placeBuildingBlock(random), 0, 2);
		world.setBlock(i + 3, j + 41, k + 38, BlocksAether.pillar, 0, 2);
		world.setBlock(i + 8, j + 41, k + 38, placeBuildingBlock(random), 0, 2);
		world.setBlock(i + 9, j + 41, k + 38, placeBuildingBlock(random), 0, 2);
		world.setBlock(i + 10, j + 41, k + 38, placeBuildingBlock(random), 0, 2);
		world.setBlock(i + 21, j + 41, k + 38, placeBuildingBlock(random), 0, 2);
		world.setBlock(i + 22, j + 41, k + 38, BlocksAether.caelestia_stone_double_slab, 0, 2);
		world.setBlock(i + 23, j + 41, k + 38, placeBuildingBlock(random), 0, 2);
		world.setBlock(i + 25, j + 41, k + 38, placeBuildingBlock(random), 0, 2);
		world.setBlock(i + 26, j + 41, k + 38, BlocksAether.locked_creeping_stone, 0, 2);
		world.setBlock(i + 52, j + 41, k + 38, placeBuildingBlock(random), 0, 2);
		world.setBlock(i + 53, j + 41, k + 38, placeBuildingBlock(random), 0, 2);
		world.setBlock(i + 69, j + 41, k + 38, placeBuildingBlock(random), 0, 2);
		world.setBlock(i + 70, j + 41, k + 38, placeBuildingBlock(random), 0, 2);
		world.setBlock(i + 75, j + 41, k + 38, BlocksAether.pillar, 0, 2);
		world.setBlock(i + 8, j + 41, k + 39, placeBuildingBlock(random), 0, 2);
		world.setBlock(i + 9, j + 41, k + 39, placeBuildingBlock(random), 0, 2);
		world.setBlock(i + 10, j + 41, k + 39, placeBuildingBlock(random), 0, 2);
		world.setBlock(i + 25, j + 41, k + 39, placeBuildingBlock(random), 0, 2);
		world.setBlock(i + 26, j + 41, k + 39, placeBuildingBlock(random), 0, 2);
		world.setBlock(i + 52, j + 41, k + 39, placeBuildingBlock(random), 0, 2);
		world.setBlock(i + 53, j + 41, k + 39, placeBuildingBlock(random), 0, 2);
		world.setBlock(i + 68, j + 41, k + 39, placeBuildingBlock(random), 0, 2);
		world.setBlock(i + 69, j + 41, k + 39, placeBuildingBlock(random), 0, 2);
		world.setBlock(i + 70, j + 41, k + 39, placeBuildingBlock(random), 0, 2);
		world.setBlock(i + 9, j + 41, k + 40, placeBuildingBlock(random), 0, 2);
		world.setBlock(i + 10, j + 41, k + 40, placeBuildingBlock(random), 0, 2);
		world.setBlock(i + 11, j + 41, k + 40, placeBuildingBlock(random), 0, 2);
		world.setBlock(i + 21, j + 41, k + 40, placeBuildingBlock(random), 0, 2);
		world.setBlock(i + 22, j + 41, k + 40, placeBuildingBlock(random), 0, 2);
		world.setBlock(i + 23, j + 41, k + 40, placeBuildingBlock(random), 0, 2);
		world.setBlock(i + 24, j + 41, k + 40, placeBuildingBlock(random), 0, 2);
		world.setBlock(i + 27, j + 41, k + 40, placeBuildingBlock(random), 0, 2);
		world.setBlock(i + 51, j + 41, k + 40, placeBuildingBlock(random), 0, 2);
		world.setBlock(i + 53, j + 41, k + 40, placeBuildingBlock(random), 0, 2);
		world.setBlock(i + 67, j + 41, k + 40, placeBuildingBlock(random), 0, 2);
		world.setBlock(i + 68, j + 41, k + 40, placeBuildingBlock(random), 0, 2);
		world.setBlock(i + 69, j + 41, k + 40, placeBuildingBlock(random), 0, 2);
		world.setBlock(i + 10, j + 41, k + 41, placeBuildingBlock(random), 0, 2);
		world.setBlock(i + 11, j + 41, k + 41, placeBuildingBlock(random), 0, 2);
		world.setBlock(i + 12, j + 41, k + 41, placeBuildingBlock(random), 0, 2);
		world.setBlock(i + 22, j + 41, k + 41, BlocksAether.locked_creeping_stone, 0, 2);
		world.setBlock(i + 23, j + 41, k + 41, placeBuildingBlock(random), 0, 2);
		world.setBlock(i + 28, j + 41, k + 41, placeBuildingBlock(random), 0, 2);
		world.setBlock(i + 50, j + 41, k + 41, placeBuildingBlock(random), 0, 2);
		world.setBlock(i + 54, j + 41, k + 41, placeBuildingBlock(random), 0, 2);
		world.setBlock(i + 66, j + 41, k + 41, placeBuildingBlock(random), 0, 2);
		world.setBlock(i + 67, j + 41, k + 41, placeBuildingBlock(random), 0, 2);
		world.setBlock(i + 68, j + 41, k + 41, placeBuildingBlock(random), 0, 2);
		world.setBlock(i + 11, j + 41, k + 42, placeBuildingBlock(random), 0, 2);
		world.setBlock(i + 12, j + 41, k + 42, placeBuildingBlock(random), 0, 2);
		world.setBlock(i + 13, j + 41, k + 42, placeBuildingBlock(random), 0, 2);
		world.setBlock(i + 22, j + 41, k + 42, placeBuildingBlock(random), 0, 2);
		world.setBlock(i + 29, j + 41, k + 42, placeBuildingBlock(random), 0, 2);
		world.setBlock(i + 49, j + 41, k + 42, placeBuildingBlock(random), 0, 2);
		world.setBlock(i + 55, j + 41, k + 42, placeBuildingBlock(random), 0, 2);
		world.setBlock(i + 65, j + 41, k + 42, placeBuildingBlock(random), 0, 2);
		world.setBlock(i + 66, j + 41, k + 42, placeBuildingBlock(random), 0, 2);
		world.setBlock(i + 67, j + 41, k + 42, placeBuildingBlock(random), 0, 2);
		world.setBlock(i + 12, j + 41, k + 43, placeBuildingBlock(random), 0, 2);
		world.setBlock(i + 13, j + 41, k + 43, placeBuildingBlock(random), 0, 2);
		world.setBlock(i + 14, j + 41, k + 43, placeBuildingBlock(random), 0, 2);
		world.setBlock(i + 21, j + 41, k + 43, placeBuildingBlock(random), 0, 2);
		world.setBlock(i + 30, j + 41, k + 43, placeBuildingBlock(random), 0, 2);
		world.setBlock(i + 48, j + 41, k + 43, placeBuildingBlock(random), 0, 2);
		world.setBlock(i + 56, j + 41, k + 43, placeBuildingBlock(random), 0, 2);
		world.setBlock(i + 64, j + 41, k + 43, placeBuildingBlock(random), 0, 2);
		world.setBlock(i + 65, j + 41, k + 43, placeBuildingBlock(random), 0, 2);
		world.setBlock(i + 66, j + 41, k + 43, placeBuildingBlock(random), 0, 2);
		world.setBlock(i + 13, j + 41, k + 44, placeBuildingBlock(random), 0, 2);
		world.setBlock(i + 14, j + 41, k + 44, placeBuildingBlock(random), 0, 2);
		world.setBlock(i + 15, j + 41, k + 44, placeBuildingBlock(random), 0, 2);
		world.setBlock(i + 20, j + 41, k + 44, placeBuildingBlock(random), 0, 2);
		world.setBlock(i + 31, j + 41, k + 44, placeBuildingBlock(random), 0, 2);
		world.setBlock(i + 47, j + 41, k + 44, placeBuildingBlock(random), 0, 2);
		world.setBlock(i + 48, j + 41, k + 44, placeBuildingBlock(random), 0, 2);
		world.setBlock(i + 57, j + 41, k + 44, placeBuildingBlock(random), 0, 2);
		world.setBlock(i + 63, j + 41, k + 44, placeBuildingBlock(random), 0, 2);
		world.setBlock(i + 64, j + 41, k + 44, placeBuildingBlock(random), 0, 2);
		world.setBlock(i + 65, j + 41, k + 44, placeBuildingBlock(random), 0, 2);
		world.setBlock(i + 14, j + 41, k + 45, placeBuildingBlock(random), 0, 2);
		world.setBlock(i + 15, j + 41, k + 45, placeBuildingBlock(random), 0, 2);
		world.setBlock(i + 16, j + 41, k + 45, placeBuildingBlock(random), 0, 2);
		world.setBlock(i + 19, j + 41, k + 45, placeBuildingBlock(random), 0, 2);
		world.setBlock(i + 32, j + 41, k + 45, placeBuildingBlock(random), 0, 2);
		world.setBlock(i + 46, j + 41, k + 45, placeBuildingBlock(random), 0, 2);
		world.setBlock(i + 49, j + 41, k + 45, placeBuildingBlock(random), 0, 2);
		world.setBlock(i + 58, j + 41, k + 45, placeBuildingBlock(random), 0, 2);
		world.setBlock(i + 62, j + 41, k + 45, placeBuildingBlock(random), 0, 2);
		world.setBlock(i + 63, j + 41, k + 45, placeBuildingBlock(random), 0, 2);
		world.setBlock(i + 64, j + 41, k + 45, placeBuildingBlock(random), 0, 2);
		world.setBlock(i + 11, j + 41, k + 46, BlocksAether.pillar, 0, 2);
		world.setBlock(i + 15, j + 41, k + 46, placeBuildingBlock(random), 0, 2);
		world.setBlock(i + 16, j + 41, k + 46, placeBuildingBlock(random), 0, 2);
		world.setBlock(i + 17, j + 41, k + 46, placeBuildingBlock(random), 0, 2);
		world.setBlock(i + 18, j + 41, k + 46, placeBuildingBlock(random), 0, 2);
		world.setBlock(i + 32, j + 41, k + 46, placeBuildingBlock(random), 0, 2);
		world.setBlock(i + 33, j + 41, k + 46, placeBuildingBlock(random), 0, 2);
		world.setBlock(i + 45, j + 41, k + 46, placeBuildingBlock(random), 0, 2);
		world.setBlock(i + 50, j + 41, k + 46, placeBuildingBlock(random), 0, 2);
		world.setBlock(i + 59, j + 41, k + 46, placeBuildingBlock(random), 0, 2);
		world.setBlock(i + 61, j + 41, k + 46, placeBuildingBlock(random), 0, 2);
		world.setBlock(i + 62, j + 41, k + 46, placeBuildingBlock(random), 0, 2);
		world.setBlock(i + 63, j + 41, k + 46, placeBuildingBlock(random), 0, 2);
		world.setBlock(i + 67, j + 41, k + 46, BlocksAether.pillar, 0, 2);
		world.setBlock(i + 16, j + 41, k + 47, placeBuildingBlock(random), 0, 2);
		world.setBlock(i + 17, j + 41, k + 47, placeBuildingBlock(random), 0, 2);
		world.setBlock(i + 18, j + 41, k + 47, placeBuildingBlock(random), 0, 2);
		world.setBlock(i + 31, j + 41, k + 47, placeBuildingBlock(random), 0, 2);
		world.setBlock(i + 34, j + 41, k + 47, placeBuildingBlock(random), 0, 2);
		world.setBlock(i + 44, j + 41, k + 47, placeBuildingBlock(random), 0, 2);
		world.setBlock(i + 51, j + 41, k + 47, placeBuildingBlock(random), 0, 2);
		world.setBlock(i + 60, j + 41, k + 47, placeBuildingBlock(random), 0, 2);
		world.setBlock(i + 61, j + 41, k + 47, placeBuildingBlock(random), 0, 2);
		world.setBlock(i + 62, j + 41, k + 47, placeBuildingBlock(random), 0, 2);
		world.setBlock(i + 17, j + 41, k + 48, placeBuildingBlock(random), 0, 2);
		world.setBlock(i + 18, j + 41, k + 48, placeBuildingBlock(random), 0, 2);
		world.setBlock(i + 19, j + 41, k + 48, placeBuildingBlock(random), 0, 2);
		world.setBlock(i + 30, j + 41, k + 48, placeBuildingBlock(random), 0, 2);
		world.setBlock(i + 35, j + 41, k + 48, placeBuildingBlock(random), 0, 2);
		world.setBlock(i + 43, j + 41, k + 48, placeBuildingBlock(random), 0, 2);
		world.setBlock(i + 52, j + 41, k + 48, placeBuildingBlock(random), 0, 2);
		world.setBlock(i + 59, j + 41, k + 48, placeBuildingBlock(random), 0, 2);
		world.setBlock(i + 60, j + 41, k + 48, placeBuildingBlock(random), 0, 2);
		world.setBlock(i + 61, j + 41, k + 48, placeBuildingBlock(random), 0, 2);
		world.setBlock(i + 18, j + 41, k + 49, placeBuildingBlock(random), 0, 2);
		world.setBlock(i + 19, j + 41, k + 49, placeBuildingBlock(random), 0, 2);
		world.setBlock(i + 20, j + 41, k + 49, placeBuildingBlock(random), 0, 2);
		world.setBlock(i + 29, j + 41, k + 49, placeBuildingBlock(random), 0, 2);
		world.setBlock(i + 36, j + 41, k + 49, placeBuildingBlock(random), 0, 2);
		world.setBlock(i + 39, j + 41, k + 49, BlocksAether.caelestia_stone_double_slab, 0, 2);
		world.setBlock(i + 42, j + 41, k + 49, BlocksAether.locked_creeping_stone, 0, 2);
		world.setBlock(i + 53, j + 41, k + 49, placeBuildingBlock(random), 0, 2);
		world.setBlock(i + 58, j + 41, k + 49, placeBuildingBlock(random), 0, 2);
		world.setBlock(i + 59, j + 41, k + 49, placeBuildingBlock(random), 0, 2);
		world.setBlock(i + 60, j + 41, k + 49, placeBuildingBlock(random), 0, 2);
		world.setBlock(i + 19, j + 41, k + 50, placeBuildingBlock(random), 0, 2);
		world.setBlock(i + 20, j + 41, k + 50, placeBuildingBlock(random), 0, 2);
		world.setBlock(i + 21, j + 41, k + 50, placeBuildingBlock(random), 0, 2);
		world.setBlock(i + 28, j + 41, k + 50, placeBuildingBlock(random), 0, 2);
		world.setBlock(i + 37, j + 41, k + 50, placeBuildingBlock(random), 0, 2);
		world.setBlock(i + 39, j + 41, k + 50, BlocksAether.caelestia_stone_double_slab, 0, 2);
		world.setBlock(i + 41, j + 41, k + 50, placeBuildingBlock(random), 0, 2);
		world.setBlock(i + 48, j + 45, k + 28, placeBuildingBlock(random), 0, 2);
		world.setBlock(i + 49, j + 45, k + 28, placeBuildingBlock(random), 0, 2);
		world.setBlock(i + 50, j + 45, k + 28, placeBuildingBlock(random), 0, 2);
		world.setBlock(i + 51, j + 45, k + 28, placeBuildingBlock(random), 0, 2);
		world.setBlock(i + 52, j + 45, k + 28, placeBuildingBlock(random), 0, 2);
		world.setBlock(i + 53, j + 45, k + 28, placeBuildingBlock(random), 0, 2);
		world.setBlock(i + 54, j + 45, k + 28, placeBuildingBlock(random), 0, 2);
		world.setBlock(i + 55, j + 45, k + 28, placeBuildingBlock(random), 0, 2);
		world.setBlock(i + 56, j + 45, k + 28, placeBuildingBlock(random), 0, 2);
		world.setBlock(i + 57, j + 45, k + 28, placeBuildingBlock(random), 0, 2);
		world.setBlock(i + 58, j + 45, k + 28, placeBuildingBlock(random), 0, 2);
		world.setBlock(i + 59, j + 45, k + 28, placeBuildingBlock(random), 0, 2);
		world.setBlock(i + 60, j + 45, k + 28, placeBuildingBlock(random), 0, 2);
		world.setBlock(i + 61, j + 45, k + 28, placeBuildingBlock(random), 0, 2);
		world.setBlock(i + 16, j + 45, k + 29, placeBuildingBlock(random), 0, 2);
		world.setBlock(i + 17, j + 45, k + 29, placeBuildingBlock(random), 0, 2);
		world.setBlock(i + 18, j + 45, k + 29, placeBuildingBlock(random), 0, 2);
		world.setBlock(i + 19, j + 45, k + 29, placeBuildingBlock(random), 0, 2);
		world.setBlock(i + 20, j + 45, k + 29, placeBuildingBlock(random), 0, 2);
		world.setBlock(i + 21, j + 45, k + 29, placeBuildingBlock(random), 0, 2);
		world.setBlock(i + 22, j + 45, k + 29, placeBuildingBlock(random), 0, 2);
		world.setBlock(i + 23, j + 45, k + 29, placeBuildingBlock(random), 0, 2);
		world.setBlock(i + 24, j + 45, k + 29, placeBuildingBlock(random), 0, 2);
		world.setBlock(i + 25, j + 45, k + 29, placeBuildingBlock(random), 0, 2);
		world.setBlock(i + 26, j + 45, k + 29, placeBuildingBlock(random), 0, 2);
		world.setBlock(i + 27, j + 45, k + 29, placeBuildingBlock(random), 0, 2);
		world.setBlock(i + 28, j + 45, k + 29, placeBuildingBlock(random), 0, 2);
		world.setBlock(i + 29, j + 45, k + 29, placeBuildingBlock(random), 0, 2);
		world.setBlock(i + 30, j + 45, k + 29, placeBuildingBlock(random), 0, 2);
		world.setBlock(i + 31, j + 45, k + 29, placeBuildingBlock(random), 0, 2);
		world.setBlock(i + 32, j + 45, k + 29, placeBuildingBlock(random), 0, 2);
		world.setBlock(i + 33, j + 45, k + 29, placeBuildingBlock(random), 0, 2);
		world.setBlock(i + 34, j + 45, k + 29, placeBuildingBlock(random), 0, 2);
		world.setBlock(i + 35, j + 45, k + 29, BlocksAether.caelestia_stone_double_slab, 0, 2);
		world.setBlock(i + 44, j + 45, k + 29, BlocksAether.locked_creeping_stone, 0, 2);
		world.setBlock(i + 45, j + 45, k + 29, placeBuildingBlock(random), 0, 2);
		world.setBlock(i + 46, j + 45, k + 29, placeBuildingBlock(random), 0, 2);
		world.setBlock(i + 47, j + 45, k + 29, placeBuildingBlock(random), 0, 2);
		world.setBlock(i + 48, j + 45, k + 29, placeBuildingBlock(random), 0, 2);
		world.setBlock(i + 49, j + 45, k + 29, placeBuildingBlock(random), 0, 2);
		world.setBlock(i + 50, j + 45, k + 29, placeBuildingBlock(random), 0, 2);
		world.setBlock(i + 51, j + 45, k + 29, placeBuildingBlock(random), 0, 2);
		world.setBlock(i + 52, j + 45, k + 29, placeBuildingBlock(random), 0, 2);
		world.setBlock(i + 53, j + 45, k + 29, placeBuildingBlock(random), 0, 2);
		world.setBlock(i + 54, j + 45, k + 29, placeBuildingBlock(random), 0, 2);
		world.setBlock(i + 55, j + 45, k + 29, placeBuildingBlock(random), 0, 2);
		world.setBlock(i + 56, j + 45, k + 29, placeBuildingBlock(random), 0, 2);
		world.setBlock(i + 57, j + 45, k + 29, placeBuildingBlock(random), 0, 2);
		world.setBlock(i + 58, j + 45, k + 29, placeBuildingBlock(random), 0, 2);
		world.setBlock(i + 59, j + 45, k + 29, placeBuildingBlock(random), 0, 2);
		world.setBlock(i + 60, j + 45, k + 29, placeBuildingBlock(random), 0, 2);
		world.setBlock(i + 61, j + 45, k + 29, placeBuildingBlock(random), 0, 2);
		world.setBlock(i + 62, j + 45, k + 29, placeBuildingBlock(random), 0, 2);
		world.setBlock(i + 11, j + 45, k + 30, BlocksAether.pillar, 0, 2);
		world.setBlock(i + 15, j + 45, k + 30, placeBuildingBlock(random), 0, 2);
		world.setBlock(i + 16, j + 45, k + 30, placeBuildingBlock(random), 0, 2);
		world.setBlock(i + 17, j + 45, k + 30, placeBuildingBlock(random), 0, 2);
		world.setBlock(i + 18, j + 45, k + 30, placeBuildingBlock(random), 0, 2);
		world.setBlock(i + 19, j + 45, k + 30, placeBuildingBlock(random), 0, 2);
		world.setBlock(i + 20, j + 45, k + 30, placeBuildingBlock(random), 0, 2);
		world.setBlock(i + 21, j + 45, k + 30, placeBuildingBlock(random), 0, 2);
		world.setBlock(i + 22, j + 45, k + 30, placeBuildingBlock(random), 0, 2);
		world.setBlock(i + 23, j + 45, k + 30, placeBuildingBlock(random), 0, 2);
		world.setBlock(i + 24, j + 45, k + 30, placeBuildingBlock(random), 0, 2);
		world.setBlock(i + 25, j + 45, k + 30, placeBuildingBlock(random), 0, 2);
		world.setBlock(i + 26, j + 45, k + 30, placeBuildingBlock(random), 0, 2);
		world.setBlock(i + 27, j + 45, k + 30, placeBuildingBlock(random), 0, 2);
		world.setBlock(i + 28, j + 45, k + 30, placeBuildingBlock(random), 0, 2);
		world.setBlock(i + 29, j + 45, k + 30, placeBuildingBlock(random), 0, 2);
		world.setBlock(i + 30, j + 45, k + 30, placeBuildingBlock(random), 0, 2);
		world.setBlock(i + 31, j + 45, k + 30, placeBuildingBlock(random), 0, 2);
		world.setBlock(i + 32, j + 45, k + 30, placeBuildingBlock(random), 0, 2);
		world.setBlock(i + 33, j + 45, k + 30, placeBuildingBlock(random), 0, 2);
		world.setBlock(i + 35, j + 45, k + 30, BlocksAether.caelestia_stone_double_slab, 0, 2);
		world.setBlock(i + 45, j + 45, k + 30, placeBuildingBlock(random), 0, 2);
		world.setBlock(i + 46, j + 45, k + 30, placeBuildingBlock(random), 0, 2);
		world.setBlock(i + 47, j + 45, k + 30, placeBuildingBlock(random), 0, 2);
		world.setBlock(i + 48, j + 45, k + 30, placeBuildingBlock(random), 0, 2);
		world.setBlock(i + 49, j + 45, k + 30, placeBuildingBlock(random), 0, 2);
		world.setBlock(i + 50, j + 45, k + 30, placeBuildingBlock(random), 0, 2);
		world.setBlock(i + 51, j + 45, k + 30, placeBuildingBlock(random), 0, 2);
		world.setBlock(i + 52, j + 45, k + 30, placeBuildingBlock(random), 0, 2);
		world.setBlock(i + 53, j + 45, k + 30, placeBuildingBlock(random), 0, 2);
		world.setBlock(i + 54, j + 45, k + 30, placeBuildingBlock(random), 0, 2);
		world.setBlock(i + 55, j + 45, k + 30, placeBuildingBlock(random), 0, 2);
		world.setBlock(i + 56, j + 45, k + 30, placeBuildingBlock(random), 0, 2);
		world.setBlock(i + 57, j + 45, k + 30, placeBuildingBlock(random), 0, 2);
		world.setBlock(i + 58, j + 45, k + 30, placeBuildingBlock(random), 0, 2);
		world.setBlock(i + 59, j + 45, k + 30, placeBuildingBlock(random), 0, 2);
		world.setBlock(i + 60, j + 45, k + 30, placeBuildingBlock(random), 0, 2);
		world.setBlock(i + 61, j + 45, k + 30, placeBuildingBlock(random), 0, 2);
		world.setBlock(i + 62, j + 45, k + 30, placeBuildingBlock(random), 0, 2);
		world.setBlock(i + 63, j + 45, k + 30, placeBuildingBlock(random), 0, 2);
		world.setBlock(i + 67, j + 45, k + 30, BlocksAether.pillar, 0, 2);
		world.setBlock(i + 14, j + 45, k + 31, placeBuildingBlock(random), 0, 2);
		world.setBlock(i + 15, j + 45, k + 31, placeBuildingBlock(random), 0, 2);
		world.setBlock(i + 16, j + 45, k + 31, placeBuildingBlock(random), 0, 2);
		world.setBlock(i + 17, j + 45, k + 31, placeBuildingBlock(random), 0, 2);
		world.setBlock(i + 18, j + 45, k + 31, placeBuildingBlock(random), 0, 2);
		world.setBlock(i + 19, j + 45, k + 31, placeBuildingBlock(random), 0, 2);
		world.setBlock(i + 20, j + 45, k + 31, placeBuildingBlock(random), 0, 2);
		world.setBlock(i + 21, j + 45, k + 31, placeBuildingBlock(random), 0, 2);
		world.setBlock(i + 22, j + 45, k + 31, placeBuildingBlock(random), 0, 2);
		world.setBlock(i + 23, j + 45, k + 31, placeBuildingBlock(random), 0, 2);
		world.setBlock(i + 24, j + 45, k + 31, placeBuildingBlock(random), 0, 2);
		world.setBlock(i + 25, j + 45, k + 31, placeBuildingBlock(random), 0, 2);
		world.setBlock(i + 26, j + 45, k + 31, placeBuildingBlock(random), 0, 2);
		world.setBlock(i + 27, j + 45, k + 31, placeBuildingBlock(random), 0, 2);
		world.setBlock(i + 28, j + 45, k + 31, placeBuildingBlock(random), 0, 2);
		world.setBlock(i + 29, j + 45, k + 31, placeBuildingBlock(random), 0, 2);
		world.setBlock(i + 30, j + 45, k + 31, placeBuildingBlock(random), 0, 2);
		world.setBlock(i + 31, j + 45, k + 31, placeBuildingBlock(random), 0, 2);
		world.setBlock(i + 32, j + 45, k + 31, placeBuildingBlock(random), 0, 2);
		world.setBlock(i + 46, j + 45, k + 31, placeBuildingBlock(random), 0, 2);
		world.setBlock(i + 47, j + 45, k + 31, placeBuildingBlock(random), 0, 2);
		world.setBlock(i + 48, j + 45, k + 31, placeBuildingBlock(random), 0, 2);
		world.setBlock(i + 49, j + 45, k + 31, placeBuildingBlock(random), 0, 2);
		world.setBlock(i + 50, j + 45, k + 31, placeBuildingBlock(random), 0, 2);
		world.setBlock(i + 51, j + 45, k + 31, placeBuildingBlock(random), 0, 2);
		world.setBlock(i + 52, j + 45, k + 31, placeBuildingBlock(random), 0, 2);
		world.setBlock(i + 53, j + 45, k + 31, placeBuildingBlock(random), 0, 2);
		world.setBlock(i + 54, j + 45, k + 31, placeBuildingBlock(random), 0, 2);
		world.setBlock(i + 55, j + 45, k + 31, placeBuildingBlock(random), 0, 2);
		world.setBlock(i + 56, j + 45, k + 31, placeBuildingBlock(random), 0, 2);
		world.setBlock(i + 57, j + 45, k + 31, placeBuildingBlock(random), 0, 2);
		world.setBlock(i + 58, j + 45, k + 31, placeBuildingBlock(random), 0, 2);
		world.setBlock(i + 59, j + 45, k + 31, placeBuildingBlock(random), 0, 2);
		world.setBlock(i + 60, j + 45, k + 31, placeBuildingBlock(random), 0, 2);
		world.setBlock(i + 61, j + 45, k + 31, placeBuildingBlock(random), 0, 2);
		world.setBlock(i + 62, j + 45, k + 31, placeBuildingBlock(random), 0, 2);
		world.setBlock(i + 63, j + 45, k + 31, placeBuildingBlock(random), 0, 2);
		world.setBlock(i + 64, j + 45, k + 31, placeBuildingBlock(random), 0, 2);
		world.setBlock(i + 13, j + 45, k + 32, placeBuildingBlock(random), 0, 2);
		world.setBlock(i + 14, j + 45, k + 32, placeBuildingBlock(random), 0, 2);
		world.setBlock(i + 15, j + 45, k + 32, placeBuildingBlock(random), 0, 2);
		world.setBlock(i + 16, j + 45, k + 32, placeBuildingBlock(random), 0, 2);
		world.setBlock(i + 17, j + 45, k + 32, placeBuildingBlock(random), 0, 2);
		world.setBlock(i + 18, j + 45, k + 32, placeBuildingBlock(random), 0, 2);
		world.setBlock(i + 19, j + 45, k + 32, placeBuildingBlock(random), 0, 2);
		world.setBlock(i + 20, j + 45, k + 32, placeBuildingBlock(random), 0, 2);
		world.setBlock(i + 21, j + 45, k + 32, placeBuildingBlock(random), 0, 2);
		world.setBlock(i + 22, j + 45, k + 32, placeBuildingBlock(random), 0, 2);
		world.setBlock(i + 23, j + 45, k + 32, placeBuildingBlock(random), 0, 2);
		world.setBlock(i + 24, j + 45, k + 32, placeBuildingBlock(random), 0, 2);
		world.setBlock(i + 25, j + 45, k + 32, placeBuildingBlock(random), 0, 2);
		world.setBlock(i + 26, j + 45, k + 32, placeBuildingBlock(random), 0, 2);
		world.setBlock(i + 27, j + 45, k + 32, placeBuildingBlock(random), 0, 2);
		world.setBlock(i + 28, j + 45, k + 32, placeBuildingBlock(random), 0, 2);
		world.setBlock(i + 29, j + 45, k + 32, placeBuildingBlock(random), 0, 2);
		world.setBlock(i + 30, j + 45, k + 32, placeBuildingBlock(random), 0, 2);
		world.setBlock(i + 31, j + 45, k + 32, placeBuildingBlock(random), 0, 2);
		world.setBlock(i + 47, j + 45, k + 32, placeBuildingBlock(random), 0, 2);
		world.setBlock(i + 48, j + 45, k + 32, placeBuildingBlock(random), 0, 2);
		world.setBlock(i + 49, j + 45, k + 32, placeBuildingBlock(random), 0, 2);
		world.setBlock(i + 50, j + 45, k + 32, placeBuildingBlock(random), 0, 2);
		world.setBlock(i + 51, j + 45, k + 32, placeBuildingBlock(random), 0, 2);
		world.setBlock(i + 52, j + 45, k + 32, placeBuildingBlock(random), 0, 2);
		world.setBlock(i + 53, j + 45, k + 32, placeBuildingBlock(random), 0, 2);
		world.setBlock(i + 54, j + 45, k + 32, placeBuildingBlock(random), 0, 2);
		world.setBlock(i + 55, j + 45, k + 32, placeBuildingBlock(random), 0, 2);
		world.setBlock(i + 56, j + 45, k + 32, placeBuildingBlock(random), 0, 2);
		world.setBlock(i + 57, j + 45, k + 32, placeBuildingBlock(random), 0, 2);
		world.setBlock(i + 58, j + 45, k + 32, placeBuildingBlock(random), 0, 2);
		world.setBlock(i + 59, j + 45, k + 32, placeBuildingBlock(random), 0, 2);
		world.setBlock(i + 60, j + 45, k + 32, placeBuildingBlock(random), 0, 2);
		world.setBlock(i + 61, j + 45, k + 32, placeBuildingBlock(random), 0, 2);
		world.setBlock(i + 62, j + 45, k + 32, placeBuildingBlock(random), 0, 2);
		world.setBlock(i + 63, j + 45, k + 32, placeBuildingBlock(random), 0, 2);
		world.setBlock(i + 64, j + 45, k + 32, placeBuildingBlock(random), 0, 2);
		world.setBlock(i + 65, j + 45, k + 32, placeBuildingBlock(random), 0, 2);
		world.setBlock(i + 12, j + 45, k + 33, placeBuildingBlock(random), 0, 2);
		world.setBlock(i + 13, j + 45, k + 33, placeBuildingBlock(random), 0, 2);
		world.setBlock(i + 14, j + 45, k + 33, placeBuildingBlock(random), 0, 2);
		world.setBlock(i + 15, j + 45, k + 33, placeBuildingBlock(random), 0, 2);
		world.setBlock(i + 16, j + 45, k + 33, placeBuildingBlock(random), 0, 2);
		world.setBlock(i + 17, j + 45, k + 33, placeBuildingBlock(random), 0, 2);
		world.setBlock(i + 18, j + 45, k + 33, placeBuildingBlock(random), 0, 2);
		world.setBlock(i + 19, j + 45, k + 33, placeBuildingBlock(random), 0, 2);
		world.setBlock(i + 20, j + 45, k + 33, placeBuildingBlock(random), 0, 2);
		world.setBlock(i + 21, j + 45, k + 33, placeBuildingBlock(random), 0, 2);
		world.setBlock(i + 22, j + 45, k + 33, placeBuildingBlock(random), 0, 2);
		world.setBlock(i + 23, j + 45, k + 33, placeBuildingBlock(random), 0, 2);
		world.setBlock(i + 24, j + 45, k + 33, placeBuildingBlock(random), 0, 2);
		world.setBlock(i + 25, j + 45, k + 33, placeBuildingBlock(random), 0, 2);
		world.setBlock(i + 26, j + 45, k + 33, placeBuildingBlock(random), 0, 2);
		world.setBlock(i + 27, j + 45, k + 33, placeBuildingBlock(random), 0, 2);
		world.setBlock(i + 28, j + 45, k + 33, placeBuildingBlock(random), 0, 2);
		world.setBlock(i + 29, j + 45, k + 33, placeBuildingBlock(random), 0, 2);
		world.setBlock(i + 30, j + 45, k + 33, placeBuildingBlock(random), 0, 2);
		world.setBlock(i + 48, j + 45, k + 33, placeBuildingBlock(random), 0, 2);
		world.setBlock(i + 49, j + 45, k + 33, placeBuildingBlock(random), 0, 2);
		world.setBlock(i + 50, j + 45, k + 33, placeBuildingBlock(random), 0, 2);
		world.setBlock(i + 51, j + 45, k + 33, placeBuildingBlock(random), 0, 2);
		world.setBlock(i + 52, j + 45, k + 33, placeBuildingBlock(random), 0, 2);
		world.setBlock(i + 53, j + 45, k + 33, placeBuildingBlock(random), 0, 2);
		world.setBlock(i + 54, j + 45, k + 33, placeBuildingBlock(random), 0, 2);
		world.setBlock(i + 55, j + 45, k + 33, placeBuildingBlock(random), 0, 2);
		world.setBlock(i + 56, j + 45, k + 33, placeBuildingBlock(random), 0, 2);
		world.setBlock(i + 57, j + 45, k + 33, placeBuildingBlock(random), 0, 2);
		world.setBlock(i + 58, j + 45, k + 33, placeBuildingBlock(random), 0, 2);
		world.setBlock(i + 59, j + 45, k + 33, placeBuildingBlock(random), 0, 2);
		world.setBlock(i + 60, j + 45, k + 33, placeBuildingBlock(random), 0, 2);
		world.setBlock(i + 61, j + 45, k + 33, placeBuildingBlock(random), 0, 2);
		world.setBlock(i + 62, j + 45, k + 33, placeBuildingBlock(random), 0, 2);
		world.setBlock(i + 63, j + 45, k + 33, placeBuildingBlock(random), 0, 2);
		world.setBlock(i + 64, j + 45, k + 33, placeBuildingBlock(random), 0, 2);
		world.setBlock(i + 65, j + 45, k + 33, placeBuildingBlock(random), 0, 2);
		world.setBlock(i + 66, j + 45, k + 33, placeBuildingBlock(random), 0, 2);
		world.setBlock(i + 11, j + 45, k + 34, placeBuildingBlock(random), 0, 2);
		world.setBlock(i + 12, j + 45, k + 34, placeBuildingBlock(random), 0, 2);
		world.setBlock(i + 13, j + 45, k + 34, placeBuildingBlock(random), 0, 2);
		world.setBlock(i + 14, j + 45, k + 34, placeBuildingBlock(random), 0, 2);
		world.setBlock(i + 15, j + 45, k + 34, placeBuildingBlock(random), 0, 2);
		world.setBlock(i + 16, j + 45, k + 34, placeBuildingBlock(random), 0, 2);
		world.setBlock(i + 17, j + 45, k + 34, placeBuildingBlock(random), 0, 2);
		world.setBlock(i + 18, j + 45, k + 34, placeBuildingBlock(random), 0, 2);
		world.setBlock(i + 19, j + 45, k + 34, placeBuildingBlock(random), 0, 2);
		world.setBlock(i + 20, j + 45, k + 34, placeBuildingBlock(random), 0, 2);
		world.setBlock(i + 21, j + 45, k + 34, placeBuildingBlock(random), 0, 2);
		world.setBlock(i + 22, j + 45, k + 34, placeBuildingBlock(random), 0, 2);
		world.setBlock(i + 23, j + 45, k + 34, placeBuildingBlock(random), 0, 2);
		world.setBlock(i + 24, j + 45, k + 34, placeBuildingBlock(random), 0, 2);
		world.setBlock(i + 25, j + 45, k + 34, placeBuildingBlock(random), 0, 2);
		world.setBlock(i + 26, j + 45, k + 34, placeBuildingBlock(random), 0, 2);
		world.setBlock(i + 27, j + 45, k + 34, placeBuildingBlock(random), 0, 2);
		world.setBlock(i + 28, j + 45, k + 34, placeBuildingBlock(random), 0, 2);
		world.setBlock(i + 29, j + 45, k + 34, placeBuildingBlock(random), 0, 2);
		world.setBlock(i + 49, j + 45, k + 34, placeBuildingBlock(random), 0, 2);
		world.setBlock(i + 50, j + 45, k + 34, placeBuildingBlock(random), 0, 2);
		world.setBlock(i + 51, j + 45, k + 34, placeBuildingBlock(random), 0, 2);
		world.setBlock(i + 52, j + 45, k + 34, placeBuildingBlock(random), 0, 2);
		world.setBlock(i + 53, j + 45, k + 34, placeBuildingBlock(random), 0, 2);
		world.setBlock(i + 54, j + 45, k + 34, placeBuildingBlock(random), 0, 2);
		world.setBlock(i + 55, j + 45, k + 34, placeBuildingBlock(random), 0, 2);
		world.setBlock(i + 56, j + 45, k + 34, placeBuildingBlock(random), 0, 2);
		world.setBlock(i + 57, j + 45, k + 34, placeBuildingBlock(random), 0, 2);
		world.setBlock(i + 58, j + 45, k + 34, placeBuildingBlock(random), 0, 2);
		world.setBlock(i + 59, j + 45, k + 34, placeBuildingBlock(random), 0, 2);
		world.setBlock(i + 60, j + 45, k + 34, placeBuildingBlock(random), 0, 2);
		world.setBlock(i + 61, j + 45, k + 34, placeBuildingBlock(random), 0, 2);
		world.setBlock(i + 62, j + 45, k + 34, placeBuildingBlock(random), 0, 2);
		world.setBlock(i + 63, j + 45, k + 34, placeBuildingBlock(random), 0, 2);
		world.setBlock(i + 64, j + 45, k + 34, placeBuildingBlock(random), 0, 2);
		world.setBlock(i + 65, j + 45, k + 34, placeBuildingBlock(random), 0, 2);
		world.setBlock(i + 66, j + 45, k + 34, placeBuildingBlock(random), 0, 2);
		world.setBlock(i + 67, j + 45, k + 34, placeBuildingBlock(random), 0, 2);
		world.setBlock(i + 10, j + 45, k + 35, placeBuildingBlock(random), 0, 2);
		world.setBlock(i + 11, j + 45, k + 35, placeBuildingBlock(random), 0, 2);
		world.setBlock(i + 12, j + 45, k + 35, placeBuildingBlock(random), 0, 2);
		world.setBlock(i + 13, j + 45, k + 35, placeBuildingBlock(random), 0, 2);
		world.setBlock(i + 14, j + 45, k + 35, placeBuildingBlock(random), 0, 2);
		world.setBlock(i + 15, j + 45, k + 35, placeBuildingBlock(random), 0, 2);
		world.setBlock(i + 16, j + 45, k + 35, placeBuildingBlock(random), 0, 2);
		world.setBlock(i + 17, j + 45, k + 35, placeBuildingBlock(random), 0, 2);
		world.setBlock(i + 18, j + 45, k + 35, placeBuildingBlock(random), 0, 2);
		world.setBlock(i + 19, j + 45, k + 35, placeBuildingBlock(random), 0, 2);
		world.setBlock(i + 20, j + 45, k + 35, placeBuildingBlock(random), 0, 2);
		world.setBlock(i + 21, j + 45, k + 35, placeBuildingBlock(random), 0, 2);
		world.setBlock(i + 22, j + 45, k + 35, placeBuildingBlock(random), 0, 2);
		world.setBlock(i + 23, j + 45, k + 35, placeBuildingBlock(random), 0, 2);
		world.setBlock(i + 24, j + 45, k + 35, placeBuildingBlock(random), 0, 2);
		world.setBlock(i + 25, j + 45, k + 35, placeBuildingBlock(random), 0, 2);
		world.setBlock(i + 26, j + 45, k + 35, placeBuildingBlock(random), 0, 2);
		world.setBlock(i + 27, j + 45, k + 35, placeBuildingBlock(random), 0, 2);
		world.setBlock(i + 28, j + 45, k + 35, placeBuildingBlock(random), 0, 2);
		world.setBlock(i + 50, j + 45, k + 35, placeBuildingBlock(random), 0, 2);
		world.setBlock(i + 51, j + 45, k + 35, placeBuildingBlock(random), 0, 2);
		world.setBlock(i + 52, j + 45, k + 35, placeBuildingBlock(random), 0, 2);
		world.setBlock(i + 53, j + 45, k + 35, placeBuildingBlock(random), 0, 2);
		world.setBlock(i + 54, j + 45, k + 35, placeBuildingBlock(random), 0, 2);
		world.setBlock(i + 55, j + 45, k + 35, placeBuildingBlock(random), 0, 2);
		world.setBlock(i + 56, j + 45, k + 35, placeBuildingBlock(random), 0, 2);
		world.setBlock(i + 57, j + 45, k + 35, placeBuildingBlock(random), 0, 2);
		world.setBlock(i + 58, j + 45, k + 35, placeBuildingBlock(random), 0, 2);
		world.setBlock(i + 59, j + 45, k + 35, placeBuildingBlock(random), 0, 2);
		world.setBlock(i + 60, j + 45, k + 35, placeBuildingBlock(random), 0, 2);
		world.setBlock(i + 61, j + 45, k + 35, placeBuildingBlock(random), 0, 2);
		world.setBlock(i + 62, j + 45, k + 35, placeBuildingBlock(random), 0, 2);
		world.setBlock(i + 63, j + 45, k + 35, placeBuildingBlock(random), 0, 2);
		world.setBlock(i + 64, j + 45, k + 35, placeBuildingBlock(random), 0, 2);
		world.setBlock(i + 65, j + 45, k + 35, placeBuildingBlock(random), 0, 2);
		world.setBlock(i + 66, j + 45, k + 35, placeBuildingBlock(random), 0, 2);
		world.setBlock(i + 67, j + 45, k + 35, placeBuildingBlock(random), 0, 2);
		world.setBlock(i + 68, j + 45, k + 35, placeBuildingBlock(random), 0, 2);
		world.setBlock(i + 59, j + 48, k + 27, placeBuildingBlock(random), 0, 2);
		world.setBlock(i + 60, j + 48, k + 27, placeBuildingBlock(random), 0, 2);
		world.setBlock(i + 17, j + 48, k + 28, placeBuildingBlock(random), 0, 2);
		world.setBlock(i + 18, j + 48, k + 28, placeBuildingBlock(random), 0, 2);
		world.setBlock(i + 19, j + 48, k + 28, placeBuildingBlock(random), 0, 2);
		world.setBlock(i + 30, j + 48, k + 28, placeBuildingBlock(random), 0, 2);
		world.setBlock(i + 35, j + 48, k + 28, placeBuildingBlock(random), 0, 2);
		world.setBlock(i + 43, j + 48, k + 28, placeBuildingBlock(random), 0, 2);
		world.setBlock(i + 59, j + 48, k + 28, placeBuildingBlock(random), 0, 2);
		world.setBlock(i + 60, j + 48, k + 28, placeBuildingBlock(random), 0, 2);
		world.setBlock(i + 61, j + 48, k + 28, placeBuildingBlock(random), 0, 2);
		world.setBlock(i + 16, j + 48, k + 29, placeBuildingBlock(random), 0, 2);
		world.setBlock(i + 17, j + 48, k + 29, placeBuildingBlock(random), 0, 2);
		world.setBlock(i + 18, j + 48, k + 29, placeBuildingBlock(random), 0, 2);
		world.setBlock(i + 31, j + 48, k + 29, placeBuildingBlock(random), 0, 2);
		world.setBlock(i + 34, j + 48, k + 29, BlocksAether.locked_creeping_stone, 0, 2);
		world.setBlock(i + 44, j + 48, k + 29, placeBuildingBlock(random), 0, 2);
		world.setBlock(i + 49, j + 48, k + 29, placeBuildingBlock(random), 0, 2);
		world.setBlock(i + 60, j + 48, k + 29, placeBuildingBlock(random), 0, 2);
		world.setBlock(i + 61, j + 48, k + 29, placeBuildingBlock(random), 0, 2);
		world.setBlock(i + 62, j + 48, k + 29, placeBuildingBlock(random), 0, 2);
		world.setBlock(i + 11, j + 48, k + 30, BlocksAether.pillar, 0, 2);
		world.setBlock(i + 15, j + 48, k + 30, placeBuildingBlock(random), 0, 2);
		world.setBlock(i + 16, j + 48, k + 30, placeBuildingBlock(random), 0, 2);
		world.setBlock(i + 17, j + 48, k + 30, placeBuildingBlock(random), 0, 2);
		world.setBlock(i + 18, j + 48, k + 30, placeBuildingBlock(random), 0, 2);
		world.setBlock(i + 32, j + 48, k + 30, placeBuildingBlock(random), 0, 2);
		world.setBlock(i + 33, j + 48, k + 30, placeBuildingBlock(random), 0, 2);
		world.setBlock(i + 45, j + 48, k + 30, placeBuildingBlock(random), 0, 2);
		world.setBlock(i + 48, j + 48, k + 30, placeBuildingBlock(random), 0, 2);
		world.setBlock(i + 59, j + 48, k + 30, placeBuildingBlock(random), 0, 2);
		world.setBlock(i + 61, j + 48, k + 30, placeBuildingBlock(random), 0, 2);
		world.setBlock(i + 62, j + 48, k + 30, placeBuildingBlock(random), 0, 2);
		world.setBlock(i + 63, j + 48, k + 30, placeBuildingBlock(random), 0, 2);
		world.setBlock(i + 67, j + 48, k + 30, BlocksAether.pillar, 0, 2);
		world.setBlock(i + 14, j + 48, k + 31, placeBuildingBlock(random), 0, 2);
		world.setBlock(i + 15, j + 48, k + 31, placeBuildingBlock(random), 0, 2);
		world.setBlock(i + 16, j + 48, k + 31, placeBuildingBlock(random), 0, 2);
		world.setBlock(i + 19, j + 48, k + 31, placeBuildingBlock(random), 0, 2);
		world.setBlock(i + 32, j + 48, k + 31, placeBuildingBlock(random), 0, 2);
		world.setBlock(i + 46, j + 48, k + 31, placeBuildingBlock(random), 0, 2);
		world.setBlock(i + 47, j + 48, k + 31, placeBuildingBlock(random), 0, 2);
		world.setBlock(i + 58, j + 48, k + 31, placeBuildingBlock(random), 0, 2);
		world.setBlock(i + 62, j + 48, k + 31, placeBuildingBlock(random), 0, 2);
		world.setBlock(i + 63, j + 48, k + 31, placeBuildingBlock(random), 0, 2);
		world.setBlock(i + 64, j + 48, k + 31, placeBuildingBlock(random), 0, 2);
		world.setBlock(i + 13, j + 48, k + 32, placeBuildingBlock(random), 0, 2);
		world.setBlock(i + 14, j + 48, k + 32, placeBuildingBlock(random), 0, 2);
		world.setBlock(i + 15, j + 48, k + 32, placeBuildingBlock(random), 0, 2);
		world.setBlock(i + 20, j + 48, k + 32, placeBuildingBlock(random), 0, 2);
		world.setBlock(i + 31, j + 48, k + 32, placeBuildingBlock(random), 0, 2);
		world.setBlock(i + 32, j + 48, k + 32, BlocksAether.caelestia_stone_double_slab, 0, 2);
		world.setBlock(i + 47, j + 48, k + 32, placeBuildingBlock(random), 0, 2);
		world.setBlock(i + 63, j + 48, k + 32, placeBuildingBlock(random), 0, 2);
		world.setBlock(i + 64, j + 48, k + 32, placeBuildingBlock(random), 0, 2);
		world.setBlock(i + 65, j + 48, k + 32, placeBuildingBlock(random), 0, 2);
		world.setBlock(i + 12, j + 48, k + 33, placeBuildingBlock(random), 0, 2);
		world.setBlock(i + 13, j + 48, k + 33, placeBuildingBlock(random), 0, 2);
		world.setBlock(i + 14, j + 48, k + 33, placeBuildingBlock(random), 0, 2);
		world.setBlock(i + 30, j + 48, k + 33, placeBuildingBlock(random), 0, 2);
		world.setBlock(i + 32, j + 48, k + 33, BlocksAether.caelestia_stone_double_slab, 0, 2);
		world.setBlock(i + 48, j + 48, k + 33, placeBuildingBlock(random), 0, 2);
		world.setBlock(i + 64, j + 48, k + 33, placeBuildingBlock(random), 0, 2);
		world.setBlock(i + 65, j + 48, k + 33, placeBuildingBlock(random), 0, 2);
		world.setBlock(i + 66, j + 48, k + 33, placeBuildingBlock(random), 0, 2);
		world.setBlock(i + 11, j + 48, k + 34, placeBuildingBlock(random), 0, 2);
		world.setBlock(i + 12, j + 48, k + 34, placeBuildingBlock(random), 0, 2);
		world.setBlock(i + 13, j + 48, k + 34, placeBuildingBlock(random), 0, 2);
		world.setBlock(i + 29, j + 48, k + 34, placeBuildingBlock(random), 0, 2);
		world.setBlock(i + 49, j + 48, k + 34, placeBuildingBlock(random), 0, 2);
		world.setBlock(i + 55, j + 48, k + 34, placeBuildingBlock(random), 0, 2);
		world.setBlock(i + 65, j + 48, k + 34, placeBuildingBlock(random), 0, 2);
		world.setBlock(i + 66, j + 48, k + 34, placeBuildingBlock(random), 0, 2);
		world.setBlock(i + 67, j + 48, k + 34, placeBuildingBlock(random), 0, 2);
		world.setBlock(i + 10, j + 48, k + 35, placeBuildingBlock(random), 0, 2);
		world.setBlock(i + 11, j + 48, k + 35, placeBuildingBlock(random), 0, 2);
		world.setBlock(i + 12, j + 48, k + 35, placeBuildingBlock(random), 0, 2);
		world.setBlock(i + 23, j + 48, k + 35, placeBuildingBlock(random), 0, 2);
		world.setBlock(i + 28, j + 48, k + 35, placeBuildingBlock(random), 0, 2);
		world.setBlock(i + 50, j + 48, k + 35, placeBuildingBlock(random), 0, 2);
		world.setBlock(i + 54, j + 48, k + 35, placeBuildingBlock(random), 0, 2);
		world.setBlock(i + 66, j + 48, k + 35, placeBuildingBlock(random), 0, 2);
		world.setBlock(i + 67, j + 48, k + 35, placeBuildingBlock(random), 0, 2);
		world.setBlock(i + 68, j + 48, k + 35, placeBuildingBlock(random), 0, 2);
		world.setBlock(i + 9, j + 48, k + 36, placeBuildingBlock(random), 0, 2);
		world.setBlock(i + 10, j + 48, k + 36, placeBuildingBlock(random), 0, 2);
		world.setBlock(i + 11, j + 48, k + 36, placeBuildingBlock(random), 0, 2);
		world.setBlock(i + 24, j + 48, k + 36, placeBuildingBlock(random), 0, 2);
		world.setBlock(i + 27, j + 48, k + 36, placeBuildingBlock(random), 0, 2);
		world.setBlock(i + 51, j + 48, k + 36, placeBuildingBlock(random), 0, 2);
		world.setBlock(i + 53, j + 48, k + 36, placeBuildingBlock(random), 0, 2);
		world.setBlock(i + 54, j + 48, k + 36, placeBuildingBlock(random), 0, 2);
		world.setBlock(i + 55, j + 48, k + 36, placeBuildingBlock(random), 0, 2);
		world.setBlock(i + 56, j + 48, k + 36, placeBuildingBlock(random), 0, 2);
		world.setBlock(i + 57, j + 48, k + 36, placeBuildingBlock(random), 0, 2);
		world.setBlock(i + 67, j + 48, k + 36, placeBuildingBlock(random), 0, 2);
		world.setBlock(i + 68, j + 48, k + 36, placeBuildingBlock(random), 0, 2);
		world.setBlock(i + 69, j + 48, k + 36, placeBuildingBlock(random), 0, 2);
		world.setBlock(i + 8, j + 48, k + 37, placeBuildingBlock(random), 0, 2);
		world.setBlock(i + 9, j + 48, k + 37, placeBuildingBlock(random), 0, 2);
		world.setBlock(i + 10, j + 48, k + 37, placeBuildingBlock(random), 0, 2);
		world.setBlock(i + 25, j + 48, k + 37, placeBuildingBlock(random), 0, 2);
		world.setBlock(i + 26, j + 48, k + 37, placeBuildingBlock(random), 0, 2);
		world.setBlock(i + 52, j + 48, k + 37, placeBuildingBlock(random), 0, 2);
		world.setBlock(i + 53, j + 48, k + 37, placeBuildingBlock(random), 0, 2);
		world.setBlock(i + 68, j + 48, k + 37, placeBuildingBlock(random), 0, 2);
		world.setBlock(i + 69, j + 48, k + 37, placeBuildingBlock(random), 0, 2);
		world.setBlock(i + 70, j + 48, k + 37, placeBuildingBlock(random), 0, 2);
		world.setBlock(i + 3, j + 48, k + 38, BlocksAether.pillar, 0, 2);
		world.setBlock(i + 8, j + 48, k + 38, placeBuildingBlock(random), 0, 2);
		world.setBlock(i + 9, j + 48, k + 38, placeBuildingBlock(random), 0, 2);
		world.setBlock(i + 25, j + 48, k + 38, placeBuildingBlock(random), 0, 2);
		world.setBlock(i + 26, j + 48, k + 38, placeBuildingBlock(random), 0, 2);
		world.setBlock(i + 29, j + 48, k + 38, BlocksAether.arctic_glowstone, 0, 2);
		world.setBlock(i + 52, j + 48, k + 38, placeBuildingBlock(random), 0, 2);
		world.setBlock(i + 53, j + 48, k + 38, placeBuildingBlock(random), 0, 2);
		world.setBlock(i + 55, j + 48, k + 38, placeBuildingBlock(random), 0, 2);
		world.setBlock(i + 56, j + 48, k + 38, placeBuildingBlock(random), 0, 2);
		world.setBlock(i + 57, j + 48, k + 38, placeBuildingBlock(random), 0, 2);
		world.setBlock(i + 69, j + 48, k + 38, placeBuildingBlock(random), 0, 2);
		world.setBlock(i + 70, j + 48, k + 38, placeBuildingBlock(random), 0, 2);
		world.setBlock(i + 75, j + 48, k + 38, BlocksAether.pillar, 0, 2);
		world.setBlock(i + 8, j + 48, k + 39, placeBuildingBlock(random), 0, 2);
		world.setBlock(i + 9, j + 48, k + 39, placeBuildingBlock(random), 0, 2);
		world.setBlock(i + 10, j + 48, k + 39, placeBuildingBlock(random), 0, 2);
		world.setBlock(i + 25, j + 48, k + 39, placeBuildingBlock(random), 0, 2);
		world.setBlock(i + 26, j + 48, k + 39, placeBuildingBlock(random), 0, 2);
		world.setBlock(i + 52, j + 48, k + 39, placeBuildingBlock(random), 0, 2);
		world.setBlock(i + 53, j + 48, k + 39, placeBuildingBlock(random), 0, 2);
		world.setBlock(i + 54, j + 48, k + 39, BlocksAether.caelestia_stone_slab, 0, 2);
		world.setBlock(i + 55, j + 48, k + 39, BlocksAether.caelestia_stone_double_slab, 0, 2);
		world.setBlock(i + 56, j + 48, k + 39, placeBuildingBlock(random), 0, 2);
		world.setBlock(i + 57, j + 48, k + 39, placeBuildingBlock(random), 0, 2);
		world.setBlock(i + 68, j + 48, k + 39, placeBuildingBlock(random), 0, 2);
		world.setBlock(i + 69, j + 48, k + 39, placeBuildingBlock(random), 0, 2);
		world.setBlock(i + 70, j + 48, k + 39, placeBuildingBlock(random), 0, 2);
		world.setBlock(i + 9, j + 48, k + 40, placeBuildingBlock(random), 0, 2);
		world.setBlock(i + 10, j + 48, k + 40, placeBuildingBlock(random), 0, 2);
		world.setBlock(i + 11, j + 48, k + 40, placeBuildingBlock(random), 0, 2);
		world.setBlock(i + 24, j + 48, k + 40, placeBuildingBlock(random), 0, 2);
		world.setBlock(i + 27, j + 48, k + 40, placeBuildingBlock(random), 0, 2);
		world.setBlock(i + 51, j + 48, k + 40, placeBuildingBlock(random), 0, 2);
		world.setBlock(i + 53, j + 48, k + 40, placeBuildingBlock(random), 0, 2);
		world.setBlock(i + 54, j + 48, k + 40, placeBuildingBlock(random), 0, 2);
		world.setBlock(i + 55, j + 48, k + 40, placeBuildingBlock(random), 0, 2);
		world.setBlock(i + 56, j + 48, k + 40, placeBuildingBlock(random), 0, 2);
		world.setBlock(i + 67, j + 48, k + 40, placeBuildingBlock(random), 0, 2);
		world.setBlock(i + 68, j + 48, k + 40, placeBuildingBlock(random), 0, 2);
		world.setBlock(i + 69, j + 48, k + 40, placeBuildingBlock(random), 0, 2);
		world.setBlock(i + 10, j + 48, k + 41, placeBuildingBlock(random), 0, 2);
		world.setBlock(i + 11, j + 48, k + 41, placeBuildingBlock(random), 0, 2);
		world.setBlock(i + 12, j + 48, k + 41, placeBuildingBlock(random), 0, 2);
		world.setBlock(i + 23, j + 48, k + 41, placeBuildingBlock(random), 0, 2);
		world.setBlock(i + 28, j + 48, k + 41, placeBuildingBlock(random), 0, 2);
		world.setBlock(i + 50, j + 48, k + 41, placeBuildingBlock(random), 0, 2);
		world.setBlock(i + 54, j + 48, k + 41, placeBuildingBlock(random), 0, 2);
		world.setBlock(i + 66, j + 48, k + 41, placeBuildingBlock(random), 0, 2);
		world.setBlock(i + 67, j + 48, k + 41, placeBuildingBlock(random), 0, 2);
		world.setBlock(i + 68, j + 48, k + 41, placeBuildingBlock(random), 0, 2);
		world.setBlock(i + 11, j + 48, k + 42, placeBuildingBlock(random), 0, 2);
		world.setBlock(i + 12, j + 48, k + 42, placeBuildingBlock(random), 0, 2);
		world.setBlock(i + 13, j + 48, k + 42, placeBuildingBlock(random), 0, 2);
		world.setBlock(i + 29, j + 48, k + 42, placeBuildingBlock(random), 0, 2);
		world.setBlock(i + 49, j + 48, k + 42, placeBuildingBlock(random), 0, 2);
		world.setBlock(i + 55, j + 48, k + 42, placeBuildingBlock(random), 0, 2);
		world.setBlock(i + 65, j + 48, k + 42, placeBuildingBlock(random), 0, 2);
		world.setBlock(i + 66, j + 48, k + 42, placeBuildingBlock(random), 0, 2);
		world.setBlock(i + 67, j + 48, k + 42, placeBuildingBlock(random), 0, 2);
		world.setBlock(i + 12, j + 48, k + 43, placeBuildingBlock(random), 0, 2);
		world.setBlock(i + 13, j + 48, k + 43, placeBuildingBlock(random), 0, 2);
		world.setBlock(i + 14, j + 48, k + 43, placeBuildingBlock(random), 0, 2);
		world.setBlock(i + 30, j + 48, k + 43, placeBuildingBlock(random), 0, 2);
		world.setBlock(i + 32, j + 48, k + 43, BlocksAether.caelestia_stone_double_slab, 0, 2);
		world.setBlock(i + 48, j + 48, k + 43, placeBuildingBlock(random), 0, 2);
		world.setBlock(i + 64, j + 48, k + 43, placeBuildingBlock(random), 0, 2);
		world.setBlock(i + 65, j + 48, k + 43, placeBuildingBlock(random), 0, 2);
		world.setBlock(i + 66, j + 48, k + 43, placeBuildingBlock(random), 0, 2);
		world.setBlock(i + 13, j + 48, k + 44, placeBuildingBlock(random), 0, 2);
		world.setBlock(i + 14, j + 48, k + 44, placeBuildingBlock(random), 0, 2);
		world.setBlock(i + 15, j + 48, k + 44, placeBuildingBlock(random), 0, 2);
		world.setBlock(i + 20, j + 48, k + 44, placeBuildingBlock(random), 0, 2);
		world.setBlock(i + 31, j + 48, k + 44, placeBuildingBlock(random), 0, 2);
		world.setBlock(i + 32, j + 48, k + 44, BlocksAether.caelestia_stone_double_slab, 0, 2);
		world.setBlock(i + 47, j + 48, k + 44, placeBuildingBlock(random), 0, 2);
		world.setBlock(i + 63, j + 48, k + 44, placeBuildingBlock(random), 0, 2);
		world.setBlock(i + 64, j + 48, k + 44, placeBuildingBlock(random), 0, 2);
		world.setBlock(i + 65, j + 48, k + 44, placeBuildingBlock(random), 0, 2);
		world.setBlock(i + 14, j + 48, k + 45, placeBuildingBlock(random), 0, 2);
		world.setBlock(i + 15, j + 48, k + 45, placeBuildingBlock(random), 0, 2);
		world.setBlock(i + 16, j + 48, k + 45, placeBuildingBlock(random), 0, 2);
		world.setBlock(i + 19, j + 48, k + 45, placeBuildingBlock(random), 0, 2);
		world.setBlock(i + 32, j + 48, k + 45, placeBuildingBlock(random), 0, 2);
		world.setBlock(i + 46, j + 48, k + 45, placeBuildingBlock(random), 0, 2);
		world.setBlock(i + 58, j + 48, k + 45, placeBuildingBlock(random), 0, 2);
		world.setBlock(i + 62, j + 48, k + 45, placeBuildingBlock(random), 0, 2);
		world.setBlock(i + 63, j + 48, k + 45, placeBuildingBlock(random), 0, 2);
		world.setBlock(i + 64, j + 48, k + 45, placeBuildingBlock(random), 0, 2);
		world.setBlock(i + 11, j + 48, k + 46, BlocksAether.pillar, 0, 2);
		world.setBlock(i + 15, j + 48, k + 46, placeBuildingBlock(random), 0, 2);
		world.setBlock(i + 16, j + 48, k + 46, placeBuildingBlock(random), 0, 2);
		world.setBlock(i + 17, j + 48, k + 46, placeBuildingBlock(random), 0, 2);
		world.setBlock(i + 18, j + 48, k + 46, placeBuildingBlock(random), 0, 2);
		world.setBlock(i + 32, j + 48, k + 46, placeBuildingBlock(random), 0, 2);
		world.setBlock(i + 33, j + 48, k + 46, placeBuildingBlock(random), 0, 2);
		world.setBlock(i + 45, j + 48, k + 46, placeBuildingBlock(random), 0, 2);
		world.setBlock(i + 59, j + 48, k + 46, placeBuildingBlock(random), 0, 2);
		world.setBlock(i + 61, j + 48, k + 46, placeBuildingBlock(random), 0, 2);
		world.setBlock(i + 62, j + 48, k + 46, placeBuildingBlock(random), 0, 2);
		world.setBlock(i + 63, j + 48, k + 46, placeBuildingBlock(random), 0, 2);
		world.setBlock(i + 67, j + 48, k + 46, BlocksAether.pillar, 0, 2);
		world.setBlock(i + 16, j + 48, k + 47, placeBuildingBlock(random), 0, 2);
		world.setBlock(i + 17, j + 48, k + 47, placeBuildingBlock(random), 0, 2);
		world.setBlock(i + 18, j + 48, k + 47, placeBuildingBlock(random), 0, 2);
		world.setBlock(i + 31, j + 48, k + 47, placeBuildingBlock(random), 0, 2);
		world.setBlock(i + 34, j + 48, k + 47, placeBuildingBlock(random), 0, 2);
		world.setBlock(i + 44, j + 48, k + 47, placeBuildingBlock(random), 0, 2);
		world.setBlock(i + 60, j + 48, k + 47, placeBuildingBlock(random), 0, 2);
		world.setBlock(i + 61, j + 48, k + 47, placeBuildingBlock(random), 0, 2);
		world.setBlock(i + 62, j + 48, k + 47, placeBuildingBlock(random), 0, 2);
		world.setBlock(i + 17, j + 48, k + 48, placeBuildingBlock(random), 0, 2);
		world.setBlock(i + 18, j + 48, k + 48, placeBuildingBlock(random), 0, 2);
		world.setBlock(i + 19, j + 48, k + 48, placeBuildingBlock(random), 0, 2);
		world.setBlock(i + 30, j + 48, k + 48, placeBuildingBlock(random), 0, 2);
		world.setBlock(i + 35, j + 48, k + 48, placeBuildingBlock(random), 0, 2);
		world.setBlock(i + 43, j + 48, k + 48, placeBuildingBlock(random), 0, 2);
		world.setBlock(i + 59, j + 48, k + 48, placeBuildingBlock(random), 0, 2);
		world.setBlock(i + 60, j + 48, k + 48, placeBuildingBlock(random), 0, 2);
		world.setBlock(i + 61, j + 48, k + 48, placeBuildingBlock(random), 0, 2);
		world.setBlock(i + 18, j + 48, k + 49, placeBuildingBlock(random), 0, 2);
		world.setBlock(i + 19, j + 48, k + 49, placeBuildingBlock(random), 0, 2);
		world.setBlock(i + 20, j + 48, k + 49, placeBuildingBlock(random), 0, 2);
		world.setBlock(i + 36, j + 48, k + 49, placeBuildingBlock(random), 0, 2);
		world.setBlock(i + 42, j + 48, k + 49, placeBuildingBlock(random), 0, 2);
		world.setBlock(i + 58, j + 48, k + 49, placeBuildingBlock(random), 0, 2);
		world.setBlock(i + 59, j + 48, k + 49, placeBuildingBlock(random), 0, 2);
		
		
		return true;
	}
	
	private Block placeBuildingBlock(Random random) {
        if (random.nextDouble() < 0.005) {
            return BlocksAether.fuse_trap;
        } else if (random.nextDouble() >= 0.005 && random.nextDouble() < 0.01) {
        	return BlocksAether.fuse_trap_2;
        } else if (random.nextDouble() >= 0.01 && random.nextDouble() < 0.05) {
        	return BlocksAether.locked_creeping_stone;
        } else {
            return BlocksAether.locked_fuse_stone;
        }
    }

}
