package com.gildedgames.the_aether.world.dungeon.osmium;

import java.util.Random;

import com.gildedgames.the_aether.blocks.BlocksAether;

import net.minecraft.world.World;
import net.minecraft.world.gen.feature.WorldGenerator;

public class OsmiumDungeonGen1 extends WorldGenerator {

	public OsmiumDungeonGen1() {

	}
	
	public boolean generate(final World world, final Random random, final int i, final int j, final int k) {
		
		world.setBlock(i + 39, j + 0, k + 38, BlocksAether.caelestia_stone, 0, 2);
		world.setBlock(i + 39, j + 1, k + 37, BlocksAether.caelestia_stone, 0, 2);
		world.setBlock(i + 38, j + 1, k + 38, BlocksAether.caelestia_stone, 0, 2);
		world.setBlock(i + 39, j + 1, k + 38, BlocksAether.caelestia_stone, 0, 2);
		world.setBlock(i + 40, j + 1, k + 38, BlocksAether.caelestia_stone, 0, 2);
		world.setBlock(i + 39, j + 1, k + 39, BlocksAether.caelestia_stone, 0, 2);
		world.setBlock(i + 39, j + 2, k + 36, BlocksAether.caelestia_stone, 0, 2);
		world.setBlock(i + 38, j + 2, k + 37, BlocksAether.caelestia_stone, 0, 2);
		world.setBlock(i + 39, j + 2, k + 37, BlocksAether.caelestia_stone, 0, 2);
		world.setBlock(i + 40, j + 2, k + 37, BlocksAether.caelestia_stone, 0, 2);
		world.setBlock(i + 37, j + 2, k + 38, BlocksAether.caelestia_stone, 0, 2);
		world.setBlock(i + 38, j + 2, k + 38, BlocksAether.caelestia_stone, 0, 2);
		world.setBlock(i + 39, j + 2, k + 38, BlocksAether.caelestia_stone, 0, 2);
		world.setBlock(i + 40, j + 2, k + 38, BlocksAether.caelestia_stone, 0, 2);
		world.setBlock(i + 41, j + 2, k + 38, BlocksAether.caelestia_stone, 0, 2);
		world.setBlock(i + 38, j + 2, k + 39, BlocksAether.caelestia_stone, 0, 2);
		world.setBlock(i + 39, j + 2, k + 39, BlocksAether.caelestia_stone, 0, 2);
		world.setBlock(i + 40, j + 2, k + 39, BlocksAether.caelestia_stone, 0, 2);
		world.setBlock(i + 39, j + 2, k + 40, BlocksAether.caelestia_stone, 0, 2);
		world.setBlock(i + 39, j + 3, k + 35, BlocksAether.caelestia_stone, 0, 2);
		world.setBlock(i + 38, j + 3, k + 36, BlocksAether.caelestia_stone, 0, 2);
		world.setBlock(i + 39, j + 3, k + 36, BlocksAether.caelestia_stone, 0, 2);
		world.setBlock(i + 40, j + 3, k + 36, BlocksAether.caelestia_stone, 0, 2);
		world.setBlock(i + 37, j + 3, k + 37, BlocksAether.caelestia_stone, 0, 2);
		world.setBlock(i + 38, j + 3, k + 37, BlocksAether.caelestia_stone, 0, 2);
		world.setBlock(i + 39, j + 3, k + 37, BlocksAether.caelestia_stone, 0, 2);
		world.setBlock(i + 40, j + 3, k + 37, BlocksAether.caelestia_stone, 0, 2);
		world.setBlock(i + 41, j + 3, k + 37, BlocksAether.caelestia_stone, 0, 2);
		world.setBlock(i + 36, j + 3, k + 38, BlocksAether.caelestia_stone, 0, 2);
		world.setBlock(i + 37, j + 3, k + 38, BlocksAether.caelestia_stone, 0, 2);
		world.setBlock(i + 38, j + 3, k + 38, BlocksAether.caelestia_stone, 0, 2);
		world.setBlock(i + 39, j + 3, k + 38, BlocksAether.caelestia_stone, 0, 2);
		world.setBlock(i + 40, j + 3, k + 38, BlocksAether.caelestia_stone, 0, 2);
		world.setBlock(i + 41, j + 3, k + 38, BlocksAether.caelestia_stone, 0, 2);
		world.setBlock(i + 42, j + 3, k + 38, BlocksAether.caelestia_stone, 0, 2);
		world.setBlock(i + 37, j + 3, k + 39, BlocksAether.caelestia_stone, 0, 2);
		world.setBlock(i + 38, j + 3, k + 39, BlocksAether.caelestia_stone, 0, 2);
		world.setBlock(i + 39, j + 3, k + 39, BlocksAether.caelestia_stone, 0, 2);
		world.setBlock(i + 40, j + 3, k + 39, BlocksAether.caelestia_stone, 0, 2);
		world.setBlock(i + 41, j + 3, k + 39, BlocksAether.caelestia_stone, 0, 2);
		world.setBlock(i + 38, j + 3, k + 40, BlocksAether.caelestia_stone, 0, 2);
		world.setBlock(i + 39, j + 3, k + 40, BlocksAether.caelestia_stone, 0, 2);
		world.setBlock(i + 40, j + 3, k + 40, BlocksAether.caelestia_stone, 0, 2);
		world.setBlock(i + 39, j + 3, k + 41, BlocksAether.caelestia_stone, 0, 2);
		world.setBlock(i + 39, j + 4, k + 34, BlocksAether.caelestia_stone, 0, 2);
		world.setBlock(i + 38, j + 4, k + 35, BlocksAether.caelestia_stone, 0, 2);
		world.setBlock(i + 39, j + 4, k + 35, BlocksAether.caelestia_stone, 0, 2);
		world.setBlock(i + 40, j + 4, k + 35, BlocksAether.caelestia_stone, 0, 2);
		world.setBlock(i + 37, j + 4, k + 36, BlocksAether.caelestia_stone, 0, 2);
		world.setBlock(i + 38, j + 4, k + 36, BlocksAether.caelestia_stone, 0, 2);
		world.setBlock(i + 39, j + 4, k + 36, BlocksAether.caelestia_stone, 0, 2);
		world.setBlock(i + 40, j + 4, k + 36, BlocksAether.caelestia_stone, 0, 2);
		world.setBlock(i + 41, j + 4, k + 36, BlocksAether.caelestia_stone, 0, 2);
		world.setBlock(i + 36, j + 4, k + 37, BlocksAether.caelestia_stone, 0, 2);
		world.setBlock(i + 37, j + 4, k + 37, BlocksAether.caelestia_stone, 0, 2);
		world.setBlock(i + 38, j + 4, k + 37, BlocksAether.caelestia_stone, 0, 2);
		world.setBlock(i + 39, j + 4, k + 37, BlocksAether.caelestia_stone, 0, 2);
		world.setBlock(i + 40, j + 4, k + 37, BlocksAether.caelestia_stone, 0, 2);
		world.setBlock(i + 41, j + 4, k + 37, BlocksAether.caelestia_stone, 0, 2);
		world.setBlock(i + 42, j + 4, k + 37, BlocksAether.caelestia_stone, 0, 2);
		world.setBlock(i + 35, j + 4, k + 38, BlocksAether.caelestia_stone, 0, 2);
		world.setBlock(i + 36, j + 4, k + 38, BlocksAether.caelestia_stone, 0, 2);
		world.setBlock(i + 37, j + 4, k + 38, BlocksAether.caelestia_stone, 0, 2);
		world.setBlock(i + 38, j + 4, k + 38, BlocksAether.caelestia_stone, 0, 2);
		world.setBlock(i + 39, j + 4, k + 38, BlocksAether.caelestia_stone, 0, 2);
		world.setBlock(i + 40, j + 4, k + 38, BlocksAether.caelestia_stone, 0, 2);
		world.setBlock(i + 41, j + 4, k + 38, BlocksAether.caelestia_stone, 0, 2);
		world.setBlock(i + 42, j + 4, k + 38, BlocksAether.caelestia_stone, 0, 2);
		world.setBlock(i + 43, j + 4, k + 38, BlocksAether.caelestia_stone, 0, 2);
		world.setBlock(i + 36, j + 4, k + 39, BlocksAether.caelestia_stone, 0, 2);
		world.setBlock(i + 37, j + 4, k + 39, BlocksAether.caelestia_stone, 0, 2);
		world.setBlock(i + 38, j + 4, k + 39, BlocksAether.caelestia_stone, 0, 2);
		world.setBlock(i + 39, j + 4, k + 39, BlocksAether.caelestia_stone, 0, 2);
		world.setBlock(i + 40, j + 4, k + 39, BlocksAether.caelestia_stone, 0, 2);
		world.setBlock(i + 41, j + 4, k + 39, BlocksAether.caelestia_stone, 0, 2);
		world.setBlock(i + 42, j + 4, k + 39, BlocksAether.caelestia_stone, 0, 2);
		world.setBlock(i + 37, j + 4, k + 40, BlocksAether.caelestia_stone, 0, 2);
		world.setBlock(i + 38, j + 4, k + 40, BlocksAether.caelestia_stone, 0, 2);
		world.setBlock(i + 39, j + 4, k + 40, BlocksAether.caelestia_stone, 0, 2);
		world.setBlock(i + 40, j + 4, k + 40, BlocksAether.caelestia_stone, 0, 2);
		world.setBlock(i + 41, j + 4, k + 40, BlocksAether.caelestia_stone, 0, 2);
		world.setBlock(i + 38, j + 4, k + 41, BlocksAether.caelestia_stone, 0, 2);
		world.setBlock(i + 39, j + 4, k + 41, BlocksAether.caelestia_stone, 0, 2);
		world.setBlock(i + 40, j + 4, k + 41, BlocksAether.caelestia_stone, 0, 2);
		world.setBlock(i + 39, j + 4, k + 42, BlocksAether.caelestia_stone, 0, 2);
		world.setBlock(i + 39, j + 5, k + 33, BlocksAether.caelestia_stone, 0, 2);
		world.setBlock(i + 38, j + 5, k + 34, BlocksAether.caelestia_stone, 0, 2);
		world.setBlock(i + 39, j + 5, k + 34, BlocksAether.caelestia_stone, 0, 2);
		world.setBlock(i + 40, j + 5, k + 34, BlocksAether.caelestia_stone, 0, 2);
		world.setBlock(i + 37, j + 5, k + 35, BlocksAether.caelestia_stone, 0, 2);
		world.setBlock(i + 38, j + 5, k + 35, BlocksAether.caelestia_stone, 0, 2);
		world.setBlock(i + 39, j + 5, k + 35, BlocksAether.caelestia_stone, 0, 2);
		world.setBlock(i + 40, j + 5, k + 35, BlocksAether.caelestia_stone, 0, 2);
		world.setBlock(i + 41, j + 5, k + 35, BlocksAether.caelestia_stone, 0, 2);
		world.setBlock(i + 36, j + 5, k + 36, BlocksAether.caelestia_stone, 0, 2);
		world.setBlock(i + 37, j + 5, k + 36, BlocksAether.caelestia_stone, 0, 2);
		world.setBlock(i + 38, j + 5, k + 36, BlocksAether.caelestia_stone, 0, 2);
		world.setBlock(i + 39, j + 5, k + 36, BlocksAether.caelestia_stone, 0, 2);
		world.setBlock(i + 40, j + 5, k + 36, BlocksAether.caelestia_stone, 0, 2);
		world.setBlock(i + 41, j + 5, k + 36, BlocksAether.caelestia_stone, 0, 2);
		world.setBlock(i + 42, j + 5, k + 36, BlocksAether.caelestia_stone, 0, 2);
		world.setBlock(i + 35, j + 5, k + 37, BlocksAether.caelestia_stone, 0, 2);
		world.setBlock(i + 36, j + 5, k + 37, BlocksAether.caelestia_stone, 0, 2);
		world.setBlock(i + 37, j + 5, k + 37, BlocksAether.caelestia_stone, 0, 2);
		world.setBlock(i + 38, j + 5, k + 37, BlocksAether.caelestia_stone, 0, 2);
		world.setBlock(i + 39, j + 5, k + 37, BlocksAether.caelestia_stone, 0, 2);
		world.setBlock(i + 40, j + 5, k + 37, BlocksAether.caelestia_stone, 0, 2);
		world.setBlock(i + 41, j + 5, k + 37, BlocksAether.caelestia_stone, 0, 2);
		world.setBlock(i + 42, j + 5, k + 37, BlocksAether.caelestia_stone, 0, 2);
		world.setBlock(i + 43, j + 5, k + 37, BlocksAether.caelestia_stone, 0, 2);
		world.setBlock(i + 34, j + 5, k + 38, BlocksAether.caelestia_stone, 0, 2);
		world.setBlock(i + 35, j + 5, k + 38, BlocksAether.caelestia_stone, 0, 2);
		world.setBlock(i + 36, j + 5, k + 38, BlocksAether.caelestia_stone, 0, 2);
		world.setBlock(i + 37, j + 5, k + 38, BlocksAether.caelestia_stone, 0, 2);
		world.setBlock(i + 38, j + 5, k + 38, BlocksAether.caelestia_stone, 0, 2);
		world.setBlock(i + 39, j + 5, k + 38, BlocksAether.caelestia_stone, 0, 2);
		world.setBlock(i + 40, j + 5, k + 38, BlocksAether.caelestia_stone, 0, 2);
		world.setBlock(i + 41, j + 5, k + 38, BlocksAether.caelestia_stone, 0, 2);
		world.setBlock(i + 42, j + 5, k + 38, BlocksAether.caelestia_stone, 0, 2);
		world.setBlock(i + 43, j + 5, k + 38, BlocksAether.caelestia_stone, 0, 2);
		world.setBlock(i + 44, j + 5, k + 38, BlocksAether.caelestia_stone, 0, 2);
		world.setBlock(i + 35, j + 5, k + 39, BlocksAether.caelestia_stone, 0, 2);
		world.setBlock(i + 36, j + 5, k + 39, BlocksAether.caelestia_stone, 0, 2);
		world.setBlock(i + 37, j + 5, k + 39, BlocksAether.caelestia_stone, 0, 2);
		world.setBlock(i + 38, j + 5, k + 39, BlocksAether.caelestia_stone, 0, 2);
		world.setBlock(i + 39, j + 5, k + 39, BlocksAether.caelestia_stone, 0, 2);
		world.setBlock(i + 40, j + 5, k + 39, BlocksAether.caelestia_stone, 0, 2);
		world.setBlock(i + 41, j + 5, k + 39, BlocksAether.caelestia_stone, 0, 2);
		world.setBlock(i + 42, j + 5, k + 39, BlocksAether.caelestia_stone, 0, 2);
		world.setBlock(i + 43, j + 5, k + 39, BlocksAether.caelestia_stone, 0, 2);
		world.setBlock(i + 36, j + 5, k + 40, BlocksAether.caelestia_stone, 0, 2);
		world.setBlock(i + 37, j + 5, k + 40, BlocksAether.caelestia_stone, 0, 2);
		world.setBlock(i + 38, j + 5, k + 40, BlocksAether.caelestia_stone, 0, 2);
		world.setBlock(i + 39, j + 5, k + 40, BlocksAether.caelestia_stone, 0, 2);
		world.setBlock(i + 40, j + 5, k + 40, BlocksAether.caelestia_stone, 0, 2);
		world.setBlock(i + 41, j + 5, k + 40, BlocksAether.caelestia_stone, 0, 2);
		world.setBlock(i + 42, j + 5, k + 40, BlocksAether.caelestia_stone, 0, 2);
		world.setBlock(i + 37, j + 5, k + 41, BlocksAether.caelestia_stone, 0, 2);
		world.setBlock(i + 38, j + 5, k + 41, BlocksAether.caelestia_stone, 0, 2);
		world.setBlock(i + 39, j + 5, k + 41, BlocksAether.caelestia_stone, 0, 2);
		world.setBlock(i + 40, j + 5, k + 41, BlocksAether.caelestia_stone, 0, 2);
		world.setBlock(i + 41, j + 5, k + 41, BlocksAether.caelestia_stone, 0, 2);
		world.setBlock(i + 38, j + 5, k + 42, BlocksAether.caelestia_stone, 0, 2);
		world.setBlock(i + 39, j + 5, k + 42, BlocksAether.caelestia_stone, 0, 2);
		world.setBlock(i + 40, j + 5, k + 42, BlocksAether.caelestia_stone, 0, 2);
		world.setBlock(i + 39, j + 5, k + 43, BlocksAether.caelestia_stone, 0, 2);
		world.setBlock(i + 39, j + 6, k + 32, BlocksAether.caelestia_stone, 0, 2);
		world.setBlock(i + 38, j + 6, k + 33, BlocksAether.caelestia_stone, 0, 2);
		world.setBlock(i + 39, j + 6, k + 33, BlocksAether.caelestia_stone, 0, 2);
		world.setBlock(i + 40, j + 6, k + 33, BlocksAether.caelestia_stone, 0, 2);
		world.setBlock(i + 37, j + 6, k + 34, BlocksAether.caelestia_stone, 0, 2);
		world.setBlock(i + 38, j + 6, k + 34, BlocksAether.caelestia_stone, 0, 2);
		world.setBlock(i + 39, j + 6, k + 34, BlocksAether.caelestia_stone, 0, 2);
		world.setBlock(i + 40, j + 6, k + 34, BlocksAether.caelestia_stone, 0, 2);
		world.setBlock(i + 41, j + 6, k + 34, BlocksAether.caelestia_stone, 0, 2);
		world.setBlock(i + 36, j + 6, k + 35, BlocksAether.caelestia_stone, 0, 2);
		world.setBlock(i + 37, j + 6, k + 35, BlocksAether.caelestia_stone, 0, 2);
		world.setBlock(i + 38, j + 6, k + 35, BlocksAether.caelestia_stone, 0, 2);
		world.setBlock(i + 39, j + 6, k + 35, BlocksAether.caelestia_stone, 0, 2);
		world.setBlock(i + 40, j + 6, k + 35, BlocksAether.caelestia_stone, 0, 2);
		world.setBlock(i + 41, j + 6, k + 35, BlocksAether.caelestia_stone, 0, 2);
		world.setBlock(i + 42, j + 6, k + 35, BlocksAether.caelestia_stone, 0, 2);
		world.setBlock(i + 35, j + 6, k + 36, BlocksAether.caelestia_stone, 0, 2);
		world.setBlock(i + 36, j + 6, k + 36, BlocksAether.caelestia_stone, 0, 2);
		world.setBlock(i + 37, j + 6, k + 36, BlocksAether.caelestia_stone, 0, 2);
		world.setBlock(i + 38, j + 6, k + 36, BlocksAether.caelestia_stone, 0, 2);
		world.setBlock(i + 39, j + 6, k + 36, BlocksAether.caelestia_stone, 0, 2);
		world.setBlock(i + 40, j + 6, k + 36, BlocksAether.caelestia_stone, 0, 2);
		world.setBlock(i + 41, j + 6, k + 36, BlocksAether.caelestia_stone, 0, 2);
		world.setBlock(i + 42, j + 6, k + 36, BlocksAether.caelestia_stone, 0, 2);
		world.setBlock(i + 43, j + 6, k + 36, BlocksAether.caelestia_stone, 0, 2);
		world.setBlock(i + 34, j + 6, k + 37, BlocksAether.caelestia_stone, 0, 2);
		world.setBlock(i + 35, j + 6, k + 37, BlocksAether.caelestia_stone, 0, 2);
		world.setBlock(i + 36, j + 6, k + 37, BlocksAether.caelestia_stone, 0, 2);
		world.setBlock(i + 37, j + 6, k + 37, BlocksAether.caelestia_stone, 0, 2);
		world.setBlock(i + 38, j + 6, k + 37, BlocksAether.caelestia_stone, 0, 2);
		world.setBlock(i + 39, j + 6, k + 37, BlocksAether.caelestia_stone, 0, 2);
		world.setBlock(i + 40, j + 6, k + 37, BlocksAether.caelestia_stone, 0, 2);
		world.setBlock(i + 41, j + 6, k + 37, BlocksAether.caelestia_stone, 0, 2);
		world.setBlock(i + 42, j + 6, k + 37, BlocksAether.caelestia_stone, 0, 2);
		world.setBlock(i + 43, j + 6, k + 37, BlocksAether.caelestia_stone, 0, 2);
		world.setBlock(i + 44, j + 6, k + 37, BlocksAether.caelestia_stone, 0, 2);
		world.setBlock(i + 33, j + 6, k + 38, BlocksAether.caelestia_stone, 0, 2);
		world.setBlock(i + 34, j + 6, k + 38, BlocksAether.caelestia_stone, 0, 2);
		world.setBlock(i + 35, j + 6, k + 38, BlocksAether.caelestia_stone, 0, 2);
		world.setBlock(i + 36, j + 6, k + 38, BlocksAether.caelestia_stone, 0, 2);
		world.setBlock(i + 37, j + 6, k + 38, BlocksAether.caelestia_stone, 0, 2);
		world.setBlock(i + 38, j + 6, k + 38, BlocksAether.caelestia_stone, 0, 2);
		world.setBlock(i + 39, j + 6, k + 38, BlocksAether.caelestia_stone, 0, 2);
		world.setBlock(i + 40, j + 6, k + 38, BlocksAether.caelestia_stone, 0, 2);
		world.setBlock(i + 41, j + 6, k + 38, BlocksAether.caelestia_stone, 0, 2);
		world.setBlock(i + 42, j + 6, k + 38, BlocksAether.caelestia_stone, 0, 2);
		world.setBlock(i + 43, j + 6, k + 38, BlocksAether.caelestia_stone, 0, 2);
		world.setBlock(i + 44, j + 6, k + 38, BlocksAether.caelestia_stone, 0, 2);
		world.setBlock(i + 45, j + 6, k + 38, BlocksAether.caelestia_stone, 0, 2);
		world.setBlock(i + 34, j + 6, k + 39, BlocksAether.caelestia_stone, 0, 2);
		world.setBlock(i + 35, j + 6, k + 39, BlocksAether.caelestia_stone, 0, 2);
		world.setBlock(i + 36, j + 6, k + 39, BlocksAether.caelestia_stone, 0, 2);
		world.setBlock(i + 37, j + 6, k + 39, BlocksAether.caelestia_stone, 0, 2);
		world.setBlock(i + 38, j + 6, k + 39, BlocksAether.caelestia_stone, 0, 2);
		world.setBlock(i + 39, j + 6, k + 39, BlocksAether.caelestia_stone, 0, 2);
		world.setBlock(i + 40, j + 6, k + 39, BlocksAether.caelestia_stone, 0, 2);
		world.setBlock(i + 41, j + 6, k + 39, BlocksAether.caelestia_stone, 0, 2);
		world.setBlock(i + 42, j + 6, k + 39, BlocksAether.caelestia_stone, 0, 2);
		world.setBlock(i + 43, j + 6, k + 39, BlocksAether.caelestia_stone, 0, 2);
		world.setBlock(i + 44, j + 6, k + 39, BlocksAether.caelestia_stone, 0, 2);
		world.setBlock(i + 35, j + 6, k + 40, BlocksAether.caelestia_stone, 0, 2);
		world.setBlock(i + 36, j + 6, k + 40, BlocksAether.caelestia_stone, 0, 2);
		world.setBlock(i + 37, j + 6, k + 40, BlocksAether.caelestia_stone, 0, 2);
		world.setBlock(i + 38, j + 6, k + 40, BlocksAether.caelestia_stone, 0, 2);
		world.setBlock(i + 39, j + 6, k + 40, BlocksAether.caelestia_stone, 0, 2);
		world.setBlock(i + 40, j + 6, k + 40, BlocksAether.caelestia_stone, 0, 2);
		world.setBlock(i + 41, j + 6, k + 40, BlocksAether.caelestia_stone, 0, 2);
		world.setBlock(i + 42, j + 6, k + 40, BlocksAether.caelestia_stone, 0, 2);
		world.setBlock(i + 43, j + 6, k + 40, BlocksAether.caelestia_stone, 0, 2);
		world.setBlock(i + 36, j + 6, k + 41, BlocksAether.caelestia_stone, 0, 2);
		world.setBlock(i + 37, j + 6, k + 41, BlocksAether.caelestia_stone, 0, 2);
		world.setBlock(i + 38, j + 6, k + 41, BlocksAether.caelestia_stone, 0, 2);
		world.setBlock(i + 39, j + 6, k + 41, BlocksAether.caelestia_stone, 0, 2);
		world.setBlock(i + 40, j + 6, k + 41, BlocksAether.caelestia_stone, 0, 2);
		world.setBlock(i + 41, j + 6, k + 41, BlocksAether.caelestia_stone, 0, 2);
		world.setBlock(i + 42, j + 6, k + 41, BlocksAether.caelestia_stone, 0, 2);
		world.setBlock(i + 37, j + 6, k + 42, BlocksAether.caelestia_stone, 0, 2);
		world.setBlock(i + 38, j + 6, k + 42, BlocksAether.caelestia_stone, 0, 2);
		world.setBlock(i + 39, j + 6, k + 42, BlocksAether.caelestia_stone, 0, 2);
		world.setBlock(i + 40, j + 6, k + 42, BlocksAether.caelestia_stone, 0, 2);
		world.setBlock(i + 41, j + 6, k + 42, BlocksAether.caelestia_stone, 0, 2);
		world.setBlock(i + 38, j + 6, k + 43, BlocksAether.caelestia_stone, 0, 2);
		world.setBlock(i + 39, j + 6, k + 43, BlocksAether.caelestia_stone, 0, 2);
		world.setBlock(i + 40, j + 6, k + 43, BlocksAether.caelestia_stone, 0, 2);
		world.setBlock(i + 39, j + 6, k + 44, BlocksAether.caelestia_stone, 0, 2);
		world.setBlock(i + 39, j + 7, k + 31, BlocksAether.caelestia_stone, 0, 2);
		world.setBlock(i + 38, j + 7, k + 32, BlocksAether.caelestia_stone, 0, 2);
		world.setBlock(i + 39, j + 7, k + 32, BlocksAether.caelestia_stone, 0, 2);
		world.setBlock(i + 40, j + 7, k + 32, BlocksAether.caelestia_stone, 0, 2);
		world.setBlock(i + 37, j + 7, k + 33, BlocksAether.caelestia_stone, 0, 2);
		world.setBlock(i + 38, j + 7, k + 33, BlocksAether.caelestia_stone, 0, 2);
		world.setBlock(i + 39, j + 7, k + 33, BlocksAether.caelestia_stone, 0, 2);
		world.setBlock(i + 40, j + 7, k + 33, BlocksAether.caelestia_stone, 0, 2);
		world.setBlock(i + 41, j + 7, k + 33, BlocksAether.caelestia_stone, 0, 2);
		world.setBlock(i + 36, j + 7, k + 34, BlocksAether.caelestia_stone, 0, 2);
		world.setBlock(i + 37, j + 7, k + 34, BlocksAether.caelestia_stone, 0, 2);
		world.setBlock(i + 38, j + 7, k + 34, BlocksAether.caelestia_stone, 0, 2);
		world.setBlock(i + 39, j + 7, k + 34, BlocksAether.caelestia_stone, 0, 2);
		world.setBlock(i + 40, j + 7, k + 34, BlocksAether.caelestia_stone, 0, 2);
		world.setBlock(i + 41, j + 7, k + 34, BlocksAether.caelestia_stone, 0, 2);
		world.setBlock(i + 42, j + 7, k + 34, BlocksAether.caelestia_stone, 0, 2);
		world.setBlock(i + 35, j + 7, k + 35, BlocksAether.caelestia_stone, 0, 2);
		world.setBlock(i + 36, j + 7, k + 35, BlocksAether.caelestia_stone, 0, 2);
		world.setBlock(i + 37, j + 7, k + 35, BlocksAether.caelestia_stone, 0, 2);
		world.setBlock(i + 38, j + 7, k + 35, BlocksAether.caelestia_stone, 0, 2);
		world.setBlock(i + 39, j + 7, k + 35, BlocksAether.caelestia_stone, 0, 2);
		world.setBlock(i + 40, j + 7, k + 35, BlocksAether.caelestia_stone, 0, 2);
		world.setBlock(i + 41, j + 7, k + 35, BlocksAether.caelestia_stone, 0, 2);
		world.setBlock(i + 42, j + 7, k + 35, BlocksAether.caelestia_stone, 0, 2);
		world.setBlock(i + 43, j + 7, k + 35, BlocksAether.caelestia_stone, 0, 2);
		world.setBlock(i + 34, j + 7, k + 36, BlocksAether.caelestia_stone, 0, 2);
		world.setBlock(i + 35, j + 7, k + 36, BlocksAether.caelestia_stone, 0, 2);
		world.setBlock(i + 36, j + 7, k + 36, BlocksAether.caelestia_stone, 0, 2);
		world.setBlock(i + 37, j + 7, k + 36, BlocksAether.caelestia_stone, 0, 2);
		world.setBlock(i + 38, j + 7, k + 36, BlocksAether.caelestia_stone, 0, 2);
		world.setBlock(i + 39, j + 7, k + 36, BlocksAether.caelestia_stone, 0, 2);
		world.setBlock(i + 40, j + 7, k + 36, BlocksAether.caelestia_stone, 0, 2);
		world.setBlock(i + 41, j + 7, k + 36, BlocksAether.caelestia_stone, 0, 2);
		world.setBlock(i + 42, j + 7, k + 36, BlocksAether.caelestia_stone, 0, 2);
		world.setBlock(i + 43, j + 7, k + 36, BlocksAether.caelestia_stone, 0, 2);
		world.setBlock(i + 44, j + 7, k + 36, BlocksAether.caelestia_stone, 0, 2);
		world.setBlock(i + 33, j + 7, k + 37, BlocksAether.caelestia_stone, 0, 2);
		world.setBlock(i + 34, j + 7, k + 37, BlocksAether.caelestia_stone, 0, 2);
		world.setBlock(i + 35, j + 7, k + 37, BlocksAether.caelestia_stone, 0, 2);
		world.setBlock(i + 36, j + 7, k + 37, BlocksAether.caelestia_stone, 0, 2);
		world.setBlock(i + 37, j + 7, k + 37, BlocksAether.caelestia_stone, 0, 2);
		world.setBlock(i + 38, j + 7, k + 37, BlocksAether.caelestia_stone, 0, 2);
		world.setBlock(i + 39, j + 7, k + 37, BlocksAether.caelestia_stone, 0, 2);
		world.setBlock(i + 40, j + 7, k + 37, BlocksAether.caelestia_stone, 0, 2);
		world.setBlock(i + 41, j + 7, k + 37, BlocksAether.caelestia_stone, 0, 2);
		world.setBlock(i + 42, j + 7, k + 37, BlocksAether.caelestia_stone, 0, 2);
		world.setBlock(i + 43, j + 7, k + 37, BlocksAether.caelestia_stone, 0, 2);
		world.setBlock(i + 44, j + 7, k + 37, BlocksAether.caelestia_stone, 0, 2);
		world.setBlock(i + 45, j + 7, k + 37, BlocksAether.caelestia_stone, 0, 2);
		world.setBlock(i + 32, j + 7, k + 38, BlocksAether.caelestia_stone, 0, 2);
		world.setBlock(i + 33, j + 7, k + 38, BlocksAether.caelestia_stone, 0, 2);
		world.setBlock(i + 34, j + 7, k + 38, BlocksAether.caelestia_stone, 0, 2);
		world.setBlock(i + 35, j + 7, k + 38, BlocksAether.caelestia_stone, 0, 2);
		world.setBlock(i + 36, j + 7, k + 38, BlocksAether.caelestia_stone, 0, 2);
		world.setBlock(i + 37, j + 7, k + 38, BlocksAether.caelestia_stone, 0, 2);
		world.setBlock(i + 38, j + 7, k + 38, BlocksAether.caelestia_stone, 0, 2);
		world.setBlock(i + 39, j + 7, k + 38, BlocksAether.caelestia_stone, 0, 2);
		world.setBlock(i + 40, j + 7, k + 38, BlocksAether.caelestia_stone, 0, 2);
		world.setBlock(i + 41, j + 7, k + 38, BlocksAether.caelestia_stone, 0, 2);
		world.setBlock(i + 42, j + 7, k + 38, BlocksAether.caelestia_stone, 0, 2);
		world.setBlock(i + 43, j + 7, k + 38, BlocksAether.caelestia_stone, 0, 2);
		world.setBlock(i + 44, j + 7, k + 38, BlocksAether.caelestia_stone, 0, 2);
		world.setBlock(i + 45, j + 7, k + 38, BlocksAether.caelestia_stone, 0, 2);
		world.setBlock(i + 46, j + 7, k + 38, BlocksAether.caelestia_stone, 0, 2);
		world.setBlock(i + 33, j + 7, k + 39, BlocksAether.caelestia_stone, 0, 2);
		world.setBlock(i + 34, j + 7, k + 39, BlocksAether.caelestia_stone, 0, 2);
		world.setBlock(i + 35, j + 7, k + 39, BlocksAether.caelestia_stone, 0, 2);
		world.setBlock(i + 36, j + 7, k + 39, BlocksAether.caelestia_stone, 0, 2);
		world.setBlock(i + 37, j + 7, k + 39, BlocksAether.caelestia_stone, 0, 2);
		world.setBlock(i + 38, j + 7, k + 39, BlocksAether.caelestia_stone, 0, 2);
		world.setBlock(i + 39, j + 7, k + 39, BlocksAether.caelestia_stone, 0, 2);
		world.setBlock(i + 40, j + 7, k + 39, BlocksAether.caelestia_stone, 0, 2);
		world.setBlock(i + 41, j + 7, k + 39, BlocksAether.caelestia_stone, 0, 2);
		world.setBlock(i + 42, j + 7, k + 39, BlocksAether.caelestia_stone, 0, 2);
		world.setBlock(i + 43, j + 7, k + 39, BlocksAether.caelestia_stone, 0, 2);
		world.setBlock(i + 44, j + 7, k + 39, BlocksAether.caelestia_stone, 0, 2);
		world.setBlock(i + 45, j + 7, k + 39, BlocksAether.caelestia_stone, 0, 2);
		world.setBlock(i + 34, j + 7, k + 40, BlocksAether.caelestia_stone, 0, 2);
		world.setBlock(i + 35, j + 7, k + 40, BlocksAether.caelestia_stone, 0, 2);
		world.setBlock(i + 36, j + 7, k + 40, BlocksAether.caelestia_stone, 0, 2);
		world.setBlock(i + 37, j + 7, k + 40, BlocksAether.caelestia_stone, 0, 2);
		world.setBlock(i + 38, j + 7, k + 40, BlocksAether.caelestia_stone, 0, 2);
		world.setBlock(i + 39, j + 7, k + 40, BlocksAether.caelestia_stone, 0, 2);
		world.setBlock(i + 40, j + 7, k + 40, BlocksAether.caelestia_stone, 0, 2);
		world.setBlock(i + 41, j + 7, k + 40, BlocksAether.caelestia_stone, 0, 2);
		world.setBlock(i + 42, j + 7, k + 40, BlocksAether.caelestia_stone, 0, 2);
		world.setBlock(i + 43, j + 7, k + 40, BlocksAether.caelestia_stone, 0, 2);
		world.setBlock(i + 44, j + 7, k + 40, BlocksAether.caelestia_stone, 0, 2);
		world.setBlock(i + 35, j + 7, k + 41, BlocksAether.caelestia_stone, 0, 2);
		world.setBlock(i + 36, j + 7, k + 41, BlocksAether.caelestia_stone, 0, 2);
		world.setBlock(i + 37, j + 7, k + 41, BlocksAether.caelestia_stone, 0, 2);
		world.setBlock(i + 38, j + 7, k + 41, BlocksAether.caelestia_stone, 0, 2);
		world.setBlock(i + 39, j + 7, k + 41, BlocksAether.caelestia_stone, 0, 2);
		world.setBlock(i + 40, j + 7, k + 41, BlocksAether.caelestia_stone, 0, 2);
		world.setBlock(i + 41, j + 7, k + 41, BlocksAether.caelestia_stone, 0, 2);
		world.setBlock(i + 42, j + 7, k + 41, BlocksAether.caelestia_stone, 0, 2);
		world.setBlock(i + 43, j + 7, k + 41, BlocksAether.caelestia_stone, 0, 2);
		world.setBlock(i + 36, j + 7, k + 42, BlocksAether.caelestia_stone, 0, 2);
		world.setBlock(i + 37, j + 7, k + 42, BlocksAether.caelestia_stone, 0, 2);
		world.setBlock(i + 38, j + 7, k + 42, BlocksAether.caelestia_stone, 0, 2);
		world.setBlock(i + 39, j + 7, k + 42, BlocksAether.caelestia_stone, 0, 2);
		world.setBlock(i + 40, j + 7, k + 42, BlocksAether.caelestia_stone, 0, 2);
		world.setBlock(i + 41, j + 7, k + 42, BlocksAether.caelestia_stone, 0, 2);
		world.setBlock(i + 42, j + 7, k + 42, BlocksAether.caelestia_stone, 0, 2);
		world.setBlock(i + 37, j + 7, k + 43, BlocksAether.caelestia_stone, 0, 2);
		world.setBlock(i + 38, j + 7, k + 43, BlocksAether.caelestia_stone, 0, 2);
		world.setBlock(i + 39, j + 7, k + 43, BlocksAether.caelestia_stone, 0, 2);
		world.setBlock(i + 40, j + 7, k + 43, BlocksAether.caelestia_stone, 0, 2);
		world.setBlock(i + 41, j + 7, k + 43, BlocksAether.caelestia_stone, 0, 2);
		world.setBlock(i + 38, j + 7, k + 44, BlocksAether.caelestia_stone, 0, 2);
		world.setBlock(i + 39, j + 7, k + 44, BlocksAether.caelestia_stone, 0, 2);
		world.setBlock(i + 40, j + 7, k + 44, BlocksAether.caelestia_stone, 0, 2);
		world.setBlock(i + 39, j + 7, k + 45, BlocksAether.caelestia_stone, 0, 2);
		world.setBlock(i + 39, j + 8, k + 30, BlocksAether.caelestia_stone, 0, 2);
		world.setBlock(i + 38, j + 8, k + 31, BlocksAether.caelestia_stone, 0, 2);
		world.setBlock(i + 39, j + 8, k + 31, BlocksAether.caelestia_stone, 0, 2);
		world.setBlock(i + 40, j + 8, k + 31, BlocksAether.caelestia_stone, 0, 2);
		world.setBlock(i + 37, j + 8, k + 32, BlocksAether.caelestia_stone, 0, 2);
		world.setBlock(i + 38, j + 8, k + 32, BlocksAether.caelestia_stone, 0, 2);
		world.setBlock(i + 39, j + 8, k + 32, BlocksAether.caelestia_stone, 0, 2);
		world.setBlock(i + 40, j + 8, k + 32, BlocksAether.caelestia_stone, 0, 2);
		world.setBlock(i + 41, j + 8, k + 32, BlocksAether.caelestia_stone, 0, 2);
		world.setBlock(i + 36, j + 8, k + 33, BlocksAether.caelestia_stone, 0, 2);
		world.setBlock(i + 37, j + 8, k + 33, BlocksAether.caelestia_stone, 0, 2);
		world.setBlock(i + 38, j + 8, k + 33, BlocksAether.caelestia_stone, 0, 2);
		world.setBlock(i + 39, j + 8, k + 33, BlocksAether.caelestia_stone, 0, 2);
		world.setBlock(i + 40, j + 8, k + 33, BlocksAether.caelestia_stone, 0, 2);
		world.setBlock(i + 41, j + 8, k + 33, BlocksAether.caelestia_stone, 0, 2);
		world.setBlock(i + 42, j + 8, k + 33, BlocksAether.caelestia_stone, 0, 2);
		world.setBlock(i + 35, j + 8, k + 34, BlocksAether.caelestia_stone, 0, 2);
		world.setBlock(i + 36, j + 8, k + 34, BlocksAether.caelestia_stone, 0, 2);
		world.setBlock(i + 37, j + 8, k + 34, BlocksAether.caelestia_stone, 0, 2);
		world.setBlock(i + 38, j + 8, k + 34, BlocksAether.caelestia_stone, 0, 2);
		world.setBlock(i + 39, j + 8, k + 34, BlocksAether.caelestia_stone, 0, 2);
		world.setBlock(i + 40, j + 8, k + 34, BlocksAether.caelestia_stone, 0, 2);
		world.setBlock(i + 41, j + 8, k + 34, BlocksAether.caelestia_stone, 0, 2);
		world.setBlock(i + 42, j + 8, k + 34, BlocksAether.caelestia_stone, 0, 2);
		world.setBlock(i + 43, j + 8, k + 34, BlocksAether.caelestia_stone, 0, 2);
		world.setBlock(i + 34, j + 8, k + 35, BlocksAether.caelestia_stone, 0, 2);
		world.setBlock(i + 35, j + 8, k + 35, BlocksAether.caelestia_stone, 0, 2);
		world.setBlock(i + 36, j + 8, k + 35, BlocksAether.caelestia_stone, 0, 2);
		world.setBlock(i + 37, j + 8, k + 35, BlocksAether.caelestia_stone, 0, 2);
		world.setBlock(i + 38, j + 8, k + 35, BlocksAether.caelestia_stone, 0, 2);
		world.setBlock(i + 39, j + 8, k + 35, BlocksAether.caelestia_stone, 0, 2);
		world.setBlock(i + 40, j + 8, k + 35, BlocksAether.caelestia_stone, 0, 2);
		world.setBlock(i + 41, j + 8, k + 35, BlocksAether.caelestia_stone, 0, 2);
		world.setBlock(i + 42, j + 8, k + 35, BlocksAether.caelestia_stone, 0, 2);
		world.setBlock(i + 43, j + 8, k + 35, BlocksAether.caelestia_stone, 0, 2);
		world.setBlock(i + 44, j + 8, k + 35, BlocksAether.caelestia_stone, 0, 2);
		world.setBlock(i + 33, j + 8, k + 36, BlocksAether.caelestia_stone, 0, 2);
		world.setBlock(i + 34, j + 8, k + 36, BlocksAether.caelestia_stone, 0, 2);
		world.setBlock(i + 35, j + 8, k + 36, BlocksAether.caelestia_stone, 0, 2);
		world.setBlock(i + 36, j + 8, k + 36, BlocksAether.caelestia_stone, 0, 2);
		world.setBlock(i + 37, j + 8, k + 36, BlocksAether.caelestia_stone, 0, 2);
		world.setBlock(i + 38, j + 8, k + 36, BlocksAether.caelestia_stone, 0, 2);
		world.setBlock(i + 39, j + 8, k + 36, BlocksAether.caelestia_stone, 0, 2);
		world.setBlock(i + 40, j + 8, k + 36, BlocksAether.caelestia_stone, 0, 2);
		world.setBlock(i + 41, j + 8, k + 36, BlocksAether.caelestia_stone, 0, 2);
		world.setBlock(i + 42, j + 8, k + 36, BlocksAether.caelestia_stone, 0, 2);
		world.setBlock(i + 43, j + 8, k + 36, BlocksAether.caelestia_stone, 0, 2);
		world.setBlock(i + 44, j + 8, k + 36, BlocksAether.caelestia_stone, 0, 2);
		world.setBlock(i + 45, j + 8, k + 36, BlocksAether.caelestia_stone, 0, 2);
		world.setBlock(i + 32, j + 8, k + 37, BlocksAether.caelestia_stone, 0, 2);
		world.setBlock(i + 33, j + 8, k + 37, BlocksAether.caelestia_stone, 0, 2);
		world.setBlock(i + 34, j + 8, k + 37, BlocksAether.caelestia_stone, 0, 2);
		world.setBlock(i + 35, j + 8, k + 37, BlocksAether.caelestia_stone, 0, 2);
		world.setBlock(i + 36, j + 8, k + 37, BlocksAether.caelestia_stone, 0, 2);
		world.setBlock(i + 37, j + 8, k + 37, BlocksAether.caelestia_stone, 0, 2);
		world.setBlock(i + 38, j + 8, k + 37, BlocksAether.caelestia_stone, 0, 2);
		world.setBlock(i + 39, j + 8, k + 37, BlocksAether.caelestia_stone, 0, 2);
		world.setBlock(i + 40, j + 8, k + 37, BlocksAether.caelestia_stone, 0, 2);
		world.setBlock(i + 41, j + 8, k + 37, BlocksAether.caelestia_stone, 0, 2);
		world.setBlock(i + 42, j + 8, k + 37, BlocksAether.caelestia_stone, 0, 2);
		world.setBlock(i + 43, j + 8, k + 37, BlocksAether.caelestia_stone, 0, 2);
		world.setBlock(i + 44, j + 8, k + 37, BlocksAether.caelestia_stone, 0, 2);
		world.setBlock(i + 45, j + 8, k + 37, BlocksAether.caelestia_stone, 0, 2);
		world.setBlock(i + 46, j + 8, k + 37, BlocksAether.caelestia_stone, 0, 2);
		world.setBlock(i + 31, j + 8, k + 38, BlocksAether.caelestia_stone, 0, 2);
		world.setBlock(i + 32, j + 8, k + 38, BlocksAether.caelestia_stone, 0, 2);
		world.setBlock(i + 33, j + 8, k + 38, BlocksAether.caelestia_stone, 0, 2);
		world.setBlock(i + 34, j + 8, k + 38, BlocksAether.caelestia_stone, 0, 2);
		world.setBlock(i + 35, j + 8, k + 38, BlocksAether.caelestia_stone, 0, 2);
		world.setBlock(i + 36, j + 8, k + 38, BlocksAether.caelestia_stone, 0, 2);
		world.setBlock(i + 37, j + 8, k + 38, BlocksAether.caelestia_stone, 0, 2);
		world.setBlock(i + 38, j + 8, k + 38, BlocksAether.caelestia_stone, 0, 2);
		world.setBlock(i + 39, j + 8, k + 38, BlocksAether.caelestia_stone, 0, 2);
		world.setBlock(i + 40, j + 8, k + 38, BlocksAether.caelestia_stone, 0, 2);
		world.setBlock(i + 41, j + 8, k + 38, BlocksAether.caelestia_stone, 0, 2);
		world.setBlock(i + 42, j + 8, k + 38, BlocksAether.caelestia_stone, 0, 2);
		world.setBlock(i + 43, j + 8, k + 38, BlocksAether.caelestia_stone, 0, 2);
		world.setBlock(i + 44, j + 8, k + 38, BlocksAether.caelestia_stone, 0, 2);
		world.setBlock(i + 45, j + 8, k + 38, BlocksAether.caelestia_stone, 0, 2);
		world.setBlock(i + 46, j + 8, k + 38, BlocksAether.caelestia_stone, 0, 2);
		world.setBlock(i + 47, j + 8, k + 38, BlocksAether.caelestia_stone, 0, 2);
		world.setBlock(i + 32, j + 8, k + 39, BlocksAether.caelestia_stone, 0, 2);
		world.setBlock(i + 33, j + 8, k + 39, BlocksAether.caelestia_stone, 0, 2);
		world.setBlock(i + 34, j + 8, k + 39, BlocksAether.caelestia_stone, 0, 2);
		world.setBlock(i + 35, j + 8, k + 39, BlocksAether.caelestia_stone, 0, 2);
		world.setBlock(i + 36, j + 8, k + 39, BlocksAether.caelestia_stone, 0, 2);
		world.setBlock(i + 37, j + 8, k + 39, BlocksAether.caelestia_stone, 0, 2);
		world.setBlock(i + 38, j + 8, k + 39, BlocksAether.caelestia_stone, 0, 2);
		world.setBlock(i + 39, j + 8, k + 39, BlocksAether.caelestia_stone, 0, 2);
		world.setBlock(i + 40, j + 8, k + 39, BlocksAether.caelestia_stone, 0, 2);
		world.setBlock(i + 41, j + 8, k + 39, BlocksAether.caelestia_stone, 0, 2);
		world.setBlock(i + 42, j + 8, k + 39, BlocksAether.caelestia_stone, 0, 2);
		world.setBlock(i + 43, j + 8, k + 39, BlocksAether.caelestia_stone, 0, 2);
		world.setBlock(i + 44, j + 8, k + 39, BlocksAether.caelestia_stone, 0, 2);
		world.setBlock(i + 45, j + 8, k + 39, BlocksAether.caelestia_stone, 0, 2);
		world.setBlock(i + 46, j + 8, k + 39, BlocksAether.caelestia_stone, 0, 2);
		world.setBlock(i + 33, j + 8, k + 40, BlocksAether.caelestia_stone, 0, 2);
		world.setBlock(i + 34, j + 8, k + 40, BlocksAether.caelestia_stone, 0, 2);
		world.setBlock(i + 35, j + 8, k + 40, BlocksAether.caelestia_stone, 0, 2);
		world.setBlock(i + 36, j + 8, k + 40, BlocksAether.caelestia_stone, 0, 2);
		world.setBlock(i + 37, j + 8, k + 40, BlocksAether.caelestia_stone, 0, 2);
		world.setBlock(i + 38, j + 8, k + 40, BlocksAether.caelestia_stone, 0, 2);
		world.setBlock(i + 39, j + 8, k + 40, BlocksAether.caelestia_stone, 0, 2);
		world.setBlock(i + 40, j + 8, k + 40, BlocksAether.caelestia_stone, 0, 2);
		world.setBlock(i + 41, j + 8, k + 40, BlocksAether.caelestia_stone, 0, 2);
		world.setBlock(i + 42, j + 8, k + 40, BlocksAether.caelestia_stone, 0, 2);
		world.setBlock(i + 43, j + 8, k + 40, BlocksAether.caelestia_stone, 0, 2);
		world.setBlock(i + 44, j + 8, k + 40, BlocksAether.caelestia_stone, 0, 2);
		world.setBlock(i + 45, j + 8, k + 40, BlocksAether.caelestia_stone, 0, 2);
		world.setBlock(i + 34, j + 8, k + 41, BlocksAether.caelestia_stone, 0, 2);
		world.setBlock(i + 35, j + 8, k + 41, BlocksAether.caelestia_stone, 0, 2);
		world.setBlock(i + 36, j + 8, k + 41, BlocksAether.caelestia_stone, 0, 2);
		world.setBlock(i + 37, j + 8, k + 41, BlocksAether.caelestia_stone, 0, 2);
		world.setBlock(i + 38, j + 8, k + 41, BlocksAether.caelestia_stone, 0, 2);
		world.setBlock(i + 39, j + 8, k + 41, BlocksAether.caelestia_stone, 0, 2);
		world.setBlock(i + 40, j + 8, k + 41, BlocksAether.caelestia_stone, 0, 2);
		world.setBlock(i + 41, j + 8, k + 41, BlocksAether.caelestia_stone, 0, 2);
		world.setBlock(i + 42, j + 8, k + 41, BlocksAether.caelestia_stone, 0, 2);
		world.setBlock(i + 43, j + 8, k + 41, BlocksAether.caelestia_stone, 0, 2);
		world.setBlock(i + 44, j + 8, k + 41, BlocksAether.caelestia_stone, 0, 2);
		world.setBlock(i + 35, j + 8, k + 42, BlocksAether.caelestia_stone, 0, 2);
		world.setBlock(i + 36, j + 8, k + 42, BlocksAether.caelestia_stone, 0, 2);
		world.setBlock(i + 37, j + 8, k + 42, BlocksAether.caelestia_stone, 0, 2);
		world.setBlock(i + 38, j + 8, k + 42, BlocksAether.caelestia_stone, 0, 2);
		world.setBlock(i + 39, j + 8, k + 42, BlocksAether.caelestia_stone, 0, 2);
		world.setBlock(i + 40, j + 8, k + 42, BlocksAether.caelestia_stone, 0, 2);
		world.setBlock(i + 41, j + 8, k + 42, BlocksAether.caelestia_stone, 0, 2);
		world.setBlock(i + 42, j + 8, k + 42, BlocksAether.caelestia_stone, 0, 2);
		world.setBlock(i + 43, j + 8, k + 42, BlocksAether.caelestia_stone, 0, 2);
		world.setBlock(i + 36, j + 8, k + 43, BlocksAether.caelestia_stone, 0, 2);
		world.setBlock(i + 37, j + 8, k + 43, BlocksAether.caelestia_stone, 0, 2);
		world.setBlock(i + 38, j + 8, k + 43, BlocksAether.caelestia_stone, 0, 2);
		world.setBlock(i + 39, j + 8, k + 43, BlocksAether.caelestia_stone, 0, 2);
		world.setBlock(i + 40, j + 8, k + 43, BlocksAether.caelestia_stone, 0, 2);
		world.setBlock(i + 41, j + 8, k + 43, BlocksAether.caelestia_stone, 0, 2);
		world.setBlock(i + 42, j + 8, k + 43, BlocksAether.caelestia_stone, 0, 2);
		world.setBlock(i + 37, j + 8, k + 44, BlocksAether.caelestia_stone, 0, 2);
		world.setBlock(i + 38, j + 8, k + 44, BlocksAether.caelestia_stone, 0, 2);
		world.setBlock(i + 39, j + 8, k + 44, BlocksAether.caelestia_stone, 0, 2);
		world.setBlock(i + 40, j + 8, k + 44, BlocksAether.caelestia_stone, 0, 2);
		world.setBlock(i + 41, j + 8, k + 44, BlocksAether.caelestia_stone, 0, 2);
		world.setBlock(i + 38, j + 8, k + 45, BlocksAether.caelestia_stone, 0, 2);
		world.setBlock(i + 39, j + 8, k + 45, BlocksAether.caelestia_stone, 0, 2);
		world.setBlock(i + 40, j + 8, k + 45, BlocksAether.caelestia_stone, 0, 2);
		world.setBlock(i + 39, j + 8, k + 46, BlocksAether.caelestia_stone, 0, 2);
		world.setBlock(i + 39, j + 9, k + 29, BlocksAether.caelestia_stone, 0, 2);
		world.setBlock(i + 38, j + 9, k + 30, BlocksAether.caelestia_stone, 0, 2);
		world.setBlock(i + 39, j + 9, k + 30, BlocksAether.caelestia_stone, 0, 2);
		world.setBlock(i + 40, j + 9, k + 30, BlocksAether.caelestia_stone, 0, 2);
		world.setBlock(i + 37, j + 9, k + 31, BlocksAether.caelestia_stone, 0, 2);
		world.setBlock(i + 38, j + 9, k + 31, BlocksAether.caelestia_stone, 0, 2);
		world.setBlock(i + 39, j + 9, k + 31, BlocksAether.caelestia_stone, 0, 2);
		world.setBlock(i + 40, j + 9, k + 31, BlocksAether.caelestia_stone, 0, 2);
		world.setBlock(i + 41, j + 9, k + 31, BlocksAether.caelestia_stone, 0, 2);
		world.setBlock(i + 36, j + 9, k + 32, BlocksAether.caelestia_stone, 0, 2);
		world.setBlock(i + 37, j + 9, k + 32, BlocksAether.caelestia_stone, 0, 2);
		world.setBlock(i + 38, j + 9, k + 32, BlocksAether.caelestia_stone, 0, 2);
		world.setBlock(i + 39, j + 9, k + 32, BlocksAether.caelestia_stone, 0, 2);
		world.setBlock(i + 40, j + 9, k + 32, BlocksAether.caelestia_stone, 0, 2);
		world.setBlock(i + 41, j + 9, k + 32, BlocksAether.caelestia_stone, 0, 2);
		world.setBlock(i + 42, j + 9, k + 32, BlocksAether.caelestia_stone, 0, 2);
		world.setBlock(i + 35, j + 9, k + 33, BlocksAether.caelestia_stone, 0, 2);
		world.setBlock(i + 36, j + 9, k + 33, BlocksAether.caelestia_stone, 0, 2);
		world.setBlock(i + 37, j + 9, k + 33, BlocksAether.caelestia_stone, 0, 2);
		world.setBlock(i + 38, j + 9, k + 33, BlocksAether.caelestia_stone, 0, 2);
		world.setBlock(i + 39, j + 9, k + 33, BlocksAether.caelestia_stone, 0, 2);
		world.setBlock(i + 40, j + 9, k + 33, BlocksAether.caelestia_stone, 0, 2);
		world.setBlock(i + 41, j + 9, k + 33, BlocksAether.caelestia_stone, 0, 2);
		world.setBlock(i + 42, j + 9, k + 33, BlocksAether.caelestia_stone, 0, 2);
		world.setBlock(i + 43, j + 9, k + 33, BlocksAether.caelestia_stone, 0, 2);
		world.setBlock(i + 34, j + 9, k + 34, BlocksAether.caelestia_stone, 0, 2);
		world.setBlock(i + 35, j + 9, k + 34, BlocksAether.caelestia_stone, 0, 2);
		world.setBlock(i + 36, j + 9, k + 34, BlocksAether.caelestia_stone, 0, 2);
		world.setBlock(i + 37, j + 9, k + 34, BlocksAether.caelestia_stone, 0, 2);
		world.setBlock(i + 38, j + 9, k + 34, BlocksAether.caelestia_stone, 0, 2);
		world.setBlock(i + 39, j + 9, k + 34, BlocksAether.caelestia_stone, 0, 2);
		world.setBlock(i + 40, j + 9, k + 34, BlocksAether.caelestia_stone, 0, 2);
		world.setBlock(i + 41, j + 9, k + 34, BlocksAether.caelestia_stone, 0, 2);
		world.setBlock(i + 42, j + 9, k + 34, BlocksAether.caelestia_stone, 0, 2);
		world.setBlock(i + 43, j + 9, k + 34, BlocksAether.caelestia_stone, 0, 2);
		world.setBlock(i + 44, j + 9, k + 34, BlocksAether.caelestia_stone, 0, 2);
		world.setBlock(i + 33, j + 9, k + 35, BlocksAether.caelestia_stone, 0, 2);
		world.setBlock(i + 34, j + 9, k + 35, BlocksAether.caelestia_stone, 0, 2);
		world.setBlock(i + 35, j + 9, k + 35, BlocksAether.caelestia_stone, 0, 2);
		world.setBlock(i + 36, j + 9, k + 35, BlocksAether.caelestia_stone, 0, 2);
		world.setBlock(i + 37, j + 9, k + 35, BlocksAether.caelestia_stone, 0, 2);
		world.setBlock(i + 38, j + 9, k + 35, BlocksAether.caelestia_stone, 0, 2);
		world.setBlock(i + 39, j + 9, k + 35, BlocksAether.caelestia_stone, 0, 2);
		world.setBlock(i + 40, j + 9, k + 35, BlocksAether.caelestia_stone, 0, 2);
		world.setBlock(i + 41, j + 9, k + 35, BlocksAether.caelestia_stone, 0, 2);
		world.setBlock(i + 42, j + 9, k + 35, BlocksAether.caelestia_stone, 0, 2);
		world.setBlock(i + 43, j + 9, k + 35, BlocksAether.caelestia_stone, 0, 2);
		world.setBlock(i + 44, j + 9, k + 35, BlocksAether.caelestia_stone, 0, 2);
		world.setBlock(i + 45, j + 9, k + 35, BlocksAether.caelestia_stone, 0, 2);
		world.setBlock(i + 32, j + 9, k + 36, BlocksAether.caelestia_stone, 0, 2);
		world.setBlock(i + 33, j + 9, k + 36, BlocksAether.caelestia_stone, 0, 2);
		world.setBlock(i + 34, j + 9, k + 36, BlocksAether.caelestia_stone, 0, 2);
		world.setBlock(i + 35, j + 9, k + 36, BlocksAether.caelestia_stone, 0, 2);
		world.setBlock(i + 36, j + 9, k + 36, BlocksAether.caelestia_stone, 0, 2);
		world.setBlock(i + 37, j + 9, k + 36, BlocksAether.caelestia_stone, 0, 2);
		world.setBlock(i + 38, j + 9, k + 36, BlocksAether.caelestia_stone, 0, 2);
		world.setBlock(i + 39, j + 9, k + 36, BlocksAether.caelestia_stone, 0, 2);
		world.setBlock(i + 40, j + 9, k + 36, BlocksAether.caelestia_stone, 0, 2);
		world.setBlock(i + 41, j + 9, k + 36, BlocksAether.caelestia_stone, 0, 2);
		world.setBlock(i + 42, j + 9, k + 36, BlocksAether.caelestia_stone, 0, 2);
		world.setBlock(i + 43, j + 9, k + 36, BlocksAether.caelestia_stone, 0, 2);
		world.setBlock(i + 44, j + 9, k + 36, BlocksAether.caelestia_stone, 0, 2);
		world.setBlock(i + 45, j + 9, k + 36, BlocksAether.caelestia_stone, 0, 2);
		world.setBlock(i + 46, j + 9, k + 36, BlocksAether.caelestia_stone, 0, 2);
		world.setBlock(i + 31, j + 9, k + 37, BlocksAether.caelestia_stone, 0, 2);
		world.setBlock(i + 32, j + 9, k + 37, BlocksAether.caelestia_stone, 0, 2);
		world.setBlock(i + 33, j + 9, k + 37, BlocksAether.caelestia_stone, 0, 2);
		world.setBlock(i + 34, j + 9, k + 37, BlocksAether.caelestia_stone, 0, 2);
		world.setBlock(i + 35, j + 9, k + 37, BlocksAether.caelestia_stone, 0, 2);
		world.setBlock(i + 36, j + 9, k + 37, BlocksAether.caelestia_stone, 0, 2);
		world.setBlock(i + 37, j + 9, k + 37, BlocksAether.caelestia_stone, 0, 2);
		world.setBlock(i + 38, j + 9, k + 37, BlocksAether.caelestia_stone, 0, 2);
		world.setBlock(i + 39, j + 9, k + 37, BlocksAether.caelestia_stone, 0, 2);
		world.setBlock(i + 40, j + 9, k + 37, BlocksAether.caelestia_stone, 0, 2);
		world.setBlock(i + 41, j + 9, k + 37, BlocksAether.caelestia_stone, 0, 2);
		world.setBlock(i + 42, j + 9, k + 37, BlocksAether.caelestia_stone, 0, 2);
		world.setBlock(i + 43, j + 9, k + 37, BlocksAether.caelestia_stone, 0, 2);
		world.setBlock(i + 44, j + 9, k + 37, BlocksAether.caelestia_stone, 0, 2);
		world.setBlock(i + 45, j + 9, k + 37, BlocksAether.caelestia_stone, 0, 2);
		world.setBlock(i + 46, j + 9, k + 37, BlocksAether.caelestia_stone, 0, 2);
		world.setBlock(i + 47, j + 9, k + 37, BlocksAether.caelestia_stone, 0, 2);
		world.setBlock(i + 30, j + 9, k + 38, BlocksAether.caelestia_stone, 0, 2);
		world.setBlock(i + 31, j + 9, k + 38, BlocksAether.caelestia_stone, 0, 2);
		world.setBlock(i + 32, j + 9, k + 38, BlocksAether.caelestia_stone, 0, 2);
		world.setBlock(i + 33, j + 9, k + 38, BlocksAether.caelestia_stone, 0, 2);
		world.setBlock(i + 34, j + 9, k + 38, BlocksAether.caelestia_stone, 0, 2);
		world.setBlock(i + 35, j + 9, k + 38, BlocksAether.caelestia_stone, 0, 2);
		world.setBlock(i + 36, j + 9, k + 38, BlocksAether.caelestia_stone, 0, 2);
		world.setBlock(i + 37, j + 9, k + 38, BlocksAether.caelestia_stone, 0, 2);
		world.setBlock(i + 38, j + 9, k + 38, BlocksAether.caelestia_stone, 0, 2);
		world.setBlock(i + 39, j + 9, k + 38, BlocksAether.caelestia_stone, 0, 2);
		world.setBlock(i + 40, j + 9, k + 38, BlocksAether.caelestia_stone, 0, 2);
		world.setBlock(i + 41, j + 9, k + 38, BlocksAether.caelestia_stone, 0, 2);
		world.setBlock(i + 42, j + 9, k + 38, BlocksAether.caelestia_stone, 0, 2);
		world.setBlock(i + 43, j + 9, k + 38, BlocksAether.caelestia_stone, 0, 2);
		world.setBlock(i + 44, j + 9, k + 38, BlocksAether.caelestia_stone, 0, 2);
		world.setBlock(i + 45, j + 9, k + 38, BlocksAether.caelestia_stone, 0, 2);
		world.setBlock(i + 46, j + 9, k + 38, BlocksAether.caelestia_stone, 0, 2);
		world.setBlock(i + 47, j + 9, k + 38, BlocksAether.caelestia_stone, 0, 2);
		world.setBlock(i + 48, j + 9, k + 38, BlocksAether.caelestia_stone, 0, 2);
		world.setBlock(i + 31, j + 9, k + 39, BlocksAether.caelestia_stone, 0, 2);
		world.setBlock(i + 32, j + 9, k + 39, BlocksAether.caelestia_stone, 0, 2);
		world.setBlock(i + 33, j + 9, k + 39, BlocksAether.caelestia_stone, 0, 2);
		world.setBlock(i + 34, j + 9, k + 39, BlocksAether.caelestia_stone, 0, 2);
		world.setBlock(i + 35, j + 9, k + 39, BlocksAether.caelestia_stone, 0, 2);
		world.setBlock(i + 36, j + 9, k + 39, BlocksAether.caelestia_stone, 0, 2);
		world.setBlock(i + 37, j + 9, k + 39, BlocksAether.caelestia_stone, 0, 2);
		world.setBlock(i + 38, j + 9, k + 39, BlocksAether.caelestia_stone, 0, 2);
		world.setBlock(i + 39, j + 9, k + 39, BlocksAether.caelestia_stone, 0, 2);
		world.setBlock(i + 40, j + 9, k + 39, BlocksAether.caelestia_stone, 0, 2);
		world.setBlock(i + 41, j + 9, k + 39, BlocksAether.caelestia_stone, 0, 2);
		world.setBlock(i + 42, j + 9, k + 39, BlocksAether.caelestia_stone, 0, 2);
		world.setBlock(i + 43, j + 9, k + 39, BlocksAether.caelestia_stone, 0, 2);
		world.setBlock(i + 44, j + 9, k + 39, BlocksAether.caelestia_stone, 0, 2);
		world.setBlock(i + 45, j + 9, k + 39, BlocksAether.caelestia_stone, 0, 2);
		world.setBlock(i + 46, j + 9, k + 39, BlocksAether.caelestia_stone, 0, 2);
		world.setBlock(i + 47, j + 9, k + 39, BlocksAether.caelestia_stone, 0, 2);
		world.setBlock(i + 32, j + 9, k + 40, BlocksAether.caelestia_stone, 0, 2);
		world.setBlock(i + 33, j + 9, k + 40, BlocksAether.caelestia_stone, 0, 2);
		world.setBlock(i + 34, j + 9, k + 40, BlocksAether.caelestia_stone, 0, 2);
		world.setBlock(i + 35, j + 9, k + 40, BlocksAether.caelestia_stone, 0, 2);
		world.setBlock(i + 36, j + 9, k + 40, BlocksAether.caelestia_stone, 0, 2);
		world.setBlock(i + 37, j + 9, k + 40, BlocksAether.caelestia_stone, 0, 2);
		world.setBlock(i + 38, j + 9, k + 40, BlocksAether.caelestia_stone, 0, 2);
		world.setBlock(i + 39, j + 9, k + 40, BlocksAether.caelestia_stone, 0, 2);
		world.setBlock(i + 40, j + 9, k + 40, BlocksAether.caelestia_stone, 0, 2);
		world.setBlock(i + 41, j + 9, k + 40, BlocksAether.caelestia_stone, 0, 2);
		world.setBlock(i + 42, j + 9, k + 40, BlocksAether.caelestia_stone, 0, 2);
		world.setBlock(i + 43, j + 9, k + 40, BlocksAether.caelestia_stone, 0, 2);
		world.setBlock(i + 44, j + 9, k + 40, BlocksAether.caelestia_stone, 0, 2);
		world.setBlock(i + 45, j + 9, k + 40, BlocksAether.caelestia_stone, 0, 2);
		world.setBlock(i + 46, j + 9, k + 40, BlocksAether.caelestia_stone, 0, 2);
		world.setBlock(i + 33, j + 9, k + 41, BlocksAether.caelestia_stone, 0, 2);
		world.setBlock(i + 34, j + 9, k + 41, BlocksAether.caelestia_stone, 0, 2);
		world.setBlock(i + 35, j + 9, k + 41, BlocksAether.caelestia_stone, 0, 2);
		world.setBlock(i + 36, j + 9, k + 41, BlocksAether.caelestia_stone, 0, 2);
		world.setBlock(i + 37, j + 9, k + 41, BlocksAether.caelestia_stone, 0, 2);
		world.setBlock(i + 38, j + 9, k + 41, BlocksAether.caelestia_stone, 0, 2);
		world.setBlock(i + 39, j + 9, k + 41, BlocksAether.caelestia_stone, 0, 2);
		world.setBlock(i + 40, j + 9, k + 41, BlocksAether.caelestia_stone, 0, 2);
		world.setBlock(i + 41, j + 9, k + 41, BlocksAether.caelestia_stone, 0, 2);
		world.setBlock(i + 42, j + 9, k + 41, BlocksAether.caelestia_stone, 0, 2);
		world.setBlock(i + 43, j + 9, k + 41, BlocksAether.caelestia_stone, 0, 2);
		world.setBlock(i + 44, j + 9, k + 41, BlocksAether.caelestia_stone, 0, 2);
		world.setBlock(i + 45, j + 9, k + 41, BlocksAether.caelestia_stone, 0, 2);
		world.setBlock(i + 34, j + 9, k + 42, BlocksAether.caelestia_stone, 0, 2);
		world.setBlock(i + 35, j + 9, k + 42, BlocksAether.caelestia_stone, 0, 2);
		world.setBlock(i + 36, j + 9, k + 42, BlocksAether.caelestia_stone, 0, 2);
		world.setBlock(i + 37, j + 9, k + 42, BlocksAether.caelestia_stone, 0, 2);
		world.setBlock(i + 38, j + 9, k + 42, BlocksAether.caelestia_stone, 0, 2);
		world.setBlock(i + 39, j + 9, k + 42, BlocksAether.caelestia_stone, 0, 2);
		world.setBlock(i + 40, j + 9, k + 42, BlocksAether.caelestia_stone, 0, 2);
		world.setBlock(i + 41, j + 9, k + 42, BlocksAether.caelestia_stone, 0, 2);
		world.setBlock(i + 42, j + 9, k + 42, BlocksAether.caelestia_stone, 0, 2);
		world.setBlock(i + 43, j + 9, k + 42, BlocksAether.caelestia_stone, 0, 2);
		world.setBlock(i + 44, j + 9, k + 42, BlocksAether.caelestia_stone, 0, 2);
		world.setBlock(i + 35, j + 9, k + 43, BlocksAether.caelestia_stone, 0, 2);
		world.setBlock(i + 36, j + 9, k + 43, BlocksAether.caelestia_stone, 0, 2);
		world.setBlock(i + 37, j + 9, k + 43, BlocksAether.caelestia_stone, 0, 2);
		world.setBlock(i + 38, j + 9, k + 43, BlocksAether.caelestia_stone, 0, 2);
		world.setBlock(i + 39, j + 9, k + 43, BlocksAether.caelestia_stone, 0, 2);
		world.setBlock(i + 40, j + 9, k + 43, BlocksAether.caelestia_stone, 0, 2);
		world.setBlock(i + 41, j + 9, k + 43, BlocksAether.caelestia_stone, 0, 2);
		world.setBlock(i + 42, j + 9, k + 43, BlocksAether.caelestia_stone, 0, 2);
		world.setBlock(i + 43, j + 9, k + 43, BlocksAether.caelestia_stone, 0, 2);
		world.setBlock(i + 36, j + 9, k + 44, BlocksAether.caelestia_stone, 0, 2);
		world.setBlock(i + 37, j + 9, k + 44, BlocksAether.caelestia_stone, 0, 2);
		world.setBlock(i + 38, j + 9, k + 44, BlocksAether.caelestia_stone, 0, 2);
		world.setBlock(i + 39, j + 9, k + 44, BlocksAether.caelestia_stone, 0, 2);
		world.setBlock(i + 40, j + 9, k + 44, BlocksAether.caelestia_stone, 0, 2);
		world.setBlock(i + 41, j + 9, k + 44, BlocksAether.caelestia_stone, 0, 2);
		world.setBlock(i + 42, j + 9, k + 44, BlocksAether.caelestia_stone, 0, 2);
		world.setBlock(i + 37, j + 9, k + 45, BlocksAether.caelestia_stone, 0, 2);
		world.setBlock(i + 38, j + 9, k + 45, BlocksAether.caelestia_stone, 0, 2);
		world.setBlock(i + 39, j + 9, k + 45, BlocksAether.caelestia_stone, 0, 2);
		world.setBlock(i + 40, j + 9, k + 45, BlocksAether.caelestia_stone, 0, 2);
		world.setBlock(i + 41, j + 9, k + 45, BlocksAether.caelestia_stone, 0, 2);
		world.setBlock(i + 38, j + 9, k + 46, BlocksAether.caelestia_stone, 0, 2);
		world.setBlock(i + 39, j + 9, k + 46, BlocksAether.caelestia_stone, 0, 2);
		world.setBlock(i + 40, j + 9, k + 46, BlocksAether.caelestia_stone, 0, 2);
		world.setBlock(i + 39, j + 9, k + 47, BlocksAether.caelestia_stone, 0, 2);
		world.setBlock(i + 39, j + 10, k + 28, BlocksAether.caelestia_stone, 0, 2);
		world.setBlock(i + 38, j + 10, k + 29, BlocksAether.caelestia_stone, 0, 2);
		world.setBlock(i + 39, j + 10, k + 29, BlocksAether.caelestia_stone, 0, 2);
		world.setBlock(i + 40, j + 10, k + 29, BlocksAether.caelestia_stone, 0, 2);
		world.setBlock(i + 37, j + 10, k + 30, BlocksAether.caelestia_stone, 0, 2);
		world.setBlock(i + 38, j + 10, k + 30, BlocksAether.caelestia_stone, 0, 2);
		world.setBlock(i + 39, j + 10, k + 30, BlocksAether.caelestia_stone, 0, 2);
		world.setBlock(i + 40, j + 10, k + 30, BlocksAether.caelestia_stone, 0, 2);
		world.setBlock(i + 41, j + 10, k + 30, BlocksAether.caelestia_stone, 0, 2);
		world.setBlock(i + 36, j + 10, k + 31, BlocksAether.caelestia_stone, 0, 2);
		world.setBlock(i + 37, j + 10, k + 31, BlocksAether.caelestia_stone, 0, 2);
		world.setBlock(i + 38, j + 10, k + 31, BlocksAether.caelestia_stone, 0, 2);
		world.setBlock(i + 39, j + 10, k + 31, BlocksAether.caelestia_stone, 0, 2);
		world.setBlock(i + 40, j + 10, k + 31, BlocksAether.caelestia_stone, 0, 2);
		world.setBlock(i + 41, j + 10, k + 31, BlocksAether.caelestia_stone, 0, 2);
		world.setBlock(i + 42, j + 10, k + 31, BlocksAether.caelestia_stone, 0, 2);
		world.setBlock(i + 35, j + 10, k + 32, BlocksAether.caelestia_stone, 0, 2);
		world.setBlock(i + 36, j + 10, k + 32, BlocksAether.caelestia_stone, 0, 2);
		world.setBlock(i + 37, j + 10, k + 32, BlocksAether.caelestia_stone, 0, 2);
		world.setBlock(i + 38, j + 10, k + 32, BlocksAether.caelestia_stone, 0, 2);
		world.setBlock(i + 39, j + 10, k + 32, BlocksAether.caelestia_stone, 0, 2);
		world.setBlock(i + 40, j + 10, k + 32, BlocksAether.caelestia_stone, 0, 2);
		world.setBlock(i + 41, j + 10, k + 32, BlocksAether.caelestia_stone, 0, 2);
		world.setBlock(i + 42, j + 10, k + 32, BlocksAether.caelestia_stone, 0, 2);
		world.setBlock(i + 43, j + 10, k + 32, BlocksAether.caelestia_stone, 0, 2);
		world.setBlock(i + 34, j + 10, k + 33, BlocksAether.caelestia_stone, 0, 2);
		world.setBlock(i + 35, j + 10, k + 33, BlocksAether.caelestia_stone, 0, 2);
		world.setBlock(i + 36, j + 10, k + 33, BlocksAether.caelestia_stone, 0, 2);
		world.setBlock(i + 37, j + 10, k + 33, BlocksAether.caelestia_stone, 0, 2);
		world.setBlock(i + 38, j + 10, k + 33, BlocksAether.caelestia_stone, 0, 2);
		world.setBlock(i + 39, j + 10, k + 33, BlocksAether.caelestia_stone, 0, 2);
		world.setBlock(i + 40, j + 10, k + 33, BlocksAether.caelestia_stone, 0, 2);
		world.setBlock(i + 41, j + 10, k + 33, BlocksAether.caelestia_stone, 0, 2);
		world.setBlock(i + 42, j + 10, k + 33, BlocksAether.caelestia_stone, 0, 2);
		world.setBlock(i + 43, j + 10, k + 33, BlocksAether.caelestia_stone, 0, 2);
		world.setBlock(i + 44, j + 10, k + 33, BlocksAether.caelestia_stone, 0, 2);
		world.setBlock(i + 33, j + 10, k + 34, BlocksAether.caelestia_stone, 0, 2);
		world.setBlock(i + 34, j + 10, k + 34, BlocksAether.caelestia_stone, 0, 2);
		world.setBlock(i + 35, j + 10, k + 34, BlocksAether.caelestia_stone, 0, 2);
		world.setBlock(i + 36, j + 10, k + 34, BlocksAether.caelestia_stone, 0, 2);
		world.setBlock(i + 37, j + 10, k + 34, BlocksAether.caelestia_stone, 0, 2);
		world.setBlock(i + 38, j + 10, k + 34, BlocksAether.caelestia_stone, 0, 2);
		world.setBlock(i + 39, j + 10, k + 34, BlocksAether.caelestia_stone, 0, 2);
		world.setBlock(i + 40, j + 10, k + 34, BlocksAether.caelestia_stone, 0, 2);
		world.setBlock(i + 41, j + 10, k + 34, BlocksAether.caelestia_stone, 0, 2);
		world.setBlock(i + 42, j + 10, k + 34, BlocksAether.caelestia_stone, 0, 2);
		world.setBlock(i + 43, j + 10, k + 34, BlocksAether.caelestia_stone, 0, 2);
		world.setBlock(i + 44, j + 10, k + 34, BlocksAether.caelestia_stone, 0, 2);
		world.setBlock(i + 45, j + 10, k + 34, BlocksAether.caelestia_stone, 0, 2);
		world.setBlock(i + 32, j + 10, k + 35, BlocksAether.caelestia_stone, 0, 2);
		world.setBlock(i + 33, j + 10, k + 35, BlocksAether.caelestia_stone, 0, 2);
		world.setBlock(i + 34, j + 10, k + 35, BlocksAether.caelestia_stone, 0, 2);
		world.setBlock(i + 35, j + 10, k + 35, BlocksAether.caelestia_stone, 0, 2);
		world.setBlock(i + 36, j + 10, k + 35, BlocksAether.caelestia_stone, 0, 2);
		world.setBlock(i + 37, j + 10, k + 35, BlocksAether.caelestia_stone, 0, 2);
		world.setBlock(i + 38, j + 10, k + 35, BlocksAether.caelestia_stone, 0, 2);
		world.setBlock(i + 39, j + 10, k + 35, BlocksAether.caelestia_stone, 0, 2);
		world.setBlock(i + 40, j + 10, k + 35, BlocksAether.caelestia_stone, 0, 2);
		world.setBlock(i + 41, j + 10, k + 35, BlocksAether.caelestia_stone, 0, 2);
		world.setBlock(i + 42, j + 10, k + 35, BlocksAether.caelestia_stone, 0, 2);
		world.setBlock(i + 43, j + 10, k + 35, BlocksAether.caelestia_stone, 0, 2);
		world.setBlock(i + 44, j + 10, k + 35, BlocksAether.caelestia_stone, 0, 2);
		world.setBlock(i + 45, j + 10, k + 35, BlocksAether.caelestia_stone, 0, 2);
		world.setBlock(i + 46, j + 10, k + 35, BlocksAether.caelestia_stone, 0, 2);
		world.setBlock(i + 31, j + 10, k + 36, BlocksAether.caelestia_stone, 0, 2);
		world.setBlock(i + 32, j + 10, k + 36, BlocksAether.caelestia_stone, 0, 2);
		world.setBlock(i + 33, j + 10, k + 36, BlocksAether.caelestia_stone, 0, 2);
		world.setBlock(i + 34, j + 10, k + 36, BlocksAether.caelestia_stone, 0, 2);
		world.setBlock(i + 35, j + 10, k + 36, BlocksAether.caelestia_stone, 0, 2);
		world.setBlock(i + 36, j + 10, k + 36, BlocksAether.caelestia_stone, 0, 2);
		world.setBlock(i + 37, j + 10, k + 36, BlocksAether.caelestia_stone, 0, 2);
		world.setBlock(i + 38, j + 10, k + 36, BlocksAether.caelestia_stone, 0, 2);
		world.setBlock(i + 39, j + 10, k + 36, BlocksAether.caelestia_stone, 0, 2);
		world.setBlock(i + 40, j + 10, k + 36, BlocksAether.caelestia_stone, 0, 2);
		world.setBlock(i + 41, j + 10, k + 36, BlocksAether.caelestia_stone, 0, 2);
		world.setBlock(i + 42, j + 10, k + 36, BlocksAether.caelestia_stone, 0, 2);
		world.setBlock(i + 43, j + 10, k + 36, BlocksAether.caelestia_stone, 0, 2);
		world.setBlock(i + 44, j + 10, k + 36, BlocksAether.caelestia_stone, 0, 2);
		world.setBlock(i + 45, j + 10, k + 36, BlocksAether.caelestia_stone, 0, 2);
		world.setBlock(i + 46, j + 10, k + 36, BlocksAether.caelestia_stone, 0, 2);
		world.setBlock(i + 47, j + 10, k + 36, BlocksAether.caelestia_stone, 0, 2);
		world.setBlock(i + 30, j + 10, k + 37, BlocksAether.caelestia_stone, 0, 2);
		world.setBlock(i + 31, j + 10, k + 37, BlocksAether.caelestia_stone, 0, 2);
		world.setBlock(i + 32, j + 10, k + 37, BlocksAether.caelestia_stone, 0, 2);
		world.setBlock(i + 33, j + 10, k + 37, BlocksAether.caelestia_stone, 0, 2);
		world.setBlock(i + 34, j + 10, k + 37, BlocksAether.caelestia_stone, 0, 2);
		world.setBlock(i + 35, j + 10, k + 37, BlocksAether.caelestia_stone, 0, 2);
		world.setBlock(i + 36, j + 10, k + 37, BlocksAether.caelestia_stone, 0, 2);
		world.setBlock(i + 37, j + 10, k + 37, BlocksAether.caelestia_stone, 0, 2);
		world.setBlock(i + 38, j + 10, k + 37, BlocksAether.caelestia_stone, 0, 2);
		world.setBlock(i + 39, j + 10, k + 37, BlocksAether.caelestia_stone, 0, 2);
		world.setBlock(i + 40, j + 10, k + 37, BlocksAether.caelestia_stone, 0, 2);
		world.setBlock(i + 41, j + 10, k + 37, BlocksAether.caelestia_stone, 0, 2);
		world.setBlock(i + 42, j + 10, k + 37, BlocksAether.caelestia_stone, 0, 2);
		world.setBlock(i + 43, j + 10, k + 37, BlocksAether.caelestia_stone, 0, 2);
		world.setBlock(i + 44, j + 10, k + 37, BlocksAether.caelestia_stone, 0, 2);
		world.setBlock(i + 45, j + 10, k + 37, BlocksAether.caelestia_stone, 0, 2);
		world.setBlock(i + 46, j + 10, k + 37, BlocksAether.caelestia_stone, 0, 2);
		world.setBlock(i + 47, j + 10, k + 37, BlocksAether.caelestia_stone, 0, 2);
		world.setBlock(i + 48, j + 10, k + 37, BlocksAether.caelestia_stone, 0, 2);
		world.setBlock(i + 29, j + 10, k + 38, BlocksAether.caelestia_stone, 0, 2);
		world.setBlock(i + 30, j + 10, k + 38, BlocksAether.caelestia_stone, 0, 2);
		world.setBlock(i + 31, j + 10, k + 38, BlocksAether.caelestia_stone, 0, 2);
		world.setBlock(i + 32, j + 10, k + 38, BlocksAether.caelestia_stone, 0, 2);
		world.setBlock(i + 33, j + 10, k + 38, BlocksAether.caelestia_stone, 0, 2);
		world.setBlock(i + 34, j + 10, k + 38, BlocksAether.caelestia_stone, 0, 2);
		world.setBlock(i + 35, j + 10, k + 38, BlocksAether.caelestia_stone, 0, 2);
		world.setBlock(i + 36, j + 10, k + 38, BlocksAether.caelestia_stone, 0, 2);
		world.setBlock(i + 37, j + 10, k + 38, BlocksAether.caelestia_stone, 0, 2);
		world.setBlock(i + 38, j + 10, k + 38, BlocksAether.caelestia_stone, 0, 2);
		world.setBlock(i + 39, j + 10, k + 38, BlocksAether.caelestia_stone, 0, 2);
		world.setBlock(i + 40, j + 10, k + 38, BlocksAether.caelestia_stone, 0, 2);
		world.setBlock(i + 41, j + 10, k + 38, BlocksAether.caelestia_stone, 0, 2);
		world.setBlock(i + 42, j + 10, k + 38, BlocksAether.caelestia_stone, 0, 2);
		world.setBlock(i + 43, j + 10, k + 38, BlocksAether.caelestia_stone, 0, 2);
		world.setBlock(i + 44, j + 10, k + 38, BlocksAether.caelestia_stone, 0, 2);
		world.setBlock(i + 45, j + 10, k + 38, BlocksAether.caelestia_stone, 0, 2);
		world.setBlock(i + 46, j + 10, k + 38, BlocksAether.caelestia_stone, 0, 2);
		world.setBlock(i + 47, j + 10, k + 38, BlocksAether.caelestia_stone, 0, 2);
		world.setBlock(i + 48, j + 10, k + 38, BlocksAether.caelestia_stone, 0, 2);
		world.setBlock(i + 49, j + 10, k + 38, BlocksAether.caelestia_stone, 0, 2);
		world.setBlock(i + 30, j + 10, k + 39, BlocksAether.caelestia_stone, 0, 2);
		world.setBlock(i + 31, j + 10, k + 39, BlocksAether.caelestia_stone, 0, 2);
		world.setBlock(i + 32, j + 10, k + 39, BlocksAether.caelestia_stone, 0, 2);
		world.setBlock(i + 33, j + 10, k + 39, BlocksAether.caelestia_stone, 0, 2);
		world.setBlock(i + 34, j + 10, k + 39, BlocksAether.caelestia_stone, 0, 2);
		world.setBlock(i + 35, j + 10, k + 39, BlocksAether.caelestia_stone, 0, 2);
		world.setBlock(i + 36, j + 10, k + 39, BlocksAether.caelestia_stone, 0, 2);
		world.setBlock(i + 37, j + 10, k + 39, BlocksAether.caelestia_stone, 0, 2);
		world.setBlock(i + 38, j + 10, k + 39, BlocksAether.caelestia_stone, 0, 2);
		world.setBlock(i + 39, j + 10, k + 39, BlocksAether.caelestia_stone, 0, 2);
		world.setBlock(i + 40, j + 10, k + 39, BlocksAether.caelestia_stone, 0, 2);
		world.setBlock(i + 41, j + 10, k + 39, BlocksAether.caelestia_stone, 0, 2);
		world.setBlock(i + 42, j + 10, k + 39, BlocksAether.caelestia_stone, 0, 2);
		world.setBlock(i + 43, j + 10, k + 39, BlocksAether.caelestia_stone, 0, 2);
		world.setBlock(i + 44, j + 10, k + 39, BlocksAether.caelestia_stone, 0, 2);
		world.setBlock(i + 45, j + 10, k + 39, BlocksAether.caelestia_stone, 0, 2);
		world.setBlock(i + 46, j + 10, k + 39, BlocksAether.caelestia_stone, 0, 2);
		world.setBlock(i + 47, j + 10, k + 39, BlocksAether.caelestia_stone, 0, 2);
		world.setBlock(i + 48, j + 10, k + 39, BlocksAether.caelestia_stone, 0, 2);
		world.setBlock(i + 31, j + 10, k + 40, BlocksAether.caelestia_stone, 0, 2);
		world.setBlock(i + 32, j + 10, k + 40, BlocksAether.caelestia_stone, 0, 2);
		world.setBlock(i + 33, j + 10, k + 40, BlocksAether.caelestia_stone, 0, 2);
		world.setBlock(i + 34, j + 10, k + 40, BlocksAether.caelestia_stone, 0, 2);
		world.setBlock(i + 35, j + 10, k + 40, BlocksAether.caelestia_stone, 0, 2);
		world.setBlock(i + 36, j + 10, k + 40, BlocksAether.caelestia_stone, 0, 2);
		world.setBlock(i + 37, j + 10, k + 40, BlocksAether.caelestia_stone, 0, 2);
		world.setBlock(i + 38, j + 10, k + 40, BlocksAether.caelestia_stone, 0, 2);
		world.setBlock(i + 39, j + 10, k + 40, BlocksAether.caelestia_stone, 0, 2);
		world.setBlock(i + 40, j + 10, k + 40, BlocksAether.caelestia_stone, 0, 2);
		world.setBlock(i + 41, j + 10, k + 40, BlocksAether.caelestia_stone, 0, 2);
		world.setBlock(i + 42, j + 10, k + 40, BlocksAether.caelestia_stone, 0, 2);
		world.setBlock(i + 43, j + 10, k + 40, BlocksAether.caelestia_stone, 0, 2);
		world.setBlock(i + 44, j + 10, k + 40, BlocksAether.caelestia_stone, 0, 2);
		world.setBlock(i + 45, j + 10, k + 40, BlocksAether.caelestia_stone, 0, 2);
		world.setBlock(i + 46, j + 10, k + 40, BlocksAether.caelestia_stone, 0, 2);
		world.setBlock(i + 47, j + 10, k + 40, BlocksAether.caelestia_stone, 0, 2);
		world.setBlock(i + 32, j + 10, k + 41, BlocksAether.caelestia_stone, 0, 2);
		world.setBlock(i + 33, j + 10, k + 41, BlocksAether.caelestia_stone, 0, 2);
		world.setBlock(i + 34, j + 10, k + 41, BlocksAether.caelestia_stone, 0, 2);
		world.setBlock(i + 35, j + 10, k + 41, BlocksAether.caelestia_stone, 0, 2);
		world.setBlock(i + 36, j + 10, k + 41, BlocksAether.caelestia_stone, 0, 2);
		world.setBlock(i + 37, j + 10, k + 41, BlocksAether.caelestia_stone, 0, 2);
		world.setBlock(i + 38, j + 10, k + 41, BlocksAether.caelestia_stone, 0, 2);
		world.setBlock(i + 39, j + 10, k + 41, BlocksAether.caelestia_stone, 0, 2);
		world.setBlock(i + 40, j + 10, k + 41, BlocksAether.caelestia_stone, 0, 2);
		world.setBlock(i + 41, j + 10, k + 41, BlocksAether.caelestia_stone, 0, 2);
		world.setBlock(i + 42, j + 10, k + 41, BlocksAether.caelestia_stone, 0, 2);
		world.setBlock(i + 43, j + 10, k + 41, BlocksAether.caelestia_stone, 0, 2);
		world.setBlock(i + 44, j + 10, k + 41, BlocksAether.caelestia_stone, 0, 2);
		world.setBlock(i + 45, j + 10, k + 41, BlocksAether.caelestia_stone, 0, 2);
		world.setBlock(i + 46, j + 10, k + 41, BlocksAether.caelestia_stone, 0, 2);
		world.setBlock(i + 33, j + 10, k + 42, BlocksAether.caelestia_stone, 0, 2);
		world.setBlock(i + 34, j + 10, k + 42, BlocksAether.caelestia_stone, 0, 2);
		world.setBlock(i + 35, j + 10, k + 42, BlocksAether.caelestia_stone, 0, 2);
		world.setBlock(i + 36, j + 10, k + 42, BlocksAether.caelestia_stone, 0, 2);
		world.setBlock(i + 37, j + 10, k + 42, BlocksAether.caelestia_stone, 0, 2);
		world.setBlock(i + 38, j + 10, k + 42, BlocksAether.caelestia_stone, 0, 2);
		world.setBlock(i + 39, j + 10, k + 42, BlocksAether.caelestia_stone, 0, 2);
		world.setBlock(i + 40, j + 10, k + 42, BlocksAether.caelestia_stone, 0, 2);
		world.setBlock(i + 41, j + 10, k + 42, BlocksAether.caelestia_stone, 0, 2);
		world.setBlock(i + 42, j + 10, k + 42, BlocksAether.caelestia_stone, 0, 2);
		world.setBlock(i + 43, j + 10, k + 42, BlocksAether.caelestia_stone, 0, 2);
		world.setBlock(i + 44, j + 10, k + 42, BlocksAether.caelestia_stone, 0, 2);
		world.setBlock(i + 45, j + 10, k + 42, BlocksAether.caelestia_stone, 0, 2);
		world.setBlock(i + 34, j + 10, k + 43, BlocksAether.caelestia_stone, 0, 2);
		world.setBlock(i + 35, j + 10, k + 43, BlocksAether.caelestia_stone, 0, 2);
		world.setBlock(i + 36, j + 10, k + 43, BlocksAether.caelestia_stone, 0, 2);
		world.setBlock(i + 37, j + 10, k + 43, BlocksAether.caelestia_stone, 0, 2);
		world.setBlock(i + 38, j + 10, k + 43, BlocksAether.caelestia_stone, 0, 2);
		world.setBlock(i + 39, j + 10, k + 43, BlocksAether.caelestia_stone, 0, 2);
		world.setBlock(i + 40, j + 10, k + 43, BlocksAether.caelestia_stone, 0, 2);
		world.setBlock(i + 41, j + 10, k + 43, BlocksAether.caelestia_stone, 0, 2);
		world.setBlock(i + 42, j + 10, k + 43, BlocksAether.caelestia_stone, 0, 2);
		world.setBlock(i + 43, j + 10, k + 43, BlocksAether.caelestia_stone, 0, 2);
		world.setBlock(i + 44, j + 10, k + 43, BlocksAether.caelestia_stone, 0, 2);
		world.setBlock(i + 35, j + 10, k + 44, BlocksAether.caelestia_stone, 0, 2);
		world.setBlock(i + 36, j + 10, k + 44, BlocksAether.caelestia_stone, 0, 2);
		world.setBlock(i + 37, j + 10, k + 44, BlocksAether.caelestia_stone, 0, 2);
		world.setBlock(i + 38, j + 10, k + 44, BlocksAether.caelestia_stone, 0, 2);
		world.setBlock(i + 39, j + 10, k + 44, BlocksAether.caelestia_stone, 0, 2);
		world.setBlock(i + 40, j + 10, k + 44, BlocksAether.caelestia_stone, 0, 2);
		world.setBlock(i + 41, j + 10, k + 44, BlocksAether.caelestia_stone, 0, 2);
		world.setBlock(i + 42, j + 10, k + 44, BlocksAether.caelestia_stone, 0, 2);
		world.setBlock(i + 43, j + 10, k + 44, BlocksAether.caelestia_stone, 0, 2);
		world.setBlock(i + 36, j + 10, k + 45, BlocksAether.caelestia_stone, 0, 2);
		world.setBlock(i + 37, j + 10, k + 45, BlocksAether.caelestia_stone, 0, 2);
		world.setBlock(i + 38, j + 10, k + 45, BlocksAether.caelestia_stone, 0, 2);
		world.setBlock(i + 39, j + 10, k + 45, BlocksAether.caelestia_stone, 0, 2);
		world.setBlock(i + 40, j + 10, k + 45, BlocksAether.caelestia_stone, 0, 2);
		world.setBlock(i + 41, j + 10, k + 45, BlocksAether.caelestia_stone, 0, 2);
		world.setBlock(i + 42, j + 10, k + 45, BlocksAether.caelestia_stone, 0, 2);
		world.setBlock(i + 37, j + 10, k + 46, BlocksAether.caelestia_stone, 0, 2);
		world.setBlock(i + 38, j + 10, k + 46, BlocksAether.caelestia_stone, 0, 2);
		world.setBlock(i + 39, j + 10, k + 46, BlocksAether.caelestia_stone, 0, 2);
		world.setBlock(i + 40, j + 10, k + 46, BlocksAether.caelestia_stone, 0, 2);
		world.setBlock(i + 41, j + 10, k + 46, BlocksAether.caelestia_stone, 0, 2);
		world.setBlock(i + 38, j + 10, k + 47, BlocksAether.caelestia_stone, 0, 2);
		world.setBlock(i + 39, j + 10, k + 47, BlocksAether.caelestia_stone, 0, 2);
		world.setBlock(i + 40, j + 10, k + 47, BlocksAether.caelestia_stone, 0, 2);
		world.setBlock(i + 39, j + 10, k + 48, BlocksAether.caelestia_stone, 0, 2);
		world.setBlock(i + 39, j + 11, k + 27, BlocksAether.caelestia_stone, 0, 2);
		world.setBlock(i + 38, j + 11, k + 28, BlocksAether.caelestia_stone, 0, 2);
		world.setBlock(i + 39, j + 11, k + 28, BlocksAether.caelestia_stone, 0, 2);
		world.setBlock(i + 40, j + 11, k + 28, BlocksAether.caelestia_stone, 0, 2);
		world.setBlock(i + 37, j + 11, k + 29, BlocksAether.caelestia_stone, 0, 2);
		world.setBlock(i + 38, j + 11, k + 29, BlocksAether.caelestia_stone, 0, 2);
		world.setBlock(i + 39, j + 11, k + 29, BlocksAether.caelestia_stone, 0, 2);
		world.setBlock(i + 40, j + 11, k + 29, BlocksAether.caelestia_stone, 0, 2);
		world.setBlock(i + 41, j + 11, k + 29, BlocksAether.caelestia_stone, 0, 2);
		world.setBlock(i + 36, j + 11, k + 30, BlocksAether.caelestia_stone, 0, 2);
		world.setBlock(i + 37, j + 11, k + 30, BlocksAether.caelestia_stone, 0, 2);
		world.setBlock(i + 38, j + 11, k + 30, BlocksAether.caelestia_stone, 0, 2);
		world.setBlock(i + 39, j + 11, k + 30, BlocksAether.caelestia_stone, 0, 2);
		world.setBlock(i + 40, j + 11, k + 30, BlocksAether.caelestia_stone, 0, 2);
		world.setBlock(i + 41, j + 11, k + 30, BlocksAether.caelestia_stone, 0, 2);
		world.setBlock(i + 42, j + 11, k + 30, BlocksAether.caelestia_stone, 0, 2);
		world.setBlock(i + 35, j + 11, k + 31, BlocksAether.caelestia_stone, 0, 2);
		world.setBlock(i + 36, j + 11, k + 31, BlocksAether.caelestia_stone, 0, 2);
		world.setBlock(i + 37, j + 11, k + 31, BlocksAether.caelestia_stone, 0, 2);
		world.setBlock(i + 38, j + 11, k + 31, BlocksAether.caelestia_stone, 0, 2);
		world.setBlock(i + 39, j + 11, k + 31, BlocksAether.caelestia_stone, 0, 2);
		world.setBlock(i + 40, j + 11, k + 31, BlocksAether.caelestia_stone, 0, 2);
		world.setBlock(i + 41, j + 11, k + 31, BlocksAether.caelestia_stone, 0, 2);
		world.setBlock(i + 42, j + 11, k + 31, BlocksAether.caelestia_stone, 0, 2);
		world.setBlock(i + 43, j + 11, k + 31, BlocksAether.caelestia_stone, 0, 2);
		world.setBlock(i + 34, j + 11, k + 32, BlocksAether.caelestia_stone, 0, 2);
		world.setBlock(i + 35, j + 11, k + 32, BlocksAether.caelestia_stone, 0, 2);
		world.setBlock(i + 36, j + 11, k + 32, BlocksAether.caelestia_stone, 0, 2);
		world.setBlock(i + 37, j + 11, k + 32, BlocksAether.caelestia_stone, 0, 2);
		world.setBlock(i + 38, j + 11, k + 32, BlocksAether.caelestia_stone, 0, 2);
		world.setBlock(i + 39, j + 11, k + 32, BlocksAether.caelestia_stone, 0, 2);
		world.setBlock(i + 40, j + 11, k + 32, BlocksAether.caelestia_stone, 0, 2);
		world.setBlock(i + 41, j + 11, k + 32, BlocksAether.caelestia_stone, 0, 2);
		world.setBlock(i + 42, j + 11, k + 32, BlocksAether.caelestia_stone, 0, 2);
		world.setBlock(i + 43, j + 11, k + 32, BlocksAether.caelestia_stone, 0, 2);
		world.setBlock(i + 44, j + 11, k + 32, BlocksAether.caelestia_stone, 0, 2);
		world.setBlock(i + 33, j + 11, k + 33, BlocksAether.caelestia_stone, 0, 2);
		world.setBlock(i + 34, j + 11, k + 33, BlocksAether.caelestia_stone, 0, 2);
		world.setBlock(i + 35, j + 11, k + 33, BlocksAether.caelestia_stone, 0, 2);
		world.setBlock(i + 36, j + 11, k + 33, BlocksAether.caelestia_stone, 0, 2);
		world.setBlock(i + 37, j + 11, k + 33, BlocksAether.caelestia_stone, 0, 2);
		world.setBlock(i + 38, j + 11, k + 33, BlocksAether.caelestia_stone, 0, 2);
		world.setBlock(i + 39, j + 11, k + 33, BlocksAether.caelestia_stone, 0, 2);
		world.setBlock(i + 40, j + 11, k + 33, BlocksAether.caelestia_stone, 0, 2);
		world.setBlock(i + 41, j + 11, k + 33, BlocksAether.caelestia_stone, 0, 2);
		world.setBlock(i + 42, j + 11, k + 33, BlocksAether.caelestia_stone, 0, 2);
		world.setBlock(i + 43, j + 11, k + 33, BlocksAether.caelestia_stone, 0, 2);
		world.setBlock(i + 44, j + 11, k + 33, BlocksAether.caelestia_stone, 0, 2);
		world.setBlock(i + 45, j + 11, k + 33, BlocksAether.caelestia_stone, 0, 2);
		world.setBlock(i + 32, j + 11, k + 34, BlocksAether.caelestia_stone, 0, 2);
		world.setBlock(i + 33, j + 11, k + 34, BlocksAether.caelestia_stone, 0, 2);
		world.setBlock(i + 34, j + 11, k + 34, BlocksAether.caelestia_stone, 0, 2);
		world.setBlock(i + 35, j + 11, k + 34, BlocksAether.caelestia_stone, 0, 2);
		world.setBlock(i + 36, j + 11, k + 34, BlocksAether.caelestia_stone, 0, 2);
		world.setBlock(i + 37, j + 11, k + 34, BlocksAether.caelestia_stone, 0, 2);
		world.setBlock(i + 38, j + 11, k + 34, BlocksAether.caelestia_stone, 0, 2);
		world.setBlock(i + 39, j + 11, k + 34, BlocksAether.caelestia_stone, 0, 2);
		world.setBlock(i + 40, j + 11, k + 34, BlocksAether.caelestia_stone, 0, 2);
		world.setBlock(i + 41, j + 11, k + 34, BlocksAether.caelestia_stone, 0, 2);
		world.setBlock(i + 42, j + 11, k + 34, BlocksAether.caelestia_stone, 0, 2);
		world.setBlock(i + 43, j + 11, k + 34, BlocksAether.caelestia_stone, 0, 2);
		world.setBlock(i + 44, j + 11, k + 34, BlocksAether.caelestia_stone, 0, 2);
		world.setBlock(i + 45, j + 11, k + 34, BlocksAether.caelestia_stone, 0, 2);
		world.setBlock(i + 46, j + 11, k + 34, BlocksAether.caelestia_stone, 0, 2);
		world.setBlock(i + 31, j + 11, k + 35, BlocksAether.caelestia_stone, 0, 2);
		world.setBlock(i + 32, j + 11, k + 35, BlocksAether.caelestia_stone, 0, 2);
		world.setBlock(i + 33, j + 11, k + 35, BlocksAether.caelestia_stone, 0, 2);
		world.setBlock(i + 34, j + 11, k + 35, BlocksAether.caelestia_stone, 0, 2);
		world.setBlock(i + 35, j + 11, k + 35, BlocksAether.caelestia_stone, 0, 2);
		world.setBlock(i + 36, j + 11, k + 35, BlocksAether.caelestia_stone, 0, 2);
		world.setBlock(i + 37, j + 11, k + 35, BlocksAether.caelestia_stone, 0, 2);
		world.setBlock(i + 38, j + 11, k + 35, BlocksAether.caelestia_stone, 0, 2);
		world.setBlock(i + 39, j + 11, k + 35, BlocksAether.caelestia_stone, 0, 2);
		world.setBlock(i + 40, j + 11, k + 35, BlocksAether.caelestia_stone, 0, 2);
		world.setBlock(i + 41, j + 11, k + 35, BlocksAether.caelestia_stone, 0, 2);
		world.setBlock(i + 42, j + 11, k + 35, BlocksAether.caelestia_stone, 0, 2);
		world.setBlock(i + 43, j + 11, k + 35, BlocksAether.caelestia_stone, 0, 2);
		world.setBlock(i + 44, j + 11, k + 35, BlocksAether.caelestia_stone, 0, 2);
		world.setBlock(i + 45, j + 11, k + 35, BlocksAether.caelestia_stone, 0, 2);
		world.setBlock(i + 46, j + 11, k + 35, BlocksAether.caelestia_stone, 0, 2);
		world.setBlock(i + 47, j + 11, k + 35, BlocksAether.caelestia_stone, 0, 2);
		world.setBlock(i + 30, j + 11, k + 36, BlocksAether.caelestia_stone, 0, 2);
		world.setBlock(i + 31, j + 11, k + 36, BlocksAether.caelestia_stone, 0, 2);
		world.setBlock(i + 32, j + 11, k + 36, BlocksAether.caelestia_stone, 0, 2);
		world.setBlock(i + 33, j + 11, k + 36, BlocksAether.caelestia_stone, 0, 2);
		world.setBlock(i + 34, j + 11, k + 36, BlocksAether.caelestia_stone, 0, 2);
		world.setBlock(i + 35, j + 11, k + 36, BlocksAether.caelestia_stone, 0, 2);
		world.setBlock(i + 36, j + 11, k + 36, BlocksAether.caelestia_stone, 0, 2);
		world.setBlock(i + 37, j + 11, k + 36, BlocksAether.caelestia_stone, 0, 2);
		world.setBlock(i + 38, j + 11, k + 36, BlocksAether.caelestia_stone, 0, 2);
		world.setBlock(i + 39, j + 11, k + 36, BlocksAether.caelestia_stone, 0, 2);
		world.setBlock(i + 40, j + 11, k + 36, BlocksAether.caelestia_stone, 0, 2);
		world.setBlock(i + 41, j + 11, k + 36, BlocksAether.caelestia_stone, 0, 2);
		world.setBlock(i + 42, j + 11, k + 36, BlocksAether.caelestia_stone, 0, 2);
		world.setBlock(i + 43, j + 11, k + 36, BlocksAether.caelestia_stone, 0, 2);
		world.setBlock(i + 44, j + 11, k + 36, BlocksAether.caelestia_stone, 0, 2);
		world.setBlock(i + 45, j + 11, k + 36, BlocksAether.caelestia_stone, 0, 2);
		world.setBlock(i + 46, j + 11, k + 36, BlocksAether.caelestia_stone, 0, 2);
		world.setBlock(i + 47, j + 11, k + 36, BlocksAether.caelestia_stone, 0, 2);
		world.setBlock(i + 48, j + 11, k + 36, BlocksAether.caelestia_stone, 0, 2);
		world.setBlock(i + 29, j + 11, k + 37, BlocksAether.caelestia_stone, 0, 2);
		world.setBlock(i + 30, j + 11, k + 37, BlocksAether.caelestia_stone, 0, 2);
		world.setBlock(i + 31, j + 11, k + 37, BlocksAether.caelestia_stone, 0, 2);
		world.setBlock(i + 32, j + 11, k + 37, BlocksAether.caelestia_stone, 0, 2);
		world.setBlock(i + 33, j + 11, k + 37, BlocksAether.caelestia_stone, 0, 2);
		world.setBlock(i + 34, j + 11, k + 37, BlocksAether.caelestia_stone, 0, 2);
		world.setBlock(i + 35, j + 11, k + 37, BlocksAether.caelestia_stone, 0, 2);
		world.setBlock(i + 36, j + 11, k + 37, BlocksAether.caelestia_stone, 0, 2);
		world.setBlock(i + 37, j + 11, k + 37, BlocksAether.caelestia_stone, 0, 2);
		world.setBlock(i + 38, j + 11, k + 37, BlocksAether.caelestia_stone, 0, 2);
		world.setBlock(i + 39, j + 11, k + 37, BlocksAether.caelestia_stone, 0, 2);
		world.setBlock(i + 40, j + 11, k + 37, BlocksAether.caelestia_stone, 0, 2);
		world.setBlock(i + 41, j + 11, k + 37, BlocksAether.caelestia_stone, 0, 2);
		world.setBlock(i + 42, j + 11, k + 37, BlocksAether.caelestia_stone, 0, 2);
		world.setBlock(i + 43, j + 11, k + 37, BlocksAether.caelestia_stone, 0, 2);
		world.setBlock(i + 44, j + 11, k + 37, BlocksAether.caelestia_stone, 0, 2);
		world.setBlock(i + 45, j + 11, k + 37, BlocksAether.caelestia_stone, 0, 2);
		world.setBlock(i + 46, j + 11, k + 37, BlocksAether.caelestia_stone, 0, 2);
		world.setBlock(i + 47, j + 11, k + 37, BlocksAether.caelestia_stone, 0, 2);
		world.setBlock(i + 48, j + 11, k + 37, BlocksAether.caelestia_stone, 0, 2);
		world.setBlock(i + 49, j + 11, k + 37, BlocksAether.caelestia_stone, 0, 2);
		world.setBlock(i + 28, j + 11, k + 38, BlocksAether.caelestia_stone, 0, 2);
		world.setBlock(i + 29, j + 11, k + 38, BlocksAether.caelestia_stone, 0, 2);
		world.setBlock(i + 30, j + 11, k + 38, BlocksAether.caelestia_stone, 0, 2);
		world.setBlock(i + 31, j + 11, k + 38, BlocksAether.caelestia_stone, 0, 2);
		world.setBlock(i + 32, j + 11, k + 38, BlocksAether.caelestia_stone, 0, 2);
		world.setBlock(i + 33, j + 11, k + 38, BlocksAether.caelestia_stone, 0, 2);
		world.setBlock(i + 34, j + 11, k + 38, BlocksAether.caelestia_stone, 0, 2);
		world.setBlock(i + 35, j + 11, k + 38, BlocksAether.caelestia_stone, 0, 2);
		world.setBlock(i + 36, j + 11, k + 38, BlocksAether.caelestia_stone, 0, 2);
		world.setBlock(i + 37, j + 11, k + 38, BlocksAether.caelestia_stone, 0, 2);
		world.setBlock(i + 38, j + 11, k + 38, BlocksAether.caelestia_stone, 0, 2);
		world.setBlock(i + 39, j + 11, k + 38, BlocksAether.caelestia_stone, 0, 2);
		world.setBlock(i + 40, j + 11, k + 38, BlocksAether.caelestia_stone, 0, 2);
		world.setBlock(i + 41, j + 11, k + 38, BlocksAether.caelestia_stone, 0, 2);
		world.setBlock(i + 42, j + 11, k + 38, BlocksAether.caelestia_stone, 0, 2);
		world.setBlock(i + 43, j + 11, k + 38, BlocksAether.caelestia_stone, 0, 2);
		world.setBlock(i + 44, j + 11, k + 38, BlocksAether.caelestia_stone, 0, 2);
		world.setBlock(i + 45, j + 11, k + 38, BlocksAether.caelestia_stone, 0, 2);
		world.setBlock(i + 46, j + 11, k + 38, BlocksAether.caelestia_stone, 0, 2);
		world.setBlock(i + 47, j + 11, k + 38, BlocksAether.caelestia_stone, 0, 2);
		world.setBlock(i + 48, j + 11, k + 38, BlocksAether.caelestia_stone, 0, 2);
		world.setBlock(i + 49, j + 11, k + 38, BlocksAether.caelestia_stone, 0, 2);
		world.setBlock(i + 50, j + 11, k + 38, BlocksAether.caelestia_stone, 0, 2);
		world.setBlock(i + 29, j + 11, k + 39, BlocksAether.caelestia_stone, 0, 2);
		world.setBlock(i + 30, j + 11, k + 39, BlocksAether.caelestia_stone, 0, 2);
		world.setBlock(i + 31, j + 11, k + 39, BlocksAether.caelestia_stone, 0, 2);
		world.setBlock(i + 32, j + 11, k + 39, BlocksAether.caelestia_stone, 0, 2);
		world.setBlock(i + 33, j + 11, k + 39, BlocksAether.caelestia_stone, 0, 2);
		world.setBlock(i + 34, j + 11, k + 39, BlocksAether.caelestia_stone, 0, 2);
		world.setBlock(i + 35, j + 11, k + 39, BlocksAether.caelestia_stone, 0, 2);
		world.setBlock(i + 36, j + 11, k + 39, BlocksAether.caelestia_stone, 0, 2);
		world.setBlock(i + 37, j + 11, k + 39, BlocksAether.caelestia_stone, 0, 2);
		world.setBlock(i + 38, j + 11, k + 39, BlocksAether.caelestia_stone, 0, 2);
		world.setBlock(i + 39, j + 11, k + 39, BlocksAether.caelestia_stone, 0, 2);
		world.setBlock(i + 40, j + 11, k + 39, BlocksAether.caelestia_stone, 0, 2);
		world.setBlock(i + 41, j + 11, k + 39, BlocksAether.caelestia_stone, 0, 2);
		world.setBlock(i + 42, j + 11, k + 39, BlocksAether.caelestia_stone, 0, 2);
		world.setBlock(i + 43, j + 11, k + 39, BlocksAether.caelestia_stone, 0, 2);
		world.setBlock(i + 44, j + 11, k + 39, BlocksAether.caelestia_stone, 0, 2);
		world.setBlock(i + 45, j + 11, k + 39, BlocksAether.caelestia_stone, 0, 2);
		world.setBlock(i + 46, j + 11, k + 39, BlocksAether.caelestia_stone, 0, 2);
		world.setBlock(i + 47, j + 11, k + 39, BlocksAether.caelestia_stone, 0, 2);
		world.setBlock(i + 48, j + 11, k + 39, BlocksAether.caelestia_stone, 0, 2);
		world.setBlock(i + 49, j + 11, k + 39, BlocksAether.caelestia_stone, 0, 2);
		world.setBlock(i + 30, j + 11, k + 40, BlocksAether.caelestia_stone, 0, 2);
		world.setBlock(i + 31, j + 11, k + 40, BlocksAether.caelestia_stone, 0, 2);
		world.setBlock(i + 32, j + 11, k + 40, BlocksAether.caelestia_stone, 0, 2);
		world.setBlock(i + 33, j + 11, k + 40, BlocksAether.caelestia_stone, 0, 2);
		world.setBlock(i + 34, j + 11, k + 40, BlocksAether.caelestia_stone, 0, 2);
		world.setBlock(i + 35, j + 11, k + 40, BlocksAether.caelestia_stone, 0, 2);
		world.setBlock(i + 36, j + 11, k + 40, BlocksAether.caelestia_stone, 0, 2);
		world.setBlock(i + 37, j + 11, k + 40, BlocksAether.caelestia_stone, 0, 2);
		world.setBlock(i + 38, j + 11, k + 40, BlocksAether.caelestia_stone, 0, 2);
		world.setBlock(i + 39, j + 11, k + 40, BlocksAether.caelestia_stone, 0, 2);
		world.setBlock(i + 40, j + 11, k + 40, BlocksAether.caelestia_stone, 0, 2);
		world.setBlock(i + 41, j + 11, k + 40, BlocksAether.caelestia_stone, 0, 2);
		world.setBlock(i + 42, j + 11, k + 40, BlocksAether.caelestia_stone, 0, 2);
		world.setBlock(i + 43, j + 11, k + 40, BlocksAether.caelestia_stone, 0, 2);
		world.setBlock(i + 44, j + 11, k + 40, BlocksAether.caelestia_stone, 0, 2);
		world.setBlock(i + 45, j + 11, k + 40, BlocksAether.caelestia_stone, 0, 2);
		world.setBlock(i + 46, j + 11, k + 40, BlocksAether.caelestia_stone, 0, 2);
		world.setBlock(i + 47, j + 11, k + 40, BlocksAether.caelestia_stone, 0, 2);
		world.setBlock(i + 48, j + 11, k + 40, BlocksAether.caelestia_stone, 0, 2);
		world.setBlock(i + 31, j + 11, k + 41, BlocksAether.caelestia_stone, 0, 2);
		world.setBlock(i + 32, j + 11, k + 41, BlocksAether.caelestia_stone, 0, 2);
		world.setBlock(i + 33, j + 11, k + 41, BlocksAether.caelestia_stone, 0, 2);
		world.setBlock(i + 34, j + 11, k + 41, BlocksAether.caelestia_stone, 0, 2);
		world.setBlock(i + 35, j + 11, k + 41, BlocksAether.caelestia_stone, 0, 2);
		world.setBlock(i + 36, j + 11, k + 41, BlocksAether.caelestia_stone, 0, 2);
		world.setBlock(i + 37, j + 11, k + 41, BlocksAether.caelestia_stone, 0, 2);
		world.setBlock(i + 38, j + 11, k + 41, BlocksAether.caelestia_stone, 0, 2);
		world.setBlock(i + 39, j + 11, k + 41, BlocksAether.caelestia_stone, 0, 2);
		world.setBlock(i + 40, j + 11, k + 41, BlocksAether.caelestia_stone, 0, 2);
		world.setBlock(i + 41, j + 11, k + 41, BlocksAether.caelestia_stone, 0, 2);
		world.setBlock(i + 42, j + 11, k + 41, BlocksAether.caelestia_stone, 0, 2);
		world.setBlock(i + 43, j + 11, k + 41, BlocksAether.caelestia_stone, 0, 2);
		world.setBlock(i + 44, j + 11, k + 41, BlocksAether.caelestia_stone, 0, 2);
		world.setBlock(i + 45, j + 11, k + 41, BlocksAether.caelestia_stone, 0, 2);
		world.setBlock(i + 46, j + 11, k + 41, BlocksAether.caelestia_stone, 0, 2);
		world.setBlock(i + 47, j + 11, k + 41, BlocksAether.caelestia_stone, 0, 2);
		world.setBlock(i + 32, j + 11, k + 42, BlocksAether.caelestia_stone, 0, 2);
		world.setBlock(i + 33, j + 11, k + 42, BlocksAether.caelestia_stone, 0, 2);
		world.setBlock(i + 34, j + 11, k + 42, BlocksAether.caelestia_stone, 0, 2);
		world.setBlock(i + 35, j + 11, k + 42, BlocksAether.caelestia_stone, 0, 2);
		world.setBlock(i + 36, j + 11, k + 42, BlocksAether.caelestia_stone, 0, 2);
		world.setBlock(i + 37, j + 11, k + 42, BlocksAether.caelestia_stone, 0, 2);
		world.setBlock(i + 38, j + 11, k + 42, BlocksAether.caelestia_stone, 0, 2);
		world.setBlock(i + 39, j + 11, k + 42, BlocksAether.caelestia_stone, 0, 2);
		world.setBlock(i + 40, j + 11, k + 42, BlocksAether.caelestia_stone, 0, 2);
		world.setBlock(i + 41, j + 11, k + 42, BlocksAether.caelestia_stone, 0, 2);
		world.setBlock(i + 42, j + 11, k + 42, BlocksAether.caelestia_stone, 0, 2);
		world.setBlock(i + 43, j + 11, k + 42, BlocksAether.caelestia_stone, 0, 2);
		world.setBlock(i + 44, j + 11, k + 42, BlocksAether.caelestia_stone, 0, 2);
		world.setBlock(i + 45, j + 11, k + 42, BlocksAether.caelestia_stone, 0, 2);
		world.setBlock(i + 46, j + 11, k + 42, BlocksAether.caelestia_stone, 0, 2);
		world.setBlock(i + 33, j + 11, k + 43, BlocksAether.caelestia_stone, 0, 2);
		world.setBlock(i + 34, j + 11, k + 43, BlocksAether.caelestia_stone, 0, 2);
		world.setBlock(i + 35, j + 11, k + 43, BlocksAether.caelestia_stone, 0, 2);
		world.setBlock(i + 36, j + 11, k + 43, BlocksAether.caelestia_stone, 0, 2);
		world.setBlock(i + 37, j + 11, k + 43, BlocksAether.caelestia_stone, 0, 2);
		world.setBlock(i + 38, j + 11, k + 43, BlocksAether.caelestia_stone, 0, 2);
		world.setBlock(i + 39, j + 11, k + 43, BlocksAether.caelestia_stone, 0, 2);
		world.setBlock(i + 40, j + 11, k + 43, BlocksAether.caelestia_stone, 0, 2);
		world.setBlock(i + 41, j + 11, k + 43, BlocksAether.caelestia_stone, 0, 2);
		world.setBlock(i + 42, j + 11, k + 43, BlocksAether.caelestia_stone, 0, 2);
		world.setBlock(i + 43, j + 11, k + 43, BlocksAether.caelestia_stone, 0, 2);
		world.setBlock(i + 44, j + 11, k + 43, BlocksAether.caelestia_stone, 0, 2);
		world.setBlock(i + 45, j + 11, k + 43, BlocksAether.caelestia_stone, 0, 2);
		world.setBlock(i + 34, j + 11, k + 44, BlocksAether.caelestia_stone, 0, 2);
		world.setBlock(i + 35, j + 11, k + 44, BlocksAether.caelestia_stone, 0, 2);
		world.setBlock(i + 36, j + 11, k + 44, BlocksAether.caelestia_stone, 0, 2);
		world.setBlock(i + 37, j + 11, k + 44, BlocksAether.caelestia_stone, 0, 2);
		world.setBlock(i + 38, j + 11, k + 44, BlocksAether.caelestia_stone, 0, 2);
		world.setBlock(i + 39, j + 11, k + 44, BlocksAether.caelestia_stone, 0, 2);
		world.setBlock(i + 40, j + 11, k + 44, BlocksAether.caelestia_stone, 0, 2);
		world.setBlock(i + 41, j + 11, k + 44, BlocksAether.caelestia_stone, 0, 2);
		world.setBlock(i + 42, j + 11, k + 44, BlocksAether.caelestia_stone, 0, 2);
		world.setBlock(i + 43, j + 11, k + 44, BlocksAether.caelestia_stone, 0, 2);
		world.setBlock(i + 44, j + 11, k + 44, BlocksAether.caelestia_stone, 0, 2);
		world.setBlock(i + 35, j + 11, k + 45, BlocksAether.caelestia_stone, 0, 2);
		world.setBlock(i + 36, j + 11, k + 45, BlocksAether.caelestia_stone, 0, 2);
		world.setBlock(i + 37, j + 11, k + 45, BlocksAether.caelestia_stone, 0, 2);
		world.setBlock(i + 38, j + 11, k + 45, BlocksAether.caelestia_stone, 0, 2);
		world.setBlock(i + 39, j + 11, k + 45, BlocksAether.caelestia_stone, 0, 2);
		world.setBlock(i + 40, j + 11, k + 45, BlocksAether.caelestia_stone, 0, 2);
		world.setBlock(i + 41, j + 11, k + 45, BlocksAether.caelestia_stone, 0, 2);
		world.setBlock(i + 42, j + 11, k + 45, BlocksAether.caelestia_stone, 0, 2);
		world.setBlock(i + 43, j + 11, k + 45, BlocksAether.caelestia_stone, 0, 2);
		world.setBlock(i + 36, j + 11, k + 46, BlocksAether.caelestia_stone, 0, 2);
		world.setBlock(i + 37, j + 11, k + 46, BlocksAether.caelestia_stone, 0, 2);
		world.setBlock(i + 38, j + 11, k + 46, BlocksAether.caelestia_stone, 0, 2);
		world.setBlock(i + 39, j + 11, k + 46, BlocksAether.caelestia_stone, 0, 2);
		world.setBlock(i + 40, j + 11, k + 46, BlocksAether.caelestia_stone, 0, 2);
		world.setBlock(i + 41, j + 11, k + 46, BlocksAether.caelestia_stone, 0, 2);
		world.setBlock(i + 42, j + 11, k + 46, BlocksAether.caelestia_stone, 0, 2);
		world.setBlock(i + 37, j + 11, k + 47, BlocksAether.caelestia_stone, 0, 2);
		world.setBlock(i + 38, j + 11, k + 47, BlocksAether.caelestia_stone, 0, 2);
		world.setBlock(i + 39, j + 11, k + 47, BlocksAether.caelestia_stone, 0, 2);
		world.setBlock(i + 40, j + 11, k + 47, BlocksAether.caelestia_stone, 0, 2);
		world.setBlock(i + 41, j + 11, k + 47, BlocksAether.caelestia_stone, 0, 2);
		world.setBlock(i + 38, j + 11, k + 48, BlocksAether.caelestia_stone, 0, 2);
		world.setBlock(i + 39, j + 11, k + 48, BlocksAether.caelestia_stone, 0, 2);
		world.setBlock(i + 40, j + 11, k + 48, BlocksAether.caelestia_stone, 0, 2);
		world.setBlock(i + 39, j + 11, k + 49, BlocksAether.caelestia_stone, 0, 2);
		world.setBlock(i + 39, j + 12, k + 26, BlocksAether.caelestia_stone, 0, 2);
		world.setBlock(i + 38, j + 12, k + 27, BlocksAether.caelestia_stone, 0, 2);
		world.setBlock(i + 39, j + 12, k + 27, BlocksAether.caelestia_stone, 0, 2);
		world.setBlock(i + 40, j + 12, k + 27, BlocksAether.caelestia_stone, 0, 2);
		world.setBlock(i + 37, j + 12, k + 28, BlocksAether.caelestia_stone, 0, 2);
		world.setBlock(i + 38, j + 12, k + 28, BlocksAether.caelestia_stone, 0, 2);
		world.setBlock(i + 39, j + 12, k + 28, BlocksAether.caelestia_stone, 0, 2);
		world.setBlock(i + 40, j + 12, k + 28, BlocksAether.caelestia_stone, 0, 2);
		world.setBlock(i + 41, j + 12, k + 28, BlocksAether.caelestia_stone, 0, 2);
		world.setBlock(i + 36, j + 12, k + 29, BlocksAether.caelestia_stone, 0, 2);
		world.setBlock(i + 37, j + 12, k + 29, BlocksAether.caelestia_stone, 0, 2);
		world.setBlock(i + 38, j + 12, k + 29, BlocksAether.caelestia_stone, 0, 2);
		world.setBlock(i + 39, j + 12, k + 29, BlocksAether.caelestia_stone, 0, 2);
		world.setBlock(i + 40, j + 12, k + 29, BlocksAether.caelestia_stone, 0, 2);
		world.setBlock(i + 41, j + 12, k + 29, BlocksAether.caelestia_stone, 0, 2);
		world.setBlock(i + 42, j + 12, k + 29, BlocksAether.caelestia_stone, 0, 2);
		world.setBlock(i + 35, j + 12, k + 30, BlocksAether.caelestia_stone, 0, 2);
		world.setBlock(i + 36, j + 12, k + 30, BlocksAether.caelestia_stone, 0, 2);
		world.setBlock(i + 37, j + 12, k + 30, BlocksAether.caelestia_stone, 0, 2);
		world.setBlock(i + 38, j + 12, k + 30, BlocksAether.caelestia_stone, 0, 2);
		world.setBlock(i + 39, j + 12, k + 30, BlocksAether.caelestia_stone, 0, 2);
		world.setBlock(i + 40, j + 12, k + 30, BlocksAether.caelestia_stone, 0, 2);
		world.setBlock(i + 41, j + 12, k + 30, BlocksAether.caelestia_stone, 0, 2);
		world.setBlock(i + 42, j + 12, k + 30, BlocksAether.caelestia_stone, 0, 2);
		world.setBlock(i + 43, j + 12, k + 30, BlocksAether.caelestia_stone, 0, 2);
		world.setBlock(i + 34, j + 12, k + 31, BlocksAether.caelestia_stone, 0, 2);
		world.setBlock(i + 35, j + 12, k + 31, BlocksAether.caelestia_stone, 0, 2);
		world.setBlock(i + 36, j + 12, k + 31, BlocksAether.caelestia_stone, 0, 2);
		world.setBlock(i + 37, j + 12, k + 31, BlocksAether.caelestia_stone, 0, 2);
		world.setBlock(i + 38, j + 12, k + 31, BlocksAether.caelestia_stone, 0, 2);
		world.setBlock(i + 39, j + 12, k + 31, BlocksAether.caelestia_stone, 0, 2);
		world.setBlock(i + 40, j + 12, k + 31, BlocksAether.caelestia_stone, 0, 2);
		world.setBlock(i + 41, j + 12, k + 31, BlocksAether.caelestia_stone, 0, 2);
		world.setBlock(i + 42, j + 12, k + 31, BlocksAether.caelestia_stone, 0, 2);
		world.setBlock(i + 43, j + 12, k + 31, BlocksAether.caelestia_stone, 0, 2);
		world.setBlock(i + 44, j + 12, k + 31, BlocksAether.caelestia_stone, 0, 2);
		world.setBlock(i + 33, j + 12, k + 32, BlocksAether.caelestia_stone, 0, 2);
		world.setBlock(i + 34, j + 12, k + 32, BlocksAether.caelestia_stone, 0, 2);
		world.setBlock(i + 35, j + 12, k + 32, BlocksAether.caelestia_stone, 0, 2);
		world.setBlock(i + 36, j + 12, k + 32, BlocksAether.caelestia_stone, 0, 2);
		world.setBlock(i + 37, j + 12, k + 32, BlocksAether.caelestia_stone, 0, 2);
		world.setBlock(i + 38, j + 12, k + 32, BlocksAether.caelestia_stone, 0, 2);
		world.setBlock(i + 39, j + 12, k + 32, BlocksAether.caelestia_stone, 0, 2);
		world.setBlock(i + 40, j + 12, k + 32, BlocksAether.caelestia_stone, 0, 2);
		world.setBlock(i + 41, j + 12, k + 32, BlocksAether.caelestia_stone, 0, 2);
		world.setBlock(i + 42, j + 12, k + 32, BlocksAether.caelestia_stone, 0, 2);
		world.setBlock(i + 43, j + 12, k + 32, BlocksAether.caelestia_stone, 0, 2);
		world.setBlock(i + 44, j + 12, k + 32, BlocksAether.caelestia_stone, 0, 2);
		world.setBlock(i + 45, j + 12, k + 32, BlocksAether.caelestia_stone, 0, 2);
		world.setBlock(i + 32, j + 12, k + 33, BlocksAether.caelestia_stone, 0, 2);
		world.setBlock(i + 33, j + 12, k + 33, BlocksAether.caelestia_stone, 0, 2);
		world.setBlock(i + 34, j + 12, k + 33, BlocksAether.caelestia_stone, 0, 2);
		world.setBlock(i + 35, j + 12, k + 33, BlocksAether.caelestia_stone, 0, 2);
		world.setBlock(i + 36, j + 12, k + 33, BlocksAether.caelestia_stone, 0, 2);
		world.setBlock(i + 37, j + 12, k + 33, BlocksAether.caelestia_stone, 0, 2);
		world.setBlock(i + 38, j + 12, k + 33, BlocksAether.caelestia_stone, 0, 2);
		world.setBlock(i + 39, j + 12, k + 33, BlocksAether.caelestia_stone, 0, 2);
		world.setBlock(i + 40, j + 12, k + 33, BlocksAether.caelestia_stone, 0, 2);
		world.setBlock(i + 41, j + 12, k + 33, BlocksAether.caelestia_stone, 0, 2);
		world.setBlock(i + 42, j + 12, k + 33, BlocksAether.caelestia_stone, 0, 2);
		world.setBlock(i + 43, j + 12, k + 33, BlocksAether.caelestia_stone, 0, 2);
		world.setBlock(i + 44, j + 12, k + 33, BlocksAether.caelestia_stone, 0, 2);
		world.setBlock(i + 45, j + 12, k + 33, BlocksAether.caelestia_stone, 0, 2);
		world.setBlock(i + 46, j + 12, k + 33, BlocksAether.caelestia_stone, 0, 2);
		world.setBlock(i + 31, j + 12, k + 34, BlocksAether.caelestia_stone, 0, 2);
		world.setBlock(i + 32, j + 12, k + 34, BlocksAether.caelestia_stone, 0, 2);
		world.setBlock(i + 33, j + 12, k + 34, BlocksAether.caelestia_stone, 0, 2);
		world.setBlock(i + 34, j + 12, k + 34, BlocksAether.caelestia_stone, 0, 2);
		world.setBlock(i + 35, j + 12, k + 34, BlocksAether.caelestia_stone, 0, 2);
		world.setBlock(i + 36, j + 12, k + 34, BlocksAether.caelestia_stone, 0, 2);
		world.setBlock(i + 37, j + 12, k + 34, BlocksAether.caelestia_stone, 0, 2);
		world.setBlock(i + 38, j + 12, k + 34, BlocksAether.caelestia_stone, 0, 2);
		world.setBlock(i + 39, j + 12, k + 34, BlocksAether.caelestia_stone, 0, 2);
		world.setBlock(i + 40, j + 12, k + 34, BlocksAether.caelestia_stone, 0, 2);
		world.setBlock(i + 41, j + 12, k + 34, BlocksAether.caelestia_stone, 0, 2);
		world.setBlock(i + 42, j + 12, k + 34, BlocksAether.caelestia_stone, 0, 2);
		world.setBlock(i + 43, j + 12, k + 34, BlocksAether.caelestia_stone, 0, 2);
		world.setBlock(i + 44, j + 12, k + 34, BlocksAether.caelestia_stone, 0, 2);
		world.setBlock(i + 45, j + 12, k + 34, BlocksAether.caelestia_stone, 0, 2);
		world.setBlock(i + 46, j + 12, k + 34, BlocksAether.caelestia_stone, 0, 2);
		world.setBlock(i + 47, j + 12, k + 34, BlocksAether.caelestia_stone, 0, 2);
		world.setBlock(i + 30, j + 12, k + 35, BlocksAether.caelestia_stone, 0, 2);
		world.setBlock(i + 31, j + 12, k + 35, BlocksAether.caelestia_stone, 0, 2);
		world.setBlock(i + 32, j + 12, k + 35, BlocksAether.caelestia_stone, 0, 2);
		world.setBlock(i + 33, j + 12, k + 35, BlocksAether.caelestia_stone, 0, 2);
		world.setBlock(i + 34, j + 12, k + 35, BlocksAether.caelestia_stone, 0, 2);
		world.setBlock(i + 35, j + 12, k + 35, BlocksAether.caelestia_stone, 0, 2);
		world.setBlock(i + 36, j + 12, k + 35, BlocksAether.caelestia_stone, 0, 2);
		world.setBlock(i + 37, j + 12, k + 35, BlocksAether.caelestia_stone, 0, 2);
		world.setBlock(i + 38, j + 12, k + 35, BlocksAether.caelestia_stone, 0, 2);
		world.setBlock(i + 39, j + 12, k + 35, BlocksAether.caelestia_stone, 0, 2);
		world.setBlock(i + 40, j + 12, k + 35, BlocksAether.caelestia_stone, 0, 2);
		world.setBlock(i + 41, j + 12, k + 35, BlocksAether.caelestia_stone, 0, 2);
		world.setBlock(i + 42, j + 12, k + 35, BlocksAether.caelestia_stone, 0, 2);
		world.setBlock(i + 43, j + 12, k + 35, BlocksAether.caelestia_stone, 0, 2);
		world.setBlock(i + 44, j + 12, k + 35, BlocksAether.caelestia_stone, 0, 2);
		world.setBlock(i + 45, j + 12, k + 35, BlocksAether.caelestia_stone, 0, 2);
		world.setBlock(i + 46, j + 12, k + 35, BlocksAether.caelestia_stone, 0, 2);
		world.setBlock(i + 47, j + 12, k + 35, BlocksAether.caelestia_stone, 0, 2);
		world.setBlock(i + 48, j + 12, k + 35, BlocksAether.caelestia_stone, 0, 2);
		world.setBlock(i + 29, j + 12, k + 36, BlocksAether.caelestia_stone, 0, 2);
		world.setBlock(i + 30, j + 12, k + 36, BlocksAether.caelestia_stone, 0, 2);
		world.setBlock(i + 31, j + 12, k + 36, BlocksAether.caelestia_stone, 0, 2);
		world.setBlock(i + 32, j + 12, k + 36, BlocksAether.caelestia_stone, 0, 2);
		world.setBlock(i + 33, j + 12, k + 36, BlocksAether.caelestia_stone, 0, 2);
		world.setBlock(i + 34, j + 12, k + 36, BlocksAether.caelestia_stone, 0, 2);
		world.setBlock(i + 35, j + 12, k + 36, BlocksAether.caelestia_stone, 0, 2);
		world.setBlock(i + 36, j + 12, k + 36, BlocksAether.caelestia_stone, 0, 2);
		world.setBlock(i + 37, j + 12, k + 36, BlocksAether.caelestia_stone, 0, 2);
		world.setBlock(i + 38, j + 12, k + 36, BlocksAether.caelestia_stone, 0, 2);
		world.setBlock(i + 39, j + 12, k + 36, BlocksAether.caelestia_stone, 0, 2);
		world.setBlock(i + 40, j + 12, k + 36, BlocksAether.caelestia_stone, 0, 2);
		world.setBlock(i + 41, j + 12, k + 36, BlocksAether.caelestia_stone, 0, 2);
		world.setBlock(i + 42, j + 12, k + 36, BlocksAether.caelestia_stone, 0, 2);
		world.setBlock(i + 43, j + 12, k + 36, BlocksAether.caelestia_stone, 0, 2);
		world.setBlock(i + 44, j + 12, k + 36, BlocksAether.caelestia_stone, 0, 2);
		world.setBlock(i + 45, j + 12, k + 36, BlocksAether.caelestia_stone, 0, 2);
		world.setBlock(i + 46, j + 12, k + 36, BlocksAether.caelestia_stone, 0, 2);
		world.setBlock(i + 47, j + 12, k + 36, BlocksAether.caelestia_stone, 0, 2);
		world.setBlock(i + 48, j + 12, k + 36, BlocksAether.caelestia_stone, 0, 2);
		world.setBlock(i + 49, j + 12, k + 36, BlocksAether.caelestia_stone, 0, 2);
		world.setBlock(i + 28, j + 12, k + 37, BlocksAether.caelestia_stone, 0, 2);
		world.setBlock(i + 29, j + 12, k + 37, BlocksAether.caelestia_stone, 0, 2);
		world.setBlock(i + 30, j + 12, k + 37, BlocksAether.caelestia_stone, 0, 2);
		world.setBlock(i + 31, j + 12, k + 37, BlocksAether.caelestia_stone, 0, 2);
		world.setBlock(i + 32, j + 12, k + 37, BlocksAether.caelestia_stone, 0, 2);
		world.setBlock(i + 33, j + 12, k + 37, BlocksAether.caelestia_stone, 0, 2);
		world.setBlock(i + 34, j + 12, k + 37, BlocksAether.caelestia_stone, 0, 2);
		world.setBlock(i + 35, j + 12, k + 37, BlocksAether.caelestia_stone, 0, 2);
