package com.gildedgames.the_aether.world.dungeon.osmium;

import java.util.Random;

import com.gildedgames.the_aether.blocks.BlocksAether;

import net.minecraft.world.World;
import net.minecraft.world.gen.feature.WorldGenerator;

public class OsmiumDungeonGen2 extends WorldGenerator {

	public OsmiumDungeonGen2() {

	}
	
	public boolean generate(final World world, final Random random, final int i, final int j, final int k) {
		
		world.setBlock(i + 32, j + 15, k + 36, BlocksAether.caelestia_stone, 0, 2);
		world.setBlock(i + 33, j + 15, k + 36, BlocksAether.caelestia_stone, 0, 2);
		world.setBlock(i + 34, j + 15, k + 36, BlocksAether.caelestia_stone, 0, 2);
		world.setBlock(i + 35, j + 15, k + 36, BlocksAether.caelestia_stone, 0, 2);
		world.setBlock(i + 36, j + 15, k + 36, BlocksAether.caelestia_stone, 0, 2);
		world.setBlock(i + 37, j + 15, k + 36, BlocksAether.caelestia_stone, 0, 2);
		world.setBlock(i + 38, j + 15, k + 36, BlocksAether.caelestia_stone, 0, 2);
		world.setBlock(i + 39, j + 15, k + 36, BlocksAether.caelestia_stone, 0, 2);
		world.setBlock(i + 40, j + 15, k + 36, BlocksAether.caelestia_stone, 0, 2);
		world.setBlock(i + 41, j + 15, k + 36, BlocksAether.caelestia_stone, 0, 2);
		world.setBlock(i + 42, j + 15, k + 36, BlocksAether.caelestia_stone, 0, 2);
		world.setBlock(i + 43, j + 15, k + 36, BlocksAether.caelestia_stone, 0, 2);
		world.setBlock(i + 44, j + 15, k + 36, BlocksAether.caelestia_stone, 0, 2);
		world.setBlock(i + 45, j + 15, k + 36, BlocksAether.caelestia_stone, 0, 2);
		world.setBlock(i + 46, j + 15, k + 36, BlocksAether.caelestia_stone, 0, 2);
		world.setBlock(i + 47, j + 15, k + 36, BlocksAether.caelestia_stone, 0, 2);
		world.setBlock(i + 48, j + 15, k + 36, BlocksAether.caelestia_stone, 0, 2);
		world.setBlock(i + 49, j + 15, k + 36, BlocksAether.caelestia_stone, 0, 2);
		world.setBlock(i + 50, j + 15, k + 36, BlocksAether.caelestia_stone, 0, 2);
		world.setBlock(i + 51, j + 15, k + 36, BlocksAether.caelestia_stone, 0, 2);
		world.setBlock(i + 52, j + 15, k + 36, BlocksAether.caelestia_stone, 0, 2);
		world.setBlock(i + 25, j + 15, k + 37, BlocksAether.caelestia_stone, 0, 2);
		world.setBlock(i + 26, j + 15, k + 37, BlocksAether.caelestia_stone, 0, 2);
		world.setBlock(i + 27, j + 15, k + 37, BlocksAether.caelestia_stone, 0, 2);
		world.setBlock(i + 28, j + 15, k + 37, BlocksAether.caelestia_stone, 0, 2);
		world.setBlock(i + 29, j + 15, k + 37, BlocksAether.caelestia_stone, 0, 2);
		world.setBlock(i + 30, j + 15, k + 37, BlocksAether.caelestia_stone, 0, 2);
		world.setBlock(i + 31, j + 15, k + 37, BlocksAether.caelestia_stone, 0, 2);
		world.setBlock(i + 32, j + 15, k + 37, BlocksAether.caelestia_stone, 0, 2);
		world.setBlock(i + 33, j + 15, k + 37, BlocksAether.caelestia_stone, 0, 2);
		world.setBlock(i + 34, j + 15, k + 37, BlocksAether.caelestia_stone, 0, 2);
		world.setBlock(i + 35, j + 15, k + 37, BlocksAether.caelestia_stone, 0, 2);
		world.setBlock(i + 36, j + 15, k + 37, BlocksAether.caelestia_stone, 0, 2);
		world.setBlock(i + 37, j + 15, k + 37, BlocksAether.caelestia_stone, 0, 2);
		world.setBlock(i + 38, j + 15, k + 37, BlocksAether.caelestia_stone, 0, 2);
		world.setBlock(i + 39, j + 15, k + 37, BlocksAether.caelestia_stone, 0, 2);
		world.setBlock(i + 40, j + 15, k + 37, BlocksAether.caelestia_stone, 0, 2);
		world.setBlock(i + 41, j + 15, k + 37, BlocksAether.caelestia_stone, 0, 2);
		world.setBlock(i + 42, j + 15, k + 37, BlocksAether.caelestia_stone, 0, 2);
		world.setBlock(i + 43, j + 15, k + 37, BlocksAether.caelestia_stone, 0, 2);
		world.setBlock(i + 44, j + 15, k + 37, BlocksAether.caelestia_stone, 0, 2);
		world.setBlock(i + 45, j + 15, k + 37, BlocksAether.caelestia_stone, 0, 2);
		world.setBlock(i + 46, j + 15, k + 37, BlocksAether.caelestia_stone, 0, 2);
		world.setBlock(i + 47, j + 15, k + 37, BlocksAether.caelestia_stone, 0, 2);
		world.setBlock(i + 48, j + 15, k + 37, BlocksAether.caelestia_stone, 0, 2);
		world.setBlock(i + 49, j + 15, k + 37, BlocksAether.caelestia_stone, 0, 2);
		world.setBlock(i + 50, j + 15, k + 37, BlocksAether.caelestia_stone, 0, 2);
		world.setBlock(i + 51, j + 15, k + 37, BlocksAether.caelestia_stone, 0, 2);
		world.setBlock(i + 52, j + 15, k + 37, BlocksAether.caelestia_stone, 0, 2);
		world.setBlock(i + 53, j + 15, k + 37, BlocksAether.caelestia_stone, 0, 2);
		world.setBlock(i + 24, j + 15, k + 38, BlocksAether.caelestia_stone, 0, 2);
		world.setBlock(i + 25, j + 15, k + 38, BlocksAether.caelestia_stone, 0, 2);
		world.setBlock(i + 26, j + 15, k + 38, BlocksAether.caelestia_stone, 0, 2);
		world.setBlock(i + 27, j + 15, k + 38, BlocksAether.caelestia_stone, 0, 2);
		world.setBlock(i + 28, j + 15, k + 38, BlocksAether.caelestia_stone, 0, 2);
		world.setBlock(i + 29, j + 15, k + 38, BlocksAether.caelestia_stone, 0, 2);
		world.setBlock(i + 30, j + 15, k + 38, BlocksAether.caelestia_stone, 0, 2);
		world.setBlock(i + 31, j + 15, k + 38, BlocksAether.caelestia_stone, 0, 2);
		world.setBlock(i + 32, j + 15, k + 38, BlocksAether.caelestia_stone, 0, 2);
		world.setBlock(i + 33, j + 15, k + 38, BlocksAether.caelestia_stone, 0, 2);
		world.setBlock(i + 34, j + 15, k + 38, BlocksAether.caelestia_stone, 0, 2);
		world.setBlock(i + 35, j + 15, k + 38, BlocksAether.caelestia_stone, 0, 2);
		world.setBlock(i + 36, j + 15, k + 38, BlocksAether.caelestia_stone, 0, 2);
		world.setBlock(i + 37, j + 15, k + 38, BlocksAether.caelestia_stone, 0, 2);
		world.setBlock(i + 38, j + 15, k + 38, BlocksAether.caelestia_stone, 0, 2);
		world.setBlock(i + 39, j + 15, k + 38, BlocksAether.caelestia_stone, 0, 2);
		world.setBlock(i + 40, j + 15, k + 38, BlocksAether.caelestia_stone, 0, 2);
		world.setBlock(i + 41, j + 15, k + 38, BlocksAether.caelestia_stone, 0, 2);
		world.setBlock(i + 42, j + 15, k + 38, BlocksAether.caelestia_stone, 0, 2);
		world.setBlock(i + 43, j + 15, k + 38, BlocksAether.caelestia_stone, 0, 2);
		world.setBlock(i + 44, j + 15, k + 38, BlocksAether.caelestia_stone, 0, 2);
		world.setBlock(i + 45, j + 15, k + 38, BlocksAether.caelestia_stone, 0, 2);
		world.setBlock(i + 46, j + 15, k + 38, BlocksAether.caelestia_stone, 0, 2);
		world.setBlock(i + 47, j + 15, k + 38, BlocksAether.caelestia_stone, 0, 2);
		world.setBlock(i + 48, j + 15, k + 38, BlocksAether.caelestia_stone, 0, 2);
		world.setBlock(i + 49, j + 15, k + 38, BlocksAether.caelestia_stone, 0, 2);
		world.setBlock(i + 50, j + 15, k + 38, BlocksAether.caelestia_stone, 0, 2);
		world.setBlock(i + 51, j + 15, k + 38, BlocksAether.caelestia_stone, 0, 2);
		world.setBlock(i + 52, j + 15, k + 38, BlocksAether.caelestia_stone, 0, 2);
		world.setBlock(i + 53, j + 15, k + 38, BlocksAether.caelestia_stone, 0, 2);
		world.setBlock(i + 54, j + 15, k + 38, BlocksAether.caelestia_stone, 0, 2);
		world.setBlock(i + 25, j + 15, k + 39, BlocksAether.caelestia_stone, 0, 2);
		world.setBlock(i + 26, j + 15, k + 39, BlocksAether.caelestia_stone, 0, 2);
		world.setBlock(i + 27, j + 15, k + 39, BlocksAether.caelestia_stone, 0, 2);
		world.setBlock(i + 28, j + 15, k + 39, BlocksAether.caelestia_stone, 0, 2);
		world.setBlock(i + 29, j + 15, k + 39, BlocksAether.caelestia_stone, 0, 2);
		world.setBlock(i + 30, j + 15, k + 39, BlocksAether.caelestia_stone, 0, 2);
		world.setBlock(i + 31, j + 15, k + 39, BlocksAether.caelestia_stone, 0, 2);
		world.setBlock(i + 32, j + 15, k + 39, BlocksAether.caelestia_stone, 0, 2);
		world.setBlock(i + 33, j + 15, k + 39, BlocksAether.caelestia_stone, 0, 2);
		world.setBlock(i + 34, j + 15, k + 39, BlocksAether.caelestia_stone, 0, 2);
		world.setBlock(i + 35, j + 15, k + 39, BlocksAether.caelestia_stone, 0, 2);
		world.setBlock(i + 36, j + 15, k + 39, BlocksAether.caelestia_stone, 0, 2);
		world.setBlock(i + 37, j + 15, k + 39, BlocksAether.caelestia_stone, 0, 2);
		world.setBlock(i + 38, j + 15, k + 39, BlocksAether.caelestia_stone, 0, 2);
		world.setBlock(i + 39, j + 15, k + 39, BlocksAether.caelestia_stone, 0, 2);
		world.setBlock(i + 40, j + 15, k + 39, BlocksAether.caelestia_stone, 0, 2);
		world.setBlock(i + 41, j + 15, k + 39, BlocksAether.caelestia_stone, 0, 2);
		world.setBlock(i + 42, j + 15, k + 39, BlocksAether.caelestia_stone, 0, 2);
		world.setBlock(i + 43, j + 15, k + 39, BlocksAether.caelestia_stone, 0, 2);
		world.setBlock(i + 44, j + 15, k + 39, BlocksAether.caelestia_stone, 0, 2);
		world.setBlock(i + 45, j + 15, k + 39, BlocksAether.caelestia_stone, 0, 2);
		world.setBlock(i + 46, j + 15, k + 39, BlocksAether.caelestia_stone, 0, 2);
		world.setBlock(i + 47, j + 15, k + 39, BlocksAether.caelestia_stone, 0, 2);
		world.setBlock(i + 48, j + 15, k + 39, BlocksAether.caelestia_stone, 0, 2);
		world.setBlock(i + 49, j + 15, k + 39, BlocksAether.caelestia_stone, 0, 2);
		world.setBlock(i + 50, j + 15, k + 39, BlocksAether.caelestia_stone, 0, 2);
		world.setBlock(i + 51, j + 15, k + 39, BlocksAether.caelestia_stone, 0, 2);
		world.setBlock(i + 52, j + 15, k + 39, BlocksAether.caelestia_stone, 0, 2);
		world.setBlock(i + 53, j + 15, k + 39, BlocksAether.caelestia_stone, 0, 2);
		world.setBlock(i + 26, j + 15, k + 40, BlocksAether.caelestia_stone, 0, 2);
		world.setBlock(i + 27, j + 15, k + 40, BlocksAether.caelestia_stone, 0, 2);
		world.setBlock(i + 28, j + 15, k + 40, BlocksAether.caelestia_stone, 0, 2);
		world.setBlock(i + 29, j + 15, k + 40, BlocksAether.caelestia_stone, 0, 2);
		world.setBlock(i + 30, j + 15, k + 40, BlocksAether.caelestia_stone, 0, 2);
		world.setBlock(i + 31, j + 15, k + 40, BlocksAether.caelestia_stone, 0, 2);
		world.setBlock(i + 32, j + 15, k + 40, BlocksAether.caelestia_stone, 0, 2);
		world.setBlock(i + 33, j + 15, k + 40, BlocksAether.caelestia_stone, 0, 2);
		world.setBlock(i + 34, j + 15, k + 40, BlocksAether.caelestia_stone, 0, 2);
		world.setBlock(i + 35, j + 15, k + 40, BlocksAether.caelestia_stone, 0, 2);
		world.setBlock(i + 36, j + 15, k + 40, BlocksAether.caelestia_stone, 0, 2);
		world.setBlock(i + 37, j + 15, k + 40, BlocksAether.caelestia_stone, 0, 2);
		world.setBlock(i + 38, j + 15, k + 40, BlocksAether.caelestia_stone, 0, 2);
		world.setBlock(i + 39, j + 15, k + 40, BlocksAether.caelestia_stone, 0, 2);
		world.setBlock(i + 40, j + 15, k + 40, BlocksAether.caelestia_stone, 0, 2);
		world.setBlock(i + 41, j + 15, k + 40, BlocksAether.caelestia_stone, 0, 2);
		world.setBlock(i + 42, j + 15, k + 40, BlocksAether.caelestia_stone, 0, 2);
		world.setBlock(i + 43, j + 15, k + 40, BlocksAether.caelestia_stone, 0, 2);
		world.setBlock(i + 44, j + 15, k + 40, BlocksAether.caelestia_stone, 0, 2);
		world.setBlock(i + 45, j + 15, k + 40, BlocksAether.caelestia_stone, 0, 2);
		world.setBlock(i + 46, j + 15, k + 40, BlocksAether.caelestia_stone, 0, 2);
		world.setBlock(i + 47, j + 15, k + 40, BlocksAether.caelestia_stone, 0, 2);
		world.setBlock(i + 48, j + 15, k + 40, BlocksAether.caelestia_stone, 0, 2);
		world.setBlock(i + 49, j + 15, k + 40, BlocksAether.caelestia_stone, 0, 2);
		world.setBlock(i + 50, j + 15, k + 40, BlocksAether.caelestia_stone, 0, 2);
		world.setBlock(i + 51, j + 15, k + 40, BlocksAether.caelestia_stone, 0, 2);
		world.setBlock(i + 52, j + 15, k + 40, BlocksAether.caelestia_stone, 0, 2);
		world.setBlock(i + 27, j + 15, k + 41, BlocksAether.caelestia_stone, 0, 2);
		world.setBlock(i + 28, j + 15, k + 41, BlocksAether.caelestia_stone, 0, 2);
		world.setBlock(i + 29, j + 15, k + 41, BlocksAether.caelestia_stone, 0, 2);
		world.setBlock(i + 30, j + 15, k + 41, BlocksAether.caelestia_stone, 0, 2);
		world.setBlock(i + 31, j + 15, k + 41, BlocksAether.caelestia_stone, 0, 2);
		world.setBlock(i + 32, j + 15, k + 41, BlocksAether.caelestia_stone, 0, 2);
		world.setBlock(i + 33, j + 15, k + 41, BlocksAether.caelestia_stone, 0, 2);
		world.setBlock(i + 34, j + 15, k + 41, BlocksAether.caelestia_stone, 0, 2);
		world.setBlock(i + 35, j + 15, k + 41, BlocksAether.caelestia_stone, 0, 2);
		world.setBlock(i + 36, j + 15, k + 41, BlocksAether.caelestia_stone, 0, 2);
		world.setBlock(i + 37, j + 15, k + 41, BlocksAether.caelestia_stone, 0, 2);
		world.setBlock(i + 38, j + 15, k + 41, BlocksAether.caelestia_stone, 0, 2);
		world.setBlock(i + 39, j + 15, k + 41, BlocksAether.caelestia_stone, 0, 2);
		world.setBlock(i + 40, j + 15, k + 41, BlocksAether.caelestia_stone, 0, 2);
		world.setBlock(i + 41, j + 15, k + 41, BlocksAether.caelestia_stone, 0, 2);
		world.setBlock(i + 42, j + 15, k + 41, BlocksAether.caelestia_stone, 0, 2);
		world.setBlock(i + 43, j + 15, k + 41, BlocksAether.caelestia_stone, 0, 2);
		world.setBlock(i + 44, j + 15, k + 41, BlocksAether.caelestia_stone, 0, 2);
		world.setBlock(i + 45, j + 15, k + 41, BlocksAether.caelestia_stone, 0, 2);
		world.setBlock(i + 46, j + 15, k + 41, BlocksAether.caelestia_stone, 0, 2);
		world.setBlock(i + 47, j + 15, k + 41, BlocksAether.caelestia_stone, 0, 2);
		world.setBlock(i + 48, j + 15, k + 41, BlocksAether.caelestia_stone, 0, 2);
		world.setBlock(i + 49, j + 15, k + 41, BlocksAether.caelestia_stone, 0, 2);
		world.setBlock(i + 50, j + 15, k + 41, BlocksAether.caelestia_stone, 0, 2);
		world.setBlock(i + 51, j + 15, k + 41, BlocksAether.caelestia_stone, 0, 2);
		world.setBlock(i + 28, j + 15, k + 42, BlocksAether.caelestia_stone, 0, 2);
		world.setBlock(i + 29, j + 15, k + 42, BlocksAether.caelestia_stone, 0, 2);
		world.setBlock(i + 30, j + 15, k + 42, BlocksAether.caelestia_stone, 0, 2);
		world.setBlock(i + 31, j + 15, k + 42, BlocksAether.caelestia_stone, 0, 2);
		world.setBlock(i + 32, j + 15, k + 42, BlocksAether.caelestia_stone, 0, 2);
		world.setBlock(i + 33, j + 15, k + 42, BlocksAether.caelestia_stone, 0, 2);
		world.setBlock(i + 34, j + 15, k + 42, BlocksAether.caelestia_stone, 0, 2);
		world.setBlock(i + 35, j + 15, k + 42, BlocksAether.caelestia_stone, 0, 2);
		world.setBlock(i + 36, j + 15, k + 42, BlocksAether.caelestia_stone, 0, 2);
		world.setBlock(i + 37, j + 15, k + 42, BlocksAether.caelestia_stone, 0, 2);
		world.setBlock(i + 38, j + 15, k + 42, BlocksAether.caelestia_stone, 0, 2);
		world.setBlock(i + 39, j + 15, k + 42, BlocksAether.caelestia_stone, 0, 2);
		world.setBlock(i + 40, j + 15, k + 42, BlocksAether.caelestia_stone, 0, 2);
		world.setBlock(i + 41, j + 15, k + 42, BlocksAether.caelestia_stone, 0, 2);
		world.setBlock(i + 42, j + 15, k + 42, BlocksAether.caelestia_stone, 0, 2);
		world.setBlock(i + 43, j + 15, k + 42, BlocksAether.caelestia_stone, 0, 2);
		world.setBlock(i + 44, j + 15, k + 42, BlocksAether.caelestia_stone, 0, 2);
		world.setBlock(i + 45, j + 15, k + 42, BlocksAether.caelestia_stone, 0, 2);
		world.setBlock(i + 46, j + 15, k + 42, BlocksAether.caelestia_stone, 0, 2);
		world.setBlock(i + 47, j + 15, k + 42, BlocksAether.caelestia_stone, 0, 2);
		world.setBlock(i + 48, j + 15, k + 42, BlocksAether.caelestia_stone, 0, 2);
		world.setBlock(i + 49, j + 15, k + 42, BlocksAether.caelestia_stone, 0, 2);
		world.setBlock(i + 50, j + 15, k + 42, BlocksAether.caelestia_stone, 0, 2);
		world.setBlock(i + 29, j + 15, k + 43, BlocksAether.caelestia_stone, 0, 2);
		world.setBlock(i + 30, j + 15, k + 43, BlocksAether.caelestia_stone, 0, 2);
		world.setBlock(i + 31, j + 15, k + 43, BlocksAether.caelestia_stone, 0, 2);
		world.setBlock(i + 32, j + 15, k + 43, BlocksAether.caelestia_stone, 0, 2);
		world.setBlock(i + 33, j + 15, k + 43, BlocksAether.caelestia_stone, 0, 2);
		world.setBlock(i + 34, j + 15, k + 43, BlocksAether.caelestia_stone, 0, 2);
		world.setBlock(i + 35, j + 15, k + 43, BlocksAether.caelestia_stone, 0, 2);
		world.setBlock(i + 36, j + 15, k + 43, BlocksAether.caelestia_stone, 0, 2);
		world.setBlock(i + 37, j + 15, k + 43, BlocksAether.caelestia_stone, 0, 2);
		world.setBlock(i + 38, j + 15, k + 43, BlocksAether.caelestia_stone, 0, 2);
		world.setBlock(i + 39, j + 15, k + 43, BlocksAether.caelestia_stone, 0, 2);
		world.setBlock(i + 40, j + 15, k + 43, BlocksAether.caelestia_stone, 0, 2);
		world.setBlock(i + 41, j + 15, k + 43, BlocksAether.caelestia_stone, 0, 2);
		world.setBlock(i + 42, j + 15, k + 43, BlocksAether.caelestia_stone, 0, 2);
		world.setBlock(i + 43, j + 15, k + 43, BlocksAether.caelestia_stone, 0, 2);
		world.setBlock(i + 44, j + 15, k + 43, BlocksAether.caelestia_stone, 0, 2);
		world.setBlock(i + 45, j + 15, k + 43, BlocksAether.caelestia_stone, 0, 2);
		world.setBlock(i + 46, j + 15, k + 43, BlocksAether.caelestia_stone, 0, 2);
		world.setBlock(i + 47, j + 15, k + 43, BlocksAether.caelestia_stone, 0, 2);
		world.setBlock(i + 48, j + 15, k + 43, BlocksAether.caelestia_stone, 0, 2);
		world.setBlock(i + 49, j + 15, k + 43, BlocksAether.caelestia_stone, 0, 2);
		world.setBlock(i + 30, j + 15, k + 44, BlocksAether.caelestia_stone, 0, 2);
		world.setBlock(i + 31, j + 15, k + 44, BlocksAether.caelestia_stone, 0, 2);
		world.setBlock(i + 32, j + 15, k + 44, BlocksAether.caelestia_stone, 0, 2);
		world.setBlock(i + 33, j + 15, k + 44, BlocksAether.caelestia_stone, 0, 2);
		world.setBlock(i + 34, j + 15, k + 44, BlocksAether.caelestia_stone, 0, 2);
		world.setBlock(i + 35, j + 15, k + 44, BlocksAether.caelestia_stone, 0, 2);
		world.setBlock(i + 36, j + 15, k + 44, BlocksAether.caelestia_stone, 0, 2);
		world.setBlock(i + 37, j + 15, k + 44, BlocksAether.caelestia_stone, 0, 2);
		world.setBlock(i + 38, j + 15, k + 44, BlocksAether.caelestia_stone, 0, 2);
		world.setBlock(i + 39, j + 15, k + 44, BlocksAether.caelestia_stone, 0, 2);
		world.setBlock(i + 40, j + 15, k + 44, BlocksAether.caelestia_stone, 0, 2);
		world.setBlock(i + 41, j + 15, k + 44, BlocksAether.caelestia_stone, 0, 2);
		world.setBlock(i + 42, j + 15, k + 44, BlocksAether.caelestia_stone, 0, 2);
		world.setBlock(i + 43, j + 15, k + 44, BlocksAether.caelestia_stone, 0, 2);
		world.setBlock(i + 44, j + 15, k + 44, BlocksAether.caelestia_stone, 0, 2);
		world.setBlock(i + 45, j + 15, k + 44, BlocksAether.caelestia_stone, 0, 2);
		world.setBlock(i + 46, j + 15, k + 44, BlocksAether.caelestia_stone, 0, 2);
		world.setBlock(i + 47, j + 15, k + 44, BlocksAether.caelestia_stone, 0, 2);
		world.setBlock(i + 48, j + 15, k + 44, BlocksAether.caelestia_stone, 0, 2);
		world.setBlock(i + 31, j + 15, k + 45, BlocksAether.caelestia_stone, 0, 2);
		world.setBlock(i + 32, j + 15, k + 45, BlocksAether.caelestia_stone, 0, 2);
		world.setBlock(i + 33, j + 15, k + 45, BlocksAether.caelestia_stone, 0, 2);
		world.setBlock(i + 34, j + 15, k + 45, BlocksAether.caelestia_stone, 0, 2);
		world.setBlock(i + 35, j + 15, k + 45, BlocksAether.caelestia_stone, 0, 2);
		world.setBlock(i + 36, j + 15, k + 45, BlocksAether.caelestia_stone, 0, 2);
		world.setBlock(i + 37, j + 15, k + 45, BlocksAether.caelestia_stone, 0, 2);
		world.setBlock(i + 38, j + 15, k + 45, BlocksAether.caelestia_stone, 0, 2);
		world.setBlock(i + 39, j + 15, k + 45, BlocksAether.caelestia_stone, 0, 2);
		world.setBlock(i + 40, j + 15, k + 45, BlocksAether.caelestia_stone, 0, 2);
		world.setBlock(i + 41, j + 15, k + 45, BlocksAether.caelestia_stone, 0, 2);
		world.setBlock(i + 42, j + 15, k + 45, BlocksAether.caelestia_stone, 0, 2);
		world.setBlock(i + 43, j + 15, k + 45, BlocksAether.caelestia_stone, 0, 2);
		world.setBlock(i + 44, j + 15, k + 45, BlocksAether.caelestia_stone, 0, 2);
		world.setBlock(i + 45, j + 15, k + 45, BlocksAether.caelestia_stone, 0, 2);
		world.setBlock(i + 46, j + 15, k + 45, BlocksAether.caelestia_stone, 0, 2);
		world.setBlock(i + 47, j + 15, k + 45, BlocksAether.caelestia_stone, 0, 2);
		world.setBlock(i + 32, j + 15, k + 46, BlocksAether.caelestia_stone, 0, 2);
		world.setBlock(i + 33, j + 15, k + 46, BlocksAether.caelestia_stone, 0, 2);
		world.setBlock(i + 34, j + 15, k + 46, BlocksAether.caelestia_stone, 0, 2);
		world.setBlock(i + 35, j + 15, k + 46, BlocksAether.caelestia_stone, 0, 2);
		world.setBlock(i + 36, j + 15, k + 46, BlocksAether.caelestia_stone, 0, 2);
		world.setBlock(i + 37, j + 15, k + 46, BlocksAether.caelestia_stone, 0, 2);
		world.setBlock(i + 38, j + 15, k + 46, BlocksAether.caelestia_stone, 0, 2);
		world.setBlock(i + 39, j + 15, k + 46, BlocksAether.caelestia_stone, 0, 2);
		world.setBlock(i + 40, j + 15, k + 46, BlocksAether.caelestia_stone, 0, 2);
		world.setBlock(i + 41, j + 15, k + 46, BlocksAether.caelestia_stone, 0, 2);
		world.setBlock(i + 42, j + 15, k + 46, BlocksAether.caelestia_stone, 0, 2);
		world.setBlock(i + 43, j + 15, k + 46, BlocksAether.caelestia_stone, 0, 2);
		world.setBlock(i + 44, j + 15, k + 46, BlocksAether.caelestia_stone, 0, 2);
		world.setBlock(i + 45, j + 15, k + 46, BlocksAether.caelestia_stone, 0, 2);
		world.setBlock(i + 46, j + 15, k + 46, BlocksAether.caelestia_stone, 0, 2);
		world.setBlock(i + 33, j + 15, k + 47, BlocksAether.caelestia_stone, 0, 2);
		world.setBlock(i + 34, j + 15, k + 47, BlocksAether.caelestia_stone, 0, 2);
		world.setBlock(i + 35, j + 15, k + 47, BlocksAether.caelestia_stone, 0, 2);
		world.setBlock(i + 36, j + 15, k + 47, BlocksAether.caelestia_stone, 0, 2);
		world.setBlock(i + 37, j + 15, k + 47, BlocksAether.caelestia_stone, 0, 2);
		world.setBlock(i + 38, j + 15, k + 47, BlocksAether.caelestia_stone, 0, 2);
		world.setBlock(i + 39, j + 15, k + 47, BlocksAether.caelestia_stone, 0, 2);
		world.setBlock(i + 40, j + 15, k + 47, BlocksAether.caelestia_stone, 0, 2);
		world.setBlock(i + 41, j + 15, k + 47, BlocksAether.caelestia_stone, 0, 2);
		world.setBlock(i + 42, j + 15, k + 47, BlocksAether.caelestia_stone, 0, 2);
		world.setBlock(i + 43, j + 15, k + 47, BlocksAether.caelestia_stone, 0, 2);
		world.setBlock(i + 44, j + 15, k + 47, BlocksAether.caelestia_stone, 0, 2);
		world.setBlock(i + 45, j + 15, k + 47, BlocksAether.caelestia_stone, 0, 2);
		world.setBlock(i + 34, j + 15, k + 48, BlocksAether.caelestia_stone, 0, 2);
		world.setBlock(i + 35, j + 15, k + 48, BlocksAether.caelestia_stone, 0, 2);
		world.setBlock(i + 36, j + 15, k + 48, BlocksAether.caelestia_stone, 0, 2);
		world.setBlock(i + 37, j + 15, k + 48, BlocksAether.caelestia_stone, 0, 2);
		world.setBlock(i + 38, j + 15, k + 48, BlocksAether.caelestia_stone, 0, 2);
		world.setBlock(i + 39, j + 15, k + 48, BlocksAether.caelestia_stone, 0, 2);
		world.setBlock(i + 40, j + 15, k + 48, BlocksAether.caelestia_stone, 0, 2);
		world.setBlock(i + 41, j + 15, k + 48, BlocksAether.caelestia_stone, 0, 2);
		world.setBlock(i + 42, j + 15, k + 48, BlocksAether.caelestia_stone, 0, 2);
		world.setBlock(i + 43, j + 15, k + 48, BlocksAether.caelestia_stone, 0, 2);
		world.setBlock(i + 44, j + 15, k + 48, BlocksAether.caelestia_stone, 0, 2);
		world.setBlock(i + 35, j + 15, k + 49, BlocksAether.caelestia_stone, 0, 2);
		world.setBlock(i + 36, j + 15, k + 49, BlocksAether.caelestia_stone, 0, 2);
		world.setBlock(i + 37, j + 15, k + 49, BlocksAether.caelestia_stone, 0, 2);
		world.setBlock(i + 38, j + 15, k + 49, BlocksAether.caelestia_stone, 0, 2);
		world.setBlock(i + 39, j + 15, k + 49, BlocksAether.caelestia_stone, 0, 2);
		world.setBlock(i + 40, j + 15, k + 49, BlocksAether.caelestia_stone, 0, 2);
		world.setBlock(i + 41, j + 15, k + 49, BlocksAether.caelestia_stone, 0, 2);
		world.setBlock(i + 42, j + 15, k + 49, BlocksAether.caelestia_stone, 0, 2);
		world.setBlock(i + 43, j + 15, k + 49, BlocksAether.caelestia_stone, 0, 2);
		world.setBlock(i + 36, j + 15, k + 50, BlocksAether.caelestia_stone, 0, 2);
		world.setBlock(i + 37, j + 15, k + 50, BlocksAether.caelestia_stone, 0, 2);
		world.setBlock(i + 38, j + 15, k + 50, BlocksAether.caelestia_stone, 0, 2);
		world.setBlock(i + 39, j + 15, k + 50, BlocksAether.caelestia_stone, 0, 2);
		world.setBlock(i + 40, j + 15, k + 50, BlocksAether.caelestia_stone, 0, 2);
		world.setBlock(i + 41, j + 15, k + 50, BlocksAether.caelestia_stone, 0, 2);
		world.setBlock(i + 42, j + 15, k + 50, BlocksAether.caelestia_stone, 0, 2);
		world.setBlock(i + 37, j + 15, k + 51, BlocksAether.caelestia_stone, 0, 2);
		world.setBlock(i + 38, j + 15, k + 51, BlocksAether.caelestia_stone, 0, 2);
		world.setBlock(i + 39, j + 15, k + 51, BlocksAether.caelestia_stone, 0, 2);
		world.setBlock(i + 40, j + 15, k + 51, BlocksAether.caelestia_stone, 0, 2);
		world.setBlock(i + 41, j + 15, k + 51, BlocksAether.caelestia_stone, 0, 2);
		world.setBlock(i + 38, j + 15, k + 52, BlocksAether.caelestia_stone, 0, 2);
		world.setBlock(i + 39, j + 15, k + 52, BlocksAether.caelestia_stone, 0, 2);
		world.setBlock(i + 40, j + 15, k + 52, BlocksAether.caelestia_stone, 0, 2);
		world.setBlock(i + 39, j + 15, k + 53, BlocksAether.caelestia_stone, 0, 2);
		world.setBlock(i + 39, j + 16, k + 22, BlocksAether.caelestia_stone, 0, 2);
		world.setBlock(i + 38, j + 16, k + 23, BlocksAether.caelestia_stone, 0, 2);
		world.setBlock(i + 39, j + 16, k + 23, BlocksAether.caelestia_stone, 0, 2);
		world.setBlock(i + 40, j + 16, k + 23, BlocksAether.caelestia_stone, 0, 2);
		world.setBlock(i + 37, j + 16, k + 24, BlocksAether.caelestia_stone, 0, 2);
		world.setBlock(i + 38, j + 16, k + 24, BlocksAether.caelestia_stone, 0, 2);
		world.setBlock(i + 39, j + 16, k + 24, BlocksAether.caelestia_stone, 0, 2);
		world.setBlock(i + 40, j + 16, k + 24, BlocksAether.caelestia_stone, 0, 2);
		world.setBlock(i + 41, j + 16, k + 24, BlocksAether.caelestia_stone, 0, 2);
		world.setBlock(i + 36, j + 16, k + 25, BlocksAether.caelestia_stone, 0, 2);
		world.setBlock(i + 37, j + 16, k + 25, BlocksAether.caelestia_stone, 0, 2);
		world.setBlock(i + 38, j + 16, k + 25, BlocksAether.caelestia_stone, 0, 2);
		world.setBlock(i + 39, j + 16, k + 25, BlocksAether.caelestia_stone, 0, 2);
		world.setBlock(i + 40, j + 16, k + 25, BlocksAether.caelestia_stone, 0, 2);
		world.setBlock(i + 41, j + 16, k + 25, BlocksAether.caelestia_stone, 0, 2);
		world.setBlock(i + 42, j + 16, k + 25, BlocksAether.caelestia_stone, 0, 2);
		world.setBlock(i + 35, j + 16, k + 26, BlocksAether.caelestia_stone, 0, 2);
		world.setBlock(i + 36, j + 16, k + 26, BlocksAether.caelestia_stone, 0, 2);
		world.setBlock(i + 37, j + 16, k + 26, BlocksAether.caelestia_stone, 0, 2);
		world.setBlock(i + 38, j + 16, k + 26, BlocksAether.caelestia_stone, 0, 2);
		world.setBlock(i + 39, j + 16, k + 26, BlocksAether.caelestia_stone, 0, 2);
		world.setBlock(i + 40, j + 16, k + 26, BlocksAether.caelestia_stone, 0, 2);
		world.setBlock(i + 41, j + 16, k + 26, BlocksAether.caelestia_stone, 0, 2);
		world.setBlock(i + 42, j + 16, k + 26, BlocksAether.caelestia_stone, 0, 2);
		world.setBlock(i + 43, j + 16, k + 26, BlocksAether.caelestia_stone, 0, 2);
		world.setBlock(i + 34, j + 16, k + 27, BlocksAether.caelestia_stone, 0, 2);
		world.setBlock(i + 35, j + 16, k + 27, BlocksAether.caelestia_stone, 0, 2);
		world.setBlock(i + 36, j + 16, k + 27, BlocksAether.caelestia_stone, 0, 2);
		world.setBlock(i + 37, j + 16, k + 27, BlocksAether.caelestia_stone, 0, 2);
		world.setBlock(i + 38, j + 16, k + 27, BlocksAether.caelestia_stone, 0, 2);
		world.setBlock(i + 39, j + 16, k + 27, BlocksAether.caelestia_stone, 0, 2);
		world.setBlock(i + 40, j + 16, k + 27, BlocksAether.caelestia_stone, 0, 2);
		world.setBlock(i + 41, j + 16, k + 27, BlocksAether.caelestia_stone, 0, 2);
		world.setBlock(i + 42, j + 16, k + 27, BlocksAether.caelestia_stone, 0, 2);
		world.setBlock(i + 43, j + 16, k + 27, BlocksAether.caelestia_stone, 0, 2);
		world.setBlock(i + 44, j + 16, k + 27, BlocksAether.caelestia_stone, 0, 2);
		world.setBlock(i + 33, j + 16, k + 28, BlocksAether.caelestia_stone, 0, 2);
		world.setBlock(i + 34, j + 16, k + 28, BlocksAether.caelestia_stone, 0, 2);
		world.setBlock(i + 35, j + 16, k + 28, BlocksAether.caelestia_stone, 0, 2);
		world.setBlock(i + 36, j + 16, k + 28, BlocksAether.caelestia_stone, 0, 2);
		world.setBlock(i + 37, j + 16, k + 28, BlocksAether.caelestia_stone, 0, 2);
		world.setBlock(i + 38, j + 16, k + 28, BlocksAether.caelestia_stone, 0, 2);
		world.setBlock(i + 39, j + 16, k + 28, BlocksAether.caelestia_stone, 0, 2);
		world.setBlock(i + 40, j + 16, k + 28, BlocksAether.caelestia_stone, 0, 2);
		world.setBlock(i + 41, j + 16, k + 28, BlocksAether.caelestia_stone, 0, 2);
		world.setBlock(i + 42, j + 16, k + 28, BlocksAether.caelestia_stone, 0, 2);
		world.setBlock(i + 43, j + 16, k + 28, BlocksAether.caelestia_stone, 0, 2);
		world.setBlock(i + 44, j + 16, k + 28, BlocksAether.caelestia_stone, 0, 2);
		world.setBlock(i + 45, j + 16, k + 28, BlocksAether.caelestia_stone, 0, 2);
		world.setBlock(i + 32, j + 16, k + 29, BlocksAether.caelestia_stone, 0, 2);
		world.setBlock(i + 33, j + 16, k + 29, BlocksAether.caelestia_stone, 0, 2);
		world.setBlock(i + 34, j + 16, k + 29, BlocksAether.caelestia_stone, 0, 2);
		world.setBlock(i + 35, j + 16, k + 29, BlocksAether.caelestia_stone, 0, 2);
		world.setBlock(i + 36, j + 16, k + 29, BlocksAether.caelestia_stone, 0, 2);
		world.setBlock(i + 37, j + 16, k + 29, BlocksAether.caelestia_stone, 0, 2);
		world.setBlock(i + 38, j + 16, k + 29, BlocksAether.caelestia_stone, 0, 2);
		world.setBlock(i + 39, j + 16, k + 29, BlocksAether.caelestia_stone, 0, 2);
		world.setBlock(i + 40, j + 16, k + 29, BlocksAether.caelestia_stone, 0, 2);
		world.setBlock(i + 41, j + 16, k + 29, BlocksAether.caelestia_stone, 0, 2);
		world.setBlock(i + 42, j + 16, k + 29, BlocksAether.caelestia_stone, 0, 2);
		world.setBlock(i + 43, j + 16, k + 29, BlocksAether.caelestia_stone, 0, 2);
		world.setBlock(i + 44, j + 16, k + 29, BlocksAether.caelestia_stone, 0, 2);
		world.setBlock(i + 45, j + 16, k + 29, BlocksAether.caelestia_stone, 0, 2);
		world.setBlock(i + 46, j + 16, k + 29, BlocksAether.caelestia_stone, 0, 2);
		world.setBlock(i + 31, j + 16, k + 30, BlocksAether.caelestia_stone, 0, 2);
		world.setBlock(i + 32, j + 16, k + 30, BlocksAether.caelestia_stone, 0, 2);
		world.setBlock(i + 33, j + 16, k + 30, BlocksAether.caelestia_stone, 0, 2);
		world.setBlock(i + 34, j + 16, k + 30, BlocksAether.caelestia_stone, 0, 2);
		world.setBlock(i + 35, j + 16, k + 30, BlocksAether.caelestia_stone, 0, 2);
		world.setBlock(i + 36, j + 16, k + 30, BlocksAether.caelestia_stone, 0, 2);
		world.setBlock(i + 37, j + 16, k + 30, BlocksAether.caelestia_stone, 0, 2);
		world.setBlock(i + 38, j + 16, k + 30, BlocksAether.caelestia_stone, 0, 2);
		world.setBlock(i + 39, j + 16, k + 30, BlocksAether.caelestia_stone, 0, 2);
		world.setBlock(i + 40, j + 16, k + 30, BlocksAether.caelestia_stone, 0, 2);
		world.setBlock(i + 41, j + 16, k + 30, BlocksAether.caelestia_stone, 0, 2);
		world.setBlock(i + 42, j + 16, k + 30, BlocksAether.caelestia_stone, 0, 2);
		world.setBlock(i + 43, j + 16, k + 30, BlocksAether.caelestia_stone, 0, 2);
		world.setBlock(i + 44, j + 16, k + 30, BlocksAether.caelestia_stone, 0, 2);
		world.setBlock(i + 45, j + 16, k + 30, BlocksAether.caelestia_stone, 0, 2);
		world.setBlock(i + 46, j + 16, k + 30, BlocksAether.caelestia_stone, 0, 2);
		world.setBlock(i + 47, j + 16, k + 30, BlocksAether.caelestia_stone, 0, 2);
		world.setBlock(i + 30, j + 16, k + 31, BlocksAether.caelestia_stone, 0, 2);
		world.setBlock(i + 31, j + 16, k + 31, BlocksAether.caelestia_stone, 0, 2);
		world.setBlock(i + 32, j + 16, k + 31, BlocksAether.caelestia_stone, 0, 2);
		world.setBlock(i + 33, j + 16, k + 31, BlocksAether.caelestia_stone, 0, 2);
		world.setBlock(i + 34, j + 16, k + 31, BlocksAether.caelestia_stone, 0, 2);
		world.setBlock(i + 35, j + 16, k + 31, BlocksAether.caelestia_stone, 0, 2);
		world.setBlock(i + 36, j + 16, k + 31, BlocksAether.caelestia_stone, 0, 2);
		world.setBlock(i + 37, j + 16, k + 31, BlocksAether.caelestia_stone, 0, 2);
		world.setBlock(i + 38, j + 16, k + 31, BlocksAether.caelestia_stone, 0, 2);
		world.setBlock(i + 39, j + 16, k + 31, BlocksAether.caelestia_stone, 0, 2);
		world.setBlock(i + 40, j + 16, k + 31, BlocksAether.caelestia_stone, 0, 2);
		world.setBlock(i + 41, j + 16, k + 31, BlocksAether.caelestia_stone, 0, 2);
		world.setBlock(i + 42, j + 16, k + 31, BlocksAether.caelestia_stone, 0, 2);
		world.setBlock(i + 43, j + 16, k + 31, BlocksAether.caelestia_stone, 0, 2);
		world.setBlock(i + 44, j + 16, k + 31, BlocksAether.caelestia_stone, 0, 2);
		world.setBlock(i + 45, j + 16, k + 31, BlocksAether.caelestia_stone, 0, 2);
		world.setBlock(i + 46, j + 16, k + 31, BlocksAether.caelestia_stone, 0, 2);
		world.setBlock(i + 47, j + 16, k + 31, BlocksAether.caelestia_stone, 0, 2);
		world.setBlock(i + 48, j + 16, k + 31, BlocksAether.caelestia_stone, 0, 2);
		world.setBlock(i + 29, j + 16, k + 32, BlocksAether.caelestia_stone, 0, 2);
		world.setBlock(i + 30, j + 16, k + 32, BlocksAether.caelestia_stone, 0, 2);
		world.setBlock(i + 31, j + 16, k + 32, BlocksAether.caelestia_stone, 0, 2);
		world.setBlock(i + 32, j + 16, k + 32, BlocksAether.caelestia_stone, 0, 2);
		world.setBlock(i + 33, j + 16, k + 32, BlocksAether.caelestia_stone, 0, 2);
		world.setBlock(i + 34, j + 16, k + 32, BlocksAether.caelestia_stone, 0, 2);
		world.setBlock(i + 35, j + 16, k + 32, BlocksAether.caelestia_stone, 0, 2);
		world.setBlock(i + 36, j + 16, k + 32, BlocksAether.caelestia_stone, 0, 2);
		world.setBlock(i + 37, j + 16, k + 32, BlocksAether.caelestia_stone, 0, 2);
		world.setBlock(i + 38, j + 16, k + 32, BlocksAether.caelestia_stone, 0, 2);
		world.setBlock(i + 39, j + 16, k + 32, BlocksAether.caelestia_stone, 0, 2);
		world.setBlock(i + 40, j + 16, k + 32, BlocksAether.caelestia_stone, 0, 2);
		world.setBlock(i + 41, j + 16, k + 32, BlocksAether.caelestia_stone, 0, 2);
		world.setBlock(i + 42, j + 16, k + 32, BlocksAether.caelestia_stone, 0, 2);
		world.setBlock(i + 43, j + 16, k + 32, BlocksAether.caelestia_stone, 0, 2);
		world.setBlock(i + 44, j + 16, k + 32, BlocksAether.caelestia_stone, 0, 2);
		world.setBlock(i + 45, j + 16, k + 32, BlocksAether.caelestia_stone, 0, 2);
		world.setBlock(i + 46, j + 16, k + 32, BlocksAether.caelestia_stone, 0, 2);
		world.setBlock(i + 47, j + 16, k + 32, BlocksAether.caelestia_stone, 0, 2);
		world.setBlock(i + 48, j + 16, k + 32, BlocksAether.caelestia_stone, 0, 2);
		world.setBlock(i + 49, j + 16, k + 32, BlocksAether.caelestia_stone, 0, 2);
		world.setBlock(i + 28, j + 16, k + 33, BlocksAether.caelestia_stone, 0, 2);
		world.setBlock(i + 29, j + 16, k + 33, BlocksAether.caelestia_stone, 0, 2);
		world.setBlock(i + 30, j + 16, k + 33, BlocksAether.caelestia_stone, 0, 2);
		world.setBlock(i + 31, j + 16, k + 33, BlocksAether.caelestia_stone, 0, 2);
		world.setBlock(i + 32, j + 16, k + 33, BlocksAether.caelestia_stone, 0, 2);
		world.setBlock(i + 33, j + 16, k + 33, BlocksAether.caelestia_stone, 0, 2);
		world.setBlock(i + 34, j + 16, k + 33, BlocksAether.caelestia_stone, 0, 2);
		world.setBlock(i + 35, j + 16, k + 33, BlocksAether.caelestia_stone, 0, 2);
		world.setBlock(i + 36, j + 16, k + 33, BlocksAether.caelestia_stone, 0, 2);
		world.setBlock(i + 37, j + 16, k + 33, BlocksAether.caelestia_stone, 0, 2);
		world.setBlock(i + 38, j + 16, k + 33, BlocksAether.caelestia_stone, 0, 2);
		world.setBlock(i + 39, j + 16, k + 33, BlocksAether.caelestia_stone, 0, 2);
		world.setBlock(i + 40, j + 16, k + 33, BlocksAether.caelestia_stone, 0, 2);
		world.setBlock(i + 41, j + 16, k + 33, BlocksAether.caelestia_stone, 0, 2);
		world.setBlock(i + 42, j + 16, k + 33, BlocksAether.caelestia_stone, 0, 2);
		world.setBlock(i + 43, j + 16, k + 33, BlocksAether.caelestia_stone, 0, 2);
		world.setBlock(i + 44, j + 16, k + 33, BlocksAether.caelestia_stone, 0, 2);
		world.setBlock(i + 45, j + 16, k + 33, BlocksAether.caelestia_stone, 0, 2);
		world.setBlock(i + 46, j + 16, k + 33, BlocksAether.caelestia_stone, 0, 2);
		world.setBlock(i + 47, j + 16, k + 33, BlocksAether.caelestia_stone, 0, 2);
		world.setBlock(i + 48, j + 16, k + 33, BlocksAether.caelestia_stone, 0, 2);
		world.setBlock(i + 49, j + 16, k + 33, BlocksAether.caelestia_stone, 0, 2);
		world.setBlock(i + 50, j + 16, k + 33, BlocksAether.caelestia_stone, 0, 2);
		world.setBlock(i + 27, j + 16, k + 34, BlocksAether.caelestia_stone, 0, 2);
		world.setBlock(i + 28, j + 16, k + 34, BlocksAether.caelestia_stone, 0, 2);
		world.setBlock(i + 29, j + 16, k + 34, BlocksAether.caelestia_stone, 0, 2);
		world.setBlock(i + 30, j + 16, k + 34, BlocksAether.caelestia_stone, 0, 2);
		world.setBlock(i + 31, j + 16, k + 34, BlocksAether.caelestia_stone, 0, 2);
		world.setBlock(i + 32, j + 16, k + 34, BlocksAether.caelestia_stone, 0, 2);
		world.setBlock(i + 33, j + 16, k + 34, BlocksAether.caelestia_stone, 0, 2);
		world.setBlock(i + 34, j + 16, k + 34, BlocksAether.caelestia_stone, 0, 2);
		world.setBlock(i + 35, j + 16, k + 34, BlocksAether.caelestia_stone, 0, 2);
		world.setBlock(i + 36, j + 16, k + 34, BlocksAether.caelestia_stone, 0, 2);
		world.setBlock(i + 37, j + 16, k + 34, BlocksAether.caelestia_stone, 0, 2);
		world.setBlock(i + 38, j + 16, k + 34, BlocksAether.caelestia_stone, 0, 2);
		world.setBlock(i + 39, j + 16, k + 34, BlocksAether.caelestia_stone, 0, 2);
		world.setBlock(i + 40, j + 16, k + 34, BlocksAether.caelestia_stone, 0, 2);
		world.setBlock(i + 41, j + 16, k + 34, BlocksAether.caelestia_stone, 0, 2);
		world.setBlock(i + 42, j + 16, k + 34, BlocksAether.caelestia_stone, 0, 2);
		world.setBlock(i + 43, j + 16, k + 34, BlocksAether.caelestia_stone, 0, 2);
		world.setBlock(i + 44, j + 16, k + 34, BlocksAether.caelestia_stone, 0, 2);
		world.setBlock(i + 45, j + 16, k + 34, BlocksAether.caelestia_stone, 0, 2);
		world.setBlock(i + 46, j + 16, k + 34, BlocksAether.caelestia_stone, 0, 2);
		world.setBlock(i + 47, j + 16, k + 34, BlocksAether.caelestia_stone, 0, 2);
		world.setBlock(i + 48, j + 16, k + 34, BlocksAether.caelestia_stone, 0, 2);
		world.setBlock(i + 49, j + 16, k + 34, BlocksAether.caelestia_stone, 0, 2);
		world.setBlock(i + 50, j + 16, k + 34, BlocksAether.caelestia_stone, 0, 2);
		world.setBlock(i + 51, j + 16, k + 34, BlocksAether.caelestia_stone, 0, 2);
		world.setBlock(i + 26, j + 16, k + 35, BlocksAether.caelestia_stone, 0, 2);
		world.setBlock(i + 27, j + 16, k + 35, BlocksAether.caelestia_stone, 0, 2);
		world.setBlock(i + 28, j + 16, k + 35, BlocksAether.caelestia_stone, 0, 2);
		world.setBlock(i + 29, j + 16, k + 35, BlocksAether.caelestia_stone, 0, 2);
		world.setBlock(i + 30, j + 16, k + 35, BlocksAether.caelestia_stone, 0, 2);
		world.setBlock(i + 31, j + 16, k + 35, BlocksAether.caelestia_stone, 0, 2);
		world.setBlock(i + 32, j + 16, k + 35, BlocksAether.caelestia_stone, 0, 2);
		world.setBlock(i + 33, j + 16, k + 35, BlocksAether.caelestia_stone, 0, 2);
		world.setBlock(i + 34, j + 16, k + 35, BlocksAether.caelestia_stone, 0, 2);
		world.setBlock(i + 35, j + 16, k + 35, BlocksAether.caelestia_stone, 0, 2);
		world.setBlock(i + 36, j + 16, k + 35, BlocksAether.caelestia_stone, 0, 2);
		world.setBlock(i + 37, j + 16, k + 35, BlocksAether.caelestia_stone, 0, 2);
		world.setBlock(i + 38, j + 16, k + 35, BlocksAether.caelestia_stone, 0, 2);
		world.setBlock(i + 39, j + 16, k + 35, BlocksAether.caelestia_stone, 0, 2);
		world.setBlock(i + 40, j + 16, k + 35, BlocksAether.caelestia_stone, 0, 2);
		world.setBlock(i + 41, j + 16, k + 35, BlocksAether.caelestia_stone, 0, 2);
		world.setBlock(i + 42, j + 16, k + 35, BlocksAether.caelestia_stone, 0, 2);
		world.setBlock(i + 43, j + 16, k + 35, BlocksAether.caelestia_stone, 0, 2);
		world.setBlock(i + 44, j + 16, k + 35, BlocksAether.caelestia_stone, 0, 2);
		world.setBlock(i + 45, j + 16, k + 35, BlocksAether.caelestia_stone, 0, 2);
		world.setBlock(i + 46, j + 16, k + 35, BlocksAether.caelestia_stone, 0, 2);
		world.setBlock(i + 47, j + 16, k + 35, BlocksAether.caelestia_stone, 0, 2);
		world.setBlock(i + 48, j + 16, k + 35, BlocksAether.caelestia_stone, 0, 2);
		world.setBlock(i + 49, j + 16, k + 35, BlocksAether.caelestia_stone, 0, 2);
		world.setBlock(i + 50, j + 16, k + 35, BlocksAether.caelestia_stone, 0, 2);
		world.setBlock(i + 51, j + 16, k + 35, BlocksAether.caelestia_stone, 0, 2);
		world.setBlock(i + 52, j + 16, k + 35, BlocksAether.caelestia_stone, 0, 2);
		world.setBlock(i + 25, j + 16, k + 36, BlocksAether.caelestia_stone, 0, 2);
		world.setBlock(i + 26, j + 16, k + 36, BlocksAether.caelestia_stone, 0, 2);
		world.setBlock(i + 27, j + 16, k + 36, BlocksAether.caelestia_stone, 0, 2);
		world.setBlock(i + 28, j + 16, k + 36, BlocksAether.caelestia_stone, 0, 2);
		world.setBlock(i + 29, j + 16, k + 36, BlocksAether.caelestia_stone, 0, 2);
		world.setBlock(i + 30, j + 16, k + 36, BlocksAether.caelestia_stone, 0, 2);
		world.setBlock(i + 31, j + 16, k + 36, BlocksAether.caelestia_stone, 0, 2);
		world.setBlock(i + 32, j + 16, k + 36, BlocksAether.caelestia_stone, 0, 2);
		world.setBlock(i + 33, j + 16, k + 36, BlocksAether.caelestia_stone, 0, 2);
		world.setBlock(i + 34, j + 16, k + 36, BlocksAether.caelestia_stone, 0, 2);
		world.setBlock(i + 35, j + 16, k + 36, BlocksAether.caelestia_stone, 0, 2);
		world.setBlock(i + 36, j + 16, k + 36, BlocksAether.caelestia_stone, 0, 2);
		world.setBlock(i + 37, j + 16, k + 36, BlocksAether.caelestia_stone, 0, 2);
		world.setBlock(i + 38, j + 16, k + 36, BlocksAether.caelestia_stone, 0, 2);
		world.setBlock(i + 39, j + 16, k + 36, BlocksAether.caelestia_stone, 0, 2);
		world.setBlock(i + 40, j + 16, k + 36, BlocksAether.caelestia_stone, 0, 2);
		world.setBlock(i + 41, j + 16, k + 36, BlocksAether.caelestia_stone, 0, 2);
		world.setBlock(i + 42, j + 16, k + 36, BlocksAether.caelestia_stone, 0, 2);
		world.setBlock(i + 43, j + 16, k + 36, BlocksAether.caelestia_stone, 0, 2);
		world.setBlock(i + 44, j + 16, k + 36, BlocksAether.caelestia_stone, 0, 2);
		world.setBlock(i + 45, j + 16, k + 36, BlocksAether.caelestia_stone, 0, 2);
		world.setBlock(i + 46, j + 16, k + 36, BlocksAether.caelestia_stone, 0, 2);
		world.setBlock(i + 47, j + 16, k + 36, BlocksAether.caelestia_stone, 0, 2);
		world.setBlock(i + 48, j + 16, k + 36, BlocksAether.caelestia_stone, 0, 2);
		world.setBlock(i + 49, j + 16, k + 36, BlocksAether.caelestia_stone, 0, 2);
		world.setBlock(i + 50, j + 16, k + 36, BlocksAether.caelestia_stone, 0, 2);
		world.setBlock(i + 51, j + 16, k + 36, BlocksAether.caelestia_stone, 0, 2);
		world.setBlock(i + 52, j + 16, k + 36, BlocksAether.caelestia_stone, 0, 2);
		world.setBlock(i + 53, j + 16, k + 36, BlocksAether.caelestia_stone, 0, 2);
		world.setBlock(i + 24, j + 16, k + 37, BlocksAether.caelestia_stone, 0, 2);
		world.setBlock(i + 25, j + 16, k + 37, BlocksAether.caelestia_stone, 0, 2);
		world.setBlock(i + 26, j + 16, k + 37, BlocksAether.caelestia_stone, 0, 2);
		world.setBlock(i + 27, j + 16, k + 37, BlocksAether.caelestia_stone, 0, 2);
		world.setBlock(i + 28, j + 16, k + 37, BlocksAether.caelestia_stone, 0, 2);
		world.setBlock(i + 29, j + 16, k + 37, BlocksAether.caelestia_stone, 0, 2);
		world.setBlock(i + 30, j + 16, k + 37, BlocksAether.caelestia_stone, 0, 2);
		world.setBlock(i + 31, j + 16, k + 37, BlocksAether.caelestia_stone, 0, 2);
		world.setBlock(i + 32, j + 16, k + 37, BlocksAether.caelestia_stone, 0, 2);
		world.setBlock(i + 33, j + 16, k + 37, BlocksAether.caelestia_stone, 0, 2);
		world.setBlock(i + 34, j + 16, k + 37, BlocksAether.caelestia_stone, 0, 2);
		world.setBlock(i + 35, j + 16, k + 37, BlocksAether.caelestia_stone, 0, 2);
		world.setBlock(i + 36, j + 16, k + 37, BlocksAether.caelestia_stone, 0, 2);
		world.setBlock(i + 37, j + 16, k + 37, BlocksAether.caelestia_stone, 0, 2);
		world.setBlock(i + 38, j + 16, k + 37, BlocksAether.caelestia_stone, 0, 2);
		world.setBlock(i + 39, j + 16, k + 37, BlocksAether.caelestia_stone, 0, 2);
		world.setBlock(i + 40, j + 16, k + 37, BlocksAether.caelestia_stone, 0, 2);
		world.setBlock(i + 41, j + 16, k + 37, BlocksAether.caelestia_stone, 0, 2);
		world.setBlock(i + 42, j + 16, k + 37, BlocksAether.caelestia_stone, 0, 2);
		world.setBlock(i + 43, j + 16, k + 37, BlocksAether.caelestia_stone, 0, 2);
		world.setBlock(i + 44, j + 16, k + 37, BlocksAether.caelestia_stone, 0, 2);
		world.setBlock(i + 45, j + 16, k + 37, BlocksAether.caelestia_stone, 0, 2);
		world.setBlock(i + 46, j + 16, k + 37, BlocksAether.caelestia_stone, 0, 2);
		world.setBlock(i + 47, j + 16, k + 37, BlocksAether.caelestia_stone, 0, 2);
		world.setBlock(i + 48, j + 16, k + 37, BlocksAether.caelestia_stone, 0, 2);
		world.setBlock(i + 49, j + 16, k + 37, BlocksAether.caelestia_stone, 0, 2);
		world.setBlock(i + 50, j + 16, k + 37, BlocksAether.caelestia_stone, 0, 2);
		world.setBlock(i + 51, j + 16, k + 37, BlocksAether.caelestia_stone, 0, 2);
		world.setBlock(i + 52, j + 16, k + 37, BlocksAether.caelestia_stone, 0, 2);
		world.setBlock(i + 53, j + 16, k + 37, BlocksAether.caelestia_stone, 0, 2);
		world.setBlock(i + 54, j + 16, k + 37, BlocksAether.caelestia_stone, 0, 2);
		world.setBlock(i + 23, j + 16, k + 38, BlocksAether.caelestia_stone, 0, 2);
		world.setBlock(i + 24, j + 16, k + 38, BlocksAether.caelestia_stone, 0, 2);
		world.setBlock(i + 25, j + 16, k + 38, BlocksAether.caelestia_stone, 0, 2);
		world.setBlock(i + 26, j + 16, k + 38, BlocksAether.caelestia_stone, 0, 2);
		world.setBlock(i + 27, j + 16, k + 38, BlocksAether.caelestia_stone, 0, 2);
		world.setBlock(i + 28, j + 16, k + 38, BlocksAether.caelestia_stone, 0, 2);
		world.setBlock(i + 29, j + 16, k + 38, BlocksAether.caelestia_stone, 0, 2);
		world.setBlock(i + 30, j + 16, k + 38, BlocksAether.caelestia_stone, 0, 2);
		world.setBlock(i + 31, j + 16, k + 38, BlocksAether.caelestia_stone, 0, 2);
		world.setBlock(i + 32, j + 16, k + 38, BlocksAether.caelestia_stone, 0, 2);
		world.setBlock(i + 33, j + 16, k + 38, BlocksAether.caelestia_stone, 0, 2);
		world.setBlock(i + 34, j + 16, k + 38, BlocksAether.caelestia_stone, 0, 2);
		world.setBlock(i + 35, j + 16, k + 38, BlocksAether.caelestia_stone, 0, 2);
		world.setBlock(i + 36, j + 16, k + 38, BlocksAether.caelestia_stone, 0, 2);
		world.setBlock(i + 37, j + 16, k + 38, BlocksAether.caelestia_stone, 0, 2);
		world.setBlock(i + 38, j + 16, k + 38, BlocksAether.caelestia_stone, 0, 2);
		world.setBlock(i + 39, j + 16, k + 38, BlocksAether.caelestia_stone, 0, 2);
		world.setBlock(i + 40, j + 16, k + 38, BlocksAether.caelestia_stone, 0, 2);
		world.setBlock(i + 41, j + 16, k + 38, BlocksAether.caelestia_stone, 0, 2);
		world.setBlock(i + 42, j + 16, k + 38, BlocksAether.caelestia_stone, 0, 2);
		world.setBlock(i + 43, j + 16, k + 38, BlocksAether.caelestia_stone, 0, 2);
		world.setBlock(i + 44, j + 16, k + 38, BlocksAether.caelestia_stone, 0, 2);
		world.setBlock(i + 45, j + 16, k + 38, BlocksAether.caelestia_stone, 0, 2);
		world.setBlock(i + 46, j + 16, k + 38, BlocksAether.caelestia_stone, 0, 2);
		world.setBlock(i + 47, j + 16, k + 38, BlocksAether.caelestia_stone, 0, 2);
		world.setBlock(i + 48, j + 16, k + 38, BlocksAether.caelestia_stone, 0, 2);
		world.setBlock(i + 49, j + 16, k + 38, BlocksAether.caelestia_stone, 0, 2);
		world.setBlock(i + 50, j + 16, k + 38, BlocksAether.caelestia_stone, 0, 2);
		world.setBlock(i + 51, j + 16, k + 38, BlocksAether.caelestia_stone, 0, 2);
		world.setBlock(i + 52, j + 16, k + 38, BlocksAether.caelestia_stone, 0, 2);
		world.setBlock(i + 53, j + 16, k + 38, BlocksAether.caelestia_stone, 0, 2);
		world.setBlock(i + 54, j + 16, k + 38, BlocksAether.caelestia_stone, 0, 2);
		world.setBlock(i + 55, j + 16, k + 38, BlocksAether.caelestia_stone, 0, 2);
		world.setBlock(i + 24, j + 16, k + 39, BlocksAether.caelestia_stone, 0, 2);
		world.setBlock(i + 25, j + 16, k + 39, BlocksAether.caelestia_stone, 0, 2);
		world.setBlock(i + 26, j + 16, k + 39, BlocksAether.caelestia_stone, 0, 2);
		world.setBlock(i + 27, j + 16, k + 39, BlocksAether.caelestia_stone, 0, 2);
		world.setBlock(i + 28, j + 16, k + 39, BlocksAether.caelestia_stone, 0, 2);
		world.setBlock(i + 29, j + 16, k + 39, BlocksAether.caelestia_stone, 0, 2);
		world.setBlock(i + 30, j + 16, k + 39, BlocksAether.caelestia_stone, 0, 2);
		world.setBlock(i + 31, j + 16, k + 39, BlocksAether.caelestia_stone, 0, 2);
		world.setBlock(i + 32, j + 16, k + 39, BlocksAether.caelestia_stone, 0, 2);
		world.setBlock(i + 33, j + 16, k + 39, BlocksAether.caelestia_stone, 0, 2);
		world.setBlock(i + 34, j + 16, k + 39, BlocksAether.caelestia_stone, 0, 2);
		world.setBlock(i + 35, j + 16, k + 39, BlocksAether.caelestia_stone, 0, 2);
		world.setBlock(i + 36, j + 16, k + 39, BlocksAether.caelestia_stone, 0, 2);
		world.setBlock(i + 37, j + 16, k + 39, BlocksAether.caelestia_stone, 0, 2);
		world.setBlock(i + 38, j + 16, k + 39, BlocksAether.caelestia_stone, 0, 2);
		world.setBlock(i + 39, j + 16, k + 39, BlocksAether.caelestia_stone, 0, 2);
		world.setBlock(i + 40, j + 16, k + 39, BlocksAether.caelestia_stone, 0, 2);
		world.setBlock(i + 41, j + 16, k + 39, BlocksAether.caelestia_stone, 0, 2);
		world.setBlock(i + 42, j + 16, k + 39, BlocksAether.caelestia_stone, 0, 2);
		world.setBlock(i + 43, j + 16, k + 39, BlocksAether.caelestia_stone, 0, 2);
		world.setBlock(i + 44, j + 16, k + 39, BlocksAether.caelestia_stone, 0, 2);
		world.setBlock(i + 45, j + 16, k + 39, BlocksAether.caelestia_stone, 0, 2);
		world.setBlock(i + 46, j + 16, k + 39, BlocksAether.caelestia_stone, 0, 2);
		world.setBlock(i + 47, j + 16, k + 39, BlocksAether.caelestia_stone, 0, 2);
		world.setBlock(i + 48, j + 16, k + 39, BlocksAether.caelestia_stone, 0, 2);
		world.setBlock(i + 49, j + 16, k + 39, BlocksAether.caelestia_stone, 0, 2);
		world.setBlock(i + 50, j + 16, k + 39, BlocksAether.caelestia_stone, 0, 2);
		world.setBlock(i + 51, j + 16, k + 39, BlocksAether.caelestia_stone, 0, 2);
		world.setBlock(i + 52, j + 16, k + 39, BlocksAether.caelestia_stone, 0, 2);
		world.setBlock(i + 53, j + 16, k + 39, BlocksAether.caelestia_stone, 0, 2);
		world.setBlock(i + 54, j + 16, k + 39, BlocksAether.caelestia_stone, 0, 2);
		world.setBlock(i + 25, j + 16, k + 40, BlocksAether.caelestia_stone, 0, 2);
		world.setBlock(i + 26, j + 16, k + 40, BlocksAether.caelestia_stone, 0, 2);
		world.setBlock(i + 27, j + 16, k + 40, BlocksAether.caelestia_stone, 0, 2);
		world.setBlock(i + 28, j + 16, k + 40, BlocksAether.caelestia_stone, 0, 2);
		world.setBlock(i + 29, j + 16, k + 40, BlocksAether.caelestia_stone, 0, 2);
		world.setBlock(i + 30, j + 16, k + 40, BlocksAether.caelestia_stone, 0, 2);
		world.setBlock(i + 31, j + 16, k + 40, BlocksAether.caelestia_stone, 0, 2);
		world.setBlock(i + 32, j + 16, k + 40, BlocksAether.caelestia_stone, 0, 2);
		world.setBlock(i + 33, j + 16, k + 40, BlocksAether.caelestia_stone, 0, 2);
		world.setBlock(i + 34, j + 16, k + 40, BlocksAether.caelestia_stone, 0, 2);
		world.setBlock(i + 35, j + 16, k + 40, BlocksAether.caelestia_stone, 0, 2);
		world.setBlock(i + 36, j + 16, k + 40, BlocksAether.caelestia_stone, 0, 2);
		world.setBlock(i + 37, j + 16, k + 40, BlocksAether.caelestia_stone, 0, 2);
		world.setBlock(i + 38, j + 16, k + 40, BlocksAether.caelestia_stone, 0, 2);
		world.setBlock(i + 39, j + 16, k + 40, BlocksAether.caelestia_stone, 0, 2);
		world.setBlock(i + 40, j + 16, k + 40, BlocksAether.caelestia_stone, 0, 2);
		world.setBlock(i + 41, j + 16, k + 40, BlocksAether.caelestia_stone, 0, 2);
		world.setBlock(i + 42, j + 16, k + 40, BlocksAether.caelestia_stone, 0, 2);
		world.setBlock(i + 43, j + 16, k + 40, BlocksAether.caelestia_stone, 0, 2);
		world.setBlock(i + 44, j + 16, k + 40, BlocksAether.caelestia_stone, 0, 2);
		world.setBlock(i + 45, j + 16, k + 40, BlocksAether.caelestia_stone, 0, 2);
		world.setBlock(i + 46, j + 16, k + 40, BlocksAether.caelestia_stone, 0, 2);
		world.setBlock(i + 47, j + 16, k + 40, BlocksAether.caelestia_stone, 0, 2);
		world.setBlock(i + 48, j + 16, k + 40, BlocksAether.caelestia_stone, 0, 2);
		world.setBlock(i + 49, j + 16, k + 40, BlocksAether.caelestia_stone, 0, 2);
		world.setBlock(i + 50, j + 16, k + 40, BlocksAether.caelestia_stone, 0, 2);
		world.setBlock(i + 51, j + 16, k + 40, BlocksAether.caelestia_stone, 0, 2);
		world.setBlock(i + 52, j + 16, k + 40, BlocksAether.caelestia_stone, 0, 2);
		world.setBlock(i + 53, j + 16, k + 40, BlocksAether.caelestia_stone, 0, 2);
		world.setBlock(i + 26, j + 16, k + 41, BlocksAether.caelestia_stone, 0, 2);
		world.setBlock(i + 27, j + 16, k + 41, BlocksAether.caelestia_stone, 0, 2);
		world.setBlock(i + 28, j + 16, k + 41, BlocksAether.caelestia_stone, 0, 2);
		world.setBlock(i + 29, j + 16, k + 41, BlocksAether.caelestia_stone, 0, 2);
		world.setBlock(i + 30, j + 16, k + 41, BlocksAether.caelestia_stone, 0, 2);
		world.setBlock(i + 31, j + 16, k + 41, BlocksAether.caelestia_stone, 0, 2);
		world.setBlock(i + 32, j + 16, k + 41, BlocksAether.caelestia_stone, 0, 2);
		world.setBlock(i + 33, j + 16, k + 41, BlocksAether.caelestia_stone, 0, 2);
		world.setBlock(i + 34, j + 16, k + 41, BlocksAether.caelestia_stone, 0, 2);
		world.setBlock(i + 35, j + 16, k + 41, BlocksAether.caelestia_stone, 0, 2);
		world.setBlock(i + 36, j + 16, k + 41, BlocksAether.caelestia_stone, 0, 2);
		world.setBlock(i + 37, j + 16, k + 41, BlocksAether.caelestia_stone, 0, 2);
		world.setBlock(i + 38, j + 16, k + 41, BlocksAether.caelestia_stone, 0, 2);
		world.setBlock(i + 39, j + 16, k + 41, BlocksAether.caelestia_stone, 0, 2);
		world.setBlock(i + 40, j + 16, k + 41, BlocksAether.caelestia_stone, 0, 2);
		world.setBlock(i + 41, j + 16, k + 41, BlocksAether.caelestia_stone, 0, 2);
		world.setBlock(i + 42, j + 16, k + 41, BlocksAether.caelestia_stone, 0, 2);
		world.setBlock(i + 43, j + 16, k + 41, BlocksAether.caelestia_stone, 0, 2);
		world.setBlock(i + 44, j + 16, k + 41, BlocksAether.caelestia_stone, 0, 2);
		world.setBlock(i + 45, j + 16, k + 41, BlocksAether.caelestia_stone, 0, 2);
		world.setBlock(i + 46, j + 16, k + 41, BlocksAether.caelestia_stone, 0, 2);
		world.setBlock(i + 47, j + 16, k + 41, BlocksAether.caelestia_stone, 0, 2);
		world.setBlock(i + 48, j + 16, k + 41, BlocksAether.caelestia_stone, 0, 2);
		world.setBlock(i + 49, j + 16, k + 41, BlocksAether.caelestia_stone, 0, 2);
		world.setBlock(i + 50, j + 16, k + 41, BlocksAether.caelestia_stone, 0, 2);
		world.setBlock(i + 51, j + 16, k + 41, BlocksAether.caelestia_stone, 0, 2);
		world.setBlock(i + 52, j + 16, k + 41, BlocksAether.caelestia_stone, 0, 2);
		world.setBlock(i + 27, j + 16, k + 42, BlocksAether.caelestia_stone, 0, 2);
		world.setBlock(i + 28, j + 16, k + 42, BlocksAether.caelestia_stone, 0, 2);
		world.setBlock(i + 29, j + 16, k + 42, BlocksAether.caelestia_stone, 0, 2);
		world.setBlock(i + 30, j + 16, k + 42, BlocksAether.caelestia_stone, 0, 2);
		world.setBlock(i + 31, j + 16, k + 42, BlocksAether.caelestia_stone, 0, 2);
		world.setBlock(i + 32, j + 16, k + 42, BlocksAether.caelestia_stone, 0, 2);
		world.setBlock(i + 33, j + 16, k + 42, BlocksAether.caelestia_stone, 0, 2);
		world.setBlock(i + 34, j + 16, k + 42, BlocksAether.caelestia_stone, 0, 2);
		world.setBlock(i + 35, j + 16, k + 42, BlocksAether.caelestia_stone, 0, 2);
		world.setBlock(i + 36, j + 16, k + 42, BlocksAether.caelestia_stone, 0, 2);
		world.setBlock(i + 37, j + 16, k + 42, BlocksAether.caelestia_stone, 0, 2);
		world.setBlock(i + 38, j + 16, k + 42, BlocksAether.caelestia_stone, 0, 2);
		world.setBlock(i + 39, j + 16, k + 42, BlocksAether.caelestia_stone, 0, 2);
		world.setBlock(i + 40, j + 16, k + 42, BlocksAether.caelestia_stone, 0, 2);
		world.setBlock(i + 41, j + 16, k + 42, BlocksAether.caelestia_stone, 0, 2);
		world.setBlock(i + 42, j + 16, k + 42, BlocksAether.caelestia_stone, 0, 2);
		world.setBlock(i + 43, j + 16, k + 42, BlocksAether.caelestia_stone, 0, 2);
		world.setBlock(i + 44, j + 16, k + 42, BlocksAether.caelestia_stone, 0, 2);
		world.setBlock(i + 45, j + 16, k + 42, BlocksAether.caelestia_stone, 0, 2);
		world.setBlock(i + 46, j + 16, k + 42, BlocksAether.caelestia_stone, 0, 2);
		world.setBlock(i + 47, j + 16, k + 42, BlocksAether.caelestia_stone, 0, 2);
		world.setBlock(i + 48, j + 16, k + 42, BlocksAether.caelestia_stone, 0, 2);
		world.setBlock(i + 49, j + 16, k + 42, BlocksAether.caelestia_stone, 0, 2);
		world.setBlock(i + 50, j + 16, k + 42, BlocksAether.caelestia_stone, 0, 2);
		world.setBlock(i + 51, j + 16, k + 42, BlocksAether.caelestia_stone, 0, 2);
		world.setBlock(i + 28, j + 16, k + 43, BlocksAether.caelestia_stone, 0, 2);
		world.setBlock(i + 29, j + 16, k + 43, BlocksAether.caelestia_stone, 0, 2);
		world.setBlock(i + 30, j + 16, k + 43, BlocksAether.caelestia_stone, 0, 2);
		world.setBlock(i + 31, j + 16, k + 43, BlocksAether.caelestia_stone, 0, 2);
		world.setBlock(i + 32, j + 16, k + 43, BlocksAether.caelestia_stone, 0, 2);
		world.setBlock(i + 33, j + 16, k + 43, BlocksAether.caelestia_stone, 0, 2);
		world.setBlock(i + 34, j + 16, k + 43, BlocksAether.caelestia_stone, 0, 2);
		world.setBlock(i + 35, j + 16, k + 43, BlocksAether.caelestia_stone, 0, 2);
		world.setBlock(i + 36, j + 16, k + 43, BlocksAether.caelestia_stone, 0, 2);
		world.setBlock(i + 37, j + 16, k + 43, BlocksAether.caelestia_stone, 0, 2);
		world.setBlock(i + 38, j + 16, k + 43, BlocksAether.caelestia_stone, 0, 2);
		world.setBlock(i + 39, j + 16, k + 43, BlocksAether.caelestia_stone, 0, 2);
		world.setBlock(i + 40, j + 16, k + 43, BlocksAether.caelestia_stone, 0, 2);
		world.setBlock(i + 41, j + 16, k + 43, BlocksAether.caelestia_stone, 0, 2);
		world.setBlock(i + 42, j + 16, k + 43, BlocksAether.caelestia_stone, 0, 2);
		world.setBlock(i + 43, j + 16, k + 43, BlocksAether.caelestia_stone, 0, 2);
		world.setBlock(i + 44, j + 16, k + 43, BlocksAether.caelestia_stone, 0, 2);
		world.setBlock(i + 45, j + 16, k + 43, BlocksAether.caelestia_stone, 0, 2);
		world.setBlock(i + 46, j + 16, k + 43, BlocksAether.caelestia_stone, 0, 2);
		world.setBlock(i + 47, j + 16, k + 43, BlocksAether.caelestia_stone, 0, 2);
		world.setBlock(i + 48, j + 16, k + 43, BlocksAether.caelestia_stone, 0, 2);
		world.setBlock(i + 49, j + 16, k + 43, BlocksAether.caelestia_stone, 0, 2);
		world.setBlock(i + 50, j + 16, k + 43, BlocksAether.caelestia_stone, 0, 2);
		world.setBlock(i + 29, j + 16, k + 44, BlocksAether.caelestia_stone, 0, 2);
		world.setBlock(i + 30, j + 16, k + 44, BlocksAether.caelestia_stone, 0, 2);
		world.setBlock(i + 31, j + 16, k + 44, BlocksAether.caelestia_stone, 0, 2);
		world.setBlock(i + 32, j + 16, k + 44, BlocksAether.caelestia_stone, 0, 2);
		world.setBlock(i + 33, j + 16, k + 44, BlocksAether.caelestia_stone, 0, 2);
		world.setBlock(i + 34, j + 16, k + 44, BlocksAether.caelestia_stone, 0, 2);
		world.setBlock(i + 35, j + 16, k + 44, BlocksAether.caelestia_stone, 0, 2);
		world.setBlock(i + 36, j + 16, k + 44, BlocksAether.caelestia_stone, 0, 2);
		world.setBlock(i + 37, j + 16, k + 44, BlocksAether.caelestia_stone, 0, 2);
		world.setBlock(i + 38, j + 16, k + 44, BlocksAether.caelestia_stone, 0, 2);
		world.setBlock(i + 39, j + 16, k + 44, BlocksAether.caelestia_stone, 0, 2);
		world.setBlock(i + 40, j + 16, k + 44, BlocksAether.caelestia_stone, 0, 2);
		world.setBlock(i + 41, j + 16, k + 44, BlocksAether.caelestia_stone, 0, 2);
		world.setBlock(i + 42, j + 16, k + 44, BlocksAether.caelestia_stone, 0, 2);
		world.setBlock(i + 43, j + 16, k + 44, BlocksAether.caelestia_stone, 0, 2);
		world.setBlock(i + 44, j + 16, k + 44, BlocksAether.caelestia_stone, 0, 2);
		world.setBlock(i + 45, j + 16, k + 44, BlocksAether.caelestia_stone, 0, 2);
		world.setBlock(i + 46, j + 16, k + 44, BlocksAether.caelestia_stone, 0, 2);
		world.setBlock(i + 47, j + 16, k + 44, BlocksAether.caelestia_stone, 0, 2);
		world.setBlock(i + 48, j + 16, k + 44, BlocksAether.caelestia_stone, 0, 2);
		world.setBlock(i + 49, j + 16, k + 44, BlocksAether.caelestia_stone, 0, 2);
		world.setBlock(i + 30, j + 16, k + 45, BlocksAether.caelestia_stone, 0, 2);
		world.setBlock(i + 31, j + 16, k + 45, BlocksAether.caelestia_stone, 0, 2);
		world.setBlock(i + 32, j + 16, k + 45, BlocksAether.caelestia_stone, 0, 2);
		world.setBlock(i + 33, j + 16, k + 45, BlocksAether.caelestia_stone, 0, 2);
		world.setBlock(i + 34, j + 16, k + 45, BlocksAether.caelestia_stone, 0, 2);
		world.setBlock(i + 35, j + 16, k + 45, BlocksAether.caelestia_stone, 0, 2);
		world.setBlock(i + 36, j + 16, k + 45, BlocksAether.caelestia_stone, 0, 2);
		world.setBlock(i + 37, j + 16, k + 45, BlocksAether.caelestia_stone, 0, 2);
		world.setBlock(i + 38, j + 16, k + 45, BlocksAether.caelestia_stone, 0, 2);
		world.setBlock(i + 39, j + 16, k + 45, BlocksAether.caelestia_stone, 0, 2);
		world.setBlock(i + 40, j + 16, k + 45, BlocksAether.caelestia_stone, 0, 2);
		world.setBlock(i + 41, j + 16, k + 45, BlocksAether.caelestia_stone, 0, 2);
		world.setBlock(i + 42, j + 16, k + 45, BlocksAether.caelestia_stone, 0, 2);
		world.setBlock(i + 43, j + 16, k + 45, BlocksAether.caelestia_stone, 0, 2);
		world.setBlock(i + 44, j + 16, k + 45, BlocksAether.caelestia_stone, 0, 2);
		world.setBlock(i + 45, j + 16, k + 45, BlocksAether.caelestia_stone, 0, 2);
		world.setBlock(i + 46, j + 16, k + 45, BlocksAether.caelestia_stone, 0, 2);
		world.setBlock(i + 47, j + 16, k + 45, BlocksAether.caelestia_stone, 0, 2);
		world.setBlock(i + 48, j + 16, k + 45, BlocksAether.caelestia_stone, 0, 2);
		world.setBlock(i + 31, j + 16, k + 46, BlocksAether.caelestia_stone, 0, 2);
		world.setBlock(i + 32, j + 16, k + 46, BlocksAether.caelestia_stone, 0, 2);
		world.setBlock(i + 33, j + 16, k + 46, BlocksAether.caelestia_stone, 0, 2);
		world.setBlock(i + 34, j + 16, k + 46, BlocksAether.caelestia_stone, 0, 2);
		world.setBlock(i + 35, j + 16, k + 46, BlocksAether.caelestia_stone, 0, 2);
		world.setBlock(i + 36, j + 16, k + 46, BlocksAether.caelestia_stone, 0, 2);
		world.setBlock(i + 37, j + 16, k + 46, BlocksAether.caelestia_stone, 0, 2);
		world.setBlock(i + 38, j + 16, k + 46, BlocksAether.caelestia_stone, 0, 2);
		world.setBlock(i + 39, j + 16, k + 46, BlocksAether.caelestia_stone, 0, 2);
		world.setBlock(i + 40, j + 16, k + 46, BlocksAether.caelestia_stone, 0, 2);
		world.setBlock(i + 41, j + 16, k + 46, BlocksAether.caelestia_stone, 0, 2);
		world.setBlock(i + 42, j + 16, k + 46, BlocksAether.caelestia_stone, 0, 2);
		world.setBlock(i + 43, j + 16, k + 46, BlocksAether.caelestia_stone, 0, 2);
		world.setBlock(i + 44, j + 16, k + 46, BlocksAether.caelestia_stone, 0, 2);
		world.setBlock(i + 45, j + 16, k + 46, BlocksAether.caelestia_stone, 0, 2);
		world.setBlock(i + 46, j + 16, k + 46, BlocksAether.caelestia_stone, 0, 2);
		world.setBlock(i + 47, j + 16, k + 46, BlocksAether.caelestia_stone, 0, 2);
		world.setBlock(i + 32, j + 16, k + 47, BlocksAether.caelestia_stone, 0, 2);
		world.setBlock(i + 33, j + 16, k + 47, BlocksAether.caelestia_stone, 0, 2);
		world.setBlock(i + 34, j + 16, k + 47, BlocksAether.caelestia_stone, 0, 2);
		world.setBlock(i + 35, j + 16, k + 47, BlocksAether.caelestia_stone, 0, 2);
		world.setBlock(i + 36, j + 16, k + 47, BlocksAether.caelestia_stone, 0, 2);
		world.setBlock(i + 37, j + 16, k + 47, BlocksAether.caelestia_stone, 0, 2);
		world.setBlock(i + 38, j + 16, k + 47, BlocksAether.caelestia_stone, 0, 2);
		world.setBlock(i + 39, j + 16, k + 47, BlocksAether.caelestia_stone, 0, 2);
		world.setBlock(i + 40, j + 16, k + 47, BlocksAether.caelestia_stone, 0, 2);
		world.setBlock(i + 41, j + 16, k + 47, BlocksAether.caelestia_stone, 0, 2);
		world.setBlock(i + 42, j + 16, k + 47, BlocksAether.caelestia_stone, 0, 2);
		world.setBlock(i + 43, j + 16, k + 47, BlocksAether.caelestia_stone, 0, 2);
		world.setBlock(i + 44, j + 16, k + 47, BlocksAether.caelestia_stone, 0, 2);
		world.setBlock(i + 45, j + 16, k + 47, BlocksAether.caelestia_stone, 0, 2);
		world.setBlock(i + 46, j + 16, k + 47, BlocksAether.caelestia_stone, 0, 2);
		world.setBlock(i + 33, j + 16, k + 48, BlocksAether.caelestia_stone, 0, 2);
		world.setBlock(i + 34, j + 16, k + 48, BlocksAether.caelestia_stone, 0, 2);
		world.setBlock(i + 35, j + 16, k + 48, BlocksAether.caelestia_stone, 0, 2);
		world.setBlock(i + 36, j + 16, k + 48, BlocksAether.caelestia_stone, 0, 2);
		world.setBlock(i + 37, j + 16, k + 48, BlocksAether.caelestia_stone, 0, 2);
		world.setBlock(i + 38, j + 16, k + 48, BlocksAether.caelestia_stone, 0, 2);
		world.setBlock(i + 39, j + 16, k + 48, BlocksAether.caelestia_stone, 0, 2);
		world.setBlock(i + 40, j + 16, k + 48, BlocksAether.caelestia_stone, 0, 2);
		world.setBlock(i + 41, j + 16, k + 48, BlocksAether.caelestia_stone, 0, 2);
		world.setBlock(i + 42, j + 16, k + 48, BlocksAether.caelestia_stone, 0, 2);
		world.setBlock(i + 43, j + 16, k + 48, BlocksAether.caelestia_stone, 0, 2);
		world.setBlock(i + 44, j + 16, k + 48, BlocksAether.caelestia_stone, 0, 2);
		world.setBlock(i + 45, j + 16, k + 48, BlocksAether.caelestia_stone, 0, 2);
		world.setBlock(i + 34, j + 16, k + 49, BlocksAether.caelestia_stone, 0, 2);
		world.setBlock(i + 35, j + 16, k + 49, BlocksAether.caelestia_stone, 0, 2);
		world.setBlock(i + 36, j + 16, k + 49, BlocksAether.caelestia_stone, 0, 2);
		world.setBlock(i + 37, j + 16, k + 49, BlocksAether.caelestia_stone, 0, 2);
		world.setBlock(i + 38, j + 16, k + 49, BlocksAether.caelestia_stone, 0, 2);
		world.setBlock(i + 39, j + 16, k + 49, BlocksAether.caelestia_stone, 0, 2);
		world.setBlock(i + 40, j + 16, k + 49, BlocksAether.caelestia_stone, 0, 2);
		world.setBlock(i + 41, j + 16, k + 49, BlocksAether.caelestia_stone, 0, 2);
		world.setBlock(i + 42, j + 16, k + 49, BlocksAether.caelestia_stone, 0, 2);
		world.setBlock(i + 43, j + 16, k + 49, BlocksAether.caelestia_stone, 0, 2);
		world.setBlock(i + 44, j + 16, k + 49, BlocksAether.caelestia_stone, 0, 2);
		world.setBlock(i + 35, j + 16, k + 50, BlocksAether.caelestia_stone, 0, 2);
		world.setBlock(i + 36, j + 16, k + 50, BlocksAether.caelestia_stone, 0, 2);
		world.setBlock(i + 37, j + 16, k + 50, BlocksAether.caelestia_stone, 0, 2);
		world.setBlock(i + 38, j + 16, k + 50, BlocksAether.caelestia_stone, 0, 2);
		world.setBlock(i + 39, j + 16, k + 50, BlocksAether.caelestia_stone, 0, 2);
		world.setBlock(i + 40, j + 16, k + 50, BlocksAether.caelestia_stone, 0, 2);
		world.setBlock(i + 41, j + 16, k + 50, BlocksAether.caelestia_stone, 0, 2);
		world.setBlock(i + 42, j + 16, k + 50, BlocksAether.caelestia_stone, 0, 2);
		world.setBlock(i + 43, j + 16, k + 50, BlocksAether.caelestia_stone, 0, 2);
		world.setBlock(i + 36, j + 16, k + 51, BlocksAether.caelestia_stone, 0, 2);
		world.setBlock(i + 37, j + 16, k + 51, BlocksAether.caelestia_stone, 0, 2);
		world.setBlock(i + 38, j + 16, k + 51, BlocksAether.caelestia_stone, 0, 2);
		world.setBlock(i + 39, j + 16, k + 51, BlocksAether.caelestia_stone, 0, 2);
		world.setBlock(i + 40, j + 16, k + 51, BlocksAether.caelestia_stone, 0, 2);
		world.setBlock(i + 41, j + 16, k + 51, BlocksAether.caelestia_stone, 0, 2);
		world.setBlock(i + 42, j + 16, k + 51, BlocksAether.caelestia_stone, 0, 2);
		world.setBlock(i + 37, j + 16, k + 52, BlocksAether.caelestia_stone, 0, 2);
		world.setBlock(i + 38, j + 16, k + 52, BlocksAether.caelestia_stone, 0, 2);
		world.setBlock(i + 39, j + 16, k + 52, BlocksAether.caelestia_stone, 0, 2);
		world.setBlock(i + 40, j + 16, k + 52, BlocksAether.caelestia_stone, 0, 2);
		world.setBlock(i + 41, j + 16, k + 52, BlocksAether.caelestia_stone, 0, 2);
		world.setBlock(i + 38, j + 16, k + 53, BlocksAether.caelestia_stone, 0, 2);
		world.setBlock(i + 39, j + 16, k + 53, BlocksAether.caelestia_stone, 0, 2);
		world.setBlock(i + 40, j + 16, k + 53, BlocksAether.caelestia_stone, 0, 2);
		world.setBlock(i + 39, j + 16, k + 54, BlocksAether.caelestia_stone, 0, 2);
		world.setBlock(i + 39, j + 17, k + 21, BlocksAether.caelestia_stone, 0, 2);
		world.setBlock(i + 38, j + 17, k + 22, BlocksAether.caelestia_stone, 0, 2);
		world.setBlock(i + 39, j + 17, k + 22, BlocksAether.caelestia_stone, 0, 2);
		world.setBlock(i + 40, j + 17, k + 22, BlocksAether.caelestia_stone, 0, 2);
		world.setBlock(i + 37, j + 17, k + 23, BlocksAether.caelestia_stone, 0, 2);
		world.setBlock(i + 38, j + 17, k + 23, BlocksAether.caelestia_stone, 0, 2);
		world.setBlock(i + 39, j + 17, k + 23, BlocksAether.caelestia_stone, 0, 2);
		world.setBlock(i + 40, j + 17, k + 23, BlocksAether.caelestia_stone, 0, 2);
		world.setBlock(i + 41, j + 17, k + 23, BlocksAether.caelestia_stone, 0, 2);
		world.setBlock(i + 36, j + 17, k + 24, BlocksAether.caelestia_stone, 0, 2);
		world.setBlock(i + 37, j + 17, k + 24, BlocksAether.caelestia_stone, 0, 2);
		world.setBlock(i + 38, j + 17, k + 24, BlocksAether.caelestia_stone, 0, 2);
		world.setBlock(i + 39, j + 17, k + 24, BlocksAether.caelestia_stone, 0, 2);
		world.setBlock(i + 40, j + 17, k + 24, BlocksAether.caelestia_stone, 0, 2);
		world.setBlock(i + 41, j + 17, k + 24, BlocksAether.caelestia_stone, 0, 2);
		world.setBlock(i + 42, j + 17, k + 24, BlocksAether.caelestia_stone, 0, 2);
		world.setBlock(i + 35, j + 17, k + 25, BlocksAether.caelestia_stone, 0, 2);
		world.setBlock(i + 36, j + 17, k + 25, BlocksAether.caelestia_stone, 0, 2);
		world.setBlock(i + 37, j + 17, k + 25, BlocksAether.caelestia_stone, 0, 2);
		world.setBlock(i + 38, j + 17, k + 25, BlocksAether.caelestia_stone, 0, 2);
		world.setBlock(i + 39, j + 17, k + 25, BlocksAether.caelestia_stone, 0, 2);
		world.setBlock(i + 40, j + 17, k + 25, BlocksAether.caelestia_stone, 0, 2);
		world.setBlock(i + 41, j + 17, k + 25, BlocksAether.caelestia_stone, 0, 2);
		world.setBlock(i + 42, j + 17, k + 25, BlocksAether.caelestia_stone, 0, 2);
		world.setBlock(i + 43, j + 17, k + 25, BlocksAether.caelestia_stone, 0, 2);
		world.setBlock(i + 34, j + 17, k + 26, BlocksAether.caelestia_stone, 0, 2);
		world.setBlock(i + 35, j + 17, k + 26, BlocksAether.caelestia_stone, 0, 2);
		world.setBlock(i + 36, j + 17, k + 26, BlocksAether.caelestia_stone, 0, 2);
		world.setBlock(i + 37, j + 17, k + 26, BlocksAether.caelestia_stone, 0, 2);
		world.setBlock(i + 38, j + 17, k + 26, BlocksAether.caelestia_stone, 0, 2);
		world.setBlock(i + 39, j + 17, k + 26, BlocksAether.caelestia_stone, 0, 2);
		world.setBlock(i + 40, j + 17, k + 26, BlocksAether.caelestia_stone, 0, 2);
		world.setBlock(i + 41, j + 17, k + 26, BlocksAether.caelestia_stone, 0, 2);
		world.setBlock(i + 42, j + 17, k + 26, BlocksAether.caelestia_stone, 0, 2);
		world.setBlock(i + 43, j + 17, k + 26, BlocksAether.caelestia_stone, 0, 2);
		world.setBlock(i + 44, j + 17, k + 26, BlocksAether.caelestia_stone, 0, 2);
		world.setBlock(i + 33, j + 17, k + 27, BlocksAether.caelestia_stone, 0, 2);
		world.setBlock(i + 34, j + 17, k + 27, BlocksAether.caelestia_stone, 0, 2);
		world.setBlock(i + 35, j + 17, k + 27, BlocksAether.caelestia_stone, 0, 2);
		world.setBlock(i + 36, j + 17, k + 27, BlocksAether.caelestia_stone, 0, 2);
		world.setBlock(i + 37, j + 17, k + 27, BlocksAether.caelestia_stone, 0, 2);
		world.setBlock(i + 38, j + 17, k + 27, BlocksAether.caelestia_stone, 0, 2);
		world.setBlock(i + 39, j + 17, k + 27, BlocksAether.caelestia_stone, 0, 2);
		world.setBlock(i + 40, j + 17, k + 27, BlocksAether.caelestia_stone, 0, 2);
		world.setBlock(i + 41, j + 17, k + 27, BlocksAether.caelestia_stone, 0, 2);
		world.setBlock(i + 42, j + 17, k + 27, BlocksAether.caelestia_stone, 0, 2);
		world.setBlock(i + 43, j + 17, k + 27, BlocksAether.caelestia_stone, 0, 2);
		world.setBlock(i + 44, j + 17, k + 27, BlocksAether.caelestia_stone, 0, 2);
		world.setBlock(i + 45, j + 17, k + 27, BlocksAether.caelestia_stone, 0, 2);
		world.setBlock(i + 32, j + 17, k + 28, BlocksAether.caelestia_stone, 0, 2);
		world.setBlock(i + 33, j + 17, k + 28, BlocksAether.caelestia_stone, 0, 2);
		world.setBlock(i + 34, j + 17, k + 28, BlocksAether.caelestia_stone, 0, 2);
		world.setBlock(i + 35, j + 17, k + 28, BlocksAether.caelestia_stone, 0, 2);
		world.setBlock(i + 36, j + 17, k + 28, BlocksAether.caelestia_stone, 0, 2);
		world.setBlock(i + 37, j + 17, k + 28, BlocksAether.caelestia_stone, 0, 2);
		world.setBlock(i + 38, j + 17, k + 28, BlocksAether.caelestia_stone, 0, 2);
		world.setBlock(i + 39, j + 17, k + 28, BlocksAether.caelestia_stone, 0, 2);
		world.setBlock(i + 40, j + 17, k + 28, BlocksAether.caelestia_stone, 0, 2);
		world.setBlock(i + 41, j + 17, k + 28, BlocksAether.caelestia_stone, 0, 2);
		world.setBlock(i + 42, j + 17, k + 28, BlocksAether.caelestia_stone, 0, 2);
		world.setBlock(i + 43, j + 17, k + 28, BlocksAether.caelestia_stone, 0, 2);
		world.setBlock(i + 44, j + 17, k + 28, BlocksAether.caelestia_stone, 0, 2);
		world.setBlock(i + 45, j + 17, k + 28, BlocksAether.caelestia_stone, 0, 2);
		world.setBlock(i + 46, j + 17, k + 28, BlocksAether.caelestia_stone, 0, 2);
		world.setBlock(i + 31, j + 17, k + 29, BlocksAether.caelestia_stone, 0, 2);
		world.setBlock(i + 32, j + 17, k + 29, BlocksAether.caelestia_stone, 0, 2);
		world.setBlock(i + 33, j + 17, k + 29, BlocksAether.caelestia_stone, 0, 2);
		world.setBlock(i + 34, j + 17, k + 29, BlocksAether.caelestia_stone, 0, 2);
		world.setBlock(i + 35, j + 17, k + 29, BlocksAether.caelestia_stone, 0, 2);
		world.setBlock(i + 36, j + 17, k + 29, BlocksAether.caelestia_stone, 0, 2);
		world.setBlock(i + 37, j + 17, k + 29, BlocksAether.caelestia_stone, 0, 2);
		world.setBlock(i + 38, j + 17, k + 29, BlocksAether.caelestia_stone, 0, 2);
		world.setBlock(i + 39, j + 17, k + 29, BlocksAether.caelestia_stone, 0, 2);
		world.setBlock(i + 40, j + 17, k + 29, BlocksAether.caelestia_stone, 0, 2);
		world.setBlock(i + 41, j + 17, k + 29, BlocksAether.caelestia_stone, 0, 2);
		world.setBlock(i + 42, j + 17, k + 29, BlocksAether.caelestia_stone, 0, 2);
		world.setBlock(i + 43, j + 17, k + 29, BlocksAether.caelestia_stone, 0, 2);
		world.setBlock(i + 44, j + 17, k + 29, BlocksAether.caelestia_stone, 0, 2);
		world.setBlock(i + 45, j + 17, k + 29, BlocksAether.caelestia_stone, 0, 2);
		world.setBlock(i + 46, j + 17, k + 29, BlocksAether.caelestia_stone, 0, 2);
		world.setBlock(i + 47, j + 17, k + 29, BlocksAether.caelestia_stone, 0, 2);
		world.setBlock(i + 30, j + 17, k + 30, BlocksAether.caelestia_stone, 0, 2);
		world.setBlock(i + 31, j + 17, k + 30, BlocksAether.caelestia_stone, 0, 2);
		world.setBlock(i + 32, j + 17, k + 30, BlocksAether.caelestia_stone, 0, 2);
		world.setBlock(i + 33, j + 17, k + 30, BlocksAether.caelestia_stone, 0, 2);
		world.setBlock(i + 34, j + 17, k + 30, BlocksAether.caelestia_stone, 0, 2);
		world.setBlock(i + 35, j + 17, k + 30, BlocksAether.caelestia_stone, 0, 2);
		world.setBlock(i + 36, j + 17, k + 30, BlocksAether.caelestia_stone, 0, 2);
		world.setBlock(i + 37, j + 17, k + 30, BlocksAether.caelestia_stone, 0, 2);
		world.setBlock(i + 38, j + 17, k + 30, BlocksAether.caelestia_stone, 0, 2);
		world.setBlock(i + 39, j + 17, k + 30, BlocksAether.caelestia_stone, 0, 2);
		world.setBlock(i + 40, j + 17, k + 30, BlocksAether.caelestia_stone, 0, 2);
		world.setBlock(i + 41, j + 17, k + 30, BlocksAether.caelestia_stone, 0, 2);
		world.setBlock(i + 42, j + 17, k + 30, BlocksAether.caelestia_stone, 0, 2);
		world.setBlock(i + 43, j + 17, k + 30, BlocksAether.caelestia_stone, 0, 2);
		world.setBlock(i + 44, j + 17, k + 30, BlocksAether.caelestia_stone, 0, 2);
		world.setBlock(i + 45, j + 17, k + 30, BlocksAether.caelestia_stone, 0, 2);
		world.setBlock(i + 46, j + 17, k + 30, BlocksAether.caelestia_stone, 0, 2);
		world.setBlock(i + 47, j + 17, k + 30, BlocksAether.caelestia_stone, 0, 2);
		world.setBlock(i + 48, j + 17, k + 30, BlocksAether.caelestia_stone, 0, 2);
		world.setBlock(i + 29, j + 17, k + 31, BlocksAether.caelestia_stone, 0, 2);
		world.setBlock(i + 30, j + 17, k + 31, BlocksAether.caelestia_stone, 0, 2);
		world.setBlock(i + 31, j + 17, k + 31, BlocksAether.caelestia_stone, 0, 2);
		world.setBlock(i + 32, j + 17, k + 31, BlocksAether.caelestia_stone, 0, 2);
		world.setBlock(i + 33, j + 17, k + 31, BlocksAether.caelestia_stone, 0, 2);
		world.setBlock(i + 34, j + 17, k + 31, BlocksAether.caelestia_stone, 0, 2);
		world.setBlock(i + 35, j + 17, k + 31, BlocksAether.caelestia_stone, 0, 2);
		world.setBlock(i + 36, j + 17, k + 31, BlocksAether.caelestia_stone, 0, 2);
		world.setBlock(i + 37, j + 17, k + 31, BlocksAether.caelestia_stone, 0, 2);
		world.setBlock(i + 38, j + 17, k + 31, BlocksAether.caelestia_stone, 0, 2);
		world.setBlock(i + 39, j + 17, k + 31, BlocksAether.caelestia_stone, 0, 2);
		world.setBlock(i + 40, j + 17, k + 31, BlocksAether.caelestia_stone, 0, 2);
		world.setBlock(i + 41, j + 17, k + 31, BlocksAether.caelestia_stone, 0, 2);
		world.setBlock(i + 42, j + 17, k + 31, BlocksAether.caelestia_stone, 0, 2);
		world.setBlock(i + 43, j + 17, k + 31, BlocksAether.caelestia_stone, 0, 2);
		world.setBlock(i + 44, j + 17, k + 31, BlocksAether.caelestia_stone, 0, 2);
		world.setBlock(i + 45, j + 17, k + 31, BlocksAether.caelestia_stone, 0, 2);
		world.setBlock(i + 46, j + 17, k + 31, BlocksAether.caelestia_stone, 0, 2);
		world.setBlock(i + 47, j + 17, k + 31, BlocksAether.caelestia_stone, 0, 2);
		world.setBlock(i + 48, j + 17, k + 31, BlocksAether.caelestia_stone, 0, 2);
		world.setBlock(i + 49, j + 17, k + 31, BlocksAether.caelestia_stone, 0, 2);
		world.setBlock(i + 28, j + 17, k + 32, BlocksAether.caelestia_stone, 0, 2);
		world.setBlock(i + 29, j + 17, k + 32, BlocksAether.caelestia_stone, 0, 2);
		world.setBlock(i + 30, j + 17, k + 32, BlocksAether.caelestia_stone, 0, 2);
		world.setBlock(i + 31, j + 17, k + 32, BlocksAether.caelestia_stone, 0, 2);
		world.setBlock(i + 32, j + 17, k + 32, BlocksAether.caelestia_stone, 0, 2);
		world.setBlock(i + 33, j + 17, k + 32, BlocksAether.caelestia_stone, 0, 2);
		world.setBlock(i + 34, j + 17, k + 32, BlocksAether.caelestia_stone, 0, 2);
		world.setBlock(i + 35, j + 17, k + 32, BlocksAether.caelestia_stone, 0, 2);
		world.setBlock(i + 36, j + 17, k + 32, BlocksAether.caelestia_stone, 0, 2);
		world.setBlock(i + 37, j + 17, k + 32, BlocksAether.caelestia_stone, 0, 2);
		world.setBlock(i + 38, j + 17, k + 32, BlocksAether.caelestia_stone, 0, 2);
		world.setBlock(i + 39, j + 17, k + 32, BlocksAether.caelestia_stone, 0, 2);
		world.setBlock(i + 40, j + 17, k + 32, BlocksAether.caelestia_stone, 0, 2);
		world.setBlock(i + 41, j + 17, k + 32, BlocksAether.caelestia_stone, 0, 2);
		world.setBlock(i + 42, j + 17, k + 32, BlocksAether.caelestia_stone, 0, 2);
		world.setBlock(i + 43, j + 17, k + 32, BlocksAether.caelestia_stone, 0, 2);
		world.setBlock(i + 44, j + 17, k + 32, BlocksAether.caelestia_stone, 0, 2);
		world.setBlock(i + 45, j + 17, k + 32, BlocksAether.caelestia_stone, 0, 2);
		world.setBlock(i + 46, j + 17, k + 32, BlocksAether.caelestia_stone, 0, 2);
		world.setBlock(i + 47, j + 17, k + 32, BlocksAether.caelestia_stone, 0, 2);
		world.setBlock(i + 48, j + 17, k + 32, BlocksAether.caelestia_stone, 0, 2);
		world.setBlock(i + 49, j + 17, k + 32, BlocksAether.caelestia_stone, 0, 2);
		world.setBlock(i + 50, j + 17, k + 32, BlocksAether.caelestia_stone, 0, 2);
		world.setBlock(i + 27, j + 17, k + 33, BlocksAether.caelestia_stone, 0, 2);
		world.setBlock(i + 28, j + 17, k + 33, BlocksAether.caelestia_stone, 0, 2);
		world.setBlock(i + 29, j + 17, k + 33, BlocksAether.caelestia_stone, 0, 2);
		world.setBlock(i + 30, j + 17, k + 33, BlocksAether.caelestia_stone, 0, 2);
		world.setBlock(i + 31, j + 17, k + 33, BlocksAether.caelestia_stone, 0, 2);
		world.setBlock(i + 32, j + 17, k + 33, BlocksAether.caelestia_stone, 0, 2);
		world.setBlock(i + 33, j + 17, k + 33, BlocksAether.caelestia_stone, 0, 2);
		world.setBlock(i + 34, j + 17, k + 33, BlocksAether.caelestia_stone, 0, 2);
		world.setBlock(i + 35, j + 17, k + 33, BlocksAether.caelestia_stone, 0, 2);
		world.setBlock(i + 36, j + 17, k + 33, BlocksAether.caelestia_stone, 0, 2);
		world.setBlock(i + 37, j + 17, k + 33, BlocksAether.caelestia_stone, 0, 2);
		world.setBlock(i + 38, j + 17, k + 33, BlocksAether.caelestia_stone, 0, 2);
		world.setBlock(i + 39, j + 17, k + 33, BlocksAether.caelestia_stone, 0, 2);
		world.setBlock(i + 40, j + 17, k + 33, BlocksAether.caelestia_stone, 0, 2);
		world.setBlock(i + 41, j + 17, k + 33, BlocksAether.caelestia_stone, 0, 2);
		world.setBlock(i + 42, j + 17, k + 33, BlocksAether.caelestia_stone, 0, 2);
		world.setBlock(i + 43, j + 17, k + 33, BlocksAether.caelestia_stone, 0, 2);
		world.setBlock(i + 44, j + 17, k + 33, BlocksAether.caelestia_stone, 0, 2);
		world.setBlock(i + 45, j + 17, k + 33, BlocksAether.caelestia_stone, 0, 2);
		world.setBlock(i + 46, j + 17, k + 33, BlocksAether.caelestia_stone, 0, 2);
		world.setBlock(i + 47, j + 17, k + 33, BlocksAether.caelestia_stone, 0, 2);
		world.setBlock(i + 48, j + 17, k + 33, BlocksAether.caelestia_stone, 0, 2);
		world.setBlock(i + 49, j + 17, k + 33, BlocksAether.caelestia_stone, 0, 2);
		world.setBlock(i + 50, j + 17, k + 33, BlocksAether.caelestia_stone, 0, 2);
		world.setBlock(i + 51, j + 17, k + 33, BlocksAether.caelestia_stone, 0, 2);
		world.setBlock(i + 26, j + 17, k + 34, BlocksAether.caelestia_stone, 0, 2);
		world.setBlock(i + 27, j + 17, k + 34, BlocksAether.caelestia_stone, 0, 2);
		world.setBlock(i + 28, j + 17, k + 34, BlocksAether.caelestia_stone, 0, 2);
		world.setBlock(i + 29, j + 17, k + 34, BlocksAether.caelestia_stone, 0, 2);
		world.setBlock(i + 30, j + 17, k + 34, BlocksAether.caelestia_stone, 0, 2);
		world.setBlock(i + 31, j + 17, k + 34, BlocksAether.caelestia_stone, 0, 2);
		world.setBlock(i + 32, j + 17, k + 34, BlocksAether.caelestia_stone, 0, 2);
		world.setBlock(i + 33, j + 17, k + 34, BlocksAether.caelestia_stone, 0, 2);
		world.setBlock(i + 34, j + 17, k + 34, BlocksAether.caelestia_stone, 0, 2);
		world.setBlock(i + 35, j + 17, k + 34, BlocksAether.caelestia_stone, 0, 2);
		world.setBlock(i + 36, j + 17, k + 34, BlocksAether.caelestia_stone, 0, 2);
		world.setBlock(i + 37, j + 17, k + 34, BlocksAether.caelestia_stone, 0, 2);
		world.setBlock(i + 38, j + 17, k + 34, BlocksAether.caelestia_stone, 0, 2);
		world.setBlock(i + 39, j + 17, k + 34, BlocksAether.caelestia_stone, 0, 2);
		world.setBlock(i + 40, j + 17, k + 34, BlocksAether.caelestia_stone, 0, 2);
		world.setBlock(i + 41, j + 17, k + 34, BlocksAether.caelestia_stone, 0, 2);
		world.setBlock(i + 42, j + 17, k + 34, BlocksAether.caelestia_stone, 0, 2);
		world.setBlock(i + 43, j + 17, k + 34, BlocksAether.caelestia_stone, 0, 2);
		world.setBlock(i + 44, j + 17, k + 34, BlocksAether.caelestia_stone, 0, 2);
		world.setBlock(i + 45, j + 17, k + 34, BlocksAether.caelestia_stone, 0, 2);
		world.setBlock(i + 46, j + 17, k + 34, BlocksAether.caelestia_stone, 0, 2);
		world.setBlock(i + 47, j + 17, k + 34, BlocksAether.caelestia_stone, 0, 2);
		world.setBlock(i + 48, j + 17, k + 34, BlocksAether.caelestia_stone, 0, 2);
		world.setBlock(i + 49, j + 17, k + 34, BlocksAether.caelestia_stone, 0, 2);
		world.setBlock(i + 50, j + 17, k + 34, BlocksAether.caelestia_stone, 0, 2);
		world.setBlock(i + 51, j + 17, k + 34, BlocksAether.caelestia_stone, 0, 2);
		world.setBlock(i + 52, j + 17, k + 34, BlocksAether.caelestia_stone, 0, 2);
		world.setBlock(i + 25, j + 17, k + 35, BlocksAether.caelestia_stone, 0, 2);
		world.setBlock(i + 26, j + 17, k + 35, BlocksAether.caelestia_stone, 0, 2);
		world.setBlock(i + 27, j + 17, k + 35, BlocksAether.caelestia_stone, 0, 2);
		world.setBlock(i + 28, j + 17, k + 35, BlocksAether.caelestia_stone, 0, 2);
		world.setBlock(i + 29, j + 17, k + 35, BlocksAether.caelestia_stone, 0, 2);
		world.setBlock(i + 30, j + 17, k + 35, BlocksAether.caelestia_stone, 0, 2);
		world.setBlock(i + 31, j + 17, k + 35, BlocksAether.caelestia_stone, 0, 2);
		world.setBlock(i + 32, j + 17, k + 35, BlocksAether.caelestia_stone, 0, 2);
		world.setBlock(i + 33, j + 17, k + 35, BlocksAether.caelestia_stone, 0, 2);
		world.setBlock(i + 34, j + 17, k + 35, BlocksAether.caelestia_stone, 0, 2);
		world.setBlock(i + 35, j + 17, k + 35, BlocksAether.caelestia_stone, 0, 2);
		world.setBlock(i + 36, j + 17, k + 35, BlocksAether.caelestia_stone, 0, 2);
		world.setBlock(i + 37, j + 17, k + 35, BlocksAether.caelestia_stone, 0, 2);
		world.setBlock(i + 38, j + 17, k + 35, BlocksAether.caelestia_stone, 0, 2);
		world.setBlock(i + 39, j + 17, k + 35, BlocksAether.caelestia_stone, 0, 2);
		world.setBlock(i + 40, j + 17, k + 35, BlocksAether.caelestia_stone, 0, 2);
		world.setBlock(i + 41, j + 17, k + 35, BlocksAether.caelestia_stone, 0, 2);
		world.setBlock(i + 42, j + 17, k + 35, BlocksAether.caelestia_stone, 0, 2);
		world.setBlock(i + 43, j + 17, k + 35, BlocksAether.caelestia_stone, 0, 2);
		world.setBlock(i + 44, j + 17, k + 35, BlocksAether.caelestia_stone, 0, 2);
		world.setBlock(i + 45, j + 17, k + 35, BlocksAether.caelestia_stone, 0, 2);
		world.setBlock(i + 46, j + 17, k + 35, BlocksAether.caelestia_stone, 0, 2);
		world.setBlock(i + 47, j + 17, k + 35, BlocksAether.caelestia_stone, 0, 2);
		world.setBlock(i + 48, j + 17, k + 35, BlocksAether.caelestia_stone, 0, 2);
		world.setBlock(i + 49, j + 17, k + 35, BlocksAether.caelestia_stone, 0, 2);
		world.setBlock(i + 50, j + 17, k + 35, BlocksAether.caelestia_stone, 0, 2);
		world.setBlock(i + 51, j + 17, k + 35, BlocksAether.caelestia_stone, 0, 2);
		world.setBlock(i + 52, j + 17, k + 35, BlocksAether.caelestia_stone, 0, 2);
		world.setBlock(i + 53, j + 17, k + 35, BlocksAether.caelestia_stone, 0, 2);
		world.setBlock(i + 24, j + 17, k + 36, BlocksAether.caelestia_stone, 0, 2);
		world.setBlock(i + 25, j + 17, k + 36, BlocksAether.caelestia_stone, 0, 2);
		world.setBlock(i + 26, j + 17, k + 36, BlocksAether.caelestia_stone, 0, 2);
		world.setBlock(i + 27, j + 17, k + 36, BlocksAether.caelestia_stone, 0, 2);
		world.setBlock(i + 28, j + 17, k + 36, BlocksAether.caelestia_stone, 0, 2);
		world.setBlock(i + 29, j + 17, k + 36, BlocksAether.caelestia_stone, 0, 2);
		world.setBlock(i + 30, j + 17, k + 36, BlocksAether.caelestia_stone, 0, 2);
		world.setBlock(i + 31, j + 17, k + 36, BlocksAether.caelestia_stone, 0, 2);
		world.setBlock(i + 32, j + 17, k + 36, BlocksAether.caelestia_stone, 0, 2);
		world.setBlock(i + 33, j + 17, k + 36, BlocksAether.caelestia_stone, 0, 2);
		world.setBlock(i + 34, j + 17, k + 36, BlocksAether.caelestia_stone, 0, 2);
		world.setBlock(i + 35, j + 17, k + 36, BlocksAether.caelestia_stone, 0, 2);
		world.setBlock(i + 36, j + 17, k + 36, BlocksAether.caelestia_stone, 0, 2);
		world.setBlock(i + 37, j + 17, k + 36, BlocksAether.caelestia_stone, 0, 2);
		world.setBlock(i + 38, j + 17, k + 36, BlocksAether.caelestia_stone, 0, 2);
		world.setBlock(i + 39, j + 17, k + 36, BlocksAether.caelestia_stone, 0, 2);
		world.setBlock(i + 40, j + 17, k + 36, BlocksAether.caelestia_stone, 0, 2);
		world.setBlock(i + 41, j + 17, k + 36, BlocksAether.caelestia_stone, 0, 2);
		world.setBlock(i + 42, j + 17, k + 36, BlocksAether.caelestia_stone, 0, 2);
		world.setBlock(i + 43, j + 17, k + 36, BlocksAether.caelestia_stone, 0, 2);
		world.setBlock(i + 44, j + 17, k + 36, BlocksAether.caelestia_stone, 0, 2);
		world.setBlock(i + 45, j + 17, k + 36, BlocksAether.caelestia_stone, 0, 2);
		world.setBlock(i + 46, j + 17, k + 36, BlocksAether.caelestia_stone, 0, 2);
		world.setBlock(i + 47, j + 17, k + 36, BlocksAether.caelestia_stone, 0, 2);
		world.setBlock(i + 48, j + 17, k + 36, BlocksAether.caelestia_stone, 0, 2);
		world.setBlock(i + 49, j + 17, k + 36, BlocksAether.caelestia_stone, 0, 2);
		world.setBlock(i + 50, j + 17, k + 36, BlocksAether.caelestia_stone, 0, 2);
		world.setBlock(i + 51, j + 17, k + 36, BlocksAether.caelestia_stone, 0, 2);
		world.setBlock(i + 52, j + 17, k + 36, BlocksAether.caelestia_stone, 0, 2);
		world.setBlock(i + 53, j + 17, k + 36, BlocksAether.caelestia_stone, 0, 2);
		world.setBlock(i + 54, j + 17, k + 36, BlocksAether.caelestia_stone, 0, 2);
		world.setBlock(i + 23, j + 17, k + 37, BlocksAether.caelestia_stone, 0, 2);
		world.setBlock(i + 24, j + 17, k + 37, BlocksAether.caelestia_stone, 0, 2);
		world.setBlock(i + 25, j + 17, k + 37, BlocksAether.caelestia_stone, 0, 2);
		world.setBlock(i + 26, j + 17, k + 37, BlocksAether.caelestia_stone, 0, 2);
		world.setBlock(i + 27, j + 17, k + 37, BlocksAether.caelestia_stone, 0, 2);
		world.setBlock(i + 28, j + 17, k + 37, BlocksAether.caelestia_stone, 0, 2);
		world.setBlock(i + 29, j + 17, k + 37, BlocksAether.caelestia_stone, 0, 2);
		world.setBlock(i + 30, j + 17, k + 37, BlocksAether.caelestia_stone, 0, 2);
		world.setBlock(i + 31, j + 17, k + 37, BlocksAether.caelestia_stone, 0, 2);
		world.setBlock(i + 32, j + 17, k + 37, BlocksAether.caelestia_stone, 0, 2);
		world.setBlock(i + 33, j + 17, k + 37, BlocksAether.caelestia_stone, 0, 2);
		world.setBlock(i + 34, j + 17, k + 37, BlocksAether.caelestia_stone, 0, 2);
		world.setBlock(i + 35, j + 17, k + 37, BlocksAether.caelestia_stone, 0, 2);
		world.setBlock(i + 36, j + 17, k + 37, BlocksAether.caelestia_stone, 0, 2);
		world.setBlock(i + 37, j + 17, k + 37, BlocksAether.caelestia_stone, 0, 2);
		world.setBlock(i + 38, j + 17, k + 37, BlocksAether.caelestia_stone, 0, 2);
		world.setBlock(i + 39, j + 17, k + 37, BlocksAether.caelestia_stone, 0, 2);
		world.setBlock(i + 40, j + 17, k + 37, BlocksAether.caelestia_stone, 0, 2);
		world.setBlock(i + 41, j + 17, k + 37, BlocksAether.caelestia_stone, 0, 2);
		world.setBlock(i + 42, j + 17, k + 37, BlocksAether.caelestia_stone, 0, 2);
		world.setBlock(i + 43, j + 17, k + 37, BlocksAether.caelestia_stone, 0, 2);
		world.setBlock(i + 44, j + 17, k + 37, BlocksAether.caelestia_stone, 0, 2);
		world.setBlock(i + 45, j + 17, k + 37, BlocksAether.caelestia_stone, 0, 2);
		world.setBlock(i + 46, j + 17, k + 37, BlocksAether.caelestia_stone, 0, 2);
		world.setBlock(i + 47, j + 17, k + 37, BlocksAether.caelestia_stone, 0, 2);
		world.setBlock(i + 48, j + 17, k + 37, BlocksAether.caelestia_stone, 0, 2);
		world.setBlock(i + 49, j + 17, k + 37, BlocksAether.caelestia_stone, 0, 2);
		world.setBlock(i + 50, j + 17, k + 37, BlocksAether.caelestia_stone, 0, 2);
		world.setBlock(i + 51, j + 17, k + 37, BlocksAether.caelestia_stone, 0, 2);
		world.setBlock(i + 52, j + 17, k + 37, BlocksAether.caelestia_stone, 0, 2);
		world.setBlock(i + 53, j + 17, k + 37, BlocksAether.caelestia_stone, 0, 2);
		world.setBlock(i + 54, j + 17, k + 37, BlocksAether.caelestia_stone, 0, 2);
		world.setBlock(i + 55, j + 17, k + 37, BlocksAether.caelestia_stone, 0, 2);
		world.setBlock(i + 22, j + 17, k + 38, BlocksAether.caelestia_stone, 0, 2);
		world.setBlock(i + 23, j + 17, k + 38, BlocksAether.caelestia_stone, 0, 2);
		world.setBlock(i + 24, j + 17, k + 38, BlocksAether.caelestia_stone, 0, 2);
		world.setBlock(i + 25, j + 17, k + 38, BlocksAether.caelestia_stone, 0, 2);
		world.setBlock(i + 26, j + 17, k + 38, BlocksAether.caelestia_stone, 0, 2);
		world.setBlock(i + 27, j + 17, k + 38, BlocksAether.caelestia_stone, 0, 2);
		world.setBlock(i + 28, j + 17, k + 38, BlocksAether.caelestia_stone, 0, 2);
		world.setBlock(i + 29, j + 17, k + 38, BlocksAether.caelestia_stone, 0, 2);
		world.setBlock(i + 30, j + 17, k + 38, BlocksAether.caelestia_stone, 0, 2);
		world.setBlock(i + 31, j + 17, k + 38, BlocksAether.caelestia_stone, 0, 2);
		world.setBlock(i + 32, j + 17, k + 38, BlocksAether.caelestia_stone, 0, 2);
		world.setBlock(i + 33, j + 17, k + 38, BlocksAether.caelestia_stone, 0, 2);
		world.setBlock(i + 34, j + 17, k + 38, BlocksAether.caelestia_stone, 0, 2);
		world.setBlock(i + 35, j + 17, k + 38, BlocksAether.caelestia_stone, 0, 2);
		world.setBlock(i + 36, j + 17, k + 38, BlocksAether.caelestia_stone, 0, 2);
		world.setBlock(i + 37, j + 17, k + 38, BlocksAether.caelestia_stone, 0, 2);
		world.setBlock(i + 38, j + 17, k + 38, BlocksAether.caelestia_stone, 0, 2);
		world.setBlock(i + 39, j + 17, k + 38, BlocksAether.caelestia_stone, 0, 2);
		world.setBlock(i + 40, j + 17, k + 38, BlocksAether.caelestia_stone, 0, 2);
		world.setBlock(i + 41, j + 17, k + 38, BlocksAether.caelestia_stone, 0, 2);
		world.setBlock(i + 42, j + 17, k + 38, BlocksAether.caelestia_stone, 0, 2);
		world.setBlock(i + 43, j + 17, k + 38, BlocksAether.caelestia_stone, 0, 2);
		world.setBlock(i + 44, j + 17, k + 38, BlocksAether.caelestia_stone, 0, 2);
		world.setBlock(i + 45, j + 17, k + 38, BlocksAether.caelestia_stone, 0, 2);
		world.setBlock(i + 46, j + 17, k + 38, BlocksAether.caelestia_stone, 0, 2);
		world.setBlock(i + 47, j + 17, k + 38, BlocksAether.caelestia_stone, 0, 2);
		world.setBlock(i + 48, j + 17, k + 38, BlocksAether.caelestia_stone, 0, 2);
		world.setBlock(i + 49, j + 17, k + 38, BlocksAether.caelestia_stone, 0, 2);
		world.setBlock(i + 50, j + 17, k + 38, BlocksAether.caelestia_stone, 0, 2);
		world.setBlock(i + 51, j + 17, k + 38, BlocksAether.caelestia_stone, 0, 2);
		world.setBlock(i + 52, j + 17, k + 38, BlocksAether.caelestia_stone, 0, 2);
		world.setBlock(i + 53, j + 17, k + 38, BlocksAether.caelestia_stone, 0, 2);
		world.setBlock(i + 54, j + 17, k + 38, BlocksAether.caelestia_stone, 0, 2);
		world.setBlock(i + 55, j + 17, k + 38, BlocksAether.caelestia_stone, 0, 2);
		world.setBlock(i + 56, j + 17, k + 38, BlocksAether.caelestia_stone, 0, 2);
		world.setBlock(i + 23, j + 17, k + 39, BlocksAether.caelestia_stone, 0, 2);
		world.setBlock(i + 24, j + 17, k + 39, BlocksAether.caelestia_stone, 0, 2);
		world.setBlock(i + 25, j + 17, k + 39, BlocksAether.caelestia_stone, 0, 2);
		world.setBlock(i + 26, j + 17, k + 39, BlocksAether.caelestia_stone, 0, 2);
		world.setBlock(i + 27, j + 17, k + 39, BlocksAether.caelestia_stone, 0, 2);
		world.setBlock(i + 28, j + 17, k + 39, BlocksAether.caelestia_stone, 0, 2);
		world.setBlock(i + 29, j + 17, k + 39, BlocksAether.caelestia_stone, 0, 2);
		world.setBlock(i + 30, j + 17, k + 39, BlocksAether.caelestia_stone, 0, 2);
		world.setBlock(i + 31, j + 17, k + 39, BlocksAether.caelestia_stone, 0, 2);
		world.setBlock(i + 32, j + 17, k + 39, BlocksAether.caelestia_stone, 0, 2);
		world.setBlock(i + 33, j + 17, k + 39, BlocksAether.caelestia_stone, 0, 2);
		world.setBlock(i + 34, j + 17, k + 39, BlocksAether.caelestia_stone, 0, 2);
		world.setBlock(i + 35, j + 17, k + 39, BlocksAether.caelestia_stone, 0, 2);
		world.setBlock(i + 36, j + 17, k + 39, BlocksAether.caelestia_stone, 0, 2);
		world.setBlock(i + 37, j + 17, k + 39, BlocksAether.caelestia_stone, 0, 2);
		world.setBlock(i + 38, j + 17, k + 39, BlocksAether.caelestia_stone, 0, 2);
		world.setBlock(i + 39, j + 17, k + 39, BlocksAether.caelestia_stone, 0, 2);
		world.setBlock(i + 40, j + 17, k + 39, BlocksAether.caelestia_stone, 0, 2);
		world.setBlock(i + 41, j + 17, k + 39, BlocksAether.caelestia_stone, 0, 2);
		world.setBlock(i + 42, j + 17, k + 39, BlocksAether.caelestia_stone, 0, 2);
		world.setBlock(i + 43, j + 17, k + 39, BlocksAether.caelestia_stone, 0, 2);
		world.setBlock(i + 44, j + 17, k + 39, BlocksAether.caelestia_stone, 0, 2);
		world.setBlock(i + 45, j + 17, k + 39, BlocksAether.caelestia_stone, 0, 2);
		world.setBlock(i + 46, j + 17, k + 39, BlocksAether.caelestia_stone, 0, 2);
		world.setBlock(i + 47, j + 17, k + 39, BlocksAether.caelestia_stone, 0, 2);
		world.setBlock(i + 48, j + 17, k + 39, BlocksAether.caelestia_stone, 0, 2);
		world.setBlock(i + 49, j + 17, k + 39, BlocksAether.caelestia_stone, 0, 2);
		world.setBlock(i + 50, j + 17, k + 39, BlocksAether.caelestia_stone, 0, 2);
		world.setBlock(i + 51, j + 17, k + 39, BlocksAether.caelestia_stone, 0, 2);
		world.setBlock(i + 52, j + 17, k + 39, BlocksAether.caelestia_stone, 0, 2);
		world.setBlock(i + 53, j + 17, k + 39, BlocksAether.caelestia_stone, 0, 2);
		world.setBlock(i + 54, j + 17, k + 39, BlocksAether.caelestia_stone, 0, 2);
		world.setBlock(i + 55, j + 17, k + 39, BlocksAether.caelestia_stone, 0, 2);
		world.setBlock(i + 24, j + 17, k + 40, BlocksAether.caelestia_stone, 0, 2);
		world.setBlock(i + 25, j + 17, k + 40, BlocksAether.caelestia_stone, 0, 2);
		world.setBlock(i + 26, j + 17, k + 40, BlocksAether.caelestia_stone, 0, 2);
		world.setBlock(i + 27, j + 17, k + 40, BlocksAether.caelestia_stone, 0, 2);
		world.setBlock(i + 28, j + 17, k + 40, BlocksAether.caelestia_stone, 0, 2);
		world.setBlock(i + 29, j + 17, k + 40, BlocksAether.caelestia_stone, 0, 2);
		world.setBlock(i + 30, j + 17, k + 40, BlocksAether.caelestia_stone, 0, 2);
		world.setBlock(i + 31, j + 17, k + 40, BlocksAether.caelestia_stone, 0, 2);
		world.setBlock(i + 32, j + 17, k + 40, BlocksAether.caelestia_stone, 0, 2);
		world.setBlock(i + 33, j + 17, k + 40, BlocksAether.caelestia_stone, 0, 2);
		world.setBlock(i + 34, j + 17, k + 40, BlocksAether.caelestia_stone, 0, 2);
		world.setBlock(i + 35, j + 17, k + 40, BlocksAether.caelestia_stone, 0, 2);
		world.setBlock(i + 36, j + 17, k + 40, BlocksAether.caelestia_stone, 0, 2);
		world.setBlock(i + 37, j + 17, k + 40, BlocksAether.caelestia_stone, 0, 2);
		world.setBlock(i + 38, j + 17, k + 40, BlocksAether.caelestia_stone, 0, 2);
		world.setBlock(i + 39, j + 17, k + 40, BlocksAether.caelestia_stone, 0, 2);
		world.setBlock(i + 40, j + 17, k + 40, BlocksAether.caelestia_stone, 0, 2);
		world.setBlock(i + 41, j + 17, k + 40, BlocksAether.caelestia_stone, 0, 2);
		world.setBlock(i + 42, j + 17, k + 40, BlocksAether.caelestia_stone, 0, 2);
		world.setBlock(i + 43, j + 17, k + 40, BlocksAether.caelestia_stone, 0, 2);
		world.setBlock(i + 44, j + 17, k + 40, BlocksAether.caelestia_stone, 0, 2);
		world.setBlock(i + 45, j + 17, k + 40, BlocksAether.caelestia_stone, 0, 2);
		world.setBlock(i + 46, j + 17, k + 40, BlocksAether.caelestia_stone, 0, 2);
		world.setBlock(i + 47, j + 17, k + 40, BlocksAether.caelestia_stone, 0, 2);
		world.setBlock(i + 48, j + 17, k + 40, BlocksAether.caelestia_stone, 0, 2);
		world.setBlock(i + 49, j + 17, k + 40, BlocksAether.caelestia_stone, 0, 2);
		world.setBlock(i + 50, j + 17, k + 40, BlocksAether.caelestia_stone, 0, 2);
		world.setBlock(i + 51, j + 17, k + 40, BlocksAether.caelestia_stone, 0, 2);
		world.setBlock(i + 52, j + 17, k + 40, BlocksAether.caelestia_stone, 0, 2);
		world.setBlock(i + 53, j + 17, k + 40, BlocksAether.caelestia_stone, 0, 2);
		world.setBlock(i + 54, j + 17, k + 40, BlocksAether.caelestia_stone, 0, 2);
		world.setBlock(i + 25, j + 17, k + 41, BlocksAether.caelestia_stone, 0, 2);
		world.setBlock(i + 26, j + 17, k + 41, BlocksAether.caelestia_stone, 0, 2);
		world.setBlock(i + 27, j + 17, k + 41, BlocksAether.caelestia_stone, 0, 2);
		world.setBlock(i + 28, j + 17, k + 41, BlocksAether.caelestia_stone, 0, 2);
		world.setBlock(i + 29, j + 17, k + 41, BlocksAether.caelestia_stone, 0, 2);
		world.setBlock(i + 30, j + 17, k + 41, BlocksAether.caelestia_stone, 0, 2);
		world.setBlock(i + 31, j + 17, k + 41, BlocksAether.caelestia_stone, 0, 2);
		world.setBlock(i + 32, j + 17, k + 41, BlocksAether.caelestia_stone, 0, 2);
		world.setBlock(i + 33, j + 17, k + 41, BlocksAether.caelestia_stone, 0, 2);
		world.setBlock(i + 34, j + 17, k + 41, BlocksAether.caelestia_stone, 0, 2);
		world.setBlock(i + 35, j + 17, k + 41, BlocksAether.caelestia_stone, 0, 2);
		world.setBlock(i + 36, j + 17, k + 41, BlocksAether.caelestia_stone, 0, 2);
		world.setBlock(i + 37, j + 17, k + 41, BlocksAether.caelestia_stone, 0, 2);
		world.setBlock(i + 38, j + 17, k + 41, BlocksAether.caelestia_stone, 0, 2);
		world.setBlock(i + 39, j + 17, k + 41, BlocksAether.caelestia_stone, 0, 2);
		world.setBlock(i + 40, j + 17, k + 41, BlocksAether.caelestia_stone, 0, 2);
		world.setBlock(i + 41, j + 17, k + 41, BlocksAether.caelestia_stone, 0, 2);
		world.setBlock(i + 42, j + 17, k + 41, BlocksAether.caelestia_stone, 0, 2);
		world.setBlock(i + 43, j + 17, k + 41, BlocksAether.caelestia_stone, 0, 2);
		world.setBlock(i + 44, j + 17, k + 41, BlocksAether.caelestia_stone, 0, 2);
		world.setBlock(i + 45, j + 17, k + 41, BlocksAether.caelestia_stone, 0, 2);
		world.setBlock(i + 46, j + 17, k + 41, BlocksAether.caelestia_stone, 0, 2);
		world.setBlock(i + 47, j + 17, k + 41, BlocksAether.caelestia_stone, 0, 2);
		world.setBlock(i + 48, j + 17, k + 41, BlocksAether.caelestia_stone, 0, 2);
		world.setBlock(i + 49, j + 17, k + 41, BlocksAether.caelestia_stone, 0, 2);
		world.setBlock(i + 50, j + 17, k + 41, BlocksAether.caelestia_stone, 0, 2);
		world.setBlock(i + 51, j + 17, k + 41, BlocksAether.caelestia_stone, 0, 2);
		world.setBlock(i + 52, j + 17, k + 41, BlocksAether.caelestia_stone, 0, 2);
		world.setBlock(i + 53, j + 17, k + 41, BlocksAether.caelestia_stone, 0, 2);
		world.setBlock(i + 26, j + 17, k + 42, BlocksAether.caelestia_stone, 0, 2);
		world.setBlock(i + 27, j + 17, k + 42, BlocksAether.caelestia_stone, 0, 2);
		world.setBlock(i + 28, j + 17, k + 42, BlocksAether.caelestia_stone, 0, 2);
		world.setBlock(i + 29, j + 17, k + 42, BlocksAether.caelestia_stone, 0, 2);
		world.setBlock(i + 30, j + 17, k + 42, BlocksAether.caelestia_stone, 0, 2);
		world.setBlock(i + 31, j + 17, k + 42, BlocksAether.caelestia_stone, 0, 2);
		world.setBlock(i + 32, j + 17, k + 42, BlocksAether.caelestia_stone, 0, 2);
		world.setBlock(i + 33, j + 17, k + 42, BlocksAether.caelestia_stone, 0, 2);
